Process A (arrival time 9 ms) 16 CPU bursts (tau 100ms)
Process B (arrival time 18 ms) 21 CPU bursts (tau 100ms)

time 0ms: Simulator started for RR with time slice 128ms [Q empty]
time 9ms: Process A arrived; added to ready queue [Q A]
time 11ms: Process A started using the CPU for 56ms burst [Q empty]
time 67ms: Process A completed a CPU burst; 15 bursts to go [Q empty]
time 67ms: Process A switching out of CPU; will block on I/O until time 299ms [Q empty]
time 18ms: Process B arrived; added to ready queue [Q B]
time 71ms: Process B started using the CPU for 106ms burst [Q empty]
time 177ms: Process B completed a CPU burst; 20 bursts to go [Q empty]
time 177ms: Process B switching out of CPU; will block on I/O until time 1739ms [Q empty]
time 299ms: Process A completed I/O; added to ready queue [Q A]
time 301ms: Process A started using the CPU for 60ms burst [Q empty]
time 361ms: Process A completed a CPU burst; 14 bursts to go [Q empty]
time 361ms: Process A switching out of CPU; will block on I/O until time 1893ms [Q empty]
time 1739ms: Process B completed I/O; added to ready queue [Q B]
time 1741ms: Process B started using the CPU for 198ms burst [Q empty]
time 1869ms: Time slice expired; no preemption because ready queue is empty [Q empty]
time 1939ms: Process B completed a CPU burst; 19 bursts to go [Q empty]
time 1939ms: Process B switching out of CPU; will block on I/O until time 3071ms [Q empty]
time 1893ms: Process A completed I/O; added to ready queue [Q A]
time 1897ms: Process A started using the CPU for 39ms burst [Q empty]
time 1936ms: Process A completed a CPU burst; 13 bursts to go [Q empty]
time 1936ms: Process A switching out of CPU; will block on I/O until time 2438ms [Q empty]
time 2438ms: Process A completed I/O; added to ready queue [Q A]
time 2440ms: Process A started using the CPU for 47ms burst [Q empty]
time 2487ms: Process A completed a CPU burst; 12 bursts to go [Q empty]
time 2487ms: Process A switching out of CPU; will block on I/O until time 2509ms [Q empty]
time 2509ms: Process A completed I/O; added to ready queue [Q A]
time 2511ms: Process A started using the CPU for 137ms burst [Q empty]
time 2639ms: Time slice expired; no preemption because ready queue is empty [Q empty]
time 2648ms: Process A completed a CPU burst; 11 bursts to go [Q empty]
time 2648ms: Process A switching out of CPU; will block on I/O until time 2890ms [Q empty]
time 2890ms: Process A completed I/O; added to ready queue [Q A]
time 2892ms: Process A started using the CPU for 64ms burst [Q empty]
time 2956ms: Process A completed a CPU burst; 10 bursts to go [Q empty]
time 2956ms: Process A switching out of CPU; will block on I/O until time 3108ms [Q empty]
time 3071ms: Process B completed I/O; added to ready queue [Q B]
time 3073ms: Process B started using the CPU for 208ms burst [Q empty]
time 3201ms: Time slice expired; no preemption because ready queue is empty [Q empty]
time 3281ms: Process B completed a CPU burst; 18 bursts to go [Q empty]
time 3281ms: Process B switching out of CPU; will block on I/O until time 4903ms [Q empty]
time 3108ms: Process A completed I/O; added to ready queue [Q A]
time 3112ms: Process A started using the CPU for 68ms burst [Q empty]
time 3180ms: Process A completed a CPU burst; 9 bursts to go [Q empty]
time 3180ms: Process A switching out of CPU; will block on I/O until time 3822ms [Q empty]
time 3822ms: Process A completed I/O; added to ready queue [Q A]
time 3824ms: Process A started using the CPU for 113ms burst [Q empty]
time 3937ms: Process A completed a CPU burst; 8 bursts to go [Q empty]
time 3937ms: Process A switching out of CPU; will block on I/O until time 4099ms [Q empty]
time 4099ms: Process A completed I/O; added to ready queue [Q A]
time 4101ms: Process A started using the CPU for 11ms burst [Q empty]
time 4112ms: Process A completed a CPU burst; 7 bursts to go [Q empty]
time 4112ms: Process A switching out of CPU; will block on I/O until time 5734ms [Q empty]
time 4903ms: Process B completed I/O; added to ready queue [Q B]
time 4905ms: Process B started using the CPU for 50ms burst [Q empty]
time 4955ms: Process B completed a CPU burst; 17 bursts to go [Q empty]
time 4955ms: Process B switching out of CPU; will block on I/O until time 5417ms [Q empty]
time 5417ms: Process B completed I/O; added to ready queue [Q B]
time 5419ms: Process B started using the CPU for 82ms burst [Q empty]
time 5501ms: Process B completed a CPU burst; 16 bursts to go [Q empty]
time 5501ms: Process B switching out of CPU; will block on I/O until time 5663ms [Q empty]
time 5663ms: Process B completed I/O; added to ready queue [Q B]
time 5665ms: Process B started using the CPU for 7ms burst [Q empty]
time 5672ms: Process B completed a CPU burst; 15 bursts to go [Q empty]
time 5672ms: Process B switching out of CPU; will block on I/O until time 5974ms [Q empty]
time 5734ms: Process A completed I/O; added to ready queue [Q A]
time 5736ms: Process A started using the CPU for 24ms burst [Q empty]
time 5760ms: Process A completed a CPU burst; 6 bursts to go [Q empty]
time 5760ms: Process A switching out of CPU; will block on I/O until time 6932ms [Q empty]
time 5974ms: Process B completed I/O; added to ready queue [Q B]
time 5976ms: Process B started using the CPU for 52ms burst [Q empty]
time 6028ms: Process B completed a CPU burst; 14 bursts to go [Q empty]
time 6028ms: Process B switching out of CPU; will block on I/O until time 6150ms [Q empty]
time 6150ms: Process B completed I/O; added to ready queue [Q B]
time 6152ms: Process B started using the CPU for 228ms burst [Q empty]
time 6280ms: Time slice expired; no preemption because ready queue is empty [Q empty]
time 6380ms: Process B completed a CPU burst; 13 bursts to go [Q empty]
time 6380ms: Process B switching out of CPU; will block on I/O until time 7152ms [Q empty]
time 6932ms: Process A completed I/O; added to ready queue [Q A]
time 6934ms: Process A started using the CPU for 76ms burst [Q empty]
time 7010ms: Process A completed a CPU burst; 5 bursts to go [Q empty]
time 7010ms: Process A switching out of CPU; will block on I/O until time 7292ms [Q empty]
time 7152ms: Process B completed I/O; added to ready queue [Q B]
time 7154ms: Process B started using the CPU for 138ms burst [Q empty]
time 7282ms: Time slice expired; no preemption because ready queue is empty [Q empty]
time 7292ms: Process B completed a CPU burst; 12 bursts to go [Q empty]
time 7292ms: Process B switching out of CPU; will block on I/O until time 8114ms [Q empty]
time 7292ms: Process A completed I/O; added to ready queue [Q A]
time 7294ms: Process A started using the CPU for 122ms burst [Q empty]
time 7416ms: Process A completed a CPU burst; 4 bursts to go [Q empty]
time 7416ms: Process A switching out of CPU; will block on I/O until time 7748ms [Q empty]
time 7748ms: Process A completed I/O; added to ready queue [Q A]
time 7750ms: Process A started using the CPU for 9ms burst [Q empty]
time 7759ms: Process A completed a CPU burst; 3 bursts to go [Q empty]
time 7759ms: Process A switching out of CPU; will block on I/O until time 8441ms [Q empty]
time 8114ms: Process B completed I/O; added to ready queue [Q B]
time 8116ms: Process B started using the CPU for 67ms burst [Q empty]
time 8183ms: Process B completed a CPU burst; 11 bursts to go [Q empty]
time 8183ms: Process B switching out of CPU; will block on I/O until time 8255ms [Q empty]
time 8255ms: Process B completed I/O; added to ready queue [Q B]
time 8257ms: Process B started using the CPU for 120ms burst [Q empty]
time 8377ms: Process B completed a CPU burst; 10 bursts to go [Q empty]
time 8377ms: Process B switching out of CPU; will block on I/O until time 8509ms [Q empty]
time 8441ms: Process A completed I/O; added to ready queue [Q A]
time 8443ms: Process A started using the CPU for 62ms burst [Q empty]
time 8505ms: Process A completed a CPU burst; 2 bursts to go [Q empty]
time 8505ms: Process A switching out of CPU; will block on I/O until time 9277ms [Q empty]
time 8509ms: Process B completed I/O; added to ready queue [Q B]
time 8511ms: Process B started using the CPU for 49ms burst [Q empty]
time 8560ms: Process B completed a CPU burst; 9 bursts to go [Q empty]
time 8560ms: Process B switching out of CPU; will block on I/O until time 8982ms [Q empty]
time 8982ms: Process B completed I/O; added to ready queue [Q B]
time 8984ms: Process B started using the CPU for 134ms burst [Q empty]
time 9112ms: Time slice expired; no preemption because ready queue is empty [Q empty]
time 9118ms: Process B completed a CPU burst; 8 bursts to go [Q empty]
time 9118ms: Process B switching out of CPU; will block on I/O until time 9440ms [Q empty]
time 9277ms: Process A completed I/O; added to ready queue [Q A]
time 9279ms: Process A started using the CPU for 200ms burst [Q empty]
time 9407ms: Time slice expired; no preemption because ready queue is empty [Q empty]
time 9479ms: Process A completed a CPU burst; 1 burst to go [Q empty]
time 9479ms: Process A switching out of CPU; will block on I/O until time 9591ms [Q empty]
time 9440ms: Process B completed I/O; added to ready queue [Q B]
time 9444ms: Process B started using the CPU for 144ms burst [Q empty]
time 9572ms: Time slice expired; no preemption because ready queue is empty [Q empty]
time 9588ms: Process B completed a CPU burst; 7 bursts to go [Q empty]
time 9588ms: Process B switching out of CPU; will block on I/O until time 10380ms [Q empty]
time 9591ms: Process A completed I/O; added to ready queue [Q A]
time 9593ms: Process A started using the CPU for 197ms burst [Q empty]
time 9721ms: Time slice expired; no preemption because ready queue is empty [Q empty]
time 9790ms: Process A terminated [Q empty]
time 10380ms: Process B completed I/O; added to ready queue [Q B]
time 10382ms: Process B started using the CPU for 183ms burst [Q empty]
time 10510ms: Time slice expired; no preemption because ready queue is empty [Q empty]
time 10565ms: Process B completed a CPU burst; 6 bursts to go [Q empty]
time 10565ms: Process B switching out of CPU; will block on I/O until time 10627ms [Q empty]
time 10627ms: Process B completed I/O; added to ready queue [Q B]
time 10629ms: Process B started using the CPU for 219ms burst [Q empty]
time 10757ms: Time slice expired; no preemption because ready queue is empty [Q empty]
time 10848ms: Process B completed a CPU burst; 5 bursts to go [Q empty]
time 10848ms: Process B switching out of CPU; will block on I/O until time 11080ms [Q empty]
time 11080ms: Process B completed I/O; added to ready queue [Q B]
time 11082ms: Process B started using the CPU for 64ms burst [Q empty]
time 11146ms: Process B completed a CPU burst; 4 bursts to go [Q empty]
time 11146ms: Process B switching out of CPU; will block on I/O until time 11948ms [Q empty]
time 11948ms: Process B completed I/O; added to ready queue [Q B]
time 11950ms: Process B started using the CPU for 33ms burst [Q empty]
time 11983ms: Process B completed a CPU burst; 3 bursts to go [Q empty]
time 11983ms: Process B switching out of CPU; will block on I/O until time 12725ms [Q empty]
time 12725ms: Process B completed I/O; added to ready queue [Q B]
time 12727ms: Process B started using the CPU for 63ms burst [Q empty]
time 12790ms: Process B completed a CPU burst; 2 bursts to go [Q empty]
time 12790ms: Process B switching out of CPU; will block on I/O until time 15102ms [Q empty]
time 15102ms: Process B completed I/O; added to ready queue [Q B]
time 15104ms: Process B started using the CPU for 170ms burst [Q empty]
time 15232ms: Time slice expired; no preemption because ready queue is empty [Q empty]
time 15274ms: Process B completed a CPU burst; 1 burst to go [Q empty]
time 15274ms: Process B switching out of CPU; will block on I/O until time 15846ms [Q empty]
time 15846ms: Process B completed I/O; added to ready queue [Q B]
time 15848ms: Process B started using the CPU for 212ms burst [Q empty]
time 15976ms: Time slice expired; no preemption because ready queue is empty [Q empty]
time 16060ms: Process B terminated [Q empty]
time 16062ms: Simulator ended for RR [Q empty]
