Process A (arrival time 9 ms) 16 CPU bursts (tau 100ms)
Process B (arrival time 18 ms) 21 CPU bursts (tau 100ms)
Process C (arrival time 42 ms) 4 CPU bursts (tau 100ms)
Process D (arrival time 156 ms) 11 CPU bursts (tau 100ms)
Process E (arrival time 134 ms) 55 CPU bursts (tau 100ms)
Process F (arrival time 106 ms) 34 CPU bursts (tau 100ms)
Process G (arrival time 65 ms) 80 CPU bursts (tau 100ms)
Process H (arrival time 11 ms) 83 CPU bursts (tau 100ms)
Process I (arrival time 68 ms) 77 CPU bursts (tau 100ms)
Process J (arrival time 0 ms) 10 CPU bursts (tau 100ms)
Process K (arrival time 7 ms) 13 CPU bursts (tau 100ms)
Process L (arrival time 189 ms) 7 CPU bursts (tau 100ms)
Process M (arrival time 16 ms) 48 CPU bursts (tau 100ms)
Process N (arrival time 122 ms) 31 CPU bursts (tau 100ms)
Process O (arrival time 29 ms) 31 CPU bursts (tau 100ms)
Process P (arrival time 159 ms) 16 CPU bursts (tau 100ms)

time 0ms: Simulator started for SJF [Q empty]
time 0ms: Process J (tau 100ms) arrived; added to ready queue [Q J]
time 2ms: Process J (tau 100ms) started using the CPU for 40ms burst [Q empty]
time 7ms: Process K (tau 100ms) arrived; added to ready queue [Q K]
time 9ms: Process A (tau 100ms) arrived; added to ready queue [Q AK]
time 11ms: Process H (tau 100ms) arrived; added to ready queue [Q AHK]
time 16ms: Process M (tau 100ms) arrived; added to ready queue [Q AHKM]
time 18ms: Process B (tau 100ms) arrived; added to ready queue [Q ABHKM]
time 29ms: Process O (tau 100ms) arrived; added to ready queue [Q ABHKMO]
time 42ms: Process J (tau 100ms) completed a CPU burst; 9 bursts to go [Q ABHKMO]
time 42ms: Recalculated tau from 100ms to 55ms for process J [Q ABHKMO]
time 42ms: Process J switching out of CPU; will block on I/O until time 74ms [Q ABHKMO]
time 42ms: Process C (tau 100ms) arrived; added to ready queue [Q ABCHKMO]
time 46ms: Process A (tau 100ms) started using the CPU for 56ms burst [Q BCHKMO]
time 65ms: Process G (tau 100ms) arrived; added to ready queue [Q BCGHKMO]
time 68ms: Process I (tau 100ms) arrived; added to ready queue [Q BCGHIKMO]
time 74ms: Process J (tau 55ms) completed I/O; added to ready queue [Q JBCGHIKMO]
time 102ms: Process A (tau 100ms) completed a CPU burst; 15 bursts to go [Q JBCGHIKMO]
time 102ms: Recalculated tau from 100ms to 67ms for process A [Q JBCGHIKMO]
time 102ms: Process A switching out of CPU; will block on I/O until time 334ms [Q JBCGHIKMO]
time 106ms: Process J (tau 55ms) started using the CPU for 204ms burst [Q BCGHIKMO]
time 106ms: Process F (tau 100ms) arrived; added to ready queue [Q BCFGHIKMO]
time 122ms: Process N (tau 100ms) arrived; added to ready queue [Q BCFGHIKMNO]
time 134ms: Process E (tau 100ms) arrived; added to ready queue [Q BCEFGHIKMNO]
time 156ms: Process D (tau 100ms) arrived; added to ready queue [Q BCDEFGHIKMNO]
time 159ms: Process P (tau 100ms) arrived; added to ready queue [Q BCDEFGHIKMNOP]
time 189ms: Process L (tau 100ms) arrived; added to ready queue [Q BCDEFGHIKLMNOP]
time 310ms: Process J (tau 55ms) completed a CPU burst; 8 bursts to go [Q BCDEFGHIKLMNOP]
time 310ms: Recalculated tau from 55ms to 167ms for process J [Q BCDEFGHIKLMNOP]
time 310ms: Process J switching out of CPU; will block on I/O until time 1012ms [Q BCDEFGHIKLMNOP]
time 314ms: Process B (tau 100ms) started using the CPU for 106ms burst [Q CDEFGHIKLMNOP]
time 334ms: Process A (tau 67ms) completed I/O; added to ready queue [Q ACDEFGHIKLMNOP]
time 420ms: Process B (tau 100ms) completed a CPU burst; 20 bursts to go [Q ACDEFGHIKLMNOP]
time 420ms: Recalculated tau from 100ms to 105ms for process B [Q ACDEFGHIKLMNOP]
time 420ms: Process B switching out of CPU; will block on I/O until time 1982ms [Q ACDEFGHIKLMNOP]
time 424ms: Process A (tau 67ms) started using the CPU for 60ms burst [Q CDEFGHIKLMNOP]
time 484ms: Process A (tau 67ms) completed a CPU burst; 14 bursts to go [Q CDEFGHIKLMNOP]
time 484ms: Recalculated tau from 67ms to 62ms for process A [Q CDEFGHIKLMNOP]
time 484ms: Process A switching out of CPU; will block on I/O until time 2016ms [Q CDEFGHIKLMNOP]
time 488ms: Process C (tau 100ms) started using the CPU for 94ms burst [Q DEFGHIKLMNOP]
time 582ms: Process C (tau 100ms) completed a CPU burst; 3 bursts to go [Q DEFGHIKLMNOP]
time 582ms: Recalculated tau from 100ms to 96ms for process C [Q DEFGHIKLMNOP]
time 582ms: Process C switching out of CPU; will block on I/O until time 2164ms [Q DEFGHIKLMNOP]
time 586ms: Process D (tau 100ms) started using the CPU for 148ms burst [Q EFGHIKLMNOP]
time 734ms: Process D (tau 100ms) completed a CPU burst; 10 bursts to go [Q EFGHIKLMNOP]
time 734ms: Recalculated tau from 100ms to 136ms for process D [Q EFGHIKLMNOP]
time 734ms: Process D switching out of CPU; will block on I/O until time 756ms [Q EFGHIKLMNOP]
time 738ms: Process E (tau 100ms) started using the CPU for 152ms burst [Q FGHIKLMNOP]
time 756ms: Process D (tau 136ms) completed I/O; added to ready queue [Q FGHIKLMNOPD]
time 890ms: Process E (tau 100ms) completed a CPU burst; 54 bursts to go [Q FGHIKLMNOPD]
time 890ms: Recalculated tau from 100ms to 139ms for process E [Q FGHIKLMNOPD]
time 890ms: Process E switching out of CPU; will block on I/O until time 1352ms [Q FGHIKLMNOPD]
time 894ms: Process F (tau 100ms) started using the CPU for 129ms burst [Q GHIKLMNOPD]
time 1012ms: Process J (tau 167ms) completed I/O; added to ready queue [Q GHIKLMNOPDJ]
time 1023ms: Process F (tau 100ms) completed a CPU burst; 33 bursts to go [Q GHIKLMNOPDJ]
time 1023ms: Recalculated tau from 100ms to 122ms for process F [Q GHIKLMNOPDJ]
time 1023ms: Process F switching out of CPU; will block on I/O until time 1595ms [Q GHIKLMNOPDJ]
time 1027ms: Process G (tau 100ms) started using the CPU for 70ms burst [Q HIKLMNOPDJ]
time 1097ms: Process G (tau 100ms) completed a CPU burst; 79 bursts to go [Q HIKLMNOPDJ]
time 1097ms: Recalculated tau from 100ms to 78ms for process G [Q HIKLMNOPDJ]
time 1097ms: Process G switching out of CPU; will block on I/O until time 1409ms [Q HIKLMNOPDJ]
time 1101ms: Process H (tau 100ms) started using the CPU for 96ms burst [Q IKLMNOPDJ]
time 1197ms: Process H (tau 100ms) completed a CPU burst; 82 bursts to go [Q IKLMNOPDJ]
time 1197ms: Recalculated tau from 100ms to 97ms for process H [Q IKLMNOPDJ]
time 1197ms: Process H switching out of CPU; will block on I/O until time 1869ms [Q IKLMNOPDJ]
time 1201ms: Process I (tau 100ms) started using the CPU for 220ms burst [Q KLMNOPDJ]
time 1352ms: Process E (tau 139ms) completed I/O; added to ready queue [Q KLMNOPDEJ]
time 1409ms: Process G (tau 78ms) completed I/O; added to ready queue [Q GKLMNOPDEJ]
time 1421ms: Process I (tau 100ms) completed a CPU burst; 76 bursts to go [Q GKLMNOPDEJ]
time 1421ms: Recalculated tau from 100ms to 190ms for process I [Q GKLMNOPDEJ]
time 1421ms: Process I switching out of CPU; will block on I/O until time 1613ms [Q GKLMNOPDEJ]
time 1425ms: Process G (tau 78ms) started using the CPU for 40ms burst [Q KLMNOPDEJ]
time 1465ms: Process G (tau 78ms) completed a CPU burst; 78 bursts to go [Q KLMNOPDEJ]
time 1465ms: Recalculated tau from 78ms to 50ms for process G [Q KLMNOPDEJ]
time 1465ms: Process G switching out of CPU; will block on I/O until time 1527ms [Q KLMNOPDEJ]
time 1469ms: Process K (tau 100ms) started using the CPU for 64ms burst [Q LMNOPDEJ]
time 1527ms: Process G (tau 50ms) completed I/O; added to ready queue [Q GLMNOPDEJ]
time 1533ms: Process K (tau 100ms) completed a CPU burst; 12 bursts to go [Q GLMNOPDEJ]
time 1533ms: Recalculated tau from 100ms to 73ms for process K [Q GLMNOPDEJ]
time 1533ms: Process K switching out of CPU; will block on I/O until time 2495ms [Q GLMNOPDEJ]
time 1537ms: Process G (tau 50ms) started using the CPU for 65ms burst [Q LMNOPDEJ]
time 1595ms: Process F (tau 122ms) completed I/O; added to ready queue [Q LMNOPFDEJ]
time 1602ms: Process G (tau 50ms) completed a CPU burst; 77 bursts to go [Q LMNOPFDEJ]
time 1602ms: Recalculated tau from 50ms to 62ms for process G [Q LMNOPFDEJ]
time 1602ms: Process G switching out of CPU; will block on I/O until time 2044ms [Q LMNOPFDEJ]
time 1606ms: Process L (tau 100ms) started using the CPU for 135ms burst [Q MNOPFDEJ]
time 1613ms: Process I (tau 190ms) completed I/O; added to ready queue [Q MNOPFDEJI]
time 1741ms: Process L (tau 100ms) completed a CPU burst; 6 bursts to go [Q MNOPFDEJI]
time 1741ms: Recalculated tau from 100ms to 127ms for process L [Q MNOPFDEJI]
time 1741ms: Process L switching out of CPU; will block on I/O until time 2483ms [Q MNOPFDEJI]
time 1745ms: Process M (tau 100ms) started using the CPU for 22ms burst [Q NOPFDEJI]
time 1767ms: Process M (tau 100ms) completed a CPU burst; 47 bursts to go [Q NOPFDEJI]
time 1767ms: Recalculated tau from 100ms to 42ms for process M [Q NOPFDEJI]
time 1767ms: Process M switching out of CPU; will block on I/O until time 1939ms [Q NOPFDEJI]
time 1771ms: Process N (tau 100ms) started using the CPU for 213ms burst [Q OPFDEJI]
time 1869ms: Process H (tau 97ms) completed I/O; added to ready queue [Q HOPFDEJI]
time 1939ms: Process M (tau 42ms) completed I/O; added to ready queue [Q MHOPFDEJI]
time 1982ms: Process B (tau 105ms) completed I/O; added to ready queue [Q MHOPBFDEJI]
time 1984ms: Process N (tau 100ms) completed a CPU burst; 30 bursts to go [Q MHOPBFDEJI]
time 1984ms: Recalculated tau from 100ms to 185ms for process N [Q MHOPBFDEJI]
time 1984ms: Process N switching out of CPU; will block on I/O until time 2136ms [Q MHOPBFDEJI]
time 1988ms: Process M (tau 42ms) started using the CPU for 93ms burst [Q HOPBFDEJI]
time 2016ms: Process A (tau 62ms) completed I/O; added to ready queue [Q AHOPBFDEJI]
time 2044ms: Process G (tau 62ms) completed I/O; added to ready queue [Q AGHOPBFDEJI]
time 2081ms: Process M (tau 42ms) completed a CPU burst; 46 bursts to go [Q AGHOPBFDEJI]
time 2081ms: Recalculated tau from 42ms to 81ms for process M [Q AGHOPBFDEJI]
time 2081ms: Process M switching out of CPU; will block on I/O until time 2503ms [Q AGHOPBFDEJI]
time 2085ms: Process A (tau 62ms) started using the CPU for 39ms burst [Q GHOPBFDEJI]
time 2124ms: Process A (tau 62ms) completed a CPU burst; 13 bursts to go [Q GHOPBFDEJI]
time 2124ms: Recalculated tau from 62ms to 45ms for process A [Q GHOPBFDEJI]
time 2124ms: Process A switching out of CPU; will block on I/O until time 2626ms [Q GHOPBFDEJI]
time 2128ms: Process G (tau 62ms) started using the CPU for 13ms burst [Q HOPBFDEJI]
time 2136ms: Process N (tau 185ms) completed I/O; added to ready queue [Q HOPBFDEJNI]
time 2141ms: Process G (tau 62ms) completed a CPU burst; 76 bursts to go [Q HOPBFDEJNI]
time 2141ms: Recalculated tau from 62ms to 26ms for process G [Q HOPBFDEJNI]
time 2141ms: Process G switching out of CPU; will block on I/O until time 2523ms [Q HOPBFDEJNI]
time 2145ms: Process H (tau 97ms) started using the CPU for 48ms burst [Q OPBFDEJNI]
time 2164ms: Process C (tau 96ms) completed I/O; added to ready queue [Q COPBFDEJNI]
time 2193ms: Process H (tau 97ms) completed a CPU burst; 81 bursts to go [Q COPBFDEJNI]
time 2193ms: Recalculated tau from 97ms to 61ms for process H [Q COPBFDEJNI]
time 2193ms: Process H switching out of CPU; will block on I/O until time 2415ms [Q COPBFDEJNI]
time 2197ms: Process C (tau 96ms) started using the CPU for 117ms burst [Q OPBFDEJNI]
time 2314ms: Process C (tau 96ms) completed a CPU burst; 2 bursts to go [Q OPBFDEJNI]
time 2314ms: Recalculated tau from 96ms to 112ms for process C [Q OPBFDEJNI]
time 2314ms: Process C switching out of CPU; will block on I/O until time 2486ms [Q OPBFDEJNI]
time 2318ms: Process O (tau 100ms) started using the CPU for 156ms burst [Q PBFDEJNI]
time 2415ms: Process H (tau 61ms) completed I/O; added to ready queue [Q HPBFDEJNI]
time 2474ms: Process O (tau 100ms) completed a CPU burst; 30 bursts to go [Q HPBFDEJNI]
time 2474ms: Recalculated tau from 100ms to 142ms for process O [Q HPBFDEJNI]
time 2474ms: Process O switching out of CPU; will block on I/O until time 3146ms [Q HPBFDEJNI]
time 2478ms: Process H (tau 61ms) started using the CPU for 72ms burst [Q PBFDEJNI]
time 2483ms: Process L (tau 127ms) completed I/O; added to ready queue [Q PBFLDEJNI]
time 2486ms: Process C (tau 112ms) completed I/O; added to ready queue [Q PBCFLDEJNI]
time 2495ms: Process K (tau 73ms) completed I/O; added to ready queue [Q KPBCFLDEJNI]
time 2503ms: Process M (tau 81ms) completed I/O; added to ready queue [Q KMPBCFLDEJNI]
time 2523ms: Process G (tau 26ms) completed I/O; added to ready queue [Q GKMPBCFLDEJNI]
time 2550ms: Process H (tau 61ms) completed a CPU burst; 80 bursts to go [Q GKMPBCFLDEJNI]
time 2550ms: Recalculated tau from 61ms to 70ms for process H [Q GKMPBCFLDEJNI]
time 2550ms: Process H switching out of CPU; will block on I/O until time 2972ms [Q GKMPBCFLDEJNI]
time 2554ms: Process G (tau 26ms) started using the CPU for 128ms burst [Q KMPBCFLDEJNI]
time 2626ms: Process A (tau 45ms) completed I/O; added to ready queue [Q AKMPBCFLDEJNI]
time 2682ms: Process G (tau 26ms) completed a CPU burst; 75 bursts to go [Q AKMPBCFLDEJNI]
time 2682ms: Recalculated tau from 26ms to 103ms for process G [Q AKMPBCFLDEJNI]
time 2682ms: Process G switching out of CPU; will block on I/O until time 4904ms [Q AKMPBCFLDEJNI]
time 2686ms: Process A (tau 45ms) started using the CPU for 47ms burst [Q KMPBCFLDEJNI]
time 2733ms: Process A (tau 45ms) completed a CPU burst; 12 bursts to go [Q KMPBCFLDEJNI]
time 2733ms: Recalculated tau from 45ms to 47ms for process A [Q KMPBCFLDEJNI]
time 2733ms: Process A switching out of CPU; will block on I/O until time 2755ms [Q KMPBCFLDEJNI]
time 2737ms: Process K (tau 73ms) started using the CPU for 56ms burst [Q MPBCFLDEJNI]
time 2755ms: Process A (tau 47ms) completed I/O; added to ready queue [Q AMPBCFLDEJNI]
time 2793ms: Process K (tau 73ms) completed a CPU burst; 11 bursts to go [Q AMPBCFLDEJNI]
time 2793ms: Recalculated tau from 73ms to 61ms for process K [Q AMPBCFLDEJNI]
time 2793ms: Process K switching out of CPU; will block on I/O until time 3525ms [Q AMPBCFLDEJNI]
time 2797ms: Process A (tau 47ms) started using the CPU for 137ms burst [Q MPBCFLDEJNI]
time 2934ms: Process A (tau 47ms) completed a CPU burst; 11 bursts to go [Q MPBCFLDEJNI]
time 2934ms: Recalculated tau from 47ms to 115ms for process A [Q MPBCFLDEJNI]
time 2934ms: Process A switching out of CPU; will block on I/O until time 3176ms [Q MPBCFLDEJNI]
time 2938ms: Process M (tau 81ms) started using the CPU for 79ms burst [Q PBCFLDEJNI]
time 2972ms: Process H (tau 70ms) completed I/O; added to ready queue [Q HPBCFLDEJNI]
time 3017ms: Process M (tau 81ms) completed a CPU burst; 45 bursts to go [Q HPBCFLDEJNI]
time 3017ms: Recalculated tau from 81ms to 80ms for process M [Q HPBCFLDEJNI]
time 3017ms: Process M switching out of CPU; will block on I/O until time 4159ms [Q HPBCFLDEJNI]
time 3021ms: Process H (tau 70ms) started using the CPU for 12ms burst [Q PBCFLDEJNI]
time 3033ms: Process H (tau 70ms) completed a CPU burst; 79 bursts to go [Q PBCFLDEJNI]
time 3033ms: Recalculated tau from 70ms to 27ms for process H [Q PBCFLDEJNI]
time 3033ms: Process H switching out of CPU; will block on I/O until time 3165ms [Q PBCFLDEJNI]
time 3037ms: Process P (tau 100ms) started using the CPU for 4ms burst [Q BCFLDEJNI]
time 3041ms: Process P (tau 100ms) completed a CPU burst; 15 bursts to go [Q BCFLDEJNI]
time 3041ms: Recalculated tau from 100ms to 28ms for process P [Q BCFLDEJNI]
time 3041ms: Process P switching out of CPU; will block on I/O until time 4893ms [Q BCFLDEJNI]
time 3045ms: Process B (tau 105ms) started using the CPU for 198ms burst [Q CFLDEJNI]
time 3146ms: Process O (tau 142ms) completed I/O; added to ready queue [Q CFLDEOJNI]
time 3165ms: Process H (tau 27ms) completed I/O; added to ready queue [Q HCFLDEOJNI]
time 3176ms: Process A (tau 115ms) completed I/O; added to ready queue [Q HCAFLDEOJNI]
time 3243ms: Process B (tau 105ms) completed a CPU burst; 19 bursts to go [Q HCAFLDEOJNI]
time 3243ms: Recalculated tau from 105ms to 175ms for process B [Q HCAFLDEOJNI]
time 3243ms: Process B switching out of CPU; will block on I/O until time 4375ms [Q HCAFLDEOJNI]
time 3247ms: Process H (tau 27ms) started using the CPU for 41ms burst [Q CAFLDEOJNI]
time 3288ms: Process H (tau 27ms) completed a CPU burst; 78 bursts to go [Q CAFLDEOJNI]
time 3288ms: Recalculated tau from 27ms to 38ms for process H [Q CAFLDEOJNI]
time 3288ms: Process H switching out of CPU; will block on I/O until time 3500ms [Q CAFLDEOJNI]
time 3292ms: Process C (tau 112ms) started using the CPU for 85ms burst [Q AFLDEOJNI]
time 3377ms: Process C (tau 112ms) completed a CPU burst; 1 burst to go [Q AFLDEOJNI]
time 3377ms: Recalculated tau from 112ms to 92ms for process C [Q AFLDEOJNI]
time 3377ms: Process C switching out of CPU; will block on I/O until time 3589ms [Q AFLDEOJNI]
time 3381ms: Process A (tau 115ms) started using the CPU for 64ms burst [Q FLDEOJNI]
time 3445ms: Process A (tau 115ms) completed a CPU burst; 10 bursts to go [Q FLDEOJNI]
time 3445ms: Recalculated tau from 115ms to 77ms for process A [Q FLDEOJNI]
time 3445ms: Process A switching out of CPU; will block on I/O until time 3597ms [Q FLDEOJNI]
time 3449ms: Process F (tau 122ms) started using the CPU for 39ms burst [Q LDEOJNI]
time 3488ms: Process F (tau 122ms) completed a CPU burst; 32 bursts to go [Q LDEOJNI]
time 3488ms: Recalculated tau from 122ms to 60ms for process F [Q LDEOJNI]
time 3488ms: Process F switching out of CPU; will block on I/O until time 4140ms [Q LDEOJNI]
time 3492ms: Process L (tau 127ms) started using the CPU for 4ms burst [Q DEOJNI]
time 3496ms: Process L (tau 127ms) completed a CPU burst; 5 bursts to go [Q DEOJNI]
time 3496ms: Recalculated tau from 127ms to 35ms for process L [Q DEOJNI]
time 3496ms: Process L switching out of CPU; will block on I/O until time 3918ms [Q DEOJNI]
time 3500ms: Process D (tau 136ms) started using the CPU for 211ms burst [Q EOJNI]
time 3500ms: Process H (tau 38ms) completed I/O; added to ready queue [Q HEOJNI]
time 3525ms: Process K (tau 61ms) completed I/O; added to ready queue [Q HKEOJNI]
time 3589ms: Process C (tau 92ms) completed I/O; added to ready queue [Q HKCEOJNI]
time 3597ms: Process A (tau 77ms) completed I/O; added to ready queue [Q HKACEOJNI]
time 3711ms: Process D (tau 136ms) completed a CPU burst; 9 bursts to go [Q HKACEOJNI]
time 3711ms: Recalculated tau from 136ms to 193ms for process D [Q HKACEOJNI]
time 3711ms: Process D switching out of CPU; will block on I/O until time 5853ms [Q HKACEOJNI]
time 3715ms: Process H (tau 38ms) started using the CPU for 160ms burst [Q KACEOJNI]
time 3875ms: Process H (tau 38ms) completed a CPU burst; 77 bursts to go [Q KACEOJNI]
time 3875ms: Recalculated tau from 38ms to 130ms for process H [Q KACEOJNI]
time 3875ms: Process H switching out of CPU; will block on I/O until time 4477ms [Q KACEOJNI]
time 3879ms: Process K (tau 61ms) started using the CPU for 6ms burst [Q ACEOJNI]
time 3885ms: Process K (tau 61ms) completed a CPU burst; 10 bursts to go [Q ACEOJNI]
time 3885ms: Recalculated tau from 61ms to 20ms for process K [Q ACEOJNI]
time 3885ms: Process K switching out of CPU; will block on I/O until time 4587ms [Q ACEOJNI]
time 3889ms: Process A (tau 77ms) started using the CPU for 68ms burst [Q CEOJNI]
time 3918ms: Process L (tau 35ms) completed I/O; added to ready queue [Q LCEOJNI]
time 3957ms: Process A (tau 77ms) completed a CPU burst; 9 bursts to go [Q LCEOJNI]
time 3957ms: Recalculated tau from 77ms to 71ms for process A [Q LCEOJNI]
time 3957ms: Process A switching out of CPU; will block on I/O until time 4599ms [Q LCEOJNI]
time 3961ms: Process L (tau 35ms) started using the CPU for 69ms burst [Q CEOJNI]
time 4030ms: Process L (tau 35ms) completed a CPU burst; 4 bursts to go [Q CEOJNI]
time 4030ms: Recalculated tau from 35ms to 61ms for process L [Q CEOJNI]
time 4030ms: Process L switching out of CPU; will block on I/O until time 4982ms [Q CEOJNI]
time 4034ms: Process C (tau 92ms) started using the CPU for 79ms burst [Q EOJNI]
time 4113ms: Process C terminated [Q EOJNI]
time 4117ms: Process E (tau 139ms) started using the CPU for 44ms burst [Q OJNI]
time 4140ms: Process F (tau 60ms) completed I/O; added to ready queue [Q FOJNI]
time 4159ms: Process M (tau 80ms) completed I/O; added to ready queue [Q FMOJNI]
time 4161ms: Process E (tau 139ms) completed a CPU burst; 53 bursts to go [Q FMOJNI]
time 4161ms: Recalculated tau from 139ms to 68ms for process E [Q FMOJNI]
time 4161ms: Process E switching out of CPU; will block on I/O until time 4723ms [Q FMOJNI]
time 4165ms: Process F (tau 60ms) started using the CPU for 195ms burst [Q MOJNI]
time 4360ms: Process F (tau 60ms) completed a CPU burst; 31 bursts to go [Q MOJNI]
time 4360ms: Recalculated tau from 60ms to 162ms for process F [Q MOJNI]
time 4360ms: Process F switching out of CPU; will block on I/O until time 4372ms [Q MOJNI]
time 4364ms: Process M (tau 80ms) started using the CPU for 18ms burst [Q OJNI]
time 4372ms: Process F (tau 162ms) completed I/O; added to ready queue [Q OFJNI]
time 4375ms: Process B (tau 175ms) completed I/O; added to ready queue [Q OFJBNI]
time 4382ms: Process M (tau 80ms) completed a CPU burst; 44 bursts to go [Q OFJBNI]
time 4382ms: Recalculated tau from 80ms to 34ms for process M [Q OFJBNI]
time 4382ms: Process M switching out of CPU; will block on I/O until time 6354ms [Q OFJBNI]
time 4386ms: Process O (tau 142ms) started using the CPU for 106ms burst [Q FJBNI]
time 4477ms: Process H (tau 130ms) completed I/O; added to ready queue [Q HFJBNI]
time 4492ms: Process O (tau 142ms) completed a CPU burst; 29 bursts to go [Q HFJBNI]
time 4492ms: Recalculated tau from 142ms to 115ms for process O [Q HFJBNI]
time 4492ms: Process O switching out of CPU; will block on I/O until time 6984ms [Q HFJBNI]
time 4496ms: Process H (tau 130ms) started using the CPU for 28ms burst [Q FJBNI]
time 4524ms: Process H (tau 130ms) completed a CPU burst; 76 bursts to go [Q FJBNI]
time 4524ms: Recalculated tau from 130ms to 54ms for process H [Q FJBNI]
time 4524ms: Process H switching out of CPU; will block on I/O until time 5486ms [Q FJBNI]
time 4528ms: Process F (tau 162ms) started using the CPU for 72ms burst [Q JBNI]
time 4587ms: Process K (tau 20ms) completed I/O; added to ready queue [Q KJBNI]
time 4599ms: Process A (tau 71ms) completed I/O; added to ready queue [Q KAJBNI]
time 4600ms: Process F (tau 162ms) completed a CPU burst; 30 bursts to go [Q KAJBNI]
time 4600ms: Recalculated tau from 162ms to 95ms for process F [Q KAJBNI]
time 4600ms: Process F switching out of CPU; will block on I/O until time 4862ms [Q KAJBNI]
time 4604ms: Process K (tau 20ms) started using the CPU for 6ms burst [Q AJBNI]
time 4610ms: Process K (tau 20ms) completed a CPU burst; 9 bursts to go [Q AJBNI]
time 4610ms: Recalculated tau from 20ms to 10ms for process K [Q AJBNI]
time 4610ms: Process K switching out of CPU; will block on I/O until time 5362ms [Q AJBNI]
time 4614ms: Process A (tau 71ms) started using the CPU for 113ms burst [Q JBNI]
time 4723ms: Process E (tau 68ms) completed I/O; added to ready queue [Q EJBNI]
time 4727ms: Process A (tau 71ms) completed a CPU burst; 8 bursts to go [Q EJBNI]
time 4727ms: Recalculated tau from 71ms to 103ms for process A [Q EJBNI]
time 4727ms: Process A switching out of CPU; will block on I/O until time 4889ms [Q EJBNI]
time 4731ms: Process E (tau 68ms) started using the CPU for 2ms burst [Q JBNI]
time 4733ms: Process E (tau 68ms) completed a CPU burst; 52 bursts to go [Q JBNI]
time 4733ms: Recalculated tau from 68ms to 19ms for process E [Q JBNI]
time 4733ms: Process E switching out of CPU; will block on I/O until time 4985ms [Q JBNI]
time 4737ms: Process J (tau 167ms) started using the CPU for 28ms burst [Q BNI]
time 4765ms: Process J (tau 167ms) completed a CPU burst; 7 bursts to go [Q BNI]
time 4765ms: Recalculated tau from 167ms to 63ms for process J [Q BNI]
time 4765ms: Process J switching out of CPU; will block on I/O until time 4987ms [Q BNI]
time 4769ms: Process B (tau 175ms) started using the CPU for 208ms burst [Q NI]
time 4862ms: Process F (tau 95ms) completed I/O; added to ready queue [Q FNI]
time 4889ms: Process A (tau 103ms) completed I/O; added to ready queue [Q FANI]
time 4893ms: Process P (tau 28ms) completed I/O; added to ready queue [Q PFANI]
time 4904ms: Process G (tau 103ms) completed I/O; added to ready queue [Q PFAGNI]
time 4977ms: Process B (tau 175ms) completed a CPU burst; 18 bursts to go [Q PFAGNI]
time 4977ms: Recalculated tau from 175ms to 200ms for process B [Q PFAGNI]
time 4977ms: Process B switching out of CPU; will block on I/O until time 6599ms [Q PFAGNI]
time 4981ms: Process P (tau 28ms) started using the CPU for 52ms burst [Q FAGNI]
time 4982ms: Process L (tau 61ms) completed I/O; added to ready queue [Q LFAGNI]
time 4985ms: Process E (tau 19ms) completed I/O; added to ready queue [Q ELFAGNI]
time 4987ms: Process J (tau 63ms) completed I/O; added to ready queue [Q ELJFAGNI]
time 5033ms: Process P (tau 28ms) completed a CPU burst; 14 bursts to go [Q ELJFAGNI]
time 5033ms: Recalculated tau from 28ms to 46ms for process P [Q ELJFAGNI]
time 5033ms: Process P switching out of CPU; will block on I/O until time 6125ms [Q ELJFAGNI]
time 5037ms: Process E (tau 19ms) started using the CPU for 42ms burst [Q LJFAGNI]
time 5079ms: Process E (tau 19ms) completed a CPU burst; 51 bursts to go [Q LJFAGNI]
time 5079ms: Recalculated tau from 19ms to 37ms for process E [Q LJFAGNI]
time 5079ms: Process E switching out of CPU; will block on I/O until time 5131ms [Q LJFAGNI]
time 5083ms: Process L (tau 61ms) started using the CPU for 25ms burst [Q JFAGNI]
time 5108ms: Process L (tau 61ms) completed a CPU burst; 3 bursts to go [Q JFAGNI]
time 5108ms: Recalculated tau from 61ms to 34ms for process L [Q JFAGNI]
time 5108ms: Process L switching out of CPU; will block on I/O until time 6300ms [Q JFAGNI]
time 5112ms: Process J (tau 63ms) started using the CPU for 120ms burst [Q FAGNI]
time 5131ms: Process E (tau 37ms) completed I/O; added to ready queue [Q EFAGNI]
time 5232ms: Process J (tau 63ms) completed a CPU burst; 6 bursts to go [Q EFAGNI]
time 5232ms: Recalculated tau from 63ms to 106ms for process J [Q EFAGNI]
time 5232ms: Process J switching out of CPU; will block on I/O until time 5794ms [Q EFAGNI]
time 5236ms: Process E (tau 37ms) started using the CPU for 108ms burst [Q FAGNI]
time 5344ms: Process E (tau 37ms) completed a CPU burst; 50 bursts to go [Q FAGNI]
time 5344ms: Recalculated tau from 37ms to 91ms for process E [Q FAGNI]
time 5344ms: Process E switching out of CPU; will block on I/O until time 5436ms [Q FAGNI]
time 5348ms: Process F (tau 95ms) started using the CPU for 8ms burst [Q AGNI]
time 5356ms: Process F (tau 95ms) completed a CPU burst; 29 bursts to go [Q AGNI]
time 5356ms: Recalculated tau from 95ms to 30ms for process F [Q AGNI]
time 5356ms: Process F switching out of CPU; will block on I/O until time 5688ms [Q AGNI]
time 5360ms: Process A (tau 103ms) started using the CPU for 11ms burst [Q GNI]
time 5362ms: Process K (tau 10ms) completed I/O; added to ready queue [Q KGNI]
time 5371ms: Process A (tau 103ms) completed a CPU burst; 7 bursts to go [Q KGNI]
time 5371ms: Recalculated tau from 103ms to 34ms for process A [Q KGNI]
time 5371ms: Process A switching out of CPU; will block on I/O until time 6993ms [Q KGNI]
time 5375ms: Process K (tau 10ms) started using the CPU for 157ms burst [Q GNI]
time 5436ms: Process E (tau 91ms) completed I/O; added to ready queue [Q EGNI]
time 5486ms: Process H (tau 54ms) completed I/O; added to ready queue [Q HEGNI]
time 5532ms: Process K (tau 10ms) completed a CPU burst; 8 bursts to go [Q HEGNI]
time 5532ms: Recalculated tau from 10ms to 121ms for process K [Q HEGNI]
time 5532ms: Process K switching out of CPU; will block on I/O until time 5694ms [Q HEGNI]
time 5536ms: Process H (tau 54ms) started using the CPU for 51ms burst [Q EGNI]
time 5587ms: Process H (tau 54ms) completed a CPU burst; 75 bursts to go [Q EGNI]
time 5587ms: Recalculated tau from 54ms to 52ms for process H [Q EGNI]
time 5587ms: Process H switching out of CPU; will block on I/O until time 5819ms [Q EGNI]
time 5591ms: Process E (tau 91ms) started using the CPU for 6ms burst [Q GNI]
time 5597ms: Process E (tau 91ms) completed a CPU burst; 49 bursts to go [Q GNI]
time 5597ms: Recalculated tau from 91ms to 28ms for process E [Q GNI]
time 5597ms: Process E switching out of CPU; will block on I/O until time 5919ms [Q GNI]
time 5601ms: Process G (tau 103ms) started using the CPU for 15ms burst [Q NI]
time 5616ms: Process G (tau 103ms) completed a CPU burst; 74 bursts to go [Q NI]
time 5616ms: Recalculated tau from 103ms to 37ms for process G [Q NI]
time 5616ms: Process G switching out of CPU; will block on I/O until time 6558ms [Q NI]
time 5620ms: Process N (tau 185ms) started using the CPU for 132ms burst [Q I]
time 5688ms: Process F (tau 30ms) completed I/O; added to ready queue [Q FI]
time 5694ms: Process K (tau 121ms) completed I/O; added to ready queue [Q FKI]
time 5752ms: Process N (tau 185ms) completed a CPU burst; 29 bursts to go [Q FKI]
time 5752ms: Recalculated tau from 185ms to 146ms for process N [Q FKI]
time 5752ms: Process N switching out of CPU; will block on I/O until time 7354ms [Q FKI]
time 5756ms: Process F (tau 30ms) started using the CPU for 230ms burst [Q KI]
time 5794ms: Process J (tau 106ms) completed I/O; added to ready queue [Q JKI]
time 5819ms: Process H (tau 52ms) completed I/O; added to ready queue [Q HJKI]
time 5853ms: Process D (tau 193ms) completed I/O; added to ready queue [Q HJKID]
time 5919ms: Process E (tau 28ms) completed I/O; added to ready queue [Q EHJKID]
time 5986ms: Process F (tau 30ms) completed a CPU burst; 28 bursts to go [Q EHJKID]
time 5986ms: Recalculated tau from 30ms to 180ms for process F [Q EHJKID]
time 5986ms: Process F switching out of CPU; will block on I/O until time 6018ms [Q EHJKID]
time 5990ms: Process E (tau 28ms) started using the CPU for 112ms burst [Q HJKID]
time 6018ms: Process F (tau 180ms) completed I/O; added to ready queue [Q HJKFID]
time 6102ms: Process E (tau 28ms) completed a CPU burst; 48 bursts to go [Q HJKFID]
time 6102ms: Recalculated tau from 28ms to 91ms for process E [Q HJKFID]
time 6102ms: Process E switching out of CPU; will block on I/O until time 7214ms [Q HJKFID]
time 6106ms: Process H (tau 52ms) started using the CPU for 87ms burst [Q JKFID]
time 6125ms: Process P (tau 46ms) completed I/O; added to ready queue [Q PJKFID]
time 6193ms: Process H (tau 52ms) completed a CPU burst; 74 bursts to go [Q PJKFID]
time 6193ms: Recalculated tau from 52ms to 79ms for process H [Q PJKFID]
time 6193ms: Process H switching out of CPU; will block on I/O until time 6765ms [Q PJKFID]
time 6197ms: Process P (tau 46ms) started using the CPU for 56ms burst [Q JKFID]
time 6253ms: Process P (tau 46ms) completed a CPU burst; 13 bursts to go [Q JKFID]
time 6253ms: Recalculated tau from 46ms to 54ms for process P [Q JKFID]
time 6253ms: Process P switching out of CPU; will block on I/O until time 7465ms [Q JKFID]
time 6257ms: Process J (tau 106ms) started using the CPU for 31ms burst [Q KFID]
time 6288ms: Process J (tau 106ms) completed a CPU burst; 5 bursts to go [Q KFID]
time 6288ms: Recalculated tau from 106ms to 50ms for process J [Q KFID]
time 6288ms: Process J switching out of CPU; will block on I/O until time 7150ms [Q KFID]
time 6292ms: Process K (tau 121ms) started using the CPU for 104ms burst [Q FID]
time 6300ms: Process L (tau 34ms) completed I/O; added to ready queue [Q LFID]
time 6354ms: Process M (tau 34ms) completed I/O; added to ready queue [Q LMFID]
time 6396ms: Process K (tau 121ms) completed a CPU burst; 7 bursts to go [Q LMFID]
time 6396ms: Recalculated tau from 121ms to 109ms for process K [Q LMFID]
time 6396ms: Process K switching out of CPU; will block on I/O until time 7848ms [Q LMFID]
time 6400ms: Process L (tau 34ms) started using the CPU for 2ms burst [Q MFID]
time 6402ms: Process L (tau 34ms) completed a CPU burst; 2 bursts to go [Q MFID]
time 6402ms: Recalculated tau from 34ms to 10ms for process L [Q MFID]
time 6402ms: Process L switching out of CPU; will block on I/O until time 6774ms [Q MFID]
time 6406ms: Process M (tau 34ms) started using the CPU for 66ms burst [Q FID]
time 6472ms: Process M (tau 34ms) completed a CPU burst; 43 bursts to go [Q FID]
time 6472ms: Recalculated tau from 34ms to 58ms for process M [Q FID]
time 6472ms: Process M switching out of CPU; will block on I/O until time 8284ms [Q FID]
time 6476ms: Process F (tau 180ms) started using the CPU for 33ms burst [Q ID]
time 6509ms: Process F (tau 180ms) completed a CPU burst; 27 bursts to go [Q ID]
time 6509ms: Recalculated tau from 180ms to 70ms for process F [Q ID]
time 6509ms: Process F switching out of CPU; will block on I/O until time 7071ms [Q ID]
time 6513ms: Process I (tau 190ms) started using the CPU for 16ms burst [Q D]
time 6529ms: Process I (tau 190ms) completed a CPU burst; 75 bursts to go [Q D]
time 6529ms: Recalculated tau from 190ms to 60ms for process I [Q D]
time 6529ms: Process I switching out of CPU; will block on I/O until time 8291ms [Q D]
time 6533ms: Process D (tau 193ms) started using the CPU for 9ms burst [Q empty]
time 6542ms: Process D (tau 193ms) completed a CPU burst; 8 bursts to go [Q empty]
time 6542ms: Recalculated tau from 193ms to 55ms for process D [Q empty]
time 6542ms: Process D switching out of CPU; will block on I/O until time 6924ms [Q empty]
time 6558ms: Process G (tau 37ms) completed I/O; added to ready queue [Q G]
time 6560ms: Process G (tau 37ms) started using the CPU for 112ms burst [Q empty]
time 6599ms: Process B (tau 200ms) completed I/O; added to ready queue [Q B]
time 6672ms: Process G (tau 37ms) completed a CPU burst; 73 bursts to go [Q B]
time 6672ms: Recalculated tau from 37ms to 94ms for process G [Q B]
time 6672ms: Process G switching out of CPU; will block on I/O until time 7104ms [Q B]
time 6676ms: Process B (tau 200ms) started using the CPU for 50ms burst [Q empty]
time 6726ms: Process B (tau 200ms) completed a CPU burst; 17 bursts to go [Q empty]
time 6726ms: Recalculated tau from 200ms to 88ms for process B [Q empty]
time 6726ms: Process B switching out of CPU; will block on I/O until time 7188ms [Q empty]
time 6765ms: Process H (tau 79ms) completed I/O; added to ready queue [Q H]
time 6767ms: Process H (tau 79ms) started using the CPU for 156ms burst [Q empty]
time 6774ms: Process L (tau 10ms) completed I/O; added to ready queue [Q L]
time 6923ms: Process H (tau 79ms) completed a CPU burst; 73 bursts to go [Q L]
time 6923ms: Recalculated tau from 79ms to 137ms for process H [Q L]
time 6923ms: Process H switching out of CPU; will block on I/O until time 7485ms [Q L]
time 6924ms: Process D (tau 55ms) completed I/O; added to ready queue [Q LD]
time 6927ms: Process L (tau 10ms) started using the CPU for 164ms burst [Q D]
time 6984ms: Process O (tau 115ms) completed I/O; added to ready queue [Q DO]
time 6993ms: Process A (tau 34ms) completed I/O; added to ready queue [Q ADO]
time 7071ms: Process F (tau 70ms) completed I/O; added to ready queue [Q ADFO]
time 7091ms: Process L (tau 10ms) completed a CPU burst; 1 burst to go [Q ADFO]
time 7091ms: Recalculated tau from 10ms to 126ms for process L [Q ADFO]
time 7091ms: Process L switching out of CPU; will block on I/O until time 7593ms [Q ADFO]
time 7095ms: Process A (tau 34ms) started using the CPU for 24ms burst [Q DFO]
time 7104ms: Process G (tau 94ms) completed I/O; added to ready queue [Q DFGO]
time 7119ms: Process A (tau 34ms) completed a CPU burst; 6 bursts to go [Q DFGO]
time 7119ms: Recalculated tau from 34ms to 27ms for process A [Q DFGO]
time 7119ms: Process A switching out of CPU; will block on I/O until time 8291ms [Q DFGO]
time 7123ms: Process D (tau 55ms) started using the CPU for 4ms burst [Q FGO]
time 7127ms: Process D (tau 55ms) completed a CPU burst; 7 bursts to go [Q FGO]
time 7127ms: Recalculated tau from 55ms to 17ms for process D [Q FGO]
time 7127ms: Process D switching out of CPU; will block on I/O until time 7609ms [Q FGO]
time 7131ms: Process F (tau 70ms) started using the CPU for 76ms burst [Q GO]
time 7150ms: Process J (tau 50ms) completed I/O; added to ready queue [Q JGO]
time 7188ms: Process B (tau 88ms) completed I/O; added to ready queue [Q JBGO]
time 7207ms: Process F (tau 70ms) completed a CPU burst; 26 bursts to go [Q JBGO]
time 7207ms: Recalculated tau from 70ms to 75ms for process F [Q JBGO]
time 7207ms: Process F switching out of CPU; will block on I/O until time 7589ms [Q JBGO]
time 7211ms: Process J (tau 50ms) started using the CPU for 32ms burst [Q BGO]
time 7214ms: Process E (tau 91ms) completed I/O; added to ready queue [Q BEGO]
time 7243ms: Process J (tau 50ms) completed a CPU burst; 4 bursts to go [Q BEGO]
time 7243ms: Recalculated tau from 50ms to 37ms for process J [Q BEGO]
time 7243ms: Process J switching out of CPU; will block on I/O until time 7375ms [Q BEGO]
time 7247ms: Process B (tau 88ms) started using the CPU for 82ms burst [Q EGO]
time 7329ms: Process B (tau 88ms) completed a CPU burst; 16 bursts to go [Q EGO]
time 7329ms: Recalculated tau from 88ms to 84ms for process B [Q EGO]
time 7329ms: Process B switching out of CPU; will block on I/O until time 7491ms [Q EGO]
time 7333ms: Process E (tau 91ms) started using the CPU for 12ms burst [Q GO]
time 7345ms: Process E (tau 91ms) completed a CPU burst; 47 bursts to go [Q GO]
time 7345ms: Recalculated tau from 91ms to 32ms for process E [Q GO]
time 7345ms: Process E switching out of CPU; will block on I/O until time 7797ms [Q GO]
time 7349ms: Process G (tau 94ms) started using the CPU for 30ms burst [Q O]
time 7354ms: Process N (tau 146ms) completed I/O; added to ready queue [Q ON]
time 7375ms: Process J (tau 37ms) completed I/O; added to ready queue [Q JON]
time 7379ms: Process G (tau 94ms) completed a CPU burst; 72 bursts to go [Q JON]
time 7379ms: Recalculated tau from 94ms to 46ms for process G [Q JON]
time 7379ms: Process G switching out of CPU; will block on I/O until time 7851ms [Q JON]
time 7383ms: Process J (tau 37ms) started using the CPU for 23ms burst [Q ON]
time 7406ms: Process J (tau 37ms) completed a CPU burst; 3 bursts to go [Q ON]
time 7406ms: Recalculated tau from 37ms to 27ms for process J [Q ON]
time 7406ms: Process J switching out of CPU; will block on I/O until time 7568ms [Q ON]
time 7410ms: Process O (tau 115ms) started using the CPU for 57ms burst [Q N]
time 7465ms: Process P (tau 54ms) completed I/O; added to ready queue [Q PN]
time 7467ms: Process O (tau 115ms) completed a CPU burst; 28 bursts to go [Q PN]
time 7467ms: Recalculated tau from 115ms to 72ms for process O [Q PN]
time 7467ms: Process O switching out of CPU; will block on I/O until time 7839ms [Q PN]
time 7471ms: Process P (tau 54ms) started using the CPU for 155ms burst [Q N]
time 7485ms: Process H (tau 137ms) completed I/O; added to ready queue [Q HN]
time 7491ms: Process B (tau 84ms) completed I/O; added to ready queue [Q BHN]
time 7568ms: Process J (tau 27ms) completed I/O; added to ready queue [Q JBHN]
time 7589ms: Process F (tau 75ms) completed I/O; added to ready queue [Q JFBHN]
time 7593ms: Process L (tau 126ms) completed I/O; added to ready queue [Q JFBLHN]
time 7609ms: Process D (tau 17ms) completed I/O; added to ready queue [Q DJFBLHN]
time 7626ms: Process P (tau 54ms) completed a CPU burst; 12 bursts to go [Q DJFBLHN]
time 7626ms: Recalculated tau from 54ms to 130ms for process P [Q DJFBLHN]
time 7626ms: Process P switching out of CPU; will block on I/O until time 8808ms [Q DJFBLHN]
time 7630ms: Process D (tau 17ms) started using the CPU for 149ms burst [Q JFBLHN]
time 7779ms: Process D (tau 17ms) completed a CPU burst; 6 bursts to go [Q JFBLHN]
time 7779ms: Recalculated tau from 17ms to 116ms for process D [Q JFBLHN]
time 7779ms: Process D switching out of CPU; will block on I/O until time 8591ms [Q JFBLHN]
time 7783ms: Process J (tau 27ms) started using the CPU for 51ms burst [Q FBLHN]
time 7797ms: Process E (tau 32ms) completed I/O; added to ready queue [Q EFBLHN]
time 7834ms: Process J (tau 27ms) completed a CPU burst; 2 bursts to go [Q EFBLHN]
time 7834ms: Recalculated tau from 27ms to 45ms for process J [Q EFBLHN]
time 7834ms: Process J switching out of CPU; will block on I/O until time 8806ms [Q EFBLHN]
time 7838ms: Process E (tau 32ms) started using the CPU for 9ms burst [Q FBLHN]
time 7839ms: Process O (tau 72ms) completed I/O; added to ready queue [Q OFBLHN]
time 7847ms: Process E (tau 32ms) completed a CPU burst; 46 bursts to go [Q OFBLHN]
time 7847ms: Recalculated tau from 32ms to 15ms for process E [Q OFBLHN]
time 7847ms: Process E switching out of CPU; will block on I/O until time 8519ms [Q OFBLHN]
time 7848ms: Process K (tau 109ms) completed I/O; added to ready queue [Q OFBKLHN]
time 7851ms: Process O (tau 72ms) started using the CPU for 13ms burst [Q FBKLHN]
time 7851ms: Process G (tau 46ms) completed I/O; added to ready queue [Q GFBKLHN]
time 7864ms: Process O (tau 72ms) completed a CPU burst; 27 bursts to go [Q GFBKLHN]
time 7864ms: Recalculated tau from 72ms to 28ms for process O [Q GFBKLHN]
time 7864ms: Process O switching out of CPU; will block on I/O until time 9196ms [Q GFBKLHN]
time 7868ms: Process G (tau 46ms) started using the CPU for 50ms burst [Q FBKLHN]
time 7918ms: Process G (tau 46ms) completed a CPU burst; 71 bursts to go [Q FBKLHN]
time 7918ms: Recalculated tau from 46ms to 49ms for process G [Q FBKLHN]
time 7918ms: Process G switching out of CPU; will block on I/O until time 10120ms [Q FBKLHN]
time 7922ms: Process F (tau 75ms) started using the CPU for 107ms burst [Q BKLHN]
time 8029ms: Process F (tau 75ms) completed a CPU burst; 25 bursts to go [Q BKLHN]
time 8029ms: Recalculated tau from 75ms to 99ms for process F [Q BKLHN]
time 8029ms: Process F switching out of CPU; will block on I/O until time 8211ms [Q BKLHN]
time 8033ms: Process B (tau 84ms) started using the CPU for 7ms burst [Q KLHN]
time 8040ms: Process B (tau 84ms) completed a CPU burst; 15 bursts to go [Q KLHN]
time 8040ms: Recalculated tau from 84ms to 27ms for process B [Q KLHN]
time 8040ms: Process B switching out of CPU; will block on I/O until time 8342ms [Q KLHN]
time 8044ms: Process K (tau 109ms) started using the CPU for 86ms burst [Q LHN]
time 8130ms: Process K (tau 109ms) completed a CPU burst; 6 bursts to go [Q LHN]
time 8130ms: Recalculated tau from 109ms to 92ms for process K [Q LHN]
time 8130ms: Process K switching out of CPU; will block on I/O until time 8412ms [Q LHN]
time 8134ms: Process L (tau 126ms) started using the CPU for 111ms burst [Q HN]
time 8211ms: Process F (tau 99ms) completed I/O; added to ready queue [Q FHN]
time 8245ms: Process L terminated [Q FHN]
time 8249ms: Process F (tau 99ms) started using the CPU for 89ms burst [Q HN]
time 8284ms: Process M (tau 58ms) completed I/O; added to ready queue [Q MHN]
time 8291ms: Process A (tau 27ms) completed I/O; added to ready queue [Q AMHN]
time 8291ms: Process I (tau 60ms) completed I/O; added to ready queue [Q AMIHN]
time 8338ms: Process F (tau 99ms) completed a CPU burst; 24 bursts to go [Q AMIHN]
time 8338ms: Recalculated tau from 99ms to 92ms for process F [Q AMIHN]
time 8338ms: Process F switching out of CPU; will block on I/O until time 9170ms [Q AMIHN]
time 8342ms: Process A (tau 27ms) started using the CPU for 76ms burst [Q MIHN]
time 8342ms: Process B (tau 27ms) completed I/O; added to ready queue [Q BMIHN]
time 8412ms: Process K (tau 92ms) completed I/O; added to ready queue [Q BMIKHN]
time 8418ms: Process A (tau 27ms) completed a CPU burst; 5 bursts to go [Q BMIKHN]
time 8418ms: Recalculated tau from 27ms to 64ms for process A [Q BMIKHN]
time 8418ms: Process A switching out of CPU; will block on I/O until time 8700ms [Q BMIKHN]
time 8422ms: Process B (tau 27ms) started using the CPU for 52ms burst [Q MIKHN]
time 8474ms: Process B (tau 27ms) completed a CPU burst; 14 bursts to go [Q MIKHN]
time 8474ms: Recalculated tau from 27ms to 46ms for process B [Q MIKHN]
time 8474ms: Process B switching out of CPU; will block on I/O until time 8596ms [Q MIKHN]
time 8478ms: Process M (tau 58ms) started using the CPU for 103ms burst [Q IKHN]
time 8519ms: Process E (tau 15ms) completed I/O; added to ready queue [Q EIKHN]
time 8581ms: Process M (tau 58ms) completed a CPU burst; 42 bursts to go [Q EIKHN]
time 8581ms: Recalculated tau from 58ms to 92ms for process M [Q EIKHN]
time 8581ms: Process M switching out of CPU; will block on I/O until time 8983ms [Q EIKHN]
time 8585ms: Process E (tau 15ms) started using the CPU for 62ms burst [Q IKHN]
time 8591ms: Process D (tau 116ms) completed I/O; added to ready queue [Q IKDHN]
time 8596ms: Process B (tau 46ms) completed I/O; added to ready queue [Q BIKDHN]
time 8647ms: Process E (tau 15ms) completed a CPU burst; 45 bursts to go [Q BIKDHN]
time 8647ms: Recalculated tau from 15ms to 51ms for process E [Q BIKDHN]
time 8647ms: Process E switching out of CPU; will block on I/O until time 9249ms [Q BIKDHN]
time 8651ms: Process B (tau 46ms) started using the CPU for 228ms burst [Q IKDHN]
time 8700ms: Process A (tau 64ms) completed I/O; added to ready queue [Q IAKDHN]
time 8806ms: Process J (tau 45ms) completed I/O; added to ready queue [Q JIAKDHN]
time 8808ms: Process P (tau 130ms) completed I/O; added to ready queue [Q JIAKDPHN]
time 8879ms: Process B (tau 46ms) completed a CPU burst; 13 bursts to go [Q JIAKDPHN]
time 8879ms: Recalculated tau from 46ms to 183ms for process B [Q JIAKDPHN]
time 8879ms: Process B switching out of CPU; will block on I/O until time 9651ms [Q JIAKDPHN]
time 8883ms: Process J (tau 45ms) started using the CPU for 216ms burst [Q IAKDPHN]
time 8983ms: Process M (tau 92ms) completed I/O; added to ready queue [Q IAKMDPHN]
time 9099ms: Process J (tau 45ms) completed a CPU burst; 1 burst to go [Q IAKMDPHN]
time 9099ms: Recalculated tau from 45ms to 174ms for process J [Q IAKMDPHN]
time 9099ms: Process J switching out of CPU; will block on I/O until time 9181ms [Q IAKMDPHN]
time 9103ms: Process I (tau 60ms) started using the CPU for 26ms burst [Q AKMDPHN]
time 9129ms: Process I (tau 60ms) completed a CPU burst; 74 bursts to go [Q AKMDPHN]
time 9129ms: Recalculated tau from 60ms to 35ms for process I [Q AKMDPHN]
time 9129ms: Process I switching out of CPU; will block on I/O until time 9761ms [Q AKMDPHN]
time 9133ms: Process A (tau 64ms) started using the CPU for 122ms burst [Q KMDPHN]
time 9170ms: Process F (tau 92ms) completed I/O; added to ready queue [Q FKMDPHN]
time 9181ms: Process J (tau 174ms) completed I/O; added to ready queue [Q FKMDPHNJ]
time 9196ms: Process O (tau 28ms) completed I/O; added to ready queue [Q OFKMDPHNJ]
time 9249ms: Process E (tau 51ms) completed I/O; added to ready queue [Q OEFKMDPHNJ]
time 9255ms: Process A (tau 64ms) completed a CPU burst; 4 bursts to go [Q OEFKMDPHNJ]
time 9255ms: Recalculated tau from 64ms to 108ms for process A [Q OEFKMDPHNJ]
time 9255ms: Process A switching out of CPU; will block on I/O until time 9587ms [Q OEFKMDPHNJ]
time 9259ms: Process O (tau 28ms) started using the CPU for 130ms burst [Q EFKMDPHNJ]
time 9389ms: Process O (tau 28ms) completed a CPU burst; 26 bursts to go [Q EFKMDPHNJ]
time 9389ms: Recalculated tau from 28ms to 105ms for process O [Q EFKMDPHNJ]
time 9389ms: Process O switching out of CPU; will block on I/O until time 10101ms [Q EFKMDPHNJ]
time 9393ms: Process E (tau 51ms) started using the CPU for 213ms burst [Q FKMDPHNJ]
time 9587ms: Process A (tau 108ms) completed I/O; added to ready queue [Q FKMADPHNJ]
time 9606ms: Process E (tau 51ms) completed a CPU burst; 44 bursts to go [Q FKMADPHNJ]
time 9606ms: Recalculated tau from 51ms to 173ms for process E [Q FKMADPHNJ]
time 9606ms: Process E switching out of CPU; will block on I/O until time 11538ms [Q FKMADPHNJ]
time 9610ms: Process F (tau 92ms) started using the CPU for 102ms burst [Q KMADPHNJ]
time 9651ms: Process B (tau 183ms) completed I/O; added to ready queue [Q KMADPHNJB]
time 9712ms: Process F (tau 92ms) completed a CPU burst; 23 bursts to go [Q KMADPHNJB]
time 9712ms: Recalculated tau from 92ms to 100ms for process F [Q KMADPHNJB]
time 9712ms: Process F switching out of CPU; will block on I/O until time 11064ms [Q KMADPHNJB]
time 9716ms: Process K (tau 92ms) started using the CPU for 50ms burst [Q MADPHNJB]
time 9761ms: Process I (tau 35ms) completed I/O; added to ready queue [Q IMADPHNJB]
time 9766ms: Process K (tau 92ms) completed a CPU burst; 5 bursts to go [Q IMADPHNJB]
time 9766ms: Recalculated tau from 92ms to 61ms for process K [Q IMADPHNJB]
time 9766ms: Process K switching out of CPU; will block on I/O until time 10268ms [Q IMADPHNJB]
time 9770ms: Process I (tau 35ms) started using the CPU for 45ms burst [Q MADPHNJB]
time 9815ms: Process I (tau 35ms) completed a CPU burst; 73 bursts to go [Q MADPHNJB]
time 9815ms: Recalculated tau from 35ms to 43ms for process I [Q MADPHNJB]
time 9815ms: Process I switching out of CPU; will block on I/O until time 10117ms [Q MADPHNJB]
time 9819ms: Process M (tau 92ms) started using the CPU for 171ms burst [Q ADPHNJB]
time 9990ms: Process M (tau 92ms) completed a CPU burst; 41 bursts to go [Q ADPHNJB]
time 9990ms: Recalculated tau from 92ms to 152ms for process M [Q ADPHNJB]
time 9990ms: Process M switching out of CPU; will block on I/O until time 10202ms [Q ADPHNJB]
time 9994ms: Process A (tau 108ms) started using the CPU for 9ms burst [Q DPHNJB]
time 10003ms: Process A (tau 108ms) completed a CPU burst; 3 bursts to go [Q DPHNJB]
time 10003ms: Recalculated tau from 108ms to 34ms for process A [Q DPHNJB]
time 10003ms: Process A switching out of CPU; will block on I/O until time 10685ms [Q DPHNJB]
time 10007ms: Process D (tau 116ms) started using the CPU for 52ms burst [Q PHNJB]
time 10059ms: Process D (tau 116ms) completed a CPU burst; 5 bursts to go [Q PHNJB]
time 10059ms: Recalculated tau from 116ms to 68ms for process D [Q PHNJB]
time 10059ms: Process D switching out of CPU; will block on I/O until time 10091ms [Q PHNJB]
time 10063ms: Process P (tau 130ms) started using the CPU for 4ms burst [Q HNJB]
time 10067ms: Process P (tau 130ms) completed a CPU burst; 11 bursts to go [Q HNJB]
time 10067ms: Recalculated tau from 130ms to 36ms for process P [Q HNJB]
time 10067ms: Process P switching out of CPU; will block on I/O until time 11859ms [Q HNJB]
time 10071ms: Process H (tau 137ms) started using the CPU for 184ms burst [Q NJB]
time 10091ms: Process D (tau 68ms) completed I/O; added to ready queue [Q DNJB]
time 10101ms: Process O (tau 105ms) completed I/O; added to ready queue [Q DONJB]
time 10117ms: Process I (tau 43ms) completed I/O; added to ready queue [Q IDONJB]
time 10120ms: Process G (tau 49ms) completed I/O; added to ready queue [Q IGDONJB]
time 10202ms: Process M (tau 152ms) completed I/O; added to ready queue [Q IGDONMJB]
time 10255ms: Process H (tau 137ms) completed a CPU burst; 72 bursts to go [Q IGDONMJB]
time 10255ms: Recalculated tau from 137ms to 173ms for process H [Q IGDONMJB]
time 10255ms: Process H switching out of CPU; will block on I/O until time 10517ms [Q IGDONMJB]
time 10259ms: Process I (tau 43ms) started using the CPU for 38ms burst [Q GDONMJB]
time 10268ms: Process K (tau 61ms) completed I/O; added to ready queue [Q GKDONMJB]
time 10297ms: Process I (tau 43ms) completed a CPU burst; 72 bursts to go [Q GKDONMJB]
time 10297ms: Recalculated tau from 43ms to 40ms for process I [Q GKDONMJB]
time 10297ms: Process I switching out of CPU; will block on I/O until time 10879ms [Q GKDONMJB]
time 10301ms: Process G (tau 49ms) started using the CPU for 5ms burst [Q KDONMJB]
time 10306ms: Process G (tau 49ms) completed a CPU burst; 70 bursts to go [Q KDONMJB]
time 10306ms: Recalculated tau from 49ms to 16ms for process G [Q KDONMJB]
time 10306ms: Process G switching out of CPU; will block on I/O until time 12288ms [Q KDONMJB]
time 10310ms: Process K (tau 61ms) started using the CPU for 4ms burst [Q DONMJB]
time 10314ms: Process K (tau 61ms) completed a CPU burst; 4 bursts to go [Q DONMJB]
time 10314ms: Recalculated tau from 61ms to 19ms for process K [Q DONMJB]
time 10314ms: Process K switching out of CPU; will block on I/O until time 10916ms [Q DONMJB]
time 10318ms: Process D (tau 68ms) started using the CPU for 23ms burst [Q ONMJB]
time 10341ms: Process D (tau 68ms) completed a CPU burst; 4 bursts to go [Q ONMJB]
time 10341ms: Recalculated tau from 68ms to 35ms for process D [Q ONMJB]
time 10341ms: Process D switching out of CPU; will block on I/O until time 12283ms [Q ONMJB]
time 10345ms: Process O (tau 105ms) started using the CPU for 68ms burst [Q NMJB]
time 10413ms: Process O (tau 105ms) completed a CPU burst; 25 bursts to go [Q NMJB]
time 10413ms: Recalculated tau from 105ms to 78ms for process O [Q NMJB]
time 10413ms: Process O switching out of CPU; will block on I/O until time 11585ms [Q NMJB]
time 10417ms: Process N (tau 146ms) started using the CPU for 17ms burst [Q MJB]
time 10434ms: Process N (tau 146ms) completed a CPU burst; 28 bursts to go [Q MJB]
time 10434ms: Recalculated tau from 146ms to 50ms for process N [Q MJB]
time 10434ms: Process N switching out of CPU; will block on I/O until time 11186ms [Q MJB]
time 10438ms: Process M (tau 152ms) started using the CPU for 200ms burst [Q JB]
time 10517ms: Process H (tau 173ms) completed I/O; added to ready queue [Q HJB]
time 10638ms: Process M (tau 152ms) completed a CPU burst; 40 bursts to go [Q HJB]
time 10638ms: Recalculated tau from 152ms to 188ms for process M [Q HJB]
time 10638ms: Process M switching out of CPU; will block on I/O until time 11950ms [Q HJB]
time 10642ms: Process H (tau 173ms) started using the CPU for 2ms burst [Q JB]
time 10644ms: Process H (tau 173ms) completed a CPU burst; 71 bursts to go [Q JB]
time 10644ms: Recalculated tau from 173ms to 45ms for process H [Q JB]
time 10644ms: Process H switching out of CPU; will block on I/O until time 10786ms [Q JB]
time 10648ms: Process J (tau 174ms) started using the CPU for 7ms burst [Q B]
time 10655ms: Process J terminated [Q B]
time 10659ms: Process B (tau 183ms) started using the CPU for 138ms burst [Q empty]
time 10685ms: Process A (tau 34ms) completed I/O; added to ready queue [Q A]
time 10786ms: Process H (tau 45ms) completed I/O; added to ready queue [Q AH]
time 10797ms: Process B (tau 183ms) completed a CPU burst; 12 bursts to go [Q AH]
time 10797ms: Recalculated tau from 183ms to 150ms for process B [Q AH]
time 10797ms: Process B switching out of CPU; will block on I/O until time 11619ms [Q AH]
time 10801ms: Process A (tau 34ms) started using the CPU for 62ms burst [Q H]
time 10863ms: Process A (tau 34ms) completed a CPU burst; 2 bursts to go [Q H]
time 10863ms: Recalculated tau from 34ms to 55ms for process A [Q H]
time 10863ms: Process A switching out of CPU; will block on I/O until time 11635ms [Q H]
time 10867ms: Process H (tau 45ms) started using the CPU for 29ms burst [Q empty]
time 10879ms: Process I (tau 40ms) completed I/O; added to ready queue [Q I]
time 10896ms: Process H (tau 45ms) completed a CPU burst; 70 bursts to go [Q I]
time 10896ms: Recalculated tau from 45ms to 33ms for process H [Q I]
time 10896ms: Process H switching out of CPU; will block on I/O until time 13118ms [Q I]
time 10900ms: Process I (tau 40ms) started using the CPU for 79ms burst [Q empty]
time 10916ms: Process K (tau 19ms) completed I/O; added to ready queue [Q K]
time 10979ms: Process I (tau 40ms) completed a CPU burst; 71 bursts to go [Q K]
time 10979ms: Recalculated tau from 40ms to 70ms for process I [Q K]
time 10979ms: Process I switching out of CPU; will block on I/O until time 12141ms [Q K]
time 10983ms: Process K (tau 19ms) started using the CPU for 21ms burst [Q empty]
time 11004ms: Process K (tau 19ms) completed a CPU burst; 3 bursts to go [Q empty]
time 11004ms: Recalculated tau from 19ms to 21ms for process K [Q empty]
time 11004ms: Process K switching out of CPU; will block on I/O until time 11656ms [Q empty]
time 11064ms: Process F (tau 100ms) completed I/O; added to ready queue [Q F]
time 11066ms: Process F (tau 100ms) started using the CPU for 147ms burst [Q empty]
time 11186ms: Process N (tau 50ms) completed I/O; added to ready queue [Q N]
time 11213ms: Process F (tau 100ms) completed a CPU burst; 22 bursts to go [Q N]
time 11213ms: Recalculated tau from 100ms to 136ms for process F [Q N]
time 11213ms: Process F switching out of CPU; will block on I/O until time 11265ms [Q N]
time 11217ms: Process N (tau 50ms) started using the CPU for 71ms burst [Q empty]
time 11265ms: Process F (tau 136ms) completed I/O; added to ready queue [Q F]
time 11288ms: Process N (tau 50ms) completed a CPU burst; 27 bursts to go [Q F]
time 11288ms: Recalculated tau from 50ms to 66ms for process N [Q F]
time 11288ms: Process N switching out of CPU; will block on I/O until time 13230ms [Q F]
time 11292ms: Process F (tau 136ms) started using the CPU for 97ms burst [Q empty]
time 11389ms: Process F (tau 136ms) completed a CPU burst; 21 bursts to go [Q empty]
time 11389ms: Recalculated tau from 136ms to 107ms for process F [Q empty]
time 11389ms: Process F switching out of CPU; will block on I/O until time 11431ms [Q empty]
time 11431ms: Process F (tau 107ms) completed I/O; added to ready queue [Q F]
time 11433ms: Process F (tau 107ms) started using the CPU for 157ms burst [Q empty]
time 11538ms: Process E (tau 173ms) completed I/O; added to ready queue [Q E]
time 11585ms: Process O (tau 78ms) completed I/O; added to ready queue [Q OE]
time 11590ms: Process F (tau 107ms) completed a CPU burst; 20 bursts to go [Q OE]
time 11590ms: Recalculated tau from 107ms to 145ms for process F [Q OE]
time 11590ms: Process F switching out of CPU; will block on I/O until time 11692ms [Q OE]
time 11594ms: Process O (tau 78ms) started using the CPU for 136ms burst [Q E]
time 11619ms: Process B (tau 150ms) completed I/O; added to ready queue [Q BE]
time 11635ms: Process A (tau 55ms) completed I/O; added to ready queue [Q ABE]
time 11656ms: Process K (tau 21ms) completed I/O; added to ready queue [Q KABE]
time 11692ms: Process F (tau 145ms) completed I/O; added to ready queue [Q KAFBE]
time 11730ms: Process O (tau 78ms) completed a CPU burst; 24 bursts to go [Q KAFBE]
time 11730ms: Recalculated tau from 78ms to 122ms for process O [Q KAFBE]
time 11730ms: Process O switching out of CPU; will block on I/O until time 12782ms [Q KAFBE]
time 11734ms: Process K (tau 21ms) started using the CPU for 120ms burst [Q AFBE]
time 11854ms: Process K (tau 21ms) completed a CPU burst; 2 bursts to go [Q AFBE]
time 11854ms: Recalculated tau from 21ms to 96ms for process K [Q AFBE]
time 11854ms: Process K switching out of CPU; will block on I/O until time 12546ms [Q AFBE]
time 11858ms: Process A (tau 55ms) started using the CPU for 200ms burst [Q FBE]
time 11859ms: Process P (tau 36ms) completed I/O; added to ready queue [Q PFBE]
time 11950ms: Process M (tau 188ms) completed I/O; added to ready queue [Q PFBEM]
time 12058ms: Process A (tau 55ms) completed a CPU burst; 1 burst to go [Q PFBEM]
time 12058ms: Recalculated tau from 55ms to 164ms for process A [Q PFBEM]
time 12058ms: Process A switching out of CPU; will block on I/O until time 12170ms [Q PFBEM]
time 12062ms: Process P (tau 36ms) started using the CPU for 105ms burst [Q FBEM]
time 12141ms: Process I (tau 70ms) completed I/O; added to ready queue [Q IFBEM]
time 12167ms: Process P (tau 36ms) completed a CPU burst; 10 bursts to go [Q IFBEM]
time 12167ms: Recalculated tau from 36ms to 88ms for process P [Q IFBEM]
time 12167ms: Process P switching out of CPU; will block on I/O until time 12759ms [Q IFBEM]
time 12170ms: Process A (tau 164ms) completed I/O; added to ready queue [Q FBAEM]
time 12171ms: Process I (tau 70ms) started using the CPU for 84ms burst [Q FBAEM]
time 12255ms: Process I (tau 70ms) completed a CPU burst; 70 bursts to go [Q FBAEM]
time 12255ms: Recalculated tau from 70ms to 81ms for process I [Q FBAEM]
time 12255ms: Process I switching out of CPU; will block on I/O until time 12767ms [Q FBAEM]
time 12259ms: Process F (tau 145ms) started using the CPU for 24ms burst [Q BAEM]
time 12283ms: Process F (tau 145ms) completed a CPU burst; 19 bursts to go [Q BAEM]
time 12283ms: Recalculated tau from 145ms to 55ms for process F [Q BAEM]
time 12283ms: Process F switching out of CPU; will block on I/O until time 13255ms [Q BAEM]
time 12283ms: Process D (tau 35ms) completed I/O; added to ready queue [Q DBAEM]
time 12287ms: Process D (tau 35ms) started using the CPU for 76ms burst [Q BAEM]
time 12288ms: Process G (tau 16ms) completed I/O; added to ready queue [Q GBAEM]
time 12363ms: Process D (tau 35ms) completed a CPU burst; 3 bursts to go [Q GBAEM]
time 12363ms: Recalculated tau from 35ms to 66ms for process D [Q GBAEM]
time 12363ms: Process D switching out of CPU; will block on I/O until time 13095ms [Q GBAEM]
time 12367ms: Process G (tau 16ms) started using the CPU for 122ms burst [Q BAEM]
time 12489ms: Process G (tau 16ms) completed a CPU burst; 69 bursts to go [Q BAEM]
time 12489ms: Recalculated tau from 16ms to 96ms for process G [Q BAEM]
time 12489ms: Process G switching out of CPU; will block on I/O until time 12841ms [Q BAEM]
time 12493ms: Process B (tau 150ms) started using the CPU for 67ms burst [Q AEM]
time 12546ms: Process K (tau 96ms) completed I/O; added to ready queue [Q KAEM]
time 12560ms: Process B (tau 150ms) completed a CPU burst; 11 bursts to go [Q KAEM]
time 12560ms: Recalculated tau from 150ms to 88ms for process B [Q KAEM]
time 12560ms: Process B switching out of CPU; will block on I/O until time 12632ms [Q KAEM]
time 12564ms: Process K (tau 96ms) started using the CPU for 199ms burst [Q AEM]
time 12632ms: Process B (tau 88ms) completed I/O; added to ready queue [Q BAEM]
time 12759ms: Process P (tau 88ms) completed I/O; added to ready queue [Q BPAEM]
time 12763ms: Process K (tau 96ms) completed a CPU burst; 1 burst to go [Q BPAEM]
time 12763ms: Recalculated tau from 96ms to 174ms for process K [Q BPAEM]
time 12763ms: Process K switching out of CPU; will block on I/O until time 13415ms [Q BPAEM]
time 12767ms: Process B (tau 88ms) started using the CPU for 120ms burst [Q PAEM]
time 12767ms: Process I (tau 81ms) completed I/O; added to ready queue [Q IPAEM]
time 12782ms: Process O (tau 122ms) completed I/O; added to ready queue [Q IPOAEM]
time 12841ms: Process G (tau 96ms) completed I/O; added to ready queue [Q IPGOAEM]
time 12887ms: Process B (tau 88ms) completed a CPU burst; 10 bursts to go [Q IPGOAEM]
time 12887ms: Recalculated tau from 88ms to 112ms for process B [Q IPGOAEM]
time 12887ms: Process B switching out of CPU; will block on I/O until time 13019ms [Q IPGOAEM]
time 12891ms: Process I (tau 81ms) started using the CPU for 27ms burst [Q PGOAEM]
time 12918ms: Process I (tau 81ms) completed a CPU burst; 69 bursts to go [Q PGOAEM]
time 12918ms: Recalculated tau from 81ms to 41ms for process I [Q PGOAEM]
time 12918ms: Process I switching out of CPU; will block on I/O until time 14820ms [Q PGOAEM]
time 12922ms: Process P (tau 88ms) started using the CPU for 16ms burst [Q GOAEM]
time 12938ms: Process P (tau 88ms) completed a CPU burst; 9 bursts to go [Q GOAEM]
time 12938ms: Recalculated tau from 88ms to 34ms for process P [Q GOAEM]
time 12938ms: Process P switching out of CPU; will block on I/O until time 13590ms [Q GOAEM]
time 12942ms: Process G (tau 96ms) started using the CPU for 31ms burst [Q OAEM]
time 12973ms: Process G (tau 96ms) completed a CPU burst; 68 bursts to go [Q OAEM]
time 12973ms: Recalculated tau from 96ms to 48ms for process G [Q OAEM]
time 12973ms: Process G switching out of CPU; will block on I/O until time 13045ms [Q OAEM]
time 12977ms: Process O (tau 122ms) started using the CPU for 69ms burst [Q AEM]
time 13019ms: Process B (tau 112ms) completed I/O; added to ready queue [Q BAEM]
time 13045ms: Process G (tau 48ms) completed I/O; added to ready queue [Q GBAEM]
time 13046ms: Process O (tau 122ms) completed a CPU burst; 23 bursts to go [Q GBAEM]
time 13046ms: Recalculated tau from 122ms to 83ms for process O [Q GBAEM]
time 13046ms: Process O switching out of CPU; will block on I/O until time 13798ms [Q GBAEM]
time 13050ms: Process G (tau 48ms) started using the CPU for 61ms burst [Q BAEM]
time 13095ms: Process D (tau 66ms) completed I/O; added to ready queue [Q DBAEM]
time 13111ms: Process G (tau 48ms) completed a CPU burst; 67 bursts to go [Q DBAEM]
time 13111ms: Recalculated tau from 48ms to 58ms for process G [Q DBAEM]
time 13111ms: Process G switching out of CPU; will block on I/O until time 13853ms [Q DBAEM]
time 13115ms: Process D (tau 66ms) started using the CPU for 50ms burst [Q BAEM]
time 13118ms: Process H (tau 33ms) completed I/O; added to ready queue [Q HBAEM]
time 13165ms: Process D (tau 66ms) completed a CPU burst; 2 bursts to go [Q HBAEM]
time 13165ms: Recalculated tau from 66ms to 54ms for process D [Q HBAEM]
time 13165ms: Process D switching out of CPU; will block on I/O until time 13287ms [Q HBAEM]
time 13169ms: Process H (tau 33ms) started using the CPU for 76ms burst [Q BAEM]
time 13230ms: Process N (tau 66ms) completed I/O; added to ready queue [Q NBAEM]
time 13245ms: Process H (tau 33ms) completed a CPU burst; 69 bursts to go [Q NBAEM]
time 13245ms: Recalculated tau from 33ms to 66ms for process H [Q NBAEM]
time 13245ms: Process H switching out of CPU; will block on I/O until time 15367ms [Q NBAEM]
time 13249ms: Process N (tau 66ms) started using the CPU for 27ms burst [Q BAEM]
time 13255ms: Process F (tau 55ms) completed I/O; added to ready queue [Q FBAEM]
time 13276ms: Process N (tau 66ms) completed a CPU burst; 26 bursts to go [Q FBAEM]
time 13276ms: Recalculated tau from 66ms to 37ms for process N [Q FBAEM]
time 13276ms: Process N switching out of CPU; will block on I/O until time 13548ms [Q FBAEM]
time 13280ms: Process F (tau 55ms) started using the CPU for 31ms burst [Q BAEM]
time 13287ms: Process D (tau 54ms) completed I/O; added to ready queue [Q DBAEM]
time 13311ms: Process F (tau 55ms) completed a CPU burst; 18 bursts to go [Q DBAEM]
time 13311ms: Recalculated tau from 55ms to 37ms for process F [Q DBAEM]
time 13311ms: Process F switching out of CPU; will block on I/O until time 13523ms [Q DBAEM]
time 13315ms: Process D (tau 54ms) started using the CPU for 24ms burst [Q BAEM]
time 13339ms: Process D (tau 54ms) completed a CPU burst; 1 burst to go [Q BAEM]
time 13339ms: Recalculated tau from 54ms to 32ms for process D [Q BAEM]
time 13339ms: Process D switching out of CPU; will block on I/O until time 13591ms [Q BAEM]
time 13343ms: Process B (tau 112ms) started using the CPU for 49ms burst [Q AEM]
time 13392ms: Process B (tau 112ms) completed a CPU burst; 9 bursts to go [Q AEM]
time 13392ms: Recalculated tau from 112ms to 65ms for process B [Q AEM]
time 13392ms: Process B switching out of CPU; will block on I/O until time 13814ms [Q AEM]
time 13396ms: Process A (tau 164ms) started using the CPU for 197ms burst [Q EM]
time 13415ms: Process K (tau 174ms) completed I/O; added to ready queue [Q EKM]
time 13523ms: Process F (tau 37ms) completed I/O; added to ready queue [Q FEKM]
time 13548ms: Process N (tau 37ms) completed I/O; added to ready queue [Q FNEKM]
time 13590ms: Process P (tau 34ms) completed I/O; added to ready queue [Q PFNEKM]
time 13591ms: Process D (tau 32ms) completed I/O; added to ready queue [Q DPFNEKM]
time 13593ms: Process A terminated [Q DPFNEKM]
time 13597ms: Process D (tau 32ms) started using the CPU for 1ms burst [Q PFNEKM]
time 13598ms: Process D terminated [Q PFNEKM]
time 13602ms: Process P (tau 34ms) started using the CPU for 219ms burst [Q FNEKM]
time 13798ms: Process O (tau 83ms) completed I/O; added to ready queue [Q FNOEKM]
time 13814ms: Process B (tau 65ms) completed I/O; added to ready queue [Q FNBOEKM]
time 13821ms: Process P (tau 34ms) completed a CPU burst; 8 bursts to go [Q FNBOEKM]
time 13821ms: Recalculated tau from 34ms to 173ms for process P [Q FNBOEKM]
time 13821ms: Process P switching out of CPU; will block on I/O until time 15873ms [Q FNBOEKM]
time 13825ms: Process F (tau 37ms) started using the CPU for 24ms burst [Q NBOEKM]
time 13849ms: Process F (tau 37ms) completed a CPU burst; 17 bursts to go [Q NBOEKM]
time 13849ms: Recalculated tau from 37ms to 28ms for process F [Q NBOEKM]
time 13849ms: Process F switching out of CPU; will block on I/O until time 14441ms [Q NBOEKM]
time 13853ms: Process N (tau 37ms) started using the CPU for 57ms burst [Q BOEKM]
time 13853ms: Process G (tau 58ms) completed I/O; added to ready queue [Q GBOEKM]
time 13910ms: Process N (tau 37ms) completed a CPU burst; 25 bursts to go [Q GBOEKM]
time 13910ms: Recalculated tau from 37ms to 52ms for process N [Q GBOEKM]
time 13910ms: Process N switching out of CPU; will block on I/O until time 14012ms [Q GBOEKM]
time 13914ms: Process G (tau 58ms) started using the CPU for 7ms burst [Q BOEKM]
time 13921ms: Process G (tau 58ms) completed a CPU burst; 66 bursts to go [Q BOEKM]
time 13921ms: Recalculated tau from 58ms to 20ms for process G [Q BOEKM]
time 13921ms: Process G switching out of CPU; will block on I/O until time 15563ms [Q BOEKM]
time 13925ms: Process B (tau 65ms) started using the CPU for 134ms burst [Q OEKM]
time 14012ms: Process N (tau 52ms) completed I/O; added to ready queue [Q NOEKM]
time 14059ms: Process B (tau 65ms) completed a CPU burst; 8 bursts to go [Q NOEKM]
time 14059ms: Recalculated tau from 65ms to 117ms for process B [Q NOEKM]
time 14059ms: Process B switching out of CPU; will block on I/O until time 14381ms [Q NOEKM]
time 14063ms: Process N (tau 52ms) started using the CPU for 84ms burst [Q OEKM]
time 14147ms: Process N (tau 52ms) completed a CPU burst; 24 bursts to go [Q OEKM]
time 14147ms: Recalculated tau from 52ms to 76ms for process N [Q OEKM]
time 14147ms: Process N switching out of CPU; will block on I/O until time 14169ms [Q OEKM]
time 14151ms: Process O (tau 83ms) started using the CPU for 6ms burst [Q EKM]
time 14157ms: Process O (tau 83ms) completed a CPU burst; 22 bursts to go [Q EKM]
time 14157ms: Recalculated tau from 83ms to 26ms for process O [Q EKM]
time 14157ms: Process O switching out of CPU; will block on I/O until time 15799ms [Q EKM]
time 14161ms: Process E (tau 173ms) started using the CPU for 54ms burst [Q KM]
time 14169ms: Process N (tau 76ms) completed I/O; added to ready queue [Q NKM]
time 14215ms: Process E (tau 173ms) completed a CPU burst; 43 bursts to go [Q NKM]
time 14215ms: Recalculated tau from 173ms to 84ms for process E [Q NKM]
time 14215ms: Process E switching out of CPU; will block on I/O until time 15167ms [Q NKM]
time 14219ms: Process N (tau 76ms) started using the CPU for 131ms burst [Q KM]
time 14350ms: Process N (tau 76ms) completed a CPU burst; 23 bursts to go [Q KM]
time 14350ms: Recalculated tau from 76ms to 118ms for process N [Q KM]
time 14350ms: Process N switching out of CPU; will block on I/O until time 14582ms [Q KM]
time 14354ms: Process K (tau 174ms) started using the CPU for 47ms burst [Q M]
time 14381ms: Process B (tau 117ms) completed I/O; added to ready queue [Q BM]
time 14401ms: Process K terminated [Q BM]
time 14405ms: Process B (tau 117ms) started using the CPU for 144ms burst [Q M]
time 14441ms: Process F (tau 28ms) completed I/O; added to ready queue [Q FM]
time 14549ms: Process B (tau 117ms) completed a CPU burst; 7 bursts to go [Q FM]
time 14549ms: Recalculated tau from 117ms to 138ms for process B [Q FM]
time 14549ms: Process B switching out of CPU; will block on I/O until time 15341ms [Q FM]
time 14553ms: Process F (tau 28ms) started using the CPU for 135ms burst [Q M]
time 14582ms: Process N (tau 118ms) completed I/O; added to ready queue [Q NM]
time 14688ms: Process F (tau 28ms) completed a CPU burst; 16 bursts to go [Q NM]
time 14688ms: Recalculated tau from 28ms to 109ms for process F [Q NM]
time 14688ms: Process F switching out of CPU; will block on I/O until time 15310ms [Q NM]
time 14692ms: Process N (tau 118ms) started using the CPU for 222ms burst [Q M]
time 14820ms: Process I (tau 41ms) completed I/O; added to ready queue [Q IM]
time 14914ms: Process N (tau 118ms) completed a CPU burst; 22 bursts to go [Q IM]
time 14914ms: Recalculated tau from 118ms to 196ms for process N [Q IM]
time 14914ms: Process N switching out of CPU; will block on I/O until time 14966ms [Q IM]
time 14918ms: Process I (tau 41ms) started using the CPU for 70ms burst [Q M]
time 14966ms: Process N (tau 196ms) completed I/O; added to ready queue [Q MN]
time 14988ms: Process I (tau 41ms) completed a CPU burst; 68 bursts to go [Q MN]
time 14988ms: Recalculated tau from 41ms to 63ms for process I [Q MN]
time 14988ms: Process I switching out of CPU; will block on I/O until time 16530ms [Q MN]
time 14992ms: Process M (tau 188ms) started using the CPU for 117ms burst [Q N]
time 15109ms: Process M (tau 188ms) completed a CPU burst; 39 bursts to go [Q N]
time 15109ms: Recalculated tau from 188ms to 135ms for process M [Q N]
time 15109ms: Process M switching out of CPU; will block on I/O until time 16451ms [Q N]
time 15113ms: Process N (tau 196ms) started using the CPU for 148ms burst [Q empty]
time 15167ms: Process E (tau 84ms) completed I/O; added to ready queue [Q E]
time 15261ms: Process N (tau 196ms) completed a CPU burst; 21 bursts to go [Q E]
time 15261ms: Recalculated tau from 196ms to 160ms for process N [Q E]
time 15261ms: Process N switching out of CPU; will block on I/O until time 16643ms [Q E]
time 15265ms: Process E (tau 84ms) started using the CPU for 126ms burst [Q empty]
time 15310ms: Process F (tau 109ms) completed I/O; added to ready queue [Q F]
time 15341ms: Process B (tau 138ms) completed I/O; added to ready queue [Q FB]
time 15367ms: Process H (tau 66ms) completed I/O; added to ready queue [Q HFB]
time 15391ms: Process E (tau 84ms) completed a CPU burst; 42 bursts to go [Q HFB]
time 15391ms: Recalculated tau from 84ms to 116ms for process E [Q HFB]
time 15391ms: Process E switching out of CPU; will block on I/O until time 17373ms [Q HFB]
time 15395ms: Process H (tau 66ms) started using the CPU for 143ms burst [Q FB]
time 15538ms: Process H (tau 66ms) completed a CPU burst; 68 bursts to go [Q FB]
time 15538ms: Recalculated tau from 66ms to 124ms for process H [Q FB]
time 15538ms: Process H switching out of CPU; will block on I/O until time 17380ms [Q FB]
time 15542ms: Process F (tau 109ms) started using the CPU for 87ms burst [Q B]
time 15563ms: Process G (tau 20ms) completed I/O; added to ready queue [Q GB]
time 15629ms: Process F (tau 109ms) completed a CPU burst; 15 bursts to go [Q GB]
time 15629ms: Recalculated tau from 109ms to 93ms for process F [Q GB]
time 15629ms: Process F switching out of CPU; will block on I/O until time 16671ms [Q GB]
time 15633ms: Process G (tau 20ms) started using the CPU for 2ms burst [Q B]
time 15635ms: Process G (tau 20ms) completed a CPU burst; 65 bursts to go [Q B]
time 15635ms: Recalculated tau from 20ms to 7ms for process G [Q B]
time 15635ms: Process G switching out of CPU; will block on I/O until time 15747ms [Q B]
time 15639ms: Process B (tau 138ms) started using the CPU for 183ms burst [Q empty]
time 15747ms: Process G (tau 7ms) completed I/O; added to ready queue [Q G]
time 15799ms: Process O (tau 26ms) completed I/O; added to ready queue [Q GO]
time 15822ms: Process B (tau 138ms) completed a CPU burst; 6 bursts to go [Q GO]
time 15822ms: Recalculated tau from 138ms to 172ms for process B [Q GO]
time 15822ms: Process B switching out of CPU; will block on I/O until time 15884ms [Q GO]
time 15826ms: Process G (tau 7ms) started using the CPU for 209ms burst [Q O]
time 15873ms: Process P (tau 173ms) completed I/O; added to ready queue [Q OP]
time 15884ms: Process B (tau 172ms) completed I/O; added to ready queue [Q OBP]
time 16035ms: Process G (tau 7ms) completed a CPU burst; 64 bursts to go [Q OBP]
time 16035ms: Recalculated tau from 7ms to 159ms for process G [Q OBP]
time 16035ms: Process G switching out of CPU; will block on I/O until time 16517ms [Q OBP]
time 16039ms: Process O (tau 26ms) started using the CPU for 187ms burst [Q BP]
time 16226ms: Process O (tau 26ms) completed a CPU burst; 21 bursts to go [Q BP]
time 16226ms: Recalculated tau from 26ms to 147ms for process O [Q BP]
time 16226ms: Process O switching out of CPU; will block on I/O until time 17898ms [Q BP]
time 16230ms: Process B (tau 172ms) started using the CPU for 219ms burst [Q P]
time 16449ms: Process B (tau 172ms) completed a CPU burst; 5 bursts to go [Q P]
time 16449ms: Recalculated tau from 172ms to 208ms for process B [Q P]
time 16449ms: Process B switching out of CPU; will block on I/O until time 16681ms [Q P]
time 16451ms: Process M (tau 135ms) completed I/O; added to ready queue [Q MP]
time 16453ms: Process M (tau 135ms) started using the CPU for 6ms burst [Q P]
time 16459ms: Process M (tau 135ms) completed a CPU burst; 38 bursts to go [Q P]
time 16459ms: Recalculated tau from 135ms to 39ms for process M [Q P]
time 16459ms: Process M switching out of CPU; will block on I/O until time 16791ms [Q P]
time 16463ms: Process P (tau 173ms) started using the CPU for 70ms burst [Q empty]
time 16517ms: Process G (tau 159ms) completed I/O; added to ready queue [Q G]
time 16530ms: Process I (tau 63ms) completed I/O; added to ready queue [Q IG]
time 16533ms: Process P (tau 173ms) completed a CPU burst; 7 bursts to go [Q IG]
time 16533ms: Recalculated tau from 173ms to 96ms for process P [Q IG]
time 16533ms: Process P switching out of CPU; will block on I/O until time 17805ms [Q IG]
time 16537ms: Process I (tau 63ms) started using the CPU for 107ms burst [Q G]
time 16643ms: Process N (tau 160ms) completed I/O; added to ready queue [Q GN]
time 16644ms: Process I (tau 63ms) completed a CPU burst; 67 bursts to go [Q GN]
time 16644ms: Recalculated tau from 63ms to 96ms for process I [Q GN]
time 16644ms: Process I switching out of CPU; will block on I/O until time 17116ms [Q GN]
time 16648ms: Process G (tau 159ms) started using the CPU for 6ms burst [Q N]
time 16654ms: Process G (tau 159ms) completed a CPU burst; 63 bursts to go [Q N]
time 16654ms: Recalculated tau from 159ms to 45ms for process G [Q N]
time 16654ms: Process G switching out of CPU; will block on I/O until time 18136ms [Q N]
time 16658ms: Process N (tau 160ms) started using the CPU for 32ms burst [Q empty]
time 16671ms: Process F (tau 93ms) completed I/O; added to ready queue [Q F]
time 16681ms: Process B (tau 208ms) completed I/O; added to ready queue [Q FB]
time 16690ms: Process N (tau 160ms) completed a CPU burst; 20 bursts to go [Q FB]
time 16690ms: Recalculated tau from 160ms to 64ms for process N [Q FB]
time 16690ms: Process N switching out of CPU; will block on I/O until time 18272ms [Q FB]
time 16694ms: Process F (tau 93ms) started using the CPU for 22ms burst [Q B]
time 16716ms: Process F (tau 93ms) completed a CPU burst; 14 bursts to go [Q B]
time 16716ms: Recalculated tau from 93ms to 40ms for process F [Q B]
time 16716ms: Process F switching out of CPU; will block on I/O until time 16868ms [Q B]
time 16720ms: Process B (tau 208ms) started using the CPU for 64ms burst [Q empty]
time 16784ms: Process B (tau 208ms) completed a CPU burst; 4 bursts to go [Q empty]
time 16784ms: Recalculated tau from 208ms to 100ms for process B [Q empty]
time 16784ms: Process B switching out of CPU; will block on I/O until time 17586ms [Q empty]
time 16791ms: Process M (tau 39ms) completed I/O; added to ready queue [Q M]
time 16793ms: Process M (tau 39ms) started using the CPU for 141ms burst [Q empty]
time 16868ms: Process F (tau 40ms) completed I/O; added to ready queue [Q F]
time 16934ms: Process M (tau 39ms) completed a CPU burst; 37 bursts to go [Q F]
time 16934ms: Recalculated tau from 39ms to 116ms for process M [Q F]
time 16934ms: Process M switching out of CPU; will block on I/O until time 17156ms [Q F]
time 16938ms: Process F (tau 40ms) started using the CPU for 52ms burst [Q empty]
time 16990ms: Process F (tau 40ms) completed a CPU burst; 13 bursts to go [Q empty]
time 16990ms: Recalculated tau from 40ms to 49ms for process F [Q empty]
time 16990ms: Process F switching out of CPU; will block on I/O until time 17082ms [Q empty]
time 17082ms: Process F (tau 49ms) completed I/O; added to ready queue [Q F]
time 17084ms: Process F (tau 49ms) started using the CPU for 90ms burst [Q empty]
time 17116ms: Process I (tau 96ms) completed I/O; added to ready queue [Q I]
time 17156ms: Process M (tau 116ms) completed I/O; added to ready queue [Q IM]
time 17174ms: Process F (tau 49ms) completed a CPU burst; 12 bursts to go [Q IM]
time 17174ms: Recalculated tau from 49ms to 80ms for process F [Q IM]
time 17174ms: Process F switching out of CPU; will block on I/O until time 19386ms [Q IM]
time 17178ms: Process I (tau 96ms) started using the CPU for 21ms burst [Q M]
time 17199ms: Process I (tau 96ms) completed a CPU burst; 66 bursts to go [Q M]
time 17199ms: Recalculated tau from 96ms to 40ms for process I [Q M]
time 17199ms: Process I switching out of CPU; will block on I/O until time 17291ms [Q M]
time 17203ms: Process M (tau 116ms) started using the CPU for 13ms burst [Q empty]
time 17216ms: Process M (tau 116ms) completed a CPU burst; 36 bursts to go [Q empty]
time 17216ms: Recalculated tau from 116ms to 39ms for process M [Q empty]
time 17216ms: Process M switching out of CPU; will block on I/O until time 17338ms [Q empty]
time 17291ms: Process I (tau 40ms) completed I/O; added to ready queue [Q I]
time 17293ms: Process I (tau 40ms) started using the CPU for 179ms burst [Q empty]
time 17338ms: Process M (tau 39ms) completed I/O; added to ready queue [Q M]
time 17373ms: Process E (tau 116ms) completed I/O; added to ready queue [Q ME]
time 17380ms: Process H (tau 124ms) completed I/O; added to ready queue [Q MEH]
time 17472ms: Process I (tau 40ms) completed a CPU burst; 65 bursts to go [Q MEH]
time 17472ms: Recalculated tau from 40ms to 145ms for process I [Q MEH]
time 17472ms: Process I switching out of CPU; will block on I/O until time 18474ms [Q MEH]
time 17476ms: Process M (tau 39ms) started using the CPU for 103ms burst [Q EH]
time 17579ms: Process M (tau 39ms) completed a CPU burst; 35 bursts to go [Q EH]
time 17579ms: Recalculated tau from 39ms to 87ms for process M [Q EH]
time 17579ms: Process M switching out of CPU; will block on I/O until time 17721ms [Q EH]
time 17583ms: Process E (tau 116ms) started using the CPU for 168ms burst [Q H]
time 17586ms: Process B (tau 100ms) completed I/O; added to ready queue [Q BH]
time 17721ms: Process M (tau 87ms) completed I/O; added to ready queue [Q MBH]
time 17751ms: Process E (tau 116ms) completed a CPU burst; 41 bursts to go [Q MBH]
time 17751ms: Recalculated tau from 116ms to 155ms for process E [Q MBH]
time 17751ms: Process E switching out of CPU; will block on I/O until time 18253ms [Q MBH]
time 17755ms: Process M (tau 87ms) started using the CPU for 15ms burst [Q BH]
time 17770ms: Process M (tau 87ms) completed a CPU burst; 34 bursts to go [Q BH]
time 17770ms: Recalculated tau from 87ms to 33ms for process M [Q BH]
time 17770ms: Process M switching out of CPU; will block on I/O until time 18882ms [Q BH]
time 17774ms: Process B (tau 100ms) started using the CPU for 33ms burst [Q H]
time 17805ms: Process P (tau 96ms) completed I/O; added to ready queue [Q PH]
time 17807ms: Process B (tau 100ms) completed a CPU burst; 3 bursts to go [Q PH]
time 17807ms: Recalculated tau from 100ms to 50ms for process B [Q PH]
time 17807ms: Process B switching out of CPU; will block on I/O until time 18549ms [Q PH]
time 17811ms: Process P (tau 96ms) started using the CPU for 55ms burst [Q H]
time 17866ms: Process P (tau 96ms) completed a CPU burst; 6 bursts to go [Q H]
time 17866ms: Recalculated tau from 96ms to 66ms for process P [Q H]
time 17866ms: Process P switching out of CPU; will block on I/O until time 20318ms [Q H]
time 17870ms: Process H (tau 124ms) started using the CPU for 32ms burst [Q empty]
time 17898ms: Process O (tau 147ms) completed I/O; added to ready queue [Q O]
time 17902ms: Process H (tau 124ms) completed a CPU burst; 67 bursts to go [Q O]
time 17902ms: Recalculated tau from 124ms to 55ms for process H [Q O]
time 17902ms: Process H switching out of CPU; will block on I/O until time 18724ms [Q O]
time 17906ms: Process O (tau 147ms) started using the CPU for 89ms burst [Q empty]
time 17995ms: Process O (tau 147ms) completed a CPU burst; 20 bursts to go [Q empty]
time 17995ms: Recalculated tau from 147ms to 104ms for process O [Q empty]
time 17995ms: Process O switching out of CPU; will block on I/O until time 19397ms [Q empty]
time 18136ms: Process G (tau 45ms) completed I/O; added to ready queue [Q G]
time 18138ms: Process G (tau 45ms) started using the CPU for 37ms burst [Q empty]
time 18175ms: Process G (tau 45ms) completed a CPU burst; 62 bursts to go [Q empty]
time 18175ms: Recalculated tau from 45ms to 39ms for process G [Q empty]
time 18175ms: Process G switching out of CPU; will block on I/O until time 19487ms [Q empty]
time 18253ms: Process E (tau 155ms) completed I/O; added to ready queue [Q E]
time 18255ms: Process E (tau 155ms) started using the CPU for 23ms burst [Q empty]
time 18272ms: Process N (tau 64ms) completed I/O; added to ready queue [Q N]
time 18278ms: Process E (tau 155ms) completed a CPU burst; 40 bursts to go [Q N]
time 18278ms: Recalculated tau from 155ms to 56ms for process E [Q N]
time 18278ms: Process E switching out of CPU; will block on I/O until time 18370ms [Q N]
time 18282ms: Process N (tau 64ms) started using the CPU for 97ms burst [Q empty]
time 18370ms: Process E (tau 56ms) completed I/O; added to ready queue [Q E]
time 18379ms: Process N (tau 64ms) completed a CPU burst; 19 bursts to go [Q E]
time 18379ms: Recalculated tau from 64ms to 89ms for process N [Q E]
time 18379ms: Process N switching out of CPU; will block on I/O until time 19291ms [Q E]
time 18383ms: Process E (tau 56ms) started using the CPU for 68ms burst [Q empty]
time 18451ms: Process E (tau 56ms) completed a CPU burst; 39 bursts to go [Q empty]
time 18451ms: Recalculated tau from 56ms to 65ms for process E [Q empty]
time 18451ms: Process E switching out of CPU; will block on I/O until time 19033ms [Q empty]
time 18474ms: Process I (tau 145ms) completed I/O; added to ready queue [Q I]
time 18476ms: Process I (tau 145ms) started using the CPU for 65ms burst [Q empty]
time 18541ms: Process I (tau 145ms) completed a CPU burst; 64 bursts to go [Q empty]
time 18541ms: Recalculated tau from 145ms to 85ms for process I [Q empty]
time 18541ms: Process I switching out of CPU; will block on I/O until time 18863ms [Q empty]
time 18549ms: Process B (tau 50ms) completed I/O; added to ready queue [Q B]
time 18551ms: Process B (tau 50ms) started using the CPU for 63ms burst [Q empty]
time 18614ms: Process B (tau 50ms) completed a CPU burst; 2 bursts to go [Q empty]
time 18614ms: Recalculated tau from 50ms to 60ms for process B [Q empty]
time 18614ms: Process B switching out of CPU; will block on I/O until time 20926ms [Q empty]
time 18724ms: Process H (tau 55ms) completed I/O; added to ready queue [Q H]
time 18726ms: Process H (tau 55ms) started using the CPU for 78ms burst [Q empty]
time 18804ms: Process H (tau 55ms) completed a CPU burst; 66 bursts to go [Q empty]
time 18804ms: Recalculated tau from 55ms to 73ms for process H [Q empty]
time 18804ms: Process H switching out of CPU; will block on I/O until time 18866ms [Q empty]
time 18863ms: Process I (tau 85ms) completed I/O; added to ready queue [Q I]
time 18866ms: Process H (tau 73ms) completed I/O; added to ready queue [Q HI]
time 18865ms: Process H (tau 73ms) started using the CPU for 16ms burst [Q I]
time 18881ms: Process H (tau 73ms) completed a CPU burst; 65 bursts to go [Q I]
time 18881ms: Recalculated tau from 73ms to 31ms for process H [Q I]
time 18881ms: Process H switching out of CPU; will block on I/O until time 19433ms [Q I]
time 18882ms: Process M (tau 33ms) completed I/O; added to ready queue [Q MI]
time 18885ms: Process M (tau 33ms) started using the CPU for 26ms burst [Q I]
time 18911ms: Process M (tau 33ms) completed a CPU burst; 33 bursts to go [Q I]
time 18911ms: Recalculated tau from 33ms to 28ms for process M [Q I]
time 18911ms: Process M switching out of CPU; will block on I/O until time 19513ms [Q I]
time 18915ms: Process I (tau 85ms) started using the CPU for 58ms burst [Q empty]
time 18973ms: Process I (tau 85ms) completed a CPU burst; 63 bursts to go [Q empty]
time 18973ms: Recalculated tau from 85ms to 65ms for process I [Q empty]
time 18973ms: Process I switching out of CPU; will block on I/O until time 20715ms [Q empty]
time 19033ms: Process E (tau 65ms) completed I/O; added to ready queue [Q E]
time 19035ms: Process E (tau 65ms) started using the CPU for 41ms burst [Q empty]
time 19076ms: Process E (tau 65ms) completed a CPU burst; 38 bursts to go [Q empty]
time 19076ms: Recalculated tau from 65ms to 47ms for process E [Q empty]
time 19076ms: Process E switching out of CPU; will block on I/O until time 19278ms [Q empty]
time 19278ms: Process E (tau 47ms) completed I/O; added to ready queue [Q E]
time 19280ms: Process E (tau 47ms) started using the CPU for 44ms burst [Q empty]
time 19291ms: Process N (tau 89ms) completed I/O; added to ready queue [Q N]
time 19324ms: Process E (tau 47ms) completed a CPU burst; 37 bursts to go [Q N]
time 19324ms: Recalculated tau from 47ms to 45ms for process E [Q N]
time 19324ms: Process E switching out of CPU; will block on I/O until time 19936ms [Q N]
time 19328ms: Process N (tau 89ms) started using the CPU for 39ms burst [Q empty]
time 19367ms: Process N (tau 89ms) completed a CPU burst; 18 bursts to go [Q empty]
time 19367ms: Recalculated tau from 89ms to 52ms for process N [Q empty]
time 19367ms: Process N switching out of CPU; will block on I/O until time 19379ms [Q empty]
time 19379ms: Process N (tau 52ms) completed I/O; added to ready queue [Q N]
time 19381ms: Process N (tau 52ms) started using the CPU for 137ms burst [Q empty]
time 19386ms: Process F (tau 80ms) completed I/O; added to ready queue [Q F]
time 19397ms: Process O (tau 104ms) completed I/O; added to ready queue [Q FO]
time 19433ms: Process H (tau 31ms) completed I/O; added to ready queue [Q HFO]
time 19487ms: Process G (tau 39ms) completed I/O; added to ready queue [Q HGFO]
time 19513ms: Process M (tau 28ms) completed I/O; added to ready queue [Q MHGFO]
time 19518ms: Process N (tau 52ms) completed a CPU burst; 17 bursts to go [Q MHGFO]
time 19518ms: Recalculated tau from 52ms to 116ms for process N [Q MHGFO]
time 19518ms: Process N switching out of CPU; will block on I/O until time 19710ms [Q MHGFO]
time 19522ms: Process M (tau 28ms) started using the CPU for 74ms burst [Q HGFO]
time 19596ms: Process M (tau 28ms) completed a CPU burst; 32 bursts to go [Q HGFO]
time 19596ms: Recalculated tau from 28ms to 63ms for process M [Q HGFO]
time 19596ms: Process M switching out of CPU; will block on I/O until time 20808ms [Q HGFO]
time 19600ms: Process H (tau 31ms) started using the CPU for 142ms burst [Q GFO]
time 19710ms: Process N (tau 116ms) completed I/O; added to ready queue [Q GFON]
time 19742ms: Process H (tau 31ms) completed a CPU burst; 64 bursts to go [Q GFON]
time 19742ms: Recalculated tau from 31ms to 115ms for process H [Q GFON]
time 19742ms: Process H switching out of CPU; will block on I/O until time 20714ms [Q GFON]
time 19746ms: Process G (tau 39ms) started using the CPU for 15ms burst [Q FON]
time 19761ms: Process G (tau 39ms) completed a CPU burst; 61 bursts to go [Q FON]
time 19761ms: Recalculated tau from 39ms to 21ms for process G [Q FON]
time 19761ms: Process G switching out of CPU; will block on I/O until time 19983ms [Q FON]
time 19765ms: Process F (tau 80ms) started using the CPU for 4ms burst [Q ON]
time 19769ms: Process F (tau 80ms) completed a CPU burst; 11 bursts to go [Q ON]
time 19769ms: Recalculated tau from 80ms to 23ms for process F [Q ON]
time 19769ms: Process F switching out of CPU; will block on I/O until time 20321ms [Q ON]
time 19773ms: Process O (tau 104ms) started using the CPU for 45ms burst [Q N]
time 19818ms: Process O (tau 104ms) completed a CPU burst; 19 bursts to go [Q N]
time 19818ms: Recalculated tau from 104ms to 60ms for process O [Q N]
time 19818ms: Process O switching out of CPU; will block on I/O until time 20280ms [Q N]
time 19822ms: Process N (tau 116ms) started using the CPU for 189ms burst [Q empty]
time 19936ms: Process E (tau 45ms) completed I/O; added to ready queue [Q E]
time 19983ms: Process G (tau 21ms) completed I/O; added to ready queue [Q GE]
time 20011ms: Process N (tau 116ms) completed a CPU burst; 16 bursts to go [Q GE]
time 20011ms: Recalculated tau from 116ms to 171ms for process N [Q GE]
time 20011ms: Process N switching out of CPU; will block on I/O until time 21643ms [Q GE]
time 20015ms: Process G (tau 21ms) started using the CPU for 47ms burst [Q E]
time 20062ms: Process G (tau 21ms) completed a CPU burst; 60 bursts to go [Q E]
time 20062ms: Recalculated tau from 21ms to 41ms for process G [Q E]
time 20062ms: Process G switching out of CPU; will block on I/O until time 20824ms [Q E]
time 20066ms: Process E (tau 45ms) started using the CPU for 74ms burst [Q empty]
time 20140ms: Process E (tau 45ms) completed a CPU burst; 36 bursts to go [Q empty]
time 20140ms: Recalculated tau from 45ms to 67ms for process E [Q empty]
time 20140ms: Process E switching out of CPU; will block on I/O until time 22002ms [Q empty]
time 20280ms: Process O (tau 60ms) completed I/O; added to ready queue [Q O]
time 20282ms: Process O (tau 60ms) started using the CPU for 50ms burst [Q empty]
time 20318ms: Process P (tau 66ms) completed I/O; added to ready queue [Q P]
time 20321ms: Process F (tau 23ms) completed I/O; added to ready queue [Q FP]
time 20332ms: Process O (tau 60ms) completed a CPU burst; 18 bursts to go [Q FP]
time 20332ms: Recalculated tau from 60ms to 53ms for process O [Q FP]
time 20332ms: Process O switching out of CPU; will block on I/O until time 21444ms [Q FP]
time 20336ms: Process F (tau 23ms) started using the CPU for 30ms burst [Q P]
time 20366ms: Process F (tau 23ms) completed a CPU burst; 10 bursts to go [Q P]
time 20366ms: Recalculated tau from 23ms to 29ms for process F [Q P]
time 20366ms: Process F switching out of CPU; will block on I/O until time 20828ms [Q P]
time 20370ms: Process P (tau 66ms) started using the CPU for 212ms burst [Q empty]
time 20582ms: Process P (tau 66ms) completed a CPU burst; 5 bursts to go [Q empty]
time 20582ms: Recalculated tau from 66ms to 176ms for process P [Q empty]
time 20582ms: Process P switching out of CPU; will block on I/O until time 22754ms [Q empty]
time 20714ms: Process H (tau 115ms) completed I/O; added to ready queue [Q H]
time 20715ms: Process I (tau 65ms) completed I/O; added to ready queue [Q IH]
time 20716ms: Process I (tau 65ms) started using the CPU for 95ms burst [Q H]
time 20808ms: Process M (tau 63ms) completed I/O; added to ready queue [Q MH]
time 20811ms: Process I (tau 65ms) completed a CPU burst; 62 bursts to go [Q MH]
time 20811ms: Recalculated tau from 65ms to 88ms for process I [Q MH]
time 20811ms: Process I switching out of CPU; will block on I/O until time 22233ms [Q MH]
time 20815ms: Process M (tau 63ms) started using the CPU for 6ms burst [Q H]
time 20821ms: Process M (tau 63ms) completed a CPU burst; 31 bursts to go [Q H]
time 20821ms: Recalculated tau from 63ms to 21ms for process M [Q H]
time 20821ms: Process M switching out of CPU; will block on I/O until time 21863ms [Q H]
time 20824ms: Process G (tau 41ms) completed I/O; added to ready queue [Q G]
time 20825ms: Process G (tau 41ms) started using the CPU for 82ms burst [Q H]
time 20828ms: Process F (tau 29ms) completed I/O; added to ready queue [Q FH]
time 20907ms: Process G (tau 41ms) completed a CPU burst; 59 bursts to go [Q FH]
time 20907ms: Recalculated tau from 41ms to 72ms for process G [Q FH]
time 20907ms: Process G switching out of CPU; will block on I/O until time 20939ms [Q FH]
time 20911ms: Process F (tau 29ms) started using the CPU for 183ms burst [Q H]
time 20926ms: Process B (tau 60ms) completed I/O; added to ready queue [Q BH]
time 20939ms: Process G (tau 72ms) completed I/O; added to ready queue [Q BGH]
time 21094ms: Process F (tau 29ms) completed a CPU burst; 9 bursts to go [Q BGH]
time 21094ms: Recalculated tau from 29ms to 145ms for process F [Q BGH]
time 21094ms: Process F switching out of CPU; will block on I/O until time 21506ms [Q BGH]
time 21098ms: Process B (tau 60ms) started using the CPU for 170ms burst [Q GH]
time 21268ms: Process B (tau 60ms) completed a CPU burst; 1 burst to go [Q GH]
time 21268ms: Recalculated tau from 60ms to 143ms for process B [Q GH]
time 21268ms: Process B switching out of CPU; will block on I/O until time 21840ms [Q GH]
time 21272ms: Process G (tau 72ms) started using the CPU for 57ms burst [Q H]
time 21329ms: Process G (tau 72ms) completed a CPU burst; 58 bursts to go [Q H]
time 21329ms: Recalculated tau from 72ms to 61ms for process G [Q H]
time 21329ms: Process G switching out of CPU; will block on I/O until time 21541ms [Q H]
time 21333ms: Process H (tau 115ms) started using the CPU for 62ms burst [Q empty]
time 21395ms: Process H (tau 115ms) completed a CPU burst; 63 bursts to go [Q empty]
time 21395ms: Recalculated tau from 115ms to 76ms for process H [Q empty]
time 21395ms: Process H switching out of CPU; will block on I/O until time 21647ms [Q empty]
time 21444ms: Process O (tau 53ms) completed I/O; added to ready queue [Q O]
time 21446ms: Process O (tau 53ms) started using the CPU for 133ms burst [Q empty]
time 21506ms: Process F (tau 145ms) completed I/O; added to ready queue [Q F]
time 21541ms: Process G (tau 61ms) completed I/O; added to ready queue [Q GF]
time 21579ms: Process O (tau 53ms) completed a CPU burst; 17 bursts to go [Q GF]
time 21579ms: Recalculated tau from 53ms to 113ms for process O [Q GF]
time 21579ms: Process O switching out of CPU; will block on I/O until time 22861ms [Q GF]
time 21583ms: Process G (tau 61ms) started using the CPU for 89ms burst [Q F]
time 21643ms: Process N (tau 171ms) completed I/O; added to ready queue [Q FN]
time 21647ms: Process H (tau 76ms) completed I/O; added to ready queue [Q HFN]
time 21672ms: Process G (tau 61ms) completed a CPU burst; 57 bursts to go [Q HFN]
time 21672ms: Recalculated tau from 61ms to 82ms for process G [Q HFN]
time 21672ms: Process G switching out of CPU; will block on I/O until time 22594ms [Q HFN]
time 21676ms: Process H (tau 76ms) started using the CPU for 248ms burst [Q FN]
time 21840ms: Process B (tau 143ms) completed I/O; added to ready queue [Q BFN]
time 21863ms: Process M (tau 21ms) completed I/O; added to ready queue [Q MBFN]
time 21924ms: Process H (tau 76ms) completed a CPU burst; 62 bursts to go [Q MBFN]
time 21924ms: Recalculated tau from 76ms to 205ms for process H [Q MBFN]
time 21924ms: Process H switching out of CPU; will block on I/O until time 22746ms [Q MBFN]
time 21928ms: Process M (tau 21ms) started using the CPU for 216ms burst [Q BFN]
time 22002ms: Process E (tau 67ms) completed I/O; added to ready queue [Q EBFN]
time 22144ms: Process M (tau 21ms) completed a CPU burst; 30 bursts to go [Q EBFN]
time 22144ms: Recalculated tau from 21ms to 168ms for process M [Q EBFN]
time 22144ms: Process M switching out of CPU; will block on I/O until time 23346ms [Q EBFN]
time 22148ms: Process E (tau 67ms) started using the CPU for 117ms burst [Q BFN]
time 22233ms: Process I (tau 88ms) completed I/O; added to ready queue [Q IBFN]
time 22265ms: Process E (tau 67ms) completed a CPU burst; 35 bursts to go [Q IBFN]
time 22265ms: Recalculated tau from 67ms to 105ms for process E [Q IBFN]
time 22265ms: Process E switching out of CPU; will block on I/O until time 23267ms [Q IBFN]
time 22269ms: Process I (tau 88ms) started using the CPU for 78ms burst [Q BFN]
time 22347ms: Process I (tau 88ms) completed a CPU burst; 61 bursts to go [Q BFN]
