Process A (arrival time 9 ms) 16 CPU bursts (tau 100ms)
Process B (arrival time 18 ms) 21 CPU bursts (tau 100ms)
Process C (arrival time 42 ms) 4 CPU bursts (tau 100ms)
Process D (arrival time 156 ms) 11 CPU bursts (tau 100ms)
Process E (arrival time 134 ms) 55 CPU bursts (tau 100ms)
Process F (arrival time 106 ms) 34 CPU bursts (tau 100ms)
Process G (arrival time 65 ms) 80 CPU bursts (tau 100ms)
Process H (arrival time 11 ms) 83 CPU bursts (tau 100ms)
Process I (arrival time 68 ms) 77 CPU bursts (tau 100ms)
Process J (arrival time 0 ms) 10 CPU bursts (tau 100ms)
Process K (arrival time 7 ms) 13 CPU bursts (tau 100ms)
Process L (arrival time 189 ms) 7 CPU bursts (tau 100ms)
Process M (arrival time 16 ms) 48 CPU bursts (tau 100ms)
Process N (arrival time 122 ms) 31 CPU bursts (tau 100ms)
Process O (arrival time 29 ms) 31 CPU bursts (tau 100ms)
Process P (arrival time 159 ms) 16 CPU bursts (tau 100ms)

time 0ms: Simulator started for FCFS [Q empty]
time 0ms: Process J arrived; added to ready queue [Q J]
time 2ms: Process J started using the CPU for 40ms burst [Q empty]
time 7ms: Process K arrived; added to ready queue [Q K]
time 9ms: Process A arrived; added to ready queue [Q KA]
time 11ms: Process H arrived; added to ready queue [Q KAH]
time 16ms: Process M arrived; added to ready queue [Q KAHM]
time 18ms: Process B arrived; added to ready queue [Q KAHMB]
time 29ms: Process O arrived; added to ready queue [Q KAHMBO]
time 42ms: Process J completed a CPU burst; 9 bursts to go [Q KAHMBO]
time 42ms: Process J switching out of CPU; will block on I/O until time 74ms [Q KAHMBO]
time 42ms: Process C arrived; added to ready queue [Q KAHMBOC]
time 46ms: Process K started using the CPU for 64ms burst [Q AHMBOC]
time 65ms: Process G arrived; added to ready queue [Q AHMBOCG]
time 68ms: Process I arrived; added to ready queue [Q AHMBOCGI]
time 74ms: Process J completed I/O; added to ready queue [Q AHMBOCGIJ]
time 106ms: Process F arrived; added to ready queue [Q AHMBOCGIJF]
time 110ms: Process K completed a CPU burst; 12 bursts to go [Q AHMBOCGIJF]
time 110ms: Process K switching out of CPU; will block on I/O until time 1072ms [Q AHMBOCGIJF]
time 114ms: Process A started using the CPU for 56ms burst [Q HMBOCGIJF]
time 122ms: Process N arrived; added to ready queue [Q HMBOCGIJFN]
time 134ms: Process E arrived; added to ready queue [Q HMBOCGIJFNE]
time 156ms: Process D arrived; added to ready queue [Q HMBOCGIJFNED]
time 159ms: Process P arrived; added to ready queue [Q HMBOCGIJFNEDP]
time 170ms: Process A completed a CPU burst; 15 bursts to go [Q HMBOCGIJFNEDP]
time 170ms: Process A switching out of CPU; will block on I/O until time 402ms [Q HMBOCGIJFNEDP]
time 174ms: Process H started using the CPU for 96ms burst [Q MBOCGIJFNEDP]
time 189ms: Process L arrived; added to ready queue [Q MBOCGIJFNEDPL]
time 270ms: Process H completed a CPU burst; 82 bursts to go [Q MBOCGIJFNEDPL]
time 270ms: Process H switching out of CPU; will block on I/O until time 942ms [Q MBOCGIJFNEDPL]
time 274ms: Process M started using the CPU for 22ms burst [Q BOCGIJFNEDPL]
time 296ms: Process M completed a CPU burst; 47 bursts to go [Q BOCGIJFNEDPL]
time 296ms: Process M switching out of CPU; will block on I/O until time 468ms [Q BOCGIJFNEDPL]
time 300ms: Process B started using the CPU for 106ms burst [Q OCGIJFNEDPL]
time 402ms: Process A completed I/O; added to ready queue [Q OCGIJFNEDPLA]
time 406ms: Process B completed a CPU burst; 20 bursts to go [Q OCGIJFNEDPLA]
time 406ms: Process B switching out of CPU; will block on I/O until time 1968ms [Q OCGIJFNEDPLA]
time 410ms: Process O started using the CPU for 156ms burst [Q CGIJFNEDPLA]
time 468ms: Process M completed I/O; added to ready queue [Q CGIJFNEDPLAM]
time 566ms: Process O completed a CPU burst; 30 bursts to go [Q CGIJFNEDPLAM]
time 566ms: Process O switching out of CPU; will block on I/O until time 1238ms [Q CGIJFNEDPLAM]
time 570ms: Process C started using the CPU for 94ms burst [Q GIJFNEDPLAM]
time 664ms: Process C completed a CPU burst; 3 bursts to go [Q GIJFNEDPLAM]
time 664ms: Process C switching out of CPU; will block on I/O until time 2246ms [Q GIJFNEDPLAM]
time 668ms: Process G started using the CPU for 70ms burst [Q IJFNEDPLAM]
time 738ms: Process G completed a CPU burst; 79 bursts to go [Q IJFNEDPLAM]
time 738ms: Process G switching out of CPU; will block on I/O until time 1050ms [Q IJFNEDPLAM]
time 742ms: Process I started using the CPU for 220ms burst [Q JFNEDPLAM]
time 942ms: Process H completed I/O; added to ready queue [Q JFNEDPLAMH]
time 962ms: Process I completed a CPU burst; 76 bursts to go [Q JFNEDPLAMH]
time 962ms: Process I switching out of CPU; will block on I/O until time 1154ms [Q JFNEDPLAMH]
time 966ms: Process J started using the CPU for 204ms burst [Q FNEDPLAMH]
time 1050ms: Process G completed I/O; added to ready queue [Q FNEDPLAMHG]
time 1072ms: Process K completed I/O; added to ready queue [Q FNEDPLAMHGK]
time 1154ms: Process I completed I/O; added to ready queue [Q FNEDPLAMHGKI]
time 1170ms: Process J completed a CPU burst; 8 bursts to go [Q FNEDPLAMHGKI]
time 1170ms: Process J switching out of CPU; will block on I/O until time 1872ms [Q FNEDPLAMHGKI]
time 1174ms: Process F started using the CPU for 129ms burst [Q NEDPLAMHGKI]
time 1238ms: Process O completed I/O; added to ready queue [Q NEDPLAMHGKIO]
time 1303ms: Process F completed a CPU burst; 33 bursts to go [Q NEDPLAMHGKIO]
time 1303ms: Process F switching out of CPU; will block on I/O until time 1875ms [Q NEDPLAMHGKIO]
time 1307ms: Process N started using the CPU for 213ms burst [Q EDPLAMHGKIO]
time 1520ms: Process N completed a CPU burst; 30 bursts to go [Q EDPLAMHGKIO]
time 1520ms: Process N switching out of CPU; will block on I/O until time 1672ms [Q EDPLAMHGKIO]
time 1524ms: Process E started using the CPU for 152ms burst [Q DPLAMHGKIO]
time 1672ms: Process N completed I/O; added to ready queue [Q DPLAMHGKION]
time 1676ms: Process E completed a CPU burst; 54 bursts to go [Q DPLAMHGKION]
time 1676ms: Process E switching out of CPU; will block on I/O until time 2138ms [Q DPLAMHGKION]
time 1680ms: Process D started using the CPU for 148ms burst [Q PLAMHGKION]
time 1828ms: Process D completed a CPU burst; 10 bursts to go [Q PLAMHGKION]
time 1828ms: Process D switching out of CPU; will block on I/O until time 1850ms [Q PLAMHGKION]
time 1832ms: Process P started using the CPU for 4ms burst [Q LAMHGKION]
time 1836ms: Process P completed a CPU burst; 15 bursts to go [Q LAMHGKION]
time 1836ms: Process P switching out of CPU; will block on I/O until time 3688ms [Q LAMHGKION]
time 1840ms: Process L started using the CPU for 135ms burst [Q AMHGKION]
time 1850ms: Process D completed I/O; added to ready queue [Q AMHGKIOND]
time 1872ms: Process J completed I/O; added to ready queue [Q AMHGKIONDJ]
time 1875ms: Process F completed I/O; added to ready queue [Q AMHGKIONDJF]
time 1968ms: Process B completed I/O; added to ready queue [Q AMHGKIONDJFB]
time 1975ms: Process L completed a CPU burst; 6 bursts to go [Q AMHGKIONDJFB]
time 1975ms: Process L switching out of CPU; will block on I/O until time 2717ms [Q AMHGKIONDJFB]
time 1979ms: Process A started using the CPU for 60ms burst [Q MHGKIONDJFB]
time 2039ms: Process A completed a CPU burst; 14 bursts to go [Q MHGKIONDJFB]
time 2039ms: Process A switching out of CPU; will block on I/O until time 3571ms [Q MHGKIONDJFB]
time 2043ms: Process M started using the CPU for 93ms burst [Q HGKIONDJFB]
time 2136ms: Process M completed a CPU burst; 46 bursts to go [Q HGKIONDJFB]
time 2136ms: Process M switching out of CPU; will block on I/O until time 2558ms [Q HGKIONDJFB]
time 2138ms: Process E completed I/O; added to ready queue [Q GKIONDJFBE]
time 2140ms: Process H started using the CPU for 48ms burst [Q GKIONDJFBE]
time 2188ms: Process H completed a CPU burst; 81 bursts to go [Q GKIONDJFBE]
time 2188ms: Process H switching out of CPU; will block on I/O until time 2410ms [Q GKIONDJFBE]
time 2192ms: Process G started using the CPU for 40ms burst [Q KIONDJFBE]
time 2232ms: Process G completed a CPU burst; 78 bursts to go [Q KIONDJFBE]
time 2232ms: Process G switching out of CPU; will block on I/O until time 2294ms [Q KIONDJFBE]
time 2236ms: Process K started using the CPU for 56ms burst [Q IONDJFBE]
time 2246ms: Process C completed I/O; added to ready queue [Q IONDJFBEC]
time 2292ms: Process K completed a CPU burst; 11 bursts to go [Q IONDJFBEC]
time 2292ms: Process K switching out of CPU; will block on I/O until time 3024ms [Q IONDJFBEC]
time 2294ms: Process G completed I/O; added to ready queue [Q ONDJFBECG]
time 2296ms: Process I started using the CPU for 16ms burst [Q ONDJFBECG]
time 2312ms: Process I completed a CPU burst; 75 bursts to go [Q ONDJFBECG]
time 2312ms: Process I switching out of CPU; will block on I/O until time 4074ms [Q ONDJFBECG]
time 2316ms: Process O started using the CPU for 106ms burst [Q NDJFBECG]
time 2410ms: Process H completed I/O; added to ready queue [Q NDJFBECGH]
time 2422ms: Process O completed a CPU burst; 29 bursts to go [Q NDJFBECGH]
time 2422ms: Process O switching out of CPU; will block on I/O until time 4914ms [Q NDJFBECGH]
time 2426ms: Process N started using the CPU for 132ms burst [Q DJFBECGH]
time 2558ms: Process N completed a CPU burst; 29 bursts to go [Q DJFBECGH]
time 2558ms: Process N switching out of CPU; will block on I/O until time 4160ms [Q DJFBECGH]
time 2558ms: Process M completed I/O; added to ready queue [Q DJFBECGHM]
time 2562ms: Process D started using the CPU for 211ms burst [Q JFBECGHM]
time 2717ms: Process L completed I/O; added to ready queue [Q JFBECGHML]
time 2773ms: Process D completed a CPU burst; 9 bursts to go [Q JFBECGHML]
time 2773ms: Process D switching out of CPU; will block on I/O until time 4915ms [Q JFBECGHML]
time 2777ms: Process J started using the CPU for 28ms burst [Q FBECGHML]
time 2805ms: Process J completed a CPU burst; 7 bursts to go [Q FBECGHML]
time 2805ms: Process J switching out of CPU; will block on I/O until time 3027ms [Q FBECGHML]
time 2809ms: Process F started using the CPU for 39ms burst [Q BECGHML]
time 2848ms: Process F completed a CPU burst; 32 bursts to go [Q BECGHML]
time 2848ms: Process F switching out of CPU; will block on I/O until time 3500ms [Q BECGHML]
time 2852ms: Process B started using the CPU for 198ms burst [Q ECGHML]
time 3024ms: Process K completed I/O; added to ready queue [Q ECGHMLK]
time 3027ms: Process J completed I/O; added to ready queue [Q ECGHMLKJ]
time 3050ms: Process B completed a CPU burst; 19 bursts to go [Q ECGHMLKJ]
time 3050ms: Process B switching out of CPU; will block on I/O until time 4182ms [Q ECGHMLKJ]
time 3054ms: Process E started using the CPU for 44ms burst [Q CGHMLKJ]
time 3098ms: Process E completed a CPU burst; 53 bursts to go [Q CGHMLKJ]
time 3098ms: Process E switching out of CPU; will block on I/O until time 3660ms [Q CGHMLKJ]
time 3102ms: Process C started using the CPU for 117ms burst [Q GHMLKJ]
time 3219ms: Process C completed a CPU burst; 2 bursts to go [Q GHMLKJ]
time 3219ms: Process C switching out of CPU; will block on I/O until time 3391ms [Q GHMLKJ]
time 3223ms: Process G started using the CPU for 65ms burst [Q HMLKJ]
time 3288ms: Process G completed a CPU burst; 77 bursts to go [Q HMLKJ]
time 3288ms: Process G switching out of CPU; will block on I/O until time 3730ms [Q HMLKJ]
time 3292ms: Process H started using the CPU for 72ms burst [Q MLKJ]
time 3364ms: Process H completed a CPU burst; 80 bursts to go [Q MLKJ]
time 3364ms: Process H switching out of CPU; will block on I/O until time 3786ms [Q MLKJ]
time 3368ms: Process M started using the CPU for 79ms burst [Q LKJ]
time 3391ms: Process C completed I/O; added to ready queue [Q LKJC]
time 3447ms: Process M completed a CPU burst; 45 bursts to go [Q LKJC]
time 3447ms: Process M switching out of CPU; will block on I/O until time 4589ms [Q LKJC]
time 3451ms: Process L started using the CPU for 4ms burst [Q KJC]
time 3455ms: Process L completed a CPU burst; 5 bursts to go [Q KJC]
time 3455ms: Process L switching out of CPU; will block on I/O until time 3877ms [Q KJC]
time 3459ms: Process K started using the CPU for 6ms burst [Q JC]
time 3465ms: Process K completed a CPU burst; 10 bursts to go [Q JC]
time 3465ms: Process K switching out of CPU; will block on I/O until time 4167ms [Q JC]
time 3469ms: Process J started using the CPU for 120ms burst [Q C]
time 3500ms: Process F completed I/O; added to ready queue [Q CF]
time 3571ms: Process A completed I/O; added to ready queue [Q CFA]
time 3589ms: Process J completed a CPU burst; 6 bursts to go [Q CFA]
time 3589ms: Process J switching out of CPU; will block on I/O until time 4151ms [Q CFA]
time 3593ms: Process C started using the CPU for 85ms burst [Q FA]
time 3660ms: Process E completed I/O; added to ready queue [Q FAE]
time 3678ms: Process C completed a CPU burst; 1 burst to go [Q FAE]
time 3678ms: Process C switching out of CPU; will block on I/O until time 3890ms [Q FAE]
time 3682ms: Process F started using the CPU for 195ms burst [Q AE]
time 3688ms: Process P completed I/O; added to ready queue [Q AEP]
time 3730ms: Process G completed I/O; added to ready queue [Q AEPG]
time 3786ms: Process H completed I/O; added to ready queue [Q AEPGH]
time 3877ms: Process F completed a CPU burst; 31 bursts to go [Q AEPGH]
time 3877ms: Process F switching out of CPU; will block on I/O until time 3889ms [Q AEPGH]
time 3877ms: Process L completed I/O; added to ready queue [Q AEPGHL]
time 3881ms: Process A started using the CPU for 39ms burst [Q EPGHL]
time 3889ms: Process F completed I/O; added to ready queue [Q EPGHLF]
time 3890ms: Process C completed I/O; added to ready queue [Q EPGHLFC]
time 3920ms: Process A completed a CPU burst; 13 bursts to go [Q EPGHLFC]
time 3920ms: Process A switching out of CPU; will block on I/O until time 4422ms [Q EPGHLFC]
time 3924ms: Process E started using the CPU for 2ms burst [Q PGHLFC]
time 3926ms: Process E completed a CPU burst; 52 bursts to go [Q PGHLFC]
time 3926ms: Process E switching out of CPU; will block on I/O until time 4178ms [Q PGHLFC]
time 3930ms: Process P started using the CPU for 52ms burst [Q GHLFC]
time 3982ms: Process P completed a CPU burst; 14 bursts to go [Q GHLFC]
time 3982ms: Process P switching out of CPU; will block on I/O until time 5074ms [Q GHLFC]
time 3986ms: Process G started using the CPU for 13ms burst [Q HLFC]
time 3999ms: Process G completed a CPU burst; 76 bursts to go [Q HLFC]
time 3999ms: Process G switching out of CPU; will block on I/O until time 4381ms [Q HLFC]
time 4003ms: Process H started using the CPU for 12ms burst [Q LFC]
time 4015ms: Process H completed a CPU burst; 79 bursts to go [Q LFC]
time 4015ms: Process H switching out of CPU; will block on I/O until time 4147ms [Q LFC]
time 4019ms: Process L started using the CPU for 69ms burst [Q FC]
time 4074ms: Process I completed I/O; added to ready queue [Q FCI]
time 4088ms: Process L completed a CPU burst; 4 bursts to go [Q FCI]
time 4088ms: Process L switching out of CPU; will block on I/O until time 5040ms [Q FCI]
time 4092ms: Process F started using the CPU for 72ms burst [Q CI]
time 4147ms: Process H completed I/O; added to ready queue [Q CIH]
time 4151ms: Process J completed I/O; added to ready queue [Q CIHJ]
time 4160ms: Process N completed I/O; added to ready queue [Q CIHJN]
time 4164ms: Process F completed a CPU burst; 30 bursts to go [Q CIHJN]
time 4164ms: Process F switching out of CPU; will block on I/O until time 4426ms [Q CIHJN]
time 4167ms: Process K completed I/O; added to ready queue [Q IHJNK]
time 4168ms: Process C started using the CPU for 79ms burst [Q IHJNK]
time 4178ms: Process E completed I/O; added to ready queue [Q IHJNKE]
time 4182ms: Process B completed I/O; added to ready queue [Q IHJNKEB]
time 4247ms: Process C terminated [Q IHJNKEB]
time 4251ms: Process I started using the CPU for 26ms burst [Q HJNKEB]
time 4277ms: Process I completed a CPU burst; 74 bursts to go [Q HJNKEB]
time 4277ms: Process I switching out of CPU; will block on I/O until time 4909ms [Q HJNKEB]
time 4281ms: Process H started using the CPU for 41ms burst [Q JNKEB]
time 4322ms: Process H completed a CPU burst; 78 bursts to go [Q JNKEB]
time 4322ms: Process H switching out of CPU; will block on I/O until time 4534ms [Q JNKEB]
time 4326ms: Process J started using the CPU for 31ms burst [Q NKEB]
time 4357ms: Process J completed a CPU burst; 5 bursts to go [Q NKEB]
time 4357ms: Process J switching out of CPU; will block on I/O until time 5219ms [Q NKEB]
time 4361ms: Process N started using the CPU for 17ms burst [Q KEB]
time 4378ms: Process N completed a CPU burst; 28 bursts to go [Q KEB]
time 4378ms: Process N switching out of CPU; will block on I/O until time 5130ms [Q KEB]
time 4381ms: Process G completed I/O; added to ready queue [Q EBG]
time 4382ms: Process K started using the CPU for 6ms burst [Q EBG]
time 4388ms: Process K completed a CPU burst; 9 bursts to go [Q EBG]
time 4388ms: Process K switching out of CPU; will block on I/O until time 5140ms [Q EBG]
time 4392ms: Process E started using the CPU for 42ms burst [Q BG]
time 4422ms: Process A completed I/O; added to ready queue [Q BGA]
time 4426ms: Process F completed I/O; added to ready queue [Q BGAF]
time 4434ms: Process E completed a CPU burst; 51 bursts to go [Q BGAF]
time 4434ms: Process E switching out of CPU; will block on I/O until time 4486ms [Q BGAF]
time 4438ms: Process B started using the CPU for 208ms burst [Q GAF]
time 4486ms: Process E completed I/O; added to ready queue [Q GAFE]
time 4534ms: Process H completed I/O; added to ready queue [Q GAFEH]
time 4589ms: Process M completed I/O; added to ready queue [Q GAFEHM]
time 4646ms: Process B completed a CPU burst; 18 bursts to go [Q GAFEHM]
time 4646ms: Process B switching out of CPU; will block on I/O until time 6268ms [Q GAFEHM]
time 4650ms: Process G started using the CPU for 128ms burst [Q AFEHM]
time 4778ms: Process G completed a CPU burst; 75 bursts to go [Q AFEHM]
time 4778ms: Process G switching out of CPU; will block on I/O until time 7000ms [Q AFEHM]
time 4782ms: Process A started using the CPU for 47ms burst [Q FEHM]
time 4829ms: Process A completed a CPU burst; 12 bursts to go [Q FEHM]
time 4829ms: Process A switching out of CPU; will block on I/O until time 4851ms [Q FEHM]
time 4833ms: Process F started using the CPU for 8ms burst [Q EHM]
time 4841ms: Process F completed a CPU burst; 29 bursts to go [Q EHM]
time 4841ms: Process F switching out of CPU; will block on I/O until time 5173ms [Q EHM]
time 4845ms: Process E started using the CPU for 108ms burst [Q HM]
time 4851ms: Process A completed I/O; added to ready queue [Q HMA]
time 4909ms: Process I completed I/O; added to ready queue [Q HMAI]
time 4914ms: Process O completed I/O; added to ready queue [Q HMAIO]
time 4915ms: Process D completed I/O; added to ready queue [Q HMAIOD]
time 4953ms: Process E completed a CPU burst; 50 bursts to go [Q HMAIOD]
time 4953ms: Process E switching out of CPU; will block on I/O until time 5045ms [Q HMAIOD]
time 4957ms: Process H started using the CPU for 160ms burst [Q MAIOD]
time 5040ms: Process L completed I/O; added to ready queue [Q MAIODL]
time 5045ms: Process E completed I/O; added to ready queue [Q MAIODLE]
time 5074ms: Process P completed I/O; added to ready queue [Q MAIODLEP]
time 5117ms: Process H completed a CPU burst; 77 bursts to go [Q MAIODLEP]
time 5117ms: Process H switching out of CPU; will block on I/O until time 5719ms [Q MAIODLEP]
time 5121ms: Process M started using the CPU for 18ms burst [Q AIODLEP]
time 5130ms: Process N completed I/O; added to ready queue [Q AIODLEPN]
time 5139ms: Process M completed a CPU burst; 44 bursts to go [Q AIODLEPN]
time 5139ms: Process M switching out of CPU; will block on I/O until time 7111ms [Q AIODLEPN]
time 5140ms: Process K completed I/O; added to ready queue [Q AIODLEPNK]
time 5143ms: Process A started using the CPU for 137ms burst [Q IODLEPNK]
time 5173ms: Process F completed I/O; added to ready queue [Q IODLEPNKF]
time 5219ms: Process J completed I/O; added to ready queue [Q IODLEPNKFJ]
time 5280ms: Process A completed a CPU burst; 11 bursts to go [Q IODLEPNKFJ]
time 5280ms: Process A switching out of CPU; will block on I/O until time 5522ms [Q IODLEPNKFJ]
time 5284ms: Process I started using the CPU for 45ms burst [Q ODLEPNKFJ]
time 5329ms: Process I completed a CPU burst; 73 bursts to go [Q ODLEPNKFJ]
time 5329ms: Process I switching out of CPU; will block on I/O until time 5631ms [Q ODLEPNKFJ]
time 5333ms: Process O started using the CPU for 57ms burst [Q DLEPNKFJ]
time 5390ms: Process O completed a CPU burst; 28 bursts to go [Q DLEPNKFJ]
time 5390ms: Process O switching out of CPU; will block on I/O until time 5762ms [Q DLEPNKFJ]
time 5394ms: Process D started using the CPU for 9ms burst [Q LEPNKFJ]
time 5403ms: Process D completed a CPU burst; 8 bursts to go [Q LEPNKFJ]
time 5403ms: Process D switching out of CPU; will block on I/O until time 5785ms [Q LEPNKFJ]
time 5407ms: Process L started using the CPU for 25ms burst [Q EPNKFJ]
time 5432ms: Process L completed a CPU burst; 3 bursts to go [Q EPNKFJ]
time 5432ms: Process L switching out of CPU; will block on I/O until time 6624ms [Q EPNKFJ]
time 5436ms: Process E started using the CPU for 6ms burst [Q PNKFJ]
time 5442ms: Process E completed a CPU burst; 49 bursts to go [Q PNKFJ]
time 5442ms: Process E switching out of CPU; will block on I/O until time 5764ms [Q PNKFJ]
time 5446ms: Process P started using the CPU for 56ms burst [Q NKFJ]
time 5502ms: Process P completed a CPU burst; 13 bursts to go [Q NKFJ]
time 5502ms: Process P switching out of CPU; will block on I/O until time 6714ms [Q NKFJ]
time 5506ms: Process N started using the CPU for 71ms burst [Q KFJ]
time 5522ms: Process A completed I/O; added to ready queue [Q KFJA]
time 5577ms: Process N completed a CPU burst; 27 bursts to go [Q KFJA]
time 5577ms: Process N switching out of CPU; will block on I/O until time 7519ms [Q KFJA]
time 5581ms: Process K started using the CPU for 157ms burst [Q FJA]
time 5631ms: Process I completed I/O; added to ready queue [Q FJAI]
time 5719ms: Process H completed I/O; added to ready queue [Q FJAIH]
time 5738ms: Process K completed a CPU burst; 8 bursts to go [Q FJAIH]
time 5738ms: Process K switching out of CPU; will block on I/O until time 5900ms [Q FJAIH]
time 5742ms: Process F started using the CPU for 230ms burst [Q JAIH]
time 5762ms: Process O completed I/O; added to ready queue [Q JAIHO]
time 5764ms: Process E completed I/O; added to ready queue [Q JAIHOE]
time 5785ms: Process D completed I/O; added to ready queue [Q JAIHOED]
time 5900ms: Process K completed I/O; added to ready queue [Q JAIHOEDK]
time 5972ms: Process F completed a CPU burst; 28 bursts to go [Q JAIHOEDK]
time 5972ms: Process F switching out of CPU; will block on I/O until time 6004ms [Q JAIHOEDK]
time 5976ms: Process J started using the CPU for 32ms burst [Q AIHOEDK]
time 6004ms: Process F completed I/O; added to ready queue [Q AIHOEDKF]
time 6008ms: Process J completed a CPU burst; 4 bursts to go [Q AIHOEDKF]
time 6008ms: Process J switching out of CPU; will block on I/O until time 6140ms [Q AIHOEDKF]
time 6012ms: Process A started using the CPU for 64ms burst [Q IHOEDKF]
time 6076ms: Process A completed a CPU burst; 10 bursts to go [Q IHOEDKF]
time 6076ms: Process A switching out of CPU; will block on I/O until time 6228ms [Q IHOEDKF]
time 6080ms: Process I started using the CPU for 38ms burst [Q HOEDKF]
time 6118ms: Process I completed a CPU burst; 72 bursts to go [Q HOEDKF]
time 6118ms: Process I switching out of CPU; will block on I/O until time 6700ms [Q HOEDKF]
time 6122ms: Process H started using the CPU for 28ms burst [Q OEDKF]
time 6140ms: Process J completed I/O; added to ready queue [Q OEDKFJ]
time 6150ms: Process H completed a CPU burst; 76 bursts to go [Q OEDKFJ]
time 6150ms: Process H switching out of CPU; will block on I/O until time 7112ms [Q OEDKFJ]
time 6154ms: Process O started using the CPU for 13ms burst [Q EDKFJ]
time 6167ms: Process O completed a CPU burst; 27 bursts to go [Q EDKFJ]
time 6167ms: Process O switching out of CPU; will block on I/O until time 7499ms [Q EDKFJ]
time 6171ms: Process E started using the CPU for 112ms burst [Q DKFJ]
time 6228ms: Process A completed I/O; added to ready queue [Q DKFJA]
time 6268ms: Process B completed I/O; added to ready queue [Q DKFJAB]
time 6283ms: Process E completed a CPU burst; 48 bursts to go [Q DKFJAB]
time 6283ms: Process E switching out of CPU; will block on I/O until time 7395ms [Q DKFJAB]
time 6287ms: Process D started using the CPU for 4ms burst [Q KFJAB]
time 6291ms: Process D completed a CPU burst; 7 bursts to go [Q KFJAB]
time 6291ms: Process D switching out of CPU; will block on I/O until time 6773ms [Q KFJAB]
time 6295ms: Process K started using the CPU for 104ms burst [Q FJAB]
time 6399ms: Process K completed a CPU burst; 7 bursts to go [Q FJAB]
time 6399ms: Process K switching out of CPU; will block on I/O until time 7851ms [Q FJAB]
time 6403ms: Process F started using the CPU for 33ms burst [Q JAB]
time 6436ms: Process F completed a CPU burst; 27 bursts to go [Q JAB]
time 6436ms: Process F switching out of CPU; will block on I/O until time 6998ms [Q JAB]
time 6440ms: Process J started using the CPU for 23ms burst [Q AB]
time 6463ms: Process J completed a CPU burst; 3 bursts to go [Q AB]
time 6463ms: Process J switching out of CPU; will block on I/O until time 6625ms [Q AB]
time 6467ms: Process A started using the CPU for 68ms burst [Q B]
time 6535ms: Process A completed a CPU burst; 9 bursts to go [Q B]
time 6535ms: Process A switching out of CPU; will block on I/O until time 7177ms [Q B]
time 6539ms: Process B started using the CPU for 50ms burst [Q empty]
time 6589ms: Process B completed a CPU burst; 17 bursts to go [Q empty]
time 6589ms: Process B switching out of CPU; will block on I/O until time 7051ms [Q empty]
time 6624ms: Process L completed I/O; added to ready queue [Q L]
time 6625ms: Process J completed I/O; added to ready queue [Q LJ]
time 6626ms: Process L started using the CPU for 2ms burst [Q J]
time 6628ms: Process L completed a CPU burst; 2 bursts to go [Q J]
time 6628ms: Process L switching out of CPU; will block on I/O until time 7000ms [Q J]
time 6632ms: Process J started using the CPU for 51ms burst [Q empty]
time 6683ms: Process J completed a CPU burst; 2 bursts to go [Q empty]
time 6683ms: Process J switching out of CPU; will block on I/O until time 7655ms [Q empty]
time 6700ms: Process I completed I/O; added to ready queue [Q I]
time 6702ms: Process I started using the CPU for 79ms burst [Q empty]
time 6714ms: Process P completed I/O; added to ready queue [Q P]
time 6773ms: Process D completed I/O; added to ready queue [Q PD]
time 6781ms: Process I completed a CPU burst; 71 bursts to go [Q PD]
time 6781ms: Process I switching out of CPU; will block on I/O until time 7943ms [Q PD]
time 6785ms: Process P started using the CPU for 155ms burst [Q D]
time 6940ms: Process P completed a CPU burst; 12 bursts to go [Q D]
time 6940ms: Process P switching out of CPU; will block on I/O until time 8122ms [Q D]
time 6944ms: Process D started using the CPU for 149ms burst [Q empty]
time 6998ms: Process F completed I/O; added to ready queue [Q F]
time 7000ms: Process G completed I/O; added to ready queue [Q FG]
time 7000ms: Process L completed I/O; added to ready queue [Q FGL]
time 7051ms: Process B completed I/O; added to ready queue [Q FGLB]
time 7093ms: Process D completed a CPU burst; 6 bursts to go [Q FGLB]
time 7093ms: Process D switching out of CPU; will block on I/O until time 7905ms [Q FGLB]
time 7097ms: Process F started using the CPU for 76ms burst [Q GLB]
time 7111ms: Process M completed I/O; added to ready queue [Q GLBM]
time 7112ms: Process H completed I/O; added to ready queue [Q GLBMH]
time 7173ms: Process F completed a CPU burst; 26 bursts to go [Q GLBMH]
time 7173ms: Process F switching out of CPU; will block on I/O until time 7555ms [Q GLBMH]
time 7177ms: Process G started using the CPU for 15ms burst [Q LBMH]
time 7177ms: Process A completed I/O; added to ready queue [Q LBMHA]
time 7192ms: Process G completed a CPU burst; 74 bursts to go [Q LBMHA]
time 7192ms: Process G switching out of CPU; will block on I/O until time 8134ms [Q LBMHA]
time 7196ms: Process L started using the CPU for 164ms burst [Q BMHA]
time 7360ms: Process L completed a CPU burst; 1 burst to go [Q BMHA]
time 7360ms: Process L switching out of CPU; will block on I/O until time 7862ms [Q BMHA]
time 7364ms: Process B started using the CPU for 82ms burst [Q MHA]
time 7395ms: Process E completed I/O; added to ready queue [Q MHAE]
time 7446ms: Process B completed a CPU burst; 16 bursts to go [Q MHAE]
time 7446ms: Process B switching out of CPU; will block on I/O until time 7608ms [Q MHAE]
time 7450ms: Process M started using the CPU for 66ms burst [Q HAE]
time 7499ms: Process O completed I/O; added to ready queue [Q HAEO]
time 7516ms: Process M completed a CPU burst; 43 bursts to go [Q HAEO]
time 7516ms: Process M switching out of CPU; will block on I/O until time 9328ms [Q HAEO]
time 7519ms: Process N completed I/O; added to ready queue [Q AEON]
time 7520ms: Process H started using the CPU for 51ms burst [Q AEON]
time 7555ms: Process F completed I/O; added to ready queue [Q AEONF]
time 7571ms: Process H completed a CPU burst; 75 bursts to go [Q AEONF]
time 7571ms: Process H switching out of CPU; will block on I/O until time 7803ms [Q AEONF]
time 7575ms: Process A started using the CPU for 113ms burst [Q EONF]
time 7608ms: Process B completed I/O; added to ready queue [Q EONFB]
time 7655ms: Process J completed I/O; added to ready queue [Q EONFBJ]
time 7688ms: Process A completed a CPU burst; 8 bursts to go [Q EONFBJ]
time 7688ms: Process A switching out of CPU; will block on I/O until time 7850ms [Q EONFBJ]
time 7692ms: Process E started using the CPU for 12ms burst [Q ONFBJ]
time 7704ms: Process E completed a CPU burst; 47 bursts to go [Q ONFBJ]
time 7704ms: Process E switching out of CPU; will block on I/O until time 8156ms [Q ONFBJ]
time 7708ms: Process O started using the CPU for 130ms burst [Q NFBJ]
time 7803ms: Process H completed I/O; added to ready queue [Q NFBJH]
time 7838ms: Process O completed a CPU burst; 26 bursts to go [Q NFBJH]
time 7838ms: Process O switching out of CPU; will block on I/O until time 8550ms [Q NFBJH]
time 7842ms: Process N started using the CPU for 27ms burst [Q FBJH]
time 7850ms: Process A completed I/O; added to ready queue [Q FBJHA]
time 7851ms: Process K completed I/O; added to ready queue [Q FBJHAK]
time 7862ms: Process L completed I/O; added to ready queue [Q FBJHAKL]
time 7869ms: Process N completed a CPU burst; 26 bursts to go [Q FBJHAKL]
time 7869ms: Process N switching out of CPU; will block on I/O until time 8141ms [Q FBJHAKL]
time 7873ms: Process F started using the CPU for 107ms burst [Q BJHAKL]
time 7905ms: Process D completed I/O; added to ready queue [Q BJHAKLD]
time 7943ms: Process I completed I/O; added to ready queue [Q BJHAKLDI]
time 7980ms: Process F completed a CPU burst; 25 bursts to go [Q BJHAKLDI]
time 7980ms: Process F switching out of CPU; will block on I/O until time 8162ms [Q BJHAKLDI]
time 7984ms: Process B started using the CPU for 7ms burst [Q JHAKLDI]
time 7991ms: Process B completed a CPU burst; 15 bursts to go [Q JHAKLDI]
time 7991ms: Process B switching out of CPU; will block on I/O until time 8293ms [Q JHAKLDI]
time 7995ms: Process J started using the CPU for 216ms burst [Q HAKLDI]
time 8122ms: Process P completed I/O; added to ready queue [Q HAKLDIP]
time 8134ms: Process G completed I/O; added to ready queue [Q HAKLDIPG]
time 8141ms: Process N completed I/O; added to ready queue [Q HAKLDIPGN]
time 8156ms: Process E completed I/O; added to ready queue [Q HAKLDIPGNE]
time 8162ms: Process F completed I/O; added to ready queue [Q HAKLDIPGNEF]
time 8211ms: Process J completed a CPU burst; 1 burst to go [Q HAKLDIPGNEF]
time 8211ms: Process J switching out of CPU; will block on I/O until time 8293ms [Q HAKLDIPGNEF]
time 8215ms: Process H started using the CPU for 87ms burst [Q AKLDIPGNEF]
time 8293ms: Process B completed I/O; added to ready queue [Q AKLDIPGNEFB]
time 8293ms: Process J completed I/O; added to ready queue [Q AKLDIPGNEFBJ]
time 8302ms: Process H completed a CPU burst; 74 bursts to go [Q AKLDIPGNEFBJ]
time 8302ms: Process H switching out of CPU; will block on I/O until time 8874ms [Q AKLDIPGNEFBJ]
time 8306ms: Process A started using the CPU for 11ms burst [Q KLDIPGNEFBJ]
time 8317ms: Process A completed a CPU burst; 7 bursts to go [Q KLDIPGNEFBJ]
time 8317ms: Process A switching out of CPU; will block on I/O until time 9939ms [Q KLDIPGNEFBJ]
time 8321ms: Process K started using the CPU for 86ms burst [Q LDIPGNEFBJ]
time 8407ms: Process K completed a CPU burst; 6 bursts to go [Q LDIPGNEFBJ]
time 8407ms: Process K switching out of CPU; will block on I/O until time 8689ms [Q LDIPGNEFBJ]
time 8411ms: Process L started using the CPU for 111ms burst [Q DIPGNEFBJ]
time 8522ms: Process L terminated [Q DIPGNEFBJ]
time 8526ms: Process D started using the CPU for 52ms burst [Q IPGNEFBJ]
time 8550ms: Process O completed I/O; added to ready queue [Q IPGNEFBJO]
time 8578ms: Process D completed a CPU burst; 5 bursts to go [Q IPGNEFBJO]
time 8578ms: Process D switching out of CPU; will block on I/O until time 8610ms [Q IPGNEFBJO]
time 8582ms: Process I started using the CPU for 84ms burst [Q PGNEFBJO]
time 8610ms: Process D completed I/O; added to ready queue [Q PGNEFBJOD]
time 8666ms: Process I completed a CPU burst; 70 bursts to go [Q PGNEFBJOD]
time 8666ms: Process I switching out of CPU; will block on I/O until time 9178ms [Q PGNEFBJOD]
time 8670ms: Process P started using the CPU for 4ms burst [Q GNEFBJOD]
time 8674ms: Process P completed a CPU burst; 11 bursts to go [Q GNEFBJOD]
time 8674ms: Process P switching out of CPU; will block on I/O until time 10466ms [Q GNEFBJOD]
time 8678ms: Process G started using the CPU for 112ms burst [Q NEFBJOD]
time 8689ms: Process K completed I/O; added to ready queue [Q NEFBJODK]
time 8790ms: Process G completed a CPU burst; 73 bursts to go [Q NEFBJODK]
time 8790ms: Process G switching out of CPU; will block on I/O until time 9222ms [Q NEFBJODK]
time 8794ms: Process N started using the CPU for 57ms burst [Q EFBJODK]
time 8851ms: Process N completed a CPU burst; 25 bursts to go [Q EFBJODK]
time 8851ms: Process N switching out of CPU; will block on I/O until time 8953ms [Q EFBJODK]
time 8855ms: Process E started using the CPU for 9ms burst [Q FBJODK]
time 8864ms: Process E completed a CPU burst; 46 bursts to go [Q FBJODK]
time 8864ms: Process E switching out of CPU; will block on I/O until time 9536ms [Q FBJODK]
time 8868ms: Process F started using the CPU for 89ms burst [Q BJODK]
time 8874ms: Process H completed I/O; added to ready queue [Q BJODKH]
time 8953ms: Process N completed I/O; added to ready queue [Q BJODKHN]
time 8957ms: Process F completed a CPU burst; 24 bursts to go [Q BJODKHN]
time 8957ms: Process F switching out of CPU; will block on I/O until time 9789ms [Q BJODKHN]
time 8961ms: Process B started using the CPU for 52ms burst [Q JODKHN]
time 9013ms: Process B completed a CPU burst; 14 bursts to go [Q JODKHN]
time 9013ms: Process B switching out of CPU; will block on I/O until time 9135ms [Q JODKHN]
time 9017ms: Process J started using the CPU for 7ms burst [Q ODKHN]
time 9024ms: Process J terminated [Q ODKHN]
time 9028ms: Process O started using the CPU for 68ms burst [Q DKHN]
time 9096ms: Process O completed a CPU burst; 25 bursts to go [Q DKHN]
time 9096ms: Process O switching out of CPU; will block on I/O until time 10268ms [Q DKHN]
time 9100ms: Process D started using the CPU for 23ms burst [Q KHN]
time 9123ms: Process D completed a CPU burst; 4 bursts to go [Q KHN]
time 9123ms: Process D switching out of CPU; will block on I/O until time 11065ms [Q KHN]
time 9127ms: Process K started using the CPU for 50ms burst [Q HN]
time 9135ms: Process B completed I/O; added to ready queue [Q HNB]
time 9177ms: Process K completed a CPU burst; 5 bursts to go [Q HNB]
time 9177ms: Process K switching out of CPU; will block on I/O until time 9679ms [Q HNB]
time 9178ms: Process I completed I/O; added to ready queue [Q HNBI]
time 9181ms: Process H started using the CPU for 156ms burst [Q NBI]
time 9222ms: Process G completed I/O; added to ready queue [Q NBIG]
time 9328ms: Process M completed I/O; added to ready queue [Q NBIGM]
time 9337ms: Process H completed a CPU burst; 73 bursts to go [Q NBIGM]
time 9337ms: Process H switching out of CPU; will block on I/O until time 9899ms [Q NBIGM]
time 9341ms: Process N started using the CPU for 84ms burst [Q BIGM]
time 9425ms: Process N completed a CPU burst; 24 bursts to go [Q BIGM]
time 9425ms: Process N switching out of CPU; will block on I/O until time 9447ms [Q BIGM]
time 9429ms: Process B started using the CPU for 228ms burst [Q IGM]
time 9447ms: Process N completed I/O; added to ready queue [Q IGMN]
time 9536ms: Process E completed I/O; added to ready queue [Q IGMNE]
time 9657ms: Process B completed a CPU burst; 13 bursts to go [Q IGMNE]
time 9657ms: Process B switching out of CPU; will block on I/O until time 10429ms [Q IGMNE]
time 9661ms: Process I started using the CPU for 27ms burst [Q GMNE]
time 9679ms: Process K completed I/O; added to ready queue [Q GMNEK]
time 9688ms: Process I completed a CPU burst; 69 bursts to go [Q GMNEK]
time 9688ms: Process I switching out of CPU; will block on I/O until time 11590ms [Q GMNEK]
time 9692ms: Process G started using the CPU for 30ms burst [Q MNEK]
time 9722ms: Process G completed a CPU burst; 72 bursts to go [Q MNEK]
time 9722ms: Process G switching out of CPU; will block on I/O until time 10194ms [Q MNEK]
time 9726ms: Process M started using the CPU for 103ms burst [Q NEK]
time 9789ms: Process F completed I/O; added to ready queue [Q NEKF]
time 9829ms: Process M completed a CPU burst; 42 bursts to go [Q NEKF]
time 9829ms: Process M switching out of CPU; will block on I/O until time 10231ms [Q NEKF]
time 9833ms: Process N started using the CPU for 131ms burst [Q EKF]
time 9899ms: Process H completed I/O; added to ready queue [Q EKFH]
time 9939ms: Process A completed I/O; added to ready queue [Q EKFHA]
time 9964ms: Process N completed a CPU burst; 23 bursts to go [Q EKFHA]
time 9964ms: Process N switching out of CPU; will block on I/O until time 10196ms [Q EKFHA]
time 9968ms: Process E started using the CPU for 62ms burst [Q KFHA]
time 10030ms: Process E completed a CPU burst; 45 bursts to go [Q KFHA]
time 10030ms: Process E switching out of CPU; will block on I/O until time 10632ms [Q KFHA]
time 10034ms: Process K started using the CPU for 4ms burst [Q FHA]
time 10038ms: Process K completed a CPU burst; 4 bursts to go [Q FHA]
time 10038ms: Process K switching out of CPU; will block on I/O until time 10640ms [Q FHA]
time 10042ms: Process F started using the CPU for 102ms burst [Q HA]
time 10144ms: Process F completed a CPU burst; 23 bursts to go [Q HA]
time 10144ms: Process F switching out of CPU; will block on I/O until time 11496ms [Q HA]
time 10148ms: Process H started using the CPU for 184ms burst [Q A]
time 10194ms: Process G completed I/O; added to ready queue [Q AG]
time 10196ms: Process N completed I/O; added to ready queue [Q AGN]
time 10231ms: Process M completed I/O; added to ready queue [Q AGNM]
time 10268ms: Process O completed I/O; added to ready queue [Q AGNMO]
time 10332ms: Process H completed a CPU burst; 72 bursts to go [Q AGNMO]
time 10332ms: Process H switching out of CPU; will block on I/O until time 10594ms [Q AGNMO]
time 10336ms: Process A started using the CPU for 24ms burst [Q GNMO]
time 10360ms: Process A completed a CPU burst; 6 bursts to go [Q GNMO]
time 10360ms: Process A switching out of CPU; will block on I/O until time 11532ms [Q GNMO]
time 10364ms: Process G started using the CPU for 50ms burst [Q NMO]
time 10414ms: Process G completed a CPU burst; 71 bursts to go [Q NMO]
time 10414ms: Process G switching out of CPU; will block on I/O until time 12616ms [Q NMO]
time 10418ms: Process N started using the CPU for 222ms burst [Q MO]
time 10429ms: Process B completed I/O; added to ready queue [Q MOB]
time 10466ms: Process P completed I/O; added to ready queue [Q MOBP]
time 10594ms: Process H completed I/O; added to ready queue [Q MOBPH]
time 10632ms: Process E completed I/O; added to ready queue [Q MOBPHE]
time 10640ms: Process N completed a CPU burst; 22 bursts to go [Q MOBPHE]
time 10640ms: Process N switching out of CPU; will block on I/O until time 10692ms [Q MOBPHE]
time 10640ms: Process K completed I/O; added to ready queue [Q MOBPHEK]
time 10644ms: Process M started using the CPU for 171ms burst [Q OBPHEK]
time 10692ms: Process N completed I/O; added to ready queue [Q OBPHEKN]
time 10815ms: Process M completed a CPU burst; 41 bursts to go [Q OBPHEKN]
time 10815ms: Process M switching out of CPU; will block on I/O until time 11027ms [Q OBPHEKN]
time 10819ms: Process O started using the CPU for 136ms burst [Q BPHEKN]
time 10955ms: Process O completed a CPU burst; 24 bursts to go [Q BPHEKN]
time 10955ms: Process O switching out of CPU; will block on I/O until time 12007ms [Q BPHEKN]
time 10959ms: Process B started using the CPU for 138ms burst [Q PHEKN]
time 11027ms: Process M completed I/O; added to ready queue [Q PHEKNM]
time 11065ms: Process D completed I/O; added to ready queue [Q PHEKNMD]
time 11097ms: Process B completed a CPU burst; 12 bursts to go [Q PHEKNMD]
time 11097ms: Process B switching out of CPU; will block on I/O until time 11919ms [Q PHEKNMD]
time 11101ms: Process P started using the CPU for 105ms burst [Q HEKNMD]
time 11206ms: Process P completed a CPU burst; 10 bursts to go [Q HEKNMD]
time 11206ms: Process P switching out of CPU; will block on I/O until time 11798ms [Q HEKNMD]
time 11210ms: Process H started using the CPU for 2ms burst [Q EKNMD]
time 11212ms: Process H completed a CPU burst; 71 bursts to go [Q EKNMD]
time 11212ms: Process H switching out of CPU; will block on I/O until time 11354ms [Q EKNMD]
time 11216ms: Process E started using the CPU for 213ms burst [Q KNMD]
time 11354ms: Process H completed I/O; added to ready queue [Q KNMDH]
time 11429ms: Process E completed a CPU burst; 44 bursts to go [Q KNMDH]
time 11429ms: Process E switching out of CPU; will block on I/O until time 13361ms [Q KNMDH]
time 11433ms: Process K started using the CPU for 21ms burst [Q NMDH]
time 11454ms: Process K completed a CPU burst; 3 bursts to go [Q NMDH]
time 11454ms: Process K switching out of CPU; will block on I/O until time 12106ms [Q NMDH]
time 11458ms: Process N started using the CPU for 148ms burst [Q MDH]
time 11496ms: Process F completed I/O; added to ready queue [Q MDHF]
time 11532ms: Process A completed I/O; added to ready queue [Q MDHFA]
time 11590ms: Process I completed I/O; added to ready queue [Q MDHFAI]
time 11606ms: Process N completed a CPU burst; 21 bursts to go [Q MDHFAI]
time 11606ms: Process N switching out of CPU; will block on I/O until time 12988ms [Q MDHFAI]
time 11610ms: Process M started using the CPU for 200ms burst [Q DHFAI]
time 11798ms: Process P completed I/O; added to ready queue [Q DHFAIP]
time 11810ms: Process M completed a CPU burst; 40 bursts to go [Q DHFAIP]
time 11810ms: Process M switching out of CPU; will block on I/O until time 13122ms [Q DHFAIP]
time 11814ms: Process D started using the CPU for 76ms burst [Q HFAIP]
time 11890ms: Process D completed a CPU burst; 3 bursts to go [Q HFAIP]
time 11890ms: Process D switching out of CPU; will block on I/O until time 12622ms [Q HFAIP]
time 11894ms: Process H started using the CPU for 29ms burst [Q FAIP]
time 11919ms: Process B completed I/O; added to ready queue [Q FAIPB]
time 11923ms: Process H completed a CPU burst; 70 bursts to go [Q FAIPB]
time 11923ms: Process H switching out of CPU; will block on I/O until time 14145ms [Q FAIPB]
time 11927ms: Process F started using the CPU for 147ms burst [Q AIPB]
time 12007ms: Process O completed I/O; added to ready queue [Q AIPBO]
time 12074ms: Process F completed a CPU burst; 22 bursts to go [Q AIPBO]
time 12074ms: Process F switching out of CPU; will block on I/O until time 12126ms [Q AIPBO]
time 12078ms: Process A started using the CPU for 76ms burst [Q IPBO]
time 12106ms: Process K completed I/O; added to ready queue [Q IPBOK]
time 12126ms: Process F completed I/O; added to ready queue [Q IPBOKF]
time 12154ms: Process A completed a CPU burst; 5 bursts to go [Q IPBOKF]
time 12154ms: Process A switching out of CPU; will block on I/O until time 12436ms [Q IPBOKF]
time 12158ms: Process I started using the CPU for 70ms burst [Q PBOKF]
time 12228ms: Process I completed a CPU burst; 68 bursts to go [Q PBOKF]
time 12228ms: Process I switching out of CPU; will block on I/O until time 13770ms [Q PBOKF]
time 12232ms: Process P started using the CPU for 16ms burst [Q BOKF]
time 12248ms: Process P completed a CPU burst; 9 bursts to go [Q BOKF]
time 12248ms: Process P switching out of CPU; will block on I/O until time 12900ms [Q BOKF]
time 12252ms: Process B started using the CPU for 67ms burst [Q OKF]
time 12319ms: Process B completed a CPU burst; 11 bursts to go [Q OKF]
time 12319ms: Process B switching out of CPU; will block on I/O until time 12391ms [Q OKF]
time 12323ms: Process O started using the CPU for 69ms burst [Q KF]
time 12391ms: Process B completed I/O; added to ready queue [Q KFB]
time 12392ms: Process O completed a CPU burst; 23 bursts to go [Q KFB]
time 12392ms: Process O switching out of CPU; will block on I/O until time 13144ms [Q KFB]
time 12396ms: Process K started using the CPU for 120ms burst [Q FB]
time 12436ms: Process A completed I/O; added to ready queue [Q FBA]
time 12516ms: Process K completed a CPU burst; 2 bursts to go [Q FBA]
time 12516ms: Process K switching out of CPU; will block on I/O until time 13208ms [Q FBA]
time 12520ms: Process F started using the CPU for 97ms burst [Q BA]
time 12616ms: Process G completed I/O; added to ready queue [Q BAG]
time 12617ms: Process F completed a CPU burst; 21 bursts to go [Q BAG]
time 12617ms: Process F switching out of CPU; will block on I/O until time 12659ms [Q BAG]
time 12621ms: Process B started using the CPU for 120ms burst [Q AG]
time 12622ms: Process D completed I/O; added to ready queue [Q AGD]
time 12659ms: Process F completed I/O; added to ready queue [Q AGDF]
time 12741ms: Process B completed a CPU burst; 10 bursts to go [Q AGDF]
time 12741ms: Process B switching out of CPU; will block on I/O until time 12873ms [Q AGDF]
time 12745ms: Process A started using the CPU for 122ms burst [Q GDF]
time 12867ms: Process A completed a CPU burst; 4 bursts to go [Q GDF]
time 12867ms: Process A switching out of CPU; will block on I/O until time 13199ms [Q GDF]
time 12871ms: Process G started using the CPU for 5ms burst [Q DF]
time 12873ms: Process B completed I/O; added to ready queue [Q DFB]
time 12876ms: Process G completed a CPU burst; 70 bursts to go [Q DFB]
time 12876ms: Process G switching out of CPU; will block on I/O until time 14858ms [Q DFB]
time 12880ms: Process D started using the CPU for 50ms burst [Q FB]
time 12900ms: Process P completed I/O; added to ready queue [Q FBP]
time 12930ms: Process D completed a CPU burst; 2 bursts to go [Q FBP]
time 12930ms: Process D switching out of CPU; will block on I/O until time 13052ms [Q FBP]
time 12934ms: Process F started using the CPU for 157ms burst [Q BP]
time 12988ms: Process N completed I/O; added to ready queue [Q BPN]
time 13052ms: Process D completed I/O; added to ready queue [Q BPND]
time 13091ms: Process F completed a CPU burst; 20 bursts to go [Q BPND]
time 13091ms: Process F switching out of CPU; will block on I/O until time 13193ms [Q BPND]
time 13095ms: Process B started using the CPU for 49ms burst [Q PND]
time 13122ms: Process M completed I/O; added to ready queue [Q PNDM]
time 13144ms: Process B completed a CPU burst; 9 bursts to go [Q PNDM]
time 13144ms: Process B switching out of CPU; will block on I/O until time 13566ms [Q PNDM]
time 13144ms: Process O completed I/O; added to ready queue [Q PNDMO]
time 13148ms: Process P started using the CPU for 219ms burst [Q NDMO]
time 13193ms: Process F completed I/O; added to ready queue [Q NDMOF]
time 13199ms: Process A completed I/O; added to ready queue [Q NDMOFA]
time 13208ms: Process K completed I/O; added to ready queue [Q NDMOFAK]
time 13361ms: Process E completed I/O; added to ready queue [Q NDMOFAKE]
time 13367ms: Process P completed a CPU burst; 8 bursts to go [Q NDMOFAKE]
time 13367ms: Process P switching out of CPU; will block on I/O until time 15419ms [Q NDMOFAKE]
time 13371ms: Process N started using the CPU for 32ms burst [Q DMOFAKE]
time 13403ms: Process N completed a CPU burst; 20 bursts to go [Q DMOFAKE]
time 13403ms: Process N switching out of CPU; will block on I/O until time 14985ms [Q DMOFAKE]
time 13407ms: Process D started using the CPU for 24ms burst [Q MOFAKE]
time 13431ms: Process D completed a CPU burst; 1 burst to go [Q MOFAKE]
time 13431ms: Process D switching out of CPU; will block on I/O until time 13683ms [Q MOFAKE]
time 13435ms: Process M started using the CPU for 117ms burst [Q OFAKE]
time 13552ms: Process M completed a CPU burst; 39 bursts to go [Q OFAKE]
time 13552ms: Process M switching out of CPU; will block on I/O until time 14894ms [Q OFAKE]
time 13556ms: Process O started using the CPU for 6ms burst [Q FAKE]
time 13562ms: Process O completed a CPU burst; 22 bursts to go [Q FAKE]
time 13562ms: Process O switching out of CPU; will block on I/O until time 15204ms [Q FAKE]
time 13566ms: Process F started using the CPU for 24ms burst [Q AKE]
time 13566ms: Process B completed I/O; added to ready queue [Q AKEB]
time 13590ms: Process F completed a CPU burst; 19 bursts to go [Q AKEB]
time 13590ms: Process F switching out of CPU; will block on I/O until time 14562ms [Q AKEB]
time 13594ms: Process A started using the CPU for 9ms burst [Q KEB]
time 13603ms: Process A completed a CPU burst; 3 bursts to go [Q KEB]
time 13603ms: Process A switching out of CPU; will block on I/O until time 14285ms [Q KEB]
time 13607ms: Process K started using the CPU for 199ms burst [Q EB]
time 13683ms: Process D completed I/O; added to ready queue [Q EBD]
time 13770ms: Process I completed I/O; added to ready queue [Q EBDI]
time 13806ms: Process K completed a CPU burst; 1 burst to go [Q EBDI]
time 13806ms: Process K switching out of CPU; will block on I/O until time 14458ms [Q EBDI]
time 13810ms: Process E started using the CPU for 54ms burst [Q BDI]
time 13864ms: Process E completed a CPU burst; 43 bursts to go [Q BDI]
time 13864ms: Process E switching out of CPU; will block on I/O until time 14816ms [Q BDI]
time 13868ms: Process B started using the CPU for 134ms burst [Q DI]
time 14002ms: Process B completed a CPU burst; 8 bursts to go [Q DI]
time 14002ms: Process B switching out of CPU; will block on I/O until time 14324ms [Q DI]
time 14006ms: Process D started using the CPU for 1ms burst [Q I]
time 14007ms: Process D terminated [Q I]
time 14011ms: Process I started using the CPU for 107ms burst [Q empty]
time 14118ms: Process I completed a CPU burst; 67 bursts to go [Q empty]
time 14118ms: Process I switching out of CPU; will block on I/O until time 14590ms [Q empty]
time 14145ms: Process H completed I/O; added to ready queue [Q H]
time 14147ms: Process H started using the CPU for 76ms burst [Q empty]
time 14223ms: Process H completed a CPU burst; 69 bursts to go [Q empty]
time 14223ms: Process H switching out of CPU; will block on I/O until time 16345ms [Q empty]
time 14285ms: Process A completed I/O; added to ready queue [Q A]
time 14287ms: Process A started using the CPU for 62ms burst [Q empty]
time 14324ms: Process B completed I/O; added to ready queue [Q B]
time 14349ms: Process A completed a CPU burst; 2 bursts to go [Q B]
time 14349ms: Process A switching out of CPU; will block on I/O until time 15121ms [Q B]
time 14353ms: Process B started using the CPU for 144ms burst [Q empty]
time 14458ms: Process K completed I/O; added to ready queue [Q K]
time 14497ms: Process B completed a CPU burst; 7 bursts to go [Q K]
time 14497ms: Process B switching out of CPU; will block on I/O until time 15289ms [Q K]
time 14501ms: Process K started using the CPU for 47ms burst [Q empty]
time 14548ms: Process K terminated [Q empty]
time 14562ms: Process F completed I/O; added to ready queue [Q F]
time 14564ms: Process F started using the CPU for 31ms burst [Q empty]
time 14590ms: Process I completed I/O; added to ready queue [Q I]
time 14595ms: Process F completed a CPU burst; 18 bursts to go [Q I]
time 14595ms: Process F switching out of CPU; will block on I/O until time 14807ms [Q I]
time 14599ms: Process I started using the CPU for 21ms burst [Q empty]
time 14620ms: Process I completed a CPU burst; 66 bursts to go [Q empty]
time 14620ms: Process I switching out of CPU; will block on I/O until time 14712ms [Q empty]
time 14712ms: Process I completed I/O; added to ready queue [Q I]
time 14714ms: Process I started using the CPU for 179ms burst [Q empty]
time 14807ms: Process F completed I/O; added to ready queue [Q F]
time 14816ms: Process E completed I/O; added to ready queue [Q FE]
time 14858ms: Process G completed I/O; added to ready queue [Q FEG]
time 14893ms: Process I completed a CPU burst; 65 bursts to go [Q FEG]
time 14893ms: Process I switching out of CPU; will block on I/O until time 15895ms [Q FEG]
time 14894ms: Process M completed I/O; added to ready queue [Q FEGM]
time 14897ms: Process F started using the CPU for 24ms burst [Q EGM]
time 14921ms: Process F completed a CPU burst; 17 bursts to go [Q EGM]
time 14921ms: Process F switching out of CPU; will block on I/O until time 15513ms [Q EGM]
time 14925ms: Process E started using the CPU for 126ms burst [Q GM]
time 14985ms: Process N completed I/O; added to ready queue [Q GMN]
time 15051ms: Process E completed a CPU burst; 42 bursts to go [Q GMN]
time 15051ms: Process E switching out of CPU; will block on I/O until time 17033ms [Q GMN]
time 15055ms: Process G started using the CPU for 122ms burst [Q MN]
time 15121ms: Process A completed I/O; added to ready queue [Q MNA]
time 15177ms: Process G completed a CPU burst; 69 bursts to go [Q MNA]
time 15177ms: Process G switching out of CPU; will block on I/O until time 15529ms [Q MNA]
time 15181ms: Process M started using the CPU for 6ms burst [Q NA]
time 15187ms: Process M completed a CPU burst; 38 bursts to go [Q NA]
time 15187ms: Process M switching out of CPU; will block on I/O until time 15519ms [Q NA]
time 15191ms: Process N started using the CPU for 97ms burst [Q A]
time 15204ms: Process O completed I/O; added to ready queue [Q AO]
time 15288ms: Process N completed a CPU burst; 19 bursts to go [Q AO]
time 15288ms: Process N switching out of CPU; will block on I/O until time 16200ms [Q AO]
time 15289ms: Process B completed I/O; added to ready queue [Q AOB]
time 15292ms: Process A started using the CPU for 200ms burst [Q OB]
time 15419ms: Process P completed I/O; added to ready queue [Q OBP]
time 15492ms: Process A completed a CPU burst; 1 burst to go [Q OBP]
time 15492ms: Process A switching out of CPU; will block on I/O until time 15604ms [Q OBP]
time 15496ms: Process O started using the CPU for 187ms burst [Q BP]
time 15513ms: Process F completed I/O; added to ready queue [Q BPF]
time 15519ms: Process M completed I/O; added to ready queue [Q BPFM]
time 15529ms: Process G completed I/O; added to ready queue [Q BPFMG]
time 15604ms: Process A completed I/O; added to ready queue [Q BPFMGA]
time 15683ms: Process O completed a CPU burst; 21 bursts to go [Q BPFMGA]
time 15683ms: Process O switching out of CPU; will block on I/O until time 17355ms [Q BPFMGA]
time 15687ms: Process B started using the CPU for 60ms burst [Q PFMGA]
time 15747ms: Process B completed a CPU burst; 6 bursts to go [Q PFMGA]
time 15747ms: Process B switching out of CPU; will block on I/O until time 15968ms [Q PFMGA]
time 15751ms: Process P started using the CPU for 70ms burst [Q FMGA]
time 15821ms: Process P completed a CPU burst; 7 bursts to go [Q FMGA]
time 15821ms: Process P switching out of CPU; will block on I/O until time 17093ms [Q FMGA]
time 15825ms: Process F started using the CPU for 135ms burst [Q MGA]
time 15895ms: Process I completed I/O; added to ready queue [Q MGAI]
time 15960ms: Process F completed a CPU burst; 16 bursts to go [Q MGAI]
time 15960ms: Process F switching out of CPU; will block on I/O until time 16582ms [Q MGAI]
time 15964ms: Process M started using the CPU for 141ms burst [Q GAI]
time 15968ms: Process B completed I/O; added to ready queue [Q GAIB]
time 16105ms: Process M completed a CPU burst; 37 bursts to go [Q GAIB]
time 16105ms: Process M switching out of CPU; will block on I/O until time 16327ms [Q GAIB]
time 16109ms: Process G started using the CPU for 31ms burst [Q AIB]
time 16140ms: Process G completed a CPU burst; 68 bursts to go [Q AIB]
time 16140ms: Process G switching out of CPU; will block on I/O until time 16212ms [Q AIB]
time 16144ms: Process A started using the CPU for 197ms burst [Q IB]
time 16200ms: Process N completed I/O; added to ready queue [Q IBN]
time 16212ms: Process G completed I/O; added to ready queue [Q IBNG]
time 16327ms: Process M completed I/O; added to ready queue [Q IBNGM]
time 16341ms: Process A terminated [Q IBNGM]
time 16345ms: Process I started using the CPU for 65ms burst [Q BNGM]
time 16345ms: Process H completed I/O; added to ready queue [Q BNGMH]
time 16410ms: Process I completed a CPU burst; 64 bursts to go [Q BNGMH]
time 16410ms: Process I switching out of CPU; will block on I/O until time 16732ms [Q BNGMH]
time 16414ms: Process B started using the CPU for 230ms burst [Q NGMH]
time 16582ms: Process F completed I/O; added to ready queue [Q NGMHF]
time 16644ms: Process B completed a CPU burst; 5 bursts to go [Q NGMHF]
time 16644ms: Process B switching out of CPU; will block on I/O until time 16710ms [Q NGMHF]
time 16648ms: Process N started using the CPU for 39ms burst [Q GMHF]
time 16687ms: Process N completed a CPU burst; 18 bursts to go [Q GMHF]
time 16687ms: Process N switching out of CPU; will block on I/O until time 16699ms [Q GMHF]
time 16691ms: Process G started using the CPU for 61ms burst [Q MHF]
time 16699ms: Process N completed I/O; added to ready queue [Q MHFN]
time 16710ms: Process B completed I/O; added to ready queue [Q MHFNB]
time 16732ms: Process I completed I/O; added to ready queue [Q MHFNBI]
time 16752ms: Process G completed a CPU burst; 67 bursts to go [Q MHFNBI]
time 16752ms: Process G switching out of CPU; will block on I/O until time 17494ms [Q MHFNBI]
time 16756ms: Process M started using the CPU for 13ms burst [Q HFNBI]
time 16769ms: Process M completed a CPU burst; 36 bursts to go [Q HFNBI]
time 16769ms: Process M switching out of CPU; will block on I/O until time 16891ms [Q HFNBI]
time 16773ms: Process H started using the CPU for 143ms burst [Q FNBI]
time 16891ms: Process M completed I/O; added to ready queue [Q FNBIM]
time 16916ms: Process H completed a CPU burst; 68 bursts to go [Q FNBIM]
time 16916ms: Process H switching out of CPU; will block on I/O until time 18758ms [Q FNBIM]
time 16920ms: Process F started using the CPU for 87ms burst [Q NBIM]
time 17007ms: Process F completed a CPU burst; 15 bursts to go [Q NBIM]
time 17007ms: Process F switching out of CPU; will block on I/O until time 18049ms [Q NBIM]
time 17011ms: Process N started using the CPU for 137ms burst [Q BIM]
time 17033ms: Process E completed I/O; added to ready queue [Q BIME]
time 17093ms: Process P completed I/O; added to ready queue [Q BIMEP]
time 17148ms: Process N completed a CPU burst; 17 bursts to go [Q BIMEP]
time 17148ms: Process N switching out of CPU; will block on I/O until time 17340ms [Q BIMEP]
time 17152ms: Process B started using the CPU for 800ms burst [Q IMEP]
time 17340ms: Process N completed I/O; added to ready queue [Q IMEPN]
time 17355ms: Process O completed I/O; added to ready queue [Q IMEPNO]
time 17494ms: Process G completed I/O; added to ready queue [Q IMEPNOG]
time 17952ms: Process B completed a CPU burst; 4 bursts to go [Q IMEPNOG]
time 17952ms: Process B switching out of CPU; will block on I/O until time 17987ms [Q IMEPNOG]
time 17956ms: Process I started using the CPU for 58ms burst [Q MEPNOG]
time 17987ms: Process B completed I/O; added to ready queue [Q MEPNOGB]
time 18014ms: Process I completed a CPU burst; 63 bursts to go [Q MEPNOGB]
time 18014ms: Process I switching out of CPU; will block on I/O until time 19756ms [Q MEPNOGB]
time 18018ms: Process M started using the CPU for 103ms burst [Q EPNOGB]
time 18049ms: Process F completed I/O; added to ready queue [Q EPNOGBF]
time 18121ms: Process M completed a CPU burst; 35 bursts to go [Q EPNOGBF]
time 18121ms: Process M switching out of CPU; will block on I/O until time 18263ms [Q EPNOGBF]
time 18125ms: Process E started using the CPU for 168ms burst [Q PNOGBF]
time 18263ms: Process M completed I/O; added to ready queue [Q PNOGBFM]
time 18293ms: Process E completed a CPU burst; 41 bursts to go [Q PNOGBFM]
time 18293ms: Process E switching out of CPU; will block on I/O until time 18795ms [Q PNOGBFM]
time 18297ms: Process P started using the CPU for 55ms burst [Q NOGBFM]
time 18352ms: Process P completed a CPU burst; 6 bursts to go [Q NOGBFM]
time 18352ms: Process P switching out of CPU; will block on I/O until time 20804ms [Q NOGBFM]
time 18356ms: Process N started using the CPU for 189ms burst [Q OGBFM]
time 18545ms: Process N completed a CPU burst; 16 bursts to go [Q OGBFM]
time 18545ms: Process N switching out of CPU; will block on I/O until time 20177ms [Q OGBFM]
time 18549ms: Process O started using the CPU for 89ms burst [Q GBFM]
time 18638ms: Process O completed a CPU burst; 20 bursts to go [Q GBFM]
time 18638ms: Process O switching out of CPU; will block on I/O until time 20040ms [Q GBFM]
time 18642ms: Process G started using the CPU for 7ms burst [Q BFM]
time 18649ms: Process G completed a CPU burst; 66 bursts to go [Q BFM]
time 18649ms: Process G switching out of CPU; will block on I/O until time 20291ms [Q BFM]
time 18653ms: Process B started using the CPU for 740ms burst [Q FM]
time 18758ms: Process H completed I/O; added to ready queue [Q FMH]
time 18795ms: Process E completed I/O; added to ready queue [Q FMHE]
time 19393ms: Process B completed a CPU burst; 3 bursts to go [Q FMHE]
time 19393ms: Process B switching out of CPU; will block on I/O until time 19458ms [Q FMHE]
time 19397ms: Process F started using the CPU for 22ms burst [Q MHE]
time 19419ms: Process F completed a CPU burst; 14 bursts to go [Q MHE]
time 19419ms: Process F switching out of CPU; will block on I/O until time 19571ms [Q MHE]
time 19423ms: Process M started using the CPU for 15ms burst [Q HE]
time 19438ms: Process M completed a CPU burst; 34 bursts to go [Q HE]
time 19438ms: Process M switching out of CPU; will block on I/O until time 20550ms [Q HE]
time 19442ms: Process H started using the CPU for 32ms burst [Q E]
time 19458ms: Process B completed I/O; added to ready queue [Q EB]
time 19474ms: Process H completed a CPU burst; 67 bursts to go [Q EB]
time 19474ms: Process H switching out of CPU; will block on I/O until time 20296ms [Q EB]
time 19478ms: Process E started using the CPU for 23ms burst [Q B]
time 19501ms: Process E completed a CPU burst; 40 bursts to go [Q B]
time 19501ms: Process E switching out of CPU; will block on I/O until time 19593ms [Q B]
time 19505ms: Process B started using the CPU for 2310ms burst [Q empty]
time 19571ms: Process F completed I/O; added to ready queue [Q F]
time 19593ms: Process E completed I/O; added to ready queue [Q FE]
time 19756ms: Process I completed I/O; added to ready queue [Q FEI]
time 20040ms: Process O completed I/O; added to ready queue [Q FEIO]
time 20177ms: Process N completed I/O; added to ready queue [Q FEION]
time 20291ms: Process G completed I/O; added to ready queue [Q FEIONG]
time 20296ms: Process H completed I/O; added to ready queue [Q FEIONGH]
time 20550ms: Process M completed I/O; added to ready queue [Q FEIONGHM]
time 20804ms: Process P completed I/O; added to ready queue [Q FEIONGHMP]
time 21815ms: Process B completed a CPU burst; 2 bursts to go [Q FEIONGHMP]
time 21815ms: Process B switching out of CPU; will block on I/O until time 21987ms [Q FEIONGHMP]
time 21819ms: Process F started using the CPU for 52ms burst [Q EIONGHMP]
time 21871ms: Process F completed a CPU burst; 13 bursts to go [Q EIONGHMP]
time 21871ms: Process F switching out of CPU; will block on I/O until time 21963ms [Q EIONGHMP]
time 21875ms: Process E started using the CPU for 68ms burst [Q IONGHMP]
time 21943ms: Process E completed a CPU burst; 39 bursts to go [Q IONGHMP]
time 21943ms: Process E switching out of CPU; will block on I/O until time 22525ms [Q IONGHMP]
time 21947ms: Process I started using the CPU for 95ms burst [Q ONGHMP]
time 21963ms: Process F completed I/O; added to ready queue [Q ONGHMPF]
time 21987ms: Process B completed I/O; added to ready queue [Q ONGHMPFB]
time 22042ms: Process I completed a CPU burst; 62 bursts to go [Q ONGHMPFB]
time 22042ms: Process I switching out of CPU; will block on I/O until time 23464ms [Q ONGHMPFB]
time 22046ms: Process O started using the CPU for 45ms burst [Q NGHMPFB]
time 22091ms: Process O completed a CPU burst; 19 bursts to go [Q NGHMPFB]
time 22091ms: Process O switching out of CPU; will block on I/O until time 22553ms [Q NGHMPFB]
time 22095ms: Process N started using the CPU for 67ms burst [Q GHMPFB]
time 22162ms: Process N completed a CPU burst; 15 bursts to go [Q GHMPFB]
time 22162ms: Process N switching out of CPU; will block on I/O until time 22584ms [Q GHMPFB]
time 22166ms: Process G started using the CPU for 2ms burst [Q HMPFB]
time 22168ms: Process G completed a CPU burst; 65 bursts to go [Q HMPFB]
time 22168ms: Process G switching out of CPU; will block on I/O until time 22280ms [Q HMPFB]
time 22172ms: Process H started using the CPU for 78ms burst [Q MPFB]
time 22250ms: Process H completed a CPU burst; 66 bursts to go [Q MPFB]
time 22250ms: Process H switching out of CPU; will block on I/O until time 22312ms [Q MPFB]
time 22254ms: Process M started using the CPU for 26ms burst [Q PFB]
time 22280ms: Process M completed a CPU burst; 33 bursts to go [Q PFB]
time 22280ms: Process M switching out of CPU; will block on I/O until time 22882ms [Q PFB]
time 22280ms: Process G completed I/O; added to ready queue [Q PFBG]
time 22284ms: Process P started using the CPU for 212ms burst [Q FBG]
time 22312ms: Process H completed I/O; added to ready queue [Q FBGH]
time 22496ms: Process P completed a CPU burst; 5 bursts to go [Q FBGH]
time 22496ms: Process P switching out of CPU; will block on I/O until time 24668ms [Q FBGH]
time 22500ms: Process F started using the CPU for 90ms burst [Q BGH]
time 22525ms: Process E completed I/O; added to ready queue [Q BGHE]
time 22553ms: Process O completed I/O; added to ready queue [Q BGHEO]
time 22584ms: Process N completed I/O; added to ready queue [Q BGHEON]
time 22590ms: Process F completed a CPU burst; 12 bursts to go [Q BGHEON]
time 22590ms: Process F switching out of CPU; will block on I/O until time 24802ms [Q BGHEON]
time 22594ms: Process B started using the CPU for 570ms burst [Q GHEON]
time 22882ms: Process M completed I/O; added to ready queue [Q GHEONM]
time 23164ms: Process B completed a CPU burst; 1 burst to go [Q GHEONM]
time 23164ms: Process B switching out of CPU; will block on I/O until time 23378ms [Q GHEONM]
time 23168ms: Process G started using the CPU for 209ms burst [Q HEONM]
time 23377ms: Process G completed a CPU burst; 64 bursts to go [Q HEONM]
time 23377ms: Process G switching out of CPU; will block on I/O until time 23859ms [Q HEONM]
time 23378ms: Process B completed I/O; added to ready queue [Q HEONMB]
time 23381ms: Process H started using the CPU for 16ms burst [Q EONMB]
time 23397ms: Process H completed a CPU burst; 65 bursts to go [Q EONMB]
time 23397ms: Process H switching out of CPU; will block on I/O until time 23949ms [Q EONMB]
time 23401ms: Process E started using the CPU for 41ms burst [Q ONMB]
time 23442ms: Process E completed a CPU burst; 38 bursts to go [Q ONMB]
time 23442ms: Process E switching out of CPU; will block on I/O until time 23644ms [Q ONMB]
time 23446ms: Process O started using the CPU for 50ms burst [Q NMB]
time 23464ms: Process I completed I/O; added to ready queue [Q NMBI]
time 23496ms: Process O completed a CPU burst; 18 bursts to go [Q NMBI]
time 23496ms: Process O switching out of CPU; will block on I/O until time 24608ms [Q NMBI]
time 23500ms: Process N started using the CPU for 35ms burst [Q MBI]
time 23535ms: Process N completed a CPU burst; 14 bursts to go [Q MBI]
time 23535ms: Process N switching out of CPU; will block on I/O until time 24577ms [Q MBI]
time 23539ms: Process M started using the CPU for 74ms burst [Q BI]
time 23613ms: Process M completed a CPU burst; 32 bursts to go [Q BI]
time 23613ms: Process M switching out of CPU; will block on I/O until time 24825ms [Q BI]
