Process A (arrival time 9 ms) 16 CPU bursts (tau 100ms)
Process B (arrival time 18 ms) 21 CPU bursts (tau 100ms)

time 0ms: Simulator started for RR with time slice 128ms [Q empty]
time 9ms: Process A arrived; added to ready queue [Q A]
time 11ms: Process A started using the CPU for 56ms burst [Q empty]
time 18ms: Process B arrived; added to ready queue [Q B]
time 67ms: Process A completed a CPU burst; 15 bursts to go [Q B]
time 67ms: Process A switching out of CPU; will block on I/O until time 299ms [Q B]
time 71ms: Process B started using the CPU for 106ms burst [Q empty]
time 177ms: Process B completed a CPU burst; 20 bursts to go [Q empty]
time 177ms: Process B switching out of CPU; will block on I/O until time 1739ms [Q empty]
time 299ms: Process A completed I/O; added to ready queue [Q A]
time 301ms: Process A started using the CPU for 60ms burst [Q empty]
time 361ms: Process A completed a CPU burst; 14 bursts to go [Q empty]
time 361ms: Process A switching out of CPU; will block on I/O until time 1893ms [Q empty]
time 1739ms: Process B completed I/O; added to ready queue [Q B]
time 1741ms: Process B started using the CPU for 198ms burst [Q empty]
time 1869ms: Time slice expired; no preemption because ready queue is empty [Q empty]
time 1893ms: Process A completed I/O; added to ready queue [Q A]
time 1939ms: Process B completed a CPU burst; 19 bursts to go [Q A]
time 1939ms: Process B switching out of CPU; will block on I/O until time 3071ms [Q A]
time 1943ms: Process A started using the CPU for 39ms burst [Q empty]
time 1982ms: Process A completed a CPU burst; 13 bursts to go [Q empty]
time 1982ms: Process A switching out of CPU; will block on I/O until time 2484ms [Q empty]
time 2484ms: Process A completed I/O; added to ready queue [Q A]
time 2486ms: Process A started using the CPU for 47ms burst [Q empty]
time 2533ms: Process A completed a CPU burst; 12 bursts to go [Q empty]
time 2533ms: Process A switching out of CPU; will block on I/O until time 2555ms [Q empty]
time 2555ms: Process A completed I/O; added to ready queue [Q A]
time 2557ms: Process A started using the CPU for 137ms burst [Q empty]
time 2685ms: Time slice expired; no preemption because ready queue is empty [Q empty]
time 2694ms: Process A completed a CPU burst; 11 bursts to go [Q empty]
time 2694ms: Process A switching out of CPU; will block on I/O until time 2936ms [Q empty]
time 2936ms: Process A completed I/O; added to ready queue [Q A]
time 2938ms: Process A started using the CPU for 64ms burst [Q empty]
time 3002ms: Process A completed a CPU burst; 10 bursts to go [Q empty]
time 3002ms: Process A switching out of CPU; will block on I/O until time 3154ms [Q empty]
time 3071ms: Process B completed I/O; added to ready queue [Q B]
time 3073ms: Process B started using the CPU for 208ms burst [Q empty]
time 3154ms: Process A completed I/O; added to ready queue [Q A]
time 3201ms: Time slice expired; process B preempted with 80ms to go [Q A]
time 3205ms: Process A started using the CPU for 68ms burst [Q B]
time 3273ms: Process A completed a CPU burst; 9 bursts to go [Q B]
time 3273ms: Process A switching out of CPU; will block on I/O until time 3915ms [Q B]
time 3277ms: Process B started using the CPU for remaining 80ms of 208ms burst [Q empty]
time 3357ms: Process B completed a CPU burst; 18 bursts to go [Q empty]
time 3357ms: Process B switching out of CPU; will block on I/O until time 4979ms [Q empty]
time 3915ms: Process A completed I/O; added to ready queue [Q A]
time 3917ms: Process A started using the CPU for 113ms burst [Q empty]
time 4030ms: Process A completed a CPU burst; 8 bursts to go [Q empty]
time 4030ms: Process A switching out of CPU; will block on I/O until time 4192ms [Q empty]
time 4192ms: Process A completed I/O; added to ready queue [Q A]
time 4194ms: Process A started using the CPU for 11ms burst [Q empty]
time 4205ms: Process A completed a CPU burst; 7 bursts to go [Q empty]
time 4205ms: Process A switching out of CPU; will block on I/O until time 5827ms [Q empty]
time 4979ms: Process B completed I/O; added to ready queue [Q B]
time 4981ms: Process B started using the CPU for 50ms burst [Q empty]
time 5031ms: Process B completed a CPU burst; 17 bursts to go [Q empty]
time 5031ms: Process B switching out of CPU; will block on I/O until time 5493ms [Q empty]
time 5493ms: Process B completed I/O; added to ready queue [Q B]
time 5495ms: Process B started using the CPU for 82ms burst [Q empty]
time 5577ms: Process B completed a CPU burst; 16 bursts to go [Q empty]
time 5577ms: Process B switching out of CPU; will block on I/O until time 5739ms [Q empty]
time 5739ms: Process B completed I/O; added to ready queue [Q B]
time 5741ms: Process B started using the CPU for 7ms burst [Q empty]
time 5748ms: Process B completed a CPU burst; 15 bursts to go [Q empty]
time 5748ms: Process B switching out of CPU; will block on I/O until time 6050ms [Q empty]
time 5827ms: Process A completed I/O; added to ready queue [Q A]
time 5829ms: Process A started using the CPU for 24ms burst [Q empty]
time 5853ms: Process A completed a CPU burst; 6 bursts to go [Q empty]
time 5853ms: Process A switching out of CPU; will block on I/O until time 7025ms [Q empty]
time 6050ms: Process B completed I/O; added to ready queue [Q B]
time 6052ms: Process B started using the CPU for 52ms burst [Q empty]
time 6104ms: Process B completed a CPU burst; 14 bursts to go [Q empty]
time 6104ms: Process B switching out of CPU; will block on I/O until time 6226ms [Q empty]
time 6226ms: Process B completed I/O; added to ready queue [Q B]
time 6228ms: Process B started using the CPU for 228ms burst [Q empty]
time 6356ms: Time slice expired; no preemption because ready queue is empty [Q empty]
time 6456ms: Process B completed a CPU burst; 13 bursts to go [Q empty]
time 6456ms: Process B switching out of CPU; will block on I/O until time 7228ms [Q empty]
time 7025ms: Process A completed I/O; added to ready queue [Q A]
time 7027ms: Process A started using the CPU for 76ms burst [Q empty]
time 7103ms: Process A completed a CPU burst; 5 bursts to go [Q empty]
time 7103ms: Process A switching out of CPU; will block on I/O until time 7385ms [Q empty]
time 7228ms: Process B completed I/O; added to ready queue [Q B]
time 7230ms: Process B started using the CPU for 138ms burst [Q empty]
time 7358ms: Time slice expired; no preemption because ready queue is empty [Q empty]
time 7368ms: Process B completed a CPU burst; 12 bursts to go [Q empty]
time 7368ms: Process B switching out of CPU; will block on I/O until time 8190ms [Q empty]
time 7385ms: Process A completed I/O; added to ready queue [Q A]
time 7387ms: Process A started using the CPU for 122ms burst [Q empty]
time 7509ms: Process A completed a CPU burst; 4 bursts to go [Q empty]
time 7509ms: Process A switching out of CPU; will block on I/O until time 7841ms [Q empty]
time 7841ms: Process A completed I/O; added to ready queue [Q A]
time 7843ms: Process A started using the CPU for 9ms burst [Q empty]
time 7852ms: Process A completed a CPU burst; 3 bursts to go [Q empty]
time 7852ms: Process A switching out of CPU; will block on I/O until time 8534ms [Q empty]
time 8190ms: Process B completed I/O; added to ready queue [Q B]
time 8192ms: Process B started using the CPU for 67ms burst [Q empty]
time 8259ms: Process B completed a CPU burst; 11 bursts to go [Q empty]
time 8259ms: Process B switching out of CPU; will block on I/O until time 8331ms [Q empty]
time 8331ms: Process B completed I/O; added to ready queue [Q B]
time 8333ms: Process B started using the CPU for 120ms burst [Q empty]
time 8453ms: Process B completed a CPU burst; 10 bursts to go [Q empty]
time 8453ms: Process B switching out of CPU; will block on I/O until time 8585ms [Q empty]
time 8534ms: Process A completed I/O; added to ready queue [Q A]
time 8536ms: Process A started using the CPU for 62ms burst [Q empty]
time 8585ms: Process B completed I/O; added to ready queue [Q B]
time 8598ms: Process A completed a CPU burst; 2 bursts to go [Q B]
time 8598ms: Process A switching out of CPU; will block on I/O until time 9370ms [Q B]
time 8602ms: Process B started using the CPU for 49ms burst [Q empty]
time 8651ms: Process B completed a CPU burst; 9 bursts to go [Q empty]
time 8651ms: Process B switching out of CPU; will block on I/O until time 9073ms [Q empty]
time 9073ms: Process B completed I/O; added to ready queue [Q B]
time 9075ms: Process B started using the CPU for 134ms burst [Q empty]
time 9203ms: Time slice expired; no preemption because ready queue is empty [Q empty]
time 9209ms: Process B completed a CPU burst; 8 bursts to go [Q empty]
time 9209ms: Process B switching out of CPU; will block on I/O until time 9531ms [Q empty]
time 9370ms: Process A completed I/O; added to ready queue [Q A]
time 9372ms: Process A started using the CPU for 200ms burst [Q empty]
time 9500ms: Time slice expired; no preemption because ready queue is empty [Q empty]
time 9531ms: Process B completed I/O; added to ready queue [Q B]
time 9572ms: Process A completed a CPU burst; 1 burst to go [Q B]
time 9572ms: Process A switching out of CPU; will block on I/O until time 9684ms [Q B]
time 9576ms: Process B started using the CPU for 144ms burst [Q empty]
time 9684ms: Process A completed I/O; added to ready queue [Q A]
time 9704ms: Time slice expired; process B preempted with 16ms to go [Q A]
time 9708ms: Process A started using the CPU for 197ms burst [Q B]
time 9836ms: Time slice expired; process A preempted with 69ms to go [Q B]
time 9840ms: Process B started using the CPU for remaining 16ms of 144ms burst [Q A]
time 9856ms: Process B completed a CPU burst; 7 bursts to go [Q A]
time 9856ms: Process B switching out of CPU; will block on I/O until time 10648ms [Q A]
time 9860ms: Process A started using the CPU for remaining 69ms of 197ms burst [Q empty]
time 9929ms: Process A terminated [Q empty]
time 10648ms: Process B completed I/O; added to ready queue [Q B]
time 10650ms: Process B started using the CPU for 183ms burst [Q empty]
time 10778ms: Time slice expired; no preemption because ready queue is empty [Q empty]
time 10833ms: Process B completed a CPU burst; 6 bursts to go [Q empty]
time 10833ms: Process B switching out of CPU; will block on I/O until time 10895ms [Q empty]
time 10895ms: Process B completed I/O; added to ready queue [Q B]
time 10897ms: Process B started using the CPU for 219ms burst [Q empty]
time 11025ms: Time slice expired; no preemption because ready queue is empty [Q empty]
time 11116ms: Process B completed a CPU burst; 5 bursts to go [Q empty]
time 11116ms: Process B switching out of CPU; will block on I/O until time 11348ms [Q empty]
time 11348ms: Process B completed I/O; added to ready queue [Q B]
time 11350ms: Process B started using the CPU for 64ms burst [Q empty]
time 11414ms: Process B completed a CPU burst; 4 bursts to go [Q empty]
time 11414ms: Process B switching out of CPU; will block on I/O until time 12216ms [Q empty]
time 12216ms: Process B completed I/O; added to ready queue [Q B]
time 12218ms: Process B started using the CPU for 33ms burst [Q empty]
time 12251ms: Process B completed a CPU burst; 3 bursts to go [Q empty]
time 12251ms: Process B switching out of CPU; will block on I/O until time 12993ms [Q empty]
time 12993ms: Process B completed I/O; added to ready queue [Q B]
time 12995ms: Process B started using the CPU for 63ms burst [Q empty]
time 13058ms: Process B completed a CPU burst; 2 bursts to go [Q empty]
time 13058ms: Process B switching out of CPU; will block on I/O until time 15370ms [Q empty]
time 15370ms: Process B completed I/O; added to ready queue [Q B]
time 15372ms: Process B started using the CPU for 170ms burst [Q empty]
time 15500ms: Time slice expired; no preemption because ready queue is empty [Q empty]
time 15542ms: Process B completed a CPU burst; 1 burst to go [Q empty]
time 15542ms: Process B switching out of CPU; will block on I/O until time 16114ms [Q empty]
time 16114ms: Process B completed I/O; added to ready queue [Q B]
time 16116ms: Process B started using the CPU for 212ms burst [Q empty]
time 16244ms: Time slice expired; no preemption because ready queue is empty [Q empty]
time 16328ms: Process B terminated [Q empty]
time 16330ms: Simulator ended for RR [Q empty]
