Process A (arrival time 9 ms) 16 CPU bursts (tau 100ms)
Process B (arrival time 18 ms) 21 CPU bursts (tau 100ms)
Process C (arrival time 42 ms) 4 CPU bursts (tau 100ms)
Process D (arrival time 156 ms) 11 CPU bursts (tau 100ms)
Process E (arrival time 134 ms) 55 CPU bursts (tau 100ms)
Process F (arrival time 106 ms) 34 CPU bursts (tau 100ms)
Process G (arrival time 65 ms) 80 CPU bursts (tau 100ms)
Process H (arrival time 11 ms) 83 CPU bursts (tau 100ms)
Process I (arrival time 68 ms) 77 CPU bursts (tau 100ms)
Process J (arrival time 0 ms) 10 CPU bursts (tau 100ms)
Process K (arrival time 7 ms) 13 CPU bursts (tau 100ms)
Process L (arrival time 189 ms) 7 CPU bursts (tau 100ms)
Process M (arrival time 16 ms) 48 CPU bursts (tau 100ms)
Process N (arrival time 122 ms) 31 CPU bursts (tau 100ms)
Process O (arrival time 29 ms) 31 CPU bursts (tau 100ms)
Process P (arrival time 159 ms) 16 CPU bursts (tau 100ms)

time 0ms: Simulator started for FCFS [Q empty]
time 0ms: Process J arrived; added to ready queue [Q J]
time 2ms: Process J started using the CPU for 40ms burst [Q empty]
time 7ms: Process K arrived; added to ready queue [Q K]
time 9ms: Process A arrived; added to ready queue [Q KA]
time 11ms: Process H arrived; added to ready queue [Q KAH]
time 16ms: Process M arrived; added to ready queue [Q KAHM]
time 18ms: Process B arrived; added to ready queue [Q KAHMB]
time 29ms: Process O arrived; added to ready queue [Q KAHMBO]
time 42ms: Process J completed a CPU burst; 9 bursts to go [Q KAHMBO]
time 42ms: Process J switching out of CPU; will block on I/O until time 74ms [Q KAHMBO]
time 42ms: Process C arrived; added to ready queue [Q KAHMBOC]
time 46ms: Process K started using the CPU for 64ms burst [Q AHMBOC]
time 65ms: Process G arrived; added to ready queue [Q AHMBOCG]
time 68ms: Process I arrived; added to ready queue [Q AHMBOCGI]
time 74ms: Process J completed I/O; added to ready queue [Q AHMBOCGIJ]
time 106ms: Process F arrived; added to ready queue [Q AHMBOCGIJF]
time 110ms: Process K completed a CPU burst; 12 bursts to go [Q AHMBOCGIJF]
time 110ms: Process K switching out of CPU; will block on I/O until time 1072ms [Q AHMBOCGIJF]
time 114ms: Process A started using the CPU for 56ms burst [Q HMBOCGIJF]
time 122ms: Process N arrived; added to ready queue [Q HMBOCGIJFN]
time 134ms: Process E arrived; added to ready queue [Q HMBOCGIJFNE]
time 156ms: Process D arrived; added to ready queue [Q HMBOCGIJFNED]
time 159ms: Process P arrived; added to ready queue [Q HMBOCGIJFNEDP]
time 170ms: Process A completed a CPU burst; 15 bursts to go [Q HMBOCGIJFNEDP]
time 170ms: Process A switching out of CPU; will block on I/O until time 402ms [Q HMBOCGIJFNEDP]
time 174ms: Process H started using the CPU for 96ms burst [Q MBOCGIJFNEDP]
time 189ms: Process L arrived; added to ready queue [Q MBOCGIJFNEDPL]
time 270ms: Process H completed a CPU burst; 82 bursts to go [Q MBOCGIJFNEDPL]
time 270ms: Process H switching out of CPU; will block on I/O until time 942ms [Q MBOCGIJFNEDPL]
time 274ms: Process M started using the CPU for 22ms burst [Q BOCGIJFNEDPL]
time 296ms: Process M completed a CPU burst; 47 bursts to go [Q BOCGIJFNEDPL]
time 296ms: Process M switching out of CPU; will block on I/O until time 468ms [Q BOCGIJFNEDPL]
time 300ms: Process B started using the CPU for 106ms burst [Q OCGIJFNEDPL]
time 402ms: Process A completed I/O; added to ready queue [Q OCGIJFNEDPLA]
time 406ms: Process B completed a CPU burst; 20 bursts to go [Q OCGIJFNEDPLA]
time 406ms: Process B switching out of CPU; will block on I/O until time 1968ms [Q OCGIJFNEDPLA]
time 410ms: Process O started using the CPU for 156ms burst [Q CGIJFNEDPLA]
time 468ms: Process M completed I/O; added to ready queue [Q CGIJFNEDPLAM]
time 566ms: Process O completed a CPU burst; 30 bursts to go [Q CGIJFNEDPLAM]
time 566ms: Process O switching out of CPU; will block on I/O until time 1238ms [Q CGIJFNEDPLAM]
time 570ms: Process C started using the CPU for 94ms burst [Q GIJFNEDPLAM]
time 664ms: Process C completed a CPU burst; 3 bursts to go [Q GIJFNEDPLAM]
time 664ms: Process C switching out of CPU; will block on I/O until time 2246ms [Q GIJFNEDPLAM]
time 668ms: Process G started using the CPU for 70ms burst [Q IJFNEDPLAM]
time 738ms: Process G completed a CPU burst; 79 bursts to go [Q IJFNEDPLAM]
time 738ms: Process G switching out of CPU; will block on I/O until time 1050ms [Q IJFNEDPLAM]
time 742ms: Process I started using the CPU for 220ms burst [Q JFNEDPLAM]
time 942ms: Process H completed I/O; added to ready queue [Q JFNEDPLAMH]
time 962ms: Process I completed a CPU burst; 76 bursts to go [Q JFNEDPLAMH]
time 962ms: Process I switching out of CPU; will block on I/O until time 1154ms [Q JFNEDPLAMH]
time 966ms: Process J started using the CPU for 204ms burst [Q FNEDPLAMH]
time 1050ms: Process G completed I/O; added to ready queue [Q FNEDPLAMHG]
time 1072ms: Process K completed I/O; added to ready queue [Q FNEDPLAMHGK]
time 1154ms: Process I completed I/O; added to ready queue [Q FNEDPLAMHGKI]
time 1170ms: Process J completed a CPU burst; 8 bursts to go [Q FNEDPLAMHGKI]
time 1170ms: Process J switching out of CPU; will block on I/O until time 1872ms [Q FNEDPLAMHGKI]
time 1174ms: Process F started using the CPU for 129ms burst [Q NEDPLAMHGKI]
time 1238ms: Process O completed I/O; added to ready queue [Q NEDPLAMHGKIO]
time 1303ms: Process F completed a CPU burst; 33 bursts to go [Q NEDPLAMHGKIO]
time 1303ms: Process F switching out of CPU; will block on I/O until time 1875ms [Q NEDPLAMHGKIO]
time 1307ms: Process N started using the CPU for 213ms burst [Q EDPLAMHGKIO]
time 1520ms: Process N completed a CPU burst; 30 bursts to go [Q EDPLAMHGKIO]
time 1520ms: Process N switching out of CPU; will block on I/O until time 1672ms [Q EDPLAMHGKIO]
time 1524ms: Process E started using the CPU for 152ms burst [Q DPLAMHGKIO]
time 1672ms: Process N completed I/O; added to ready queue [Q DPLAMHGKION]
time 1676ms: Process E completed a CPU burst; 54 bursts to go [Q DPLAMHGKION]
time 1676ms: Process E switching out of CPU; will block on I/O until time 2138ms [Q DPLAMHGKION]
time 1680ms: Process D started using the CPU for 148ms burst [Q PLAMHGKION]
time 1828ms: Process D completed a CPU burst; 10 bursts to go [Q PLAMHGKION]
time 1828ms: Process D switching out of CPU; will block on I/O until time 1850ms [Q PLAMHGKION]
time 1832ms: Process P started using the CPU for 4ms burst [Q LAMHGKION]
time 1836ms: Process P completed a CPU burst; 15 bursts to go [Q LAMHGKION]
time 1836ms: Process P switching out of CPU; will block on I/O until time 3688ms [Q LAMHGKION]
time 1840ms: Process L started using the CPU for 135ms burst [Q AMHGKION]
time 1850ms: Process D completed I/O; added to ready queue [Q AMHGKIOND]
time 1872ms: Process J completed I/O; added to ready queue [Q AMHGKIONDJ]
time 1875ms: Process F completed I/O; added to ready queue [Q AMHGKIONDJF]
time 1968ms: Process B completed I/O; added to ready queue [Q AMHGKIONDJFB]
time 1975ms: Process L completed a CPU burst; 6 bursts to go [Q AMHGKIONDJFB]
time 1975ms: Process L switching out of CPU; will block on I/O until time 2717ms [Q AMHGKIONDJFB]
time 1979ms: Process A started using the CPU for 60ms burst [Q MHGKIONDJFB]
time 2039ms: Process A completed a CPU burst; 14 bursts to go [Q MHGKIONDJFB]
time 2039ms: Process A switching out of CPU; will block on I/O until time 3571ms [Q MHGKIONDJFB]
time 2043ms: Process M started using the CPU for 93ms burst [Q HGKIONDJFB]
time 2136ms: Process M completed a CPU burst; 46 bursts to go [Q HGKIONDJFB]
time 2136ms: Process M switching out of CPU; will block on I/O until time 2558ms [Q HGKIONDJFB]
time 2138ms: Process E completed I/O; added to ready queue [Q HGKIONDJFBE]
time 2140ms: Process H started using the CPU for 48ms burst [Q GKIONDJFBE]
time 2188ms: Process H completed a CPU burst; 81 bursts to go [Q GKIONDJFBE]
time 2188ms: Process H switching out of CPU; will block on I/O until time 2410ms [Q GKIONDJFBE]
time 2192ms: Process G started using the CPU for 40ms burst [Q KIONDJFBE]
time 2232ms: Process G completed a CPU burst; 78 bursts to go [Q KIONDJFBE]
time 2232ms: Process G switching out of CPU; will block on I/O until time 2294ms [Q KIONDJFBE]
time 2236ms: Process K started using the CPU for 56ms burst [Q IONDJFBE]
time 2246ms: Process C completed I/O; added to ready queue [Q IONDJFBEC]
time 2292ms: Process K completed a CPU burst; 11 bursts to go [Q IONDJFBEC]
time 2292ms: Process K switching out of CPU; will block on I/O until time 3024ms [Q IONDJFBEC]
time 2294ms: Process G completed I/O; added to ready queue [Q IONDJFBECG]
time 2296ms: Process I started using the CPU for 16ms burst [Q ONDJFBECG]
time 2312ms: Process I completed a CPU burst; 75 bursts to go [Q ONDJFBECG]
time 2312ms: Process I switching out of CPU; will block on I/O until time 4074ms [Q ONDJFBECG]
time 2316ms: Process O started using the CPU for 106ms burst [Q NDJFBECG]
time 2410ms: Process H completed I/O; added to ready queue [Q NDJFBECGH]
time 2422ms: Process O completed a CPU burst; 29 bursts to go [Q NDJFBECGH]
time 2422ms: Process O switching out of CPU; will block on I/O until time 4914ms [Q NDJFBECGH]
time 2426ms: Process N started using the CPU for 132ms burst [Q DJFBECGH]
time 2558ms: Process N completed a CPU burst; 29 bursts to go [Q DJFBECGH]
time 2558ms: Process N switching out of CPU; will block on I/O until time 4160ms [Q DJFBECGH]
time 2558ms: Process M completed I/O; added to ready queue [Q DJFBECGHM]
time 2562ms: Process D started using the CPU for 211ms burst [Q JFBECGHM]
time 2717ms: Process L completed I/O; added to ready queue [Q JFBECGHML]
time 2773ms: Process D completed a CPU burst; 9 bursts to go [Q JFBECGHML]
time 2773ms: Process D switching out of CPU; will block on I/O until time 4915ms [Q JFBECGHML]
time 2777ms: Process J started using the CPU for 28ms burst [Q FBECGHML]
time 2805ms: Process J completed a CPU burst; 7 bursts to go [Q FBECGHML]
time 2805ms: Process J switching out of CPU; will block on I/O until time 3027ms [Q FBECGHML]
time 2809ms: Process F started using the CPU for 39ms burst [Q BECGHML]
time 2848ms: Process F completed a CPU burst; 32 bursts to go [Q BECGHML]
time 2848ms: Process F switching out of CPU; will block on I/O until time 3500ms [Q BECGHML]
time 2852ms: Process B started using the CPU for 198ms burst [Q ECGHML]
time 3024ms: Process K completed I/O; added to ready queue [Q ECGHMLK]
time 3027ms: Process J completed I/O; added to ready queue [Q ECGHMLKJ]
time 3050ms: Process B completed a CPU burst; 19 bursts to go [Q ECGHMLKJ]
time 3050ms: Process B switching out of CPU; will block on I/O until time 4182ms [Q ECGHMLKJ]
time 3054ms: Process E started using the CPU for 44ms burst [Q CGHMLKJ]
time 3098ms: Process E completed a CPU burst; 53 bursts to go [Q CGHMLKJ]
time 3098ms: Process E switching out of CPU; will block on I/O until time 3660ms [Q CGHMLKJ]
time 3102ms: Process C started using the CPU for 117ms burst [Q GHMLKJ]
time 3219ms: Process C completed a CPU burst; 2 bursts to go [Q GHMLKJ]
time 3219ms: Process C switching out of CPU; will block on I/O until time 3391ms [Q GHMLKJ]
time 3223ms: Process G started using the CPU for 65ms burst [Q HMLKJ]
time 3288ms: Process G completed a CPU burst; 77 bursts to go [Q HMLKJ]
time 3288ms: Process G switching out of CPU; will block on I/O until time 3730ms [Q HMLKJ]
time 3292ms: Process H started using the CPU for 72ms burst [Q MLKJ]
time 3364ms: Process H completed a CPU burst; 80 bursts to go [Q MLKJ]
time 3364ms: Process H switching out of CPU; will block on I/O until time 3786ms [Q MLKJ]
time 3368ms: Process M started using the CPU for 79ms burst [Q LKJ]
time 3391ms: Process C completed I/O; added to ready queue [Q LKJC]
time 3447ms: Process M completed a CPU burst; 45 bursts to go [Q LKJC]
time 3447ms: Process M switching out of CPU; will block on I/O until time 4589ms [Q LKJC]
time 3451ms: Process L started using the CPU for 4ms burst [Q KJC]
time 3455ms: Process L completed a CPU burst; 5 bursts to go [Q KJC]
time 3455ms: Process L switching out of CPU; will block on I/O until time 3877ms [Q KJC]
time 3459ms: Process K started using the CPU for 6ms burst [Q JC]
time 3465ms: Process K completed a CPU burst; 10 bursts to go [Q JC]
time 3465ms: Process K switching out of CPU; will block on I/O until time 4167ms [Q JC]
time 3469ms: Process J started using the CPU for 120ms burst [Q C]
time 3500ms: Process F completed I/O; added to ready queue [Q CF]
time 3571ms: Process A completed I/O; added to ready queue [Q CFA]
time 3589ms: Process J completed a CPU burst; 6 bursts to go [Q CFA]
time 3589ms: Process J switching out of CPU; will block on I/O until time 4151ms [Q CFA]
time 3593ms: Process C started using the CPU for 85ms burst [Q FA]
time 3660ms: Process E completed I/O; added to ready queue [Q FAE]
time 3678ms: Process C completed a CPU burst; 1 burst to go [Q FAE]
time 3678ms: Process C switching out of CPU; will block on I/O until time 3890ms [Q FAE]
time 3682ms: Process F started using the CPU for 195ms burst [Q AE]
time 3688ms: Process P completed I/O; added to ready queue [Q AEP]
time 3730ms: Process G completed I/O; added to ready queue [Q AEPG]
time 3786ms: Process H completed I/O; added to ready queue [Q AEPGH]
time 3877ms: Process F completed a CPU burst; 31 bursts to go [Q AEPGH]
time 3877ms: Process F switching out of CPU; will block on I/O until time 3889ms [Q AEPGH]
time 3877ms: Process L completed I/O; added to ready queue [Q AEPGHL]
time 3881ms: Process A started using the CPU for 39ms burst [Q EPGHL]
time 3889ms: Process F completed I/O; added to ready queue [Q EPGHLF]
time 3890ms: Process C completed I/O; added to ready queue [Q EPGHLFC]
time 3920ms: Process A completed a CPU burst; 13 bursts to go [Q EPGHLFC]
time 3920ms: Process A switching out of CPU; will block on I/O until time 4422ms [Q EPGHLFC]
time 3924ms: Process E started using the CPU for 2ms burst [Q PGHLFC]
time 3926ms: Process E completed a CPU burst; 52 bursts to go [Q PGHLFC]
time 3926ms: Process E switching out of CPU; will block on I/O until time 4178ms [Q PGHLFC]
time 3930ms: Process P started using the CPU for 52ms burst [Q GHLFC]
time 3982ms: Process P completed a CPU burst; 14 bursts to go [Q GHLFC]
time 3982ms: Process P switching out of CPU; will block on I/O until time 5074ms [Q GHLFC]
time 3986ms: Process G started using the CPU for 13ms burst [Q HLFC]
time 3999ms: Process G completed a CPU burst; 76 bursts to go [Q HLFC]
time 3999ms: Process G switching out of CPU; will block on I/O until time 4381ms [Q HLFC]
time 4003ms: Process H started using the CPU for 12ms burst [Q LFC]
time 4015ms: Process H completed a CPU burst; 79 bursts to go [Q LFC]
time 4015ms: Process H switching out of CPU; will block on I/O until time 4147ms [Q LFC]
time 4019ms: Process L started using the CPU for 69ms burst [Q FC]
time 4074ms: Process I completed I/O; added to ready queue [Q FCI]
time 4088ms: Process L completed a CPU burst; 4 bursts to go [Q FCI]
time 4088ms: Process L switching out of CPU; will block on I/O until time 5040ms [Q FCI]
time 4092ms: Process F started using the CPU for 72ms burst [Q CI]
time 4147ms: Process H completed I/O; added to ready queue [Q CIH]
time 4151ms: Process J completed I/O; added to ready queue [Q CIHJ]
time 4160ms: Process N completed I/O; added to ready queue [Q CIHJN]
time 4164ms: Process F completed a CPU burst; 30 bursts to go [Q CIHJN]
time 4164ms: Process F switching out of CPU; will block on I/O until time 4426ms [Q CIHJN]
time 4167ms: Process K completed I/O; added to ready queue [Q IHJNK]
time 4168ms: Process C started using the CPU for 79ms burst [Q IHJNK]
time 4178ms: Process E completed I/O; added to ready queue [Q IHJNKE]
time 4182ms: Process B completed I/O; added to ready queue [Q IHJNKEB]
time 4247ms: Process C terminated [Q IHJNKEB]
time 4251ms: Process I started using the CPU for 26ms burst [Q HJNKEB]
time 4277ms: Process I completed a CPU burst; 74 bursts to go [Q HJNKEB]
time 4277ms: Process I switching out of CPU; will block on I/O until time 4909ms [Q HJNKEB]
time 4281ms: Process H started using the CPU for 41ms burst [Q JNKEB]
time 4322ms: Process H completed a CPU burst; 78 bursts to go [Q JNKEB]
time 4322ms: Process H switching out of CPU; will block on I/O until time 4534ms [Q JNKEB]
time 4326ms: Process J started using the CPU for 31ms burst [Q NKEB]
time 4357ms: Process J completed a CPU burst; 5 bursts to go [Q NKEB]
time 4357ms: Process J switching out of CPU; will block on I/O until time 5219ms [Q NKEB]
time 4361ms: Process N started using the CPU for 17ms burst [Q KEB]
time 4378ms: Process N completed a CPU burst; 28 bursts to go [Q KEB]
time 4378ms: Process N switching out of CPU; will block on I/O until time 5130ms [Q KEB]
time 4381ms: Process G completed I/O; added to ready queue [Q EBG]
time 4382ms: Process K started using the CPU for 6ms burst [Q EBG]
time 4388ms: Process K completed a CPU burst; 9 bursts to go [Q EBG]
time 4388ms: Process K switching out of CPU; will block on I/O until time 5140ms [Q EBG]
time 4392ms: Process E started using the CPU for 42ms burst [Q BG]
time 4422ms: Process A completed I/O; added to ready queue [Q BGA]
time 4426ms: Process F completed I/O; added to ready queue [Q BGAF]
time 4434ms: Process E completed a CPU burst; 51 bursts to go [Q BGAF]
time 4434ms: Process E switching out of CPU; will block on I/O until time 4486ms [Q BGAF]
time 4438ms: Process B started using the CPU for 208ms burst [Q GAF]
time 4486ms: Process E completed I/O; added to ready queue [Q GAFE]
time 4534ms: Process H completed I/O; added to ready queue [Q GAFEH]
time 4589ms: Process M completed I/O; added to ready queue [Q GAFEHM]
time 4646ms: Process B completed a CPU burst; 18 bursts to go [Q GAFEHM]
time 4646ms: Process B switching out of CPU; will block on I/O until time 6268ms [Q GAFEHM]
time 4650ms: Process G started using the CPU for 128ms burst [Q AFEHM]
time 4778ms: Process G completed a CPU burst; 75 bursts to go [Q AFEHM]
time 4778ms: Process G switching out of CPU; will block on I/O until time 7000ms [Q AFEHM]
time 4782ms: Process A started using the CPU for 47ms burst [Q FEHM]
time 4829ms: Process A completed a CPU burst; 12 bursts to go [Q FEHM]
time 4829ms: Process A switching out of CPU; will block on I/O until time 4851ms [Q FEHM]
time 4833ms: Process F started using the CPU for 8ms burst [Q EHM]
time 4841ms: Process F completed a CPU burst; 29 bursts to go [Q EHM]
time 4841ms: Process F switching out of CPU; will block on I/O until time 5173ms [Q EHM]
time 4845ms: Process E started using the CPU for 108ms burst [Q HM]
time 4851ms: Process A completed I/O; added to ready queue [Q HMA]
time 4909ms: Process I completed I/O; added to ready queue [Q HMAI]
time 4914ms: Process O completed I/O; added to ready queue [Q HMAIO]
time 4915ms: Process D completed I/O; added to ready queue [Q HMAIOD]
time 4953ms: Process E completed a CPU burst; 50 bursts to go [Q HMAIOD]
time 4953ms: Process E switching out of CPU; will block on I/O until time 5045ms [Q HMAIOD]
time 4957ms: Process H started using the CPU for 160ms burst [Q MAIOD]
time 5040ms: Process L completed I/O; added to ready queue [Q MAIODL]
time 5045ms: Process E completed I/O; added to ready queue [Q MAIODLE]
time 5074ms: Process P completed I/O; added to ready queue [Q MAIODLEP]
time 5117ms: Process H completed a CPU burst; 77 bursts to go [Q MAIODLEP]
time 5117ms: Process H switching out of CPU; will block on I/O until time 5719ms [Q MAIODLEP]
time 5121ms: Process M started using the CPU for 18ms burst [Q AIODLEP]
time 5130ms: Process N completed I/O; added to ready queue [Q AIODLEPN]
time 5139ms: Process M completed a CPU burst; 44 bursts to go [Q AIODLEPN]
time 5139ms: Process M switching out of CPU; will block on I/O until time 7111ms [Q AIODLEPN]
time 5140ms: Process K completed I/O; added to ready queue [Q AIODLEPNK]
time 5143ms: Process A started using the CPU for 137ms burst [Q IODLEPNK]
time 5173ms: Process F completed I/O; added to ready queue [Q IODLEPNKF]
time 5219ms: Process J completed I/O; added to ready queue [Q IODLEPNKFJ]
time 5280ms: Process A completed a CPU burst; 11 bursts to go [Q IODLEPNKFJ]
time 5280ms: Process A switching out of CPU; will block on I/O until time 5522ms [Q IODLEPNKFJ]
time 5284ms: Process I started using the CPU for 45ms burst [Q ODLEPNKFJ]
time 5329ms: Process I completed a CPU burst; 73 bursts to go [Q ODLEPNKFJ]
time 5329ms: Process I switching out of CPU; will block on I/O until time 5631ms [Q ODLEPNKFJ]
time 5333ms: Process O started using the CPU for 57ms burst [Q DLEPNKFJ]
time 5390ms: Process O completed a CPU burst; 28 bursts to go [Q DLEPNKFJ]
time 5390ms: Process O switching out of CPU; will block on I/O until time 5762ms [Q DLEPNKFJ]
time 5394ms: Process D started using the CPU for 9ms burst [Q LEPNKFJ]
time 5403ms: Process D completed a CPU burst; 8 bursts to go [Q LEPNKFJ]
time 5403ms: Process D switching out of CPU; will block on I/O until time 5785ms [Q LEPNKFJ]
time 5407ms: Process L started using the CPU for 25ms burst [Q EPNKFJ]
time 5432ms: Process L completed a CPU burst; 3 bursts to go [Q EPNKFJ]
time 5432ms: Process L switching out of CPU; will block on I/O until time 6624ms [Q EPNKFJ]
time 5436ms: Process E started using the CPU for 6ms burst [Q PNKFJ]
time 5442ms: Process E completed a CPU burst; 49 bursts to go [Q PNKFJ]
time 5442ms: Process E switching out of CPU; will block on I/O until time 5764ms [Q PNKFJ]
time 5446ms: Process P started using the CPU for 56ms burst [Q NKFJ]
time 5502ms: Process P completed a CPU burst; 13 bursts to go [Q NKFJ]
time 5502ms: Process P switching out of CPU; will block on I/O until time 6714ms [Q NKFJ]
time 5506ms: Process N started using the CPU for 71ms burst [Q KFJ]
time 5522ms: Process A completed I/O; added to ready queue [Q KFJA]
time 5577ms: Process N completed a CPU burst; 27 bursts to go [Q KFJA]
time 5577ms: Process N switching out of CPU; will block on I/O until time 7519ms [Q KFJA]
time 5581ms: Process K started using the CPU for 157ms burst [Q FJA]
time 5631ms: Process I completed I/O; added to ready queue [Q FJAI]
time 5719ms: Process H completed I/O; added to ready queue [Q FJAIH]
time 5738ms: Process K completed a CPU burst; 8 bursts to go [Q FJAIH]
time 5738ms: Process K switching out of CPU; will block on I/O until time 5900ms [Q FJAIH]
time 5742ms: Process F started using the CPU for 230ms burst [Q JAIH]
time 5762ms: Process O completed I/O; added to ready queue [Q JAIHO]
time 5764ms: Process E completed I/O; added to ready queue [Q JAIHOE]
time 5785ms: Process D completed I/O; added to ready queue [Q JAIHOED]
time 5900ms: Process K completed I/O; added to ready queue [Q JAIHOEDK]
time 5972ms: Process F completed a CPU burst; 28 bursts to go [Q JAIHOEDK]
time 5972ms: Process F switching out of CPU; will block on I/O until time 6004ms [Q JAIHOEDK]
time 5976ms: Process J started using the CPU for 32ms burst [Q AIHOEDK]
time 6004ms: Process F completed I/O; added to ready queue [Q AIHOEDKF]
time 6008ms: Process J completed a CPU burst; 4 bursts to go [Q AIHOEDKF]
time 6008ms: Process J switching out of CPU; will block on I/O until time 6140ms [Q AIHOEDKF]
time 6012ms: Process A started using the CPU for 64ms burst [Q IHOEDKF]
time 6076ms: Process A completed a CPU burst; 10 bursts to go [Q IHOEDKF]
time 6076ms: Process A switching out of CPU; will block on I/O until time 6228ms [Q IHOEDKF]
time 6080ms: Process I started using the CPU for 38ms burst [Q HOEDKF]
time 6118ms: Process I completed a CPU burst; 72 bursts to go [Q HOEDKF]
time 6118ms: Process I switching out of CPU; will block on I/O until time 6700ms [Q HOEDKF]
time 6122ms: Process H started using the CPU for 28ms burst [Q OEDKF]
time 6140ms: Process J completed I/O; added to ready queue [Q OEDKFJ]
time 6150ms: Process H completed a CPU burst; 76 bursts to go [Q OEDKFJ]
time 6150ms: Process H switching out of CPU; will block on I/O until time 7112ms [Q OEDKFJ]
time 6154ms: Process O started using the CPU for 13ms burst [Q EDKFJ]
time 6167ms: Process O completed a CPU burst; 27 bursts to go [Q EDKFJ]
time 6167ms: Process O switching out of CPU; will block on I/O until time 7499ms [Q EDKFJ]
time 6171ms: Process E started using the CPU for 112ms burst [Q DKFJ]
time 6228ms: Process A completed I/O; added to ready queue [Q DKFJA]
time 6268ms: Process B completed I/O; added to ready queue [Q DKFJAB]
time 6283ms: Process E completed a CPU burst; 48 bursts to go [Q DKFJAB]
time 6283ms: Process E switching out of CPU; will block on I/O until time 7395ms [Q DKFJAB]
time 6287ms: Process D started using the CPU for 4ms burst [Q KFJAB]
time 6291ms: Process D completed a CPU burst; 7 bursts to go [Q KFJAB]
time 6291ms: Process D switching out of CPU; will block on I/O until time 6773ms [Q KFJAB]
time 6295ms: Process K started using the CPU for 104ms burst [Q FJAB]
time 6399ms: Process K completed a CPU burst; 7 bursts to go [Q FJAB]
time 6399ms: Process K switching out of CPU; will block on I/O until time 7851ms [Q FJAB]
time 6403ms: Process F started using the CPU for 33ms burst [Q JAB]
time 6436ms: Process F completed a CPU burst; 27 bursts to go [Q JAB]
time 6436ms: Process F switching out of CPU; will block on I/O until time 6998ms [Q JAB]
time 6440ms: Process J started using the CPU for 23ms burst [Q AB]
time 6463ms: Process J completed a CPU burst; 3 bursts to go [Q AB]
time 6463ms: Process J switching out of CPU; will block on I/O until time 6625ms [Q AB]
time 6467ms: Process A started using the CPU for 68ms burst [Q B]
time 6535ms: Process A completed a CPU burst; 9 bursts to go [Q B]
time 6535ms: Process A switching out of CPU; will block on I/O until time 7177ms [Q B]
time 6539ms: Process B started using the CPU for 50ms burst [Q empty]
time 6589ms: Process B completed a CPU burst; 17 bursts to go [Q empty]
time 6589ms: Process B switching out of CPU; will block on I/O until time 7051ms [Q empty]
time 6624ms: Process L completed I/O; added to ready queue [Q L]
time 6625ms: Process J completed I/O; added to ready queue [Q J]
time 6626ms: Process L started using the CPU for 2ms burst [Q J]
time 6628ms: Process L completed a CPU burst; 2 bursts to go [Q J]
time 6628ms: Process L switching out of CPU; will block on I/O until time 7000ms [Q J]
time 6632ms: Process J started using the CPU for 51ms burst [Q empty]
time 6683ms: Process J completed a CPU burst; 2 bursts to go [Q empty]
time 6683ms: Process J switching out of CPU; will block on I/O until time 7655ms [Q empty]
time 6700ms: Process I completed I/O; added to ready queue [Q I]
time 6702ms: Process I started using the CPU for 79ms burst [Q empty]
time 6714ms: Process P completed I/O; added to ready queue [Q P]
time 6773ms: Process D completed I/O; added to ready queue [Q PD]
time 6781ms: Process I completed a CPU burst; 71 bursts to go [Q PD]
time 6781ms: Process I switching out of CPU; will block on I/O until time 7943ms [Q PD]
time 6785ms: Process P started using the CPU for 155ms burst [Q D]
time 6940ms: Process P completed a CPU burst; 12 bursts to go [Q D]
time 6940ms: Process P switching out of CPU; will block on I/O until time 8122ms [Q D]
time 6944ms: Process D started using the CPU for 149ms burst [Q empty]
time 6998ms: Process F completed I/O; added to ready queue [Q F]
time 7000ms: Process G completed I/O; added to ready queue [Q FG]
time 7000ms: Process L completed I/O; added to ready queue [Q FGL]
time 7051ms: Process B completed I/O; added to ready queue [Q FGLB]
time 7093ms: Process D completed a CPU burst; 6 bursts to go [Q FGLB]
time 7093ms: Process D switching out of CPU; will block on I/O until time 7905ms [Q FGLB]
time 7097ms: Process F started using the CPU for 76ms burst [Q GLB]
time 7111ms: Process M completed I/O; added to ready queue [Q GLBM]
time 7112ms: Process H completed I/O; added to ready queue [Q GLBMH]
time 7173ms: Process F completed a CPU burst; 26 bursts to go [Q GLBMH]
time 7173ms: Process F switching out of CPU; will block on I/O until time 7555ms [Q GLBMH]
time 7177ms: Process G started using the CPU for 15ms burst [Q LBMH]
time 7177ms: Process A completed I/O; added to ready queue [Q LBMHA]
time 7192ms: Process G completed a CPU burst; 74 bursts to go [Q LBMHA]
time 7192ms: Process G switching out of CPU; will block on I/O until time 8134ms [Q LBMHA]
time 7196ms: Process L started using the CPU for 164ms burst [Q BMHA]
time 7360ms: Process L completed a CPU burst; 1 burst to go [Q BMHA]
time 7360ms: Process L switching out of CPU; will block on I/O until time 7862ms [Q BMHA]
time 7364ms: Process B started using the CPU for 82ms burst [Q MHA]
time 7395ms: Process E completed I/O; added to ready queue [Q MHAE]
time 7446ms: Process B completed a CPU burst; 16 bursts to go [Q MHAE]
time 7446ms: Process B switching out of CPU; will block on I/O until time 7608ms [Q MHAE]
time 7450ms: Process M started using the CPU for 66ms burst [Q HAE]
time 7499ms: Process O completed I/O; added to ready queue [Q HAEO]
time 7516ms: Process M completed a CPU burst; 43 bursts to go [Q HAEO]
time 7516ms: Process M switching out of CPU; will block on I/O until time 9328ms [Q HAEO]
time 7519ms: Process N completed I/O; added to ready queue [Q AEON]
time 7520ms: Process H started using the CPU for 51ms burst [Q AEON]
time 7555ms: Process F completed I/O; added to ready queue [Q AEONF]
time 7571ms: Process H completed a CPU burst; 75 bursts to go [Q AEONF]
time 7571ms: Process H switching out of CPU; will block on I/O until time 7803ms [Q AEONF]
time 7575ms: Process A started using the CPU for 113ms burst [Q EONF]
time 7608ms: Process B completed I/O; added to ready queue [Q EONFB]
time 7655ms: Process J completed I/O; added to ready queue [Q EONFBJ]
time 7688ms: Process A completed a CPU burst; 8 bursts to go [Q EONFBJ]
time 7688ms: Process A switching out of CPU; will block on I/O until time 7850ms [Q EONFBJ]
time 7692ms: Process E started using the CPU for 12ms burst [Q ONFBJ]
time 7704ms: Process E completed a CPU burst; 47 bursts to go [Q ONFBJ]
time 7704ms: Process E switching out of CPU; will block on I/O until time 8156ms [Q ONFBJ]
time 7708ms: Process O started using the CPU for 130ms burst [Q NFBJ]
time 7803ms: Process H completed I/O; added to ready queue [Q NFBJH]
time 7838ms: Process O completed a CPU burst; 26 bursts to go [Q NFBJH]
time 7838ms: Process O switching out of CPU; will block on I/O until time 8550ms [Q NFBJH]
time 7842ms: Process N started using the CPU for 27ms burst [Q FBJH]
time 7850ms: Process A completed I/O; added to ready queue [Q FBJHA]
time 7851ms: Process K completed I/O; added to ready queue [Q FBJHAK]
time 7862ms: Process L completed I/O; added to ready queue [Q FBJHAKL]
time 7869ms: Process N completed a CPU burst; 26 bursts to go [Q FBJHAKL]
time 7869ms: Process N switching out of CPU; will block on I/O until time 8141ms [Q FBJHAKL]
time 7873ms: Process F started using the CPU for 107ms burst [Q BJHAKL]
time 7905ms: Process D completed I/O; added to ready queue [Q BJHAKLD]
time 7943ms: Process I completed I/O; added to ready queue [Q BJHAKLDI]
time 7980ms: Process F completed a CPU burst; 25 bursts to go [Q BJHAKLDI]
time 7980ms: Process F switching out of CPU; will block on I/O until time 8162ms [Q BJHAKLDI]
time 7984ms: Process B started using the CPU for 7ms burst [Q JHAKLDI]
time 7991ms: Process B completed a CPU burst; 15 bursts to go [Q JHAKLDI]
time 7991ms: Process B switching out of CPU; will block on I/O until time 8293ms [Q JHAKLDI]
time 7995ms: Process J started using the CPU for 216ms burst [Q HAKLDI]
time 8122ms: Process P completed I/O; added to ready queue [Q HAKLDIP]
time 8134ms: Process G completed I/O; added to ready queue [Q HAKLDIPG]
time 8141ms: Process N completed I/O; added to ready queue [Q HAKLDIPGN]
time 8156ms: Process E completed I/O; added to ready queue [Q HAKLDIPGNE]
time 8162ms: Process F completed I/O; added to ready queue [Q HAKLDIPGNEF]
time 8211ms: Process J completed a CPU burst; 1 burst to go [Q HAKLDIPGNEF]
time 8211ms: Process J switching out of CPU; will block on I/O until time 8293ms [Q HAKLDIPGNEF]
time 8215ms: Process H started using the CPU for 87ms burst [Q AKLDIPGNEF]
time 8293ms: Process B completed I/O; added to ready queue [Q AKLDIPGNEFB]
time 8293ms: Process J completed I/O; added to ready queue [Q AKLDIPGNEFBJ]
time 8302ms: Process H completed a CPU burst; 74 bursts to go [Q AKLDIPGNEFBJ]
time 8302ms: Process H switching out of CPU; will block on I/O until time 8874ms [Q AKLDIPGNEFBJ]
time 8306ms: Process A started using the CPU for 11ms burst [Q KLDIPGNEFBJ]
time 8317ms: Process A completed a CPU burst; 7 bursts to go [Q KLDIPGNEFBJ]
time 8317ms: Process A switching out of CPU; will block on I/O until time 9939ms [Q KLDIPGNEFBJ]
time 8321ms: Process K started using the CPU for 86ms burst [Q LDIPGNEFBJ]
time 8407ms: Process K completed a CPU burst; 6 bursts to go [Q LDIPGNEFBJ]
time 8407ms: Process K switching out of CPU; will block on I/O until time 8689ms [Q LDIPGNEFBJ]
time 8411ms: Process L started using the CPU for 111ms burst [Q DIPGNEFBJ]
time 8522ms: Process L terminated [Q DIPGNEFBJ]
time 8526ms: Process D started using the CPU for 52ms burst [Q IPGNEFBJ]
time 8550ms: Process O completed I/O; added to ready queue [Q IPGNEFBJO]
time 8578ms: Process D completed a CPU burst; 5 bursts to go [Q IPGNEFBJO]
time 8578ms: Process D switching out of CPU; will block on I/O until time 8610ms [Q IPGNEFBJO]
time 8582ms: Process I started using the CPU for 84ms burst [Q PGNEFBJO]
time 8610ms: Process D completed I/O; added to ready queue [Q PGNEFBJOD]
time 8666ms: Process I completed a CPU burst; 70 bursts to go [Q PGNEFBJOD]
time 8666ms: Process I switching out of CPU; will block on I/O until time 9178ms [Q PGNEFBJOD]
time 8670ms: Process P started using the CPU for 4ms burst [Q GNEFBJOD]
time 8674ms: Process P completed a CPU burst; 11 bursts to go [Q GNEFBJOD]
time 8674ms: Process P switching out of CPU; will block on I/O until time 10466ms [Q GNEFBJOD]
time 8678ms: Process G started using the CPU for 112ms burst [Q NEFBJOD]
time 8689ms: Process K completed I/O; added to ready queue [Q NEFBJODK]
time 8790ms: Process G completed a CPU burst; 73 bursts to go [Q NEFBJODK]
time 8790ms: Process G switching out of CPU; will block on I/O until time 9222ms [Q NEFBJODK]
time 8794ms: Process N started using the CPU for 57ms burst [Q EFBJODK]
time 8851ms: Process N completed a CPU burst; 25 bursts to go [Q EFBJODK]
time 8851ms: Process N switching out of CPU; will block on I/O until time 8953ms [Q EFBJODK]
time 8855ms: Process E started using the CPU for 9ms burst [Q FBJODK]
time 8864ms: Process E completed a CPU burst; 46 bursts to go [Q FBJODK]
time 8864ms: Process E switching out of CPU; will block on I/O until time 9536ms [Q FBJODK]
time 8868ms: Process F started using the CPU for 89ms burst [Q BJODK]
time 8874ms: Process H completed I/O; added to ready queue [Q BJODKH]
time 8953ms: Process N completed I/O; added to ready queue [Q BJODKHN]
time 8957ms: Process F completed a CPU burst; 24 bursts to go [Q BJODKHN]
time 8957ms: Process F switching out of CPU; will block on I/O until time 9789ms [Q BJODKHN]
time 8961ms: Process B started using the CPU for 52ms burst [Q JODKHN]
time 9013ms: Process B completed a CPU burst; 14 bursts to go [Q JODKHN]
time 9013ms: Process B switching out of CPU; will block on I/O until time 9135ms [Q JODKHN]
time 9017ms: Process J started using the CPU for 7ms burst [Q ODKHN]
time 9024ms: Process J terminated [Q ODKHN]
time 9028ms: Process O started using the CPU for 68ms burst [Q DKHN]
time 9096ms: Process O completed a CPU burst; 25 bursts to go [Q DKHN]
time 9096ms: Process O switching out of CPU; will block on I/O until time 10268ms [Q DKHN]
time 9100ms: Process D started using the CPU for 23ms burst [Q KHN]
time 9123ms: Process D completed a CPU burst; 4 bursts to go [Q KHN]
time 9123ms: Process D switching out of CPU; will block on I/O until time 11065ms [Q KHN]
time 9127ms: Process K started using the CPU for 50ms burst [Q HN]
time 9135ms: Process B completed I/O; added to ready queue [Q HNB]
time 9177ms: Process K completed a CPU burst; 5 bursts to go [Q HNB]
time 9177ms: Process K switching out of CPU; will block on I/O until time 9679ms [Q HNB]
time 9178ms: Process I completed I/O; added to ready queue [Q HNBI]
time 9181ms: Process H started using the CPU for 156ms burst [Q NBI]
time 9222ms: Process G completed I/O; added to ready queue [Q NBIG]
time 9328ms: Process M completed I/O; added to ready queue [Q NBIGM]
time 9337ms: Process H completed a CPU burst; 73 bursts to go [Q NBIGM]
time 9337ms: Process H switching out of CPU; will block on I/O until time 9899ms [Q NBIGM]
time 9341ms: Process N started using the CPU for 84ms burst [Q BIGM]
time 9425ms: Process N completed a CPU burst; 24 bursts to go [Q BIGM]
time 9425ms: Process N switching out of CPU; will block on I/O until time 9447ms [Q BIGM]
time 9429ms: Process B started using the CPU for 228ms burst [Q IGM]
time 9447ms: Process N completed I/O; added to ready queue [Q IGMN]
time 9536ms: Process E completed I/O; added to ready queue [Q IGMNE]
time 9657ms: Process B completed a CPU burst; 13 bursts to go [Q IGMNE]
time 9657ms: Process B switching out of CPU; will block on I/O until time 10429ms [Q IGMNE]
time 9661ms: Process I started using the CPU for 27ms burst [Q GMNE]
time 9679ms: Process K completed I/O; added to ready queue [Q GMNEK]
time 9688ms: Process I completed a CPU burst; 69 bursts to go [Q GMNEK]
time 9688ms: Process I switching out of CPU; will block on I/O until time 11590ms [Q GMNEK]
time 9692ms: Process G started using the CPU for 30ms burst [Q MNEK]
time 9722ms: Process G completed a CPU burst; 72 bursts to go [Q MNEK]
time 9722ms: Process G switching out of CPU; will block on I/O until time 10194ms [Q MNEK]
time 9726ms: Process M started using the CPU for 103ms burst [Q NEK]
time 9789ms: Process F completed I/O; added to ready queue [Q NEKF]
time 9829ms: Process M completed a CPU burst; 42 bursts to go [Q NEKF]
time 9829ms: Process M switching out of CPU; will block on I/O until time 10231ms [Q NEKF]
time 9833ms: Process N started using the CPU for 131ms burst [Q EKF]
time 9899ms: Process H completed I/O; added to ready queue [Q EKFH]
time 9939ms: Process A completed I/O; added to ready queue [Q EKFHA]
time 9964ms: Process N completed a CPU burst; 23 bursts to go [Q EKFHA]
time 9964ms: Process N switching out of CPU; will block on I/O until time 10196ms [Q EKFHA]
time 9968ms: Process E started using the CPU for 62ms burst [Q KFHA]
time 10030ms: Process E completed a CPU burst; 45 bursts to go [Q KFHA]
time 10030ms: Process E switching out of CPU; will block on I/O until time 10632ms [Q KFHA]
time 10034ms: Process K started using the CPU for 4ms burst [Q FHA]
time 10038ms: Process K completed a CPU burst; 4 bursts to go [Q FHA]
time 10038ms: Process K switching out of CPU; will block on I/O until time 10640ms [Q FHA]
time 10042ms: Process F started using the CPU for 102ms burst [Q HA]
time 10144ms: Process F completed a CPU burst; 23 bursts to go [Q HA]
time 10144ms: Process F switching out of CPU; will block on I/O until time 11496ms [Q HA]
time 10148ms: Process H started using the CPU for 184ms burst [Q A]
time 10194ms: Process G completed I/O; added to ready queue [Q AG]
time 10196ms: Process N completed I/O; added to ready queue [Q AGN]
time 10231ms: Process M completed I/O; added to ready queue [Q AGNM]
time 10268ms: Process O completed I/O; added to ready queue [Q AGNMO]
time 10332ms: Process H completed a CPU burst; 72 bursts to go [Q AGNMO]
time 10332ms: Process H switching out of CPU; will block on I/O until time 10594ms [Q AGNMO]
time 10336ms: Process A started using the CPU for 24ms burst [Q GNMO]
time 10360ms: Process A completed a CPU burst; 6 bursts to go [Q GNMO]
time 10360ms: Process A switching out of CPU; will block on I/O until time 11532ms [Q GNMO]
time 10364ms: Process G started using the CPU for 50ms burst [Q NMO]
time 10414ms: Process G completed a CPU burst; 71 bursts to go [Q NMO]
time 10414ms: Process G switching out of CPU; will block on I/O until time 12616ms [Q NMO]
time 10418ms: Process N started using the CPU for 222ms burst [Q MO]
time 10429ms: Process B completed I/O; added to ready queue [Q MOB]
time 10466ms: Process P completed I/O; added to ready queue [Q MOBP]
time 10594ms: Process H completed I/O; added to ready queue [Q MOBPH]
time 10632ms: Process E completed I/O; added to ready queue [Q MOBPHE]
time 10640ms: Process N completed a CPU burst; 22 bursts to go [Q MOBPHE]
time 10640ms: Process N switching out of CPU; will block on I/O until time 10692ms [Q MOBPHE]
time 10640ms: Process K completed I/O; added to ready queue [Q MOBPHEK]
time 10644ms: Process M started using the CPU for 171ms burst [Q OBPHEK]
time 10692ms: Process N completed I/O; added to ready queue [Q OBPHEKN]
time 10815ms: Process M completed a CPU burst; 41 bursts to go [Q OBPHEKN]
time 10815ms: Process M switching out of CPU; will block on I/O until time 11027ms [Q OBPHEKN]
time 10819ms: Process O started using the CPU for 136ms burst [Q BPHEKN]
time 10955ms: Process O completed a CPU burst; 24 bursts to go [Q BPHEKN]
time 10955ms: Process O switching out of CPU; will block on I/O until time 12007ms [Q BPHEKN]
time 10959ms: Process B started using the CPU for 138ms burst [Q PHEKN]
time 11027ms: Process M completed I/O; added to ready queue [Q PHEKNM]
time 11065ms: Process D completed I/O; added to ready queue [Q PHEKNMD]
time 11097ms: Process B completed a CPU burst; 12 bursts to go [Q PHEKNMD]
time 11097ms: Process B switching out of CPU; will block on I/O until time 11919ms [Q PHEKNMD]
time 11101ms: Process P started using the CPU for 105ms burst [Q HEKNMD]
time 11206ms: Process P completed a CPU burst; 10 bursts to go [Q HEKNMD]
time 11206ms: Process P switching out of CPU; will block on I/O until time 11798ms [Q HEKNMD]
time 11210ms: Process H started using the CPU for 2ms burst [Q EKNMD]
time 11212ms: Process H completed a CPU burst; 71 bursts to go [Q EKNMD]
time 11212ms: Process H switching out of CPU; will block on I/O until time 11354ms [Q EKNMD]
time 11216ms: Process E started using the CPU for 213ms burst [Q KNMD]
time 11354ms: Process H completed I/O; added to ready queue [Q KNMDH]
time 11429ms: Process E completed a CPU burst; 44 bursts to go [Q KNMDH]
time 11429ms: Process E switching out of CPU; will block on I/O until time 13361ms [Q KNMDH]
time 11433ms: Process K started using the CPU for 21ms burst [Q NMDH]
time 11454ms: Process K completed a CPU burst; 3 bursts to go [Q NMDH]
time 11454ms: Process K switching out of CPU; will block on I/O until time 12106ms [Q NMDH]
time 11458ms: Process N started using the CPU for 148ms burst [Q MDH]
time 11496ms: Process F completed I/O; added to ready queue [Q MDHF]
time 11532ms: Process A completed I/O; added to ready queue [Q MDHFA]
time 11590ms: Process I completed I/O; added to ready queue [Q MDHFAI]
time 11606ms: Process N completed a CPU burst; 21 bursts to go [Q MDHFAI]
time 11606ms: Process N switching out of CPU; will block on I/O until time 12988ms [Q MDHFAI]
time 11610ms: Process M started using the CPU for 200ms burst [Q DHFAI]
time 11798ms: Process P completed I/O; added to ready queue [Q DHFAIP]
time 11810ms: Process M completed a CPU burst; 40 bursts to go [Q DHFAIP]
time 11810ms: Process M switching out of CPU; will block on I/O until time 13122ms [Q DHFAIP]
time 11814ms: Process D started using the CPU for 76ms burst [Q HFAIP]
time 11890ms: Process D completed a CPU burst; 3 bursts to go [Q HFAIP]
time 11890ms: Process D switching out of CPU; will block on I/O until time 12622ms [Q HFAIP]
time 11894ms: Process H started using the CPU for 29ms burst [Q FAIP]
time 11919ms: Process B completed I/O; added to ready queue [Q FAIPB]
time 11923ms: Process H completed a CPU burst; 70 bursts to go [Q FAIPB]
time 11923ms: Process H switching out of CPU; will block on I/O until time 14145ms [Q FAIPB]
time 11927ms: Process F started using the CPU for 147ms burst [Q AIPB]
time 12007ms: Process O completed I/O; added to ready queue [Q AIPBO]
time 12074ms: Process F completed a CPU burst; 22 bursts to go [Q AIPBO]
time 12074ms: Process F switching out of CPU; will block on I/O until time 12126ms [Q AIPBO]
time 12078ms: Process A started using the CPU for 76ms burst [Q IPBO]
time 12106ms: Process K completed I/O; added to ready queue [Q IPBOK]
time 12126ms: Process F completed I/O; added to ready queue [Q IPBOKF]
time 12154ms: Process A completed a CPU burst; 5 bursts to go [Q IPBOKF]
time 12154ms: Process A switching out of CPU; will block on I/O until time 12436ms [Q IPBOKF]
time 12158ms: Process I started using the CPU for 70ms burst [Q PBOKF]
time 12228ms: Process I completed a CPU burst; 68 bursts to go [Q PBOKF]
time 12228ms: Process I switching out of CPU; will block on I/O until time 13770ms [Q PBOKF]
time 12232ms: Process P started using the CPU for 16ms burst [Q BOKF]
time 12248ms: Process P completed a CPU burst; 9 bursts to go [Q BOKF]
time 12248ms: Process P switching out of CPU; will block on I/O until time 12900ms [Q BOKF]
time 12252ms: Process B started using the CPU for 67ms burst [Q OKF]
time 12319ms: Process B completed a CPU burst; 11 bursts to go [Q OKF]
time 12319ms: Process B switching out of CPU; will block on I/O until time 12391ms [Q OKF]
time 12323ms: Process O started using the CPU for 69ms burst [Q KF]
time 12391ms: Process B completed I/O; added to ready queue [Q KFB]
time 12392ms: Process O completed a CPU burst; 23 bursts to go [Q KFB]
time 12392ms: Process O switching out of CPU; will block on I/O until time 13144ms [Q KFB]
time 12396ms: Process K started using the CPU for 120ms burst [Q FB]
time 12436ms: Process A completed I/O; added to ready queue [Q FBA]
time 12516ms: Process K completed a CPU burst; 2 bursts to go [Q FBA]
time 12516ms: Process K switching out of CPU; will block on I/O until time 13208ms [Q FBA]
time 12520ms: Process F started using the CPU for 97ms burst [Q BA]
time 12616ms: Process G completed I/O; added to ready queue [Q BAG]
time 12617ms: Process F completed a CPU burst; 21 bursts to go [Q BAG]
time 12617ms: Process F switching out of CPU; will block on I/O until time 12659ms [Q BAG]
time 12621ms: Process B started using the CPU for 120ms burst [Q AG]
time 12622ms: Process D completed I/O; added to ready queue [Q AGD]
time 12659ms: Process F completed I/O; added to ready queue [Q AGDF]
time 12741ms: Process B completed a CPU burst; 10 bursts to go [Q AGDF]
time 12741ms: Process B switching out of CPU; will block on I/O until time 12873ms [Q AGDF]
time 12745ms: Process A started using the CPU for 122ms burst [Q GDF]
time 12867ms: Process A completed a CPU burst; 4 bursts to go [Q GDF]
time 12867ms: Process A switching out of CPU; will block on I/O until time 13199ms [Q GDF]
time 12871ms: Process G started using the CPU for 5ms burst [Q DF]
time 12873ms: Process B completed I/O; added to ready queue [Q DFB]
time 12876ms: Process G completed a CPU burst; 70 bursts to go [Q DFB]
time 12876ms: Process G switching out of CPU; will block on I/O until time 14858ms [Q DFB]
time 12880ms: Process D started using the CPU for 50ms burst [Q FB]
time 12900ms: Process P completed I/O; added to ready queue [Q FBP]
time 12930ms: Process D completed a CPU burst; 2 bursts to go [Q FBP]
time 12930ms: Process D switching out of CPU; will block on I/O until time 13052ms [Q FBP]
time 12934ms: Process F started using the CPU for 157ms burst [Q BP]
time 12988ms: Process N completed I/O; added to ready queue [Q BPN]
time 13052ms: Process D completed I/O; added to ready queue [Q BPND]
time 13091ms: Process F completed a CPU burst; 20 bursts to go [Q BPND]
time 13091ms: Process F switching out of CPU; will block on I/O until time 13193ms [Q BPND]
time 13095ms: Process B started using the CPU for 49ms burst [Q PND]
time 13122ms: Process M completed I/O; added to ready queue [Q PNDM]
time 13144ms: Process B completed a CPU burst; 9 bursts to go [Q PNDM]
time 13144ms: Process B switching out of CPU; will block on I/O until time 13566ms [Q PNDM]
time 13144ms: Process O completed I/O; added to ready queue [Q PNDMO]
time 13148ms: Process P started using the CPU for 219ms burst [Q NDMO]
time 13193ms: Process F completed I/O; added to ready queue [Q NDMOF]
time 13199ms: Process A completed I/O; added to ready queue [Q NDMOFA]
time 13208ms: Process K completed I/O; added to ready queue [Q NDMOFAK]
time 13361ms: Process E completed I/O; added to ready queue [Q NDMOFAKE]
time 13367ms: Process P completed a CPU burst; 8 bursts to go [Q NDMOFAKE]
time 13367ms: Process P switching out of CPU; will block on I/O until time 15419ms [Q NDMOFAKE]
time 13371ms: Process N started using the CPU for 32ms burst [Q DMOFAKE]
time 13403ms: Process N completed a CPU burst; 20 bursts to go [Q DMOFAKE]
time 13403ms: Process N switching out of CPU; will block on I/O until time 14985ms [Q DMOFAKE]
time 13407ms: Process D started using the CPU for 24ms burst [Q MOFAKE]
time 13431ms: Process D completed a CPU burst; 1 burst to go [Q MOFAKE]
time 13431ms: Process D switching out of CPU; will block on I/O until time 13683ms [Q MOFAKE]
time 13435ms: Process M started using the CPU for 117ms burst [Q OFAKE]
time 13552ms: Process M completed a CPU burst; 39 bursts to go [Q OFAKE]
time 13552ms: Process M switching out of CPU; will block on I/O until time 14894ms [Q OFAKE]
time 13556ms: Process O started using the CPU for 6ms burst [Q FAKE]
time 13562ms: Process O completed a CPU burst; 22 bursts to go [Q FAKE]
time 13562ms: Process O switching out of CPU; will block on I/O until time 15204ms [Q FAKE]
time 13566ms: Process F started using the CPU for 24ms burst [Q AKE]
time 13566ms: Process B completed I/O; added to ready queue [Q AKEB]
time 13590ms: Process F completed a CPU burst; 19 bursts to go [Q AKEB]
time 13590ms: Process F switching out of CPU; will block on I/O until time 14562ms [Q AKEB]
time 13594ms: Process A started using the CPU for 9ms burst [Q KEB]
time 13603ms: Process A completed a CPU burst; 3 bursts to go [Q KEB]
time 13603ms: Process A switching out of CPU; will block on I/O until time 14285ms [Q KEB]
time 13607ms: Process K started using the CPU for 199ms burst [Q EB]
time 13683ms: Process D completed I/O; added to ready queue [Q EBD]
time 13770ms: Process I completed I/O; added to ready queue [Q EBDI]
time 13806ms: Process K completed a CPU burst; 1 burst to go [Q EBDI]
time 13806ms: Process K switching out of CPU; will block on I/O until time 14458ms [Q EBDI]
time 13810ms: Process E started using the CPU for 54ms burst [Q BDI]
time 13864ms: Process E completed a CPU burst; 43 bursts to go [Q BDI]
time 13864ms: Process E switching out of CPU; will block on I/O until time 14816ms [Q BDI]
time 13868ms: Process B started using the CPU for 134ms burst [Q DI]
time 14002ms: Process B completed a CPU burst; 8 bursts to go [Q DI]
time 14002ms: Process B switching out of CPU; will block on I/O until time 14324ms [Q DI]
time 14006ms: Process D started using the CPU for 1ms burst [Q I]
time 14007ms: Process D terminated [Q I]
time 14011ms: Process I started using the CPU for 107ms burst [Q empty]
time 14118ms: Process I completed a CPU burst; 67 bursts to go [Q empty]
time 14118ms: Process I switching out of CPU; will block on I/O until time 14590ms [Q empty]
time 14145ms: Process H completed I/O; added to ready queue [Q H]
time 14147ms: Process H started using the CPU for 76ms burst [Q empty]
time 14223ms: Process H completed a CPU burst; 69 bursts to go [Q empty]
time 14223ms: Process H switching out of CPU; will block on I/O until time 16345ms [Q empty]
time 14285ms: Process A completed I/O; added to ready queue [Q A]
time 14287ms: Process A started using the CPU for 62ms burst [Q empty]
time 14324ms: Process B completed I/O; added to ready queue [Q B]
time 14349ms: Process A completed a CPU burst; 2 bursts to go [Q B]
time 14349ms: Process A switching out of CPU; will block on I/O until time 15121ms [Q B]
time 14353ms: Process B started using the CPU for 144ms burst [Q empty]
time 14458ms: Process K completed I/O; added to ready queue [Q K]
time 14497ms: Process B completed a CPU burst; 7 bursts to go [Q K]
time 14497ms: Process B switching out of CPU; will block on I/O until time 15289ms [Q K]
time 14501ms: Process K started using the CPU for 47ms burst [Q empty]
time 14548ms: Process K terminated [Q empty]
time 14562ms: Process F completed I/O; added to ready queue [Q F]
time 14564ms: Process F started using the CPU for 31ms burst [Q empty]
time 14590ms: Process I completed I/O; added to ready queue [Q I]
time 14595ms: Process F completed a CPU burst; 18 bursts to go [Q I]
time 14595ms: Process F switching out of CPU; will block on I/O until time 14807ms [Q I]
time 14599ms: Process I started using the CPU for 21ms burst [Q empty]
time 14620ms: Process I completed a CPU burst; 66 bursts to go [Q empty]
time 14620ms: Process I switching out of CPU; will block on I/O until time 14712ms [Q empty]
time 14712ms: Process I completed I/O; added to ready queue [Q I]
time 14714ms: Process I started using the CPU for 179ms burst [Q empty]
time 14807ms: Process F completed I/O; added to ready queue [Q F]
time 14816ms: Process E completed I/O; added to ready queue [Q FE]
time 14858ms: Process G completed I/O; added to ready queue [Q FEG]
time 14893ms: Process I completed a CPU burst; 65 bursts to go [Q FEG]
time 14893ms: Process I switching out of CPU; will block on I/O until time 15895ms [Q FEG]
time 14894ms: Process M completed I/O; added to ready queue [Q FEGM]
time 14897ms: Process F started using the CPU for 24ms burst [Q EGM]
time 14921ms: Process F completed a CPU burst; 17 bursts to go [Q EGM]
time 14921ms: Process F switching out of CPU; will block on I/O until time 15513ms [Q EGM]
time 14925ms: Process E started using the CPU for 126ms burst [Q GM]
time 14985ms: Process N completed I/O; added to ready queue [Q GMN]
time 15051ms: Process E completed a CPU burst; 42 bursts to go [Q GMN]
time 15051ms: Process E switching out of CPU; will block on I/O until time 17033ms [Q GMN]
time 15055ms: Process G started using the CPU for 122ms burst [Q MN]
time 15121ms: Process A completed I/O; added to ready queue [Q MNA]
time 15177ms: Process G completed a CPU burst; 69 bursts to go [Q MNA]
time 15177ms: Process G switching out of CPU; will block on I/O until time 15529ms [Q MNA]
time 15181ms: Process M started using the CPU for 6ms burst [Q NA]
time 15187ms: Process M completed a CPU burst; 38 bursts to go [Q NA]
time 15187ms: Process M switching out of CPU; will block on I/O until time 15519ms [Q NA]
time 15191ms: Process N started using the CPU for 97ms burst [Q A]
time 15204ms: Process O completed I/O; added to ready queue [Q AO]
time 15288ms: Process N completed a CPU burst; 19 bursts to go [Q AO]
time 15288ms: Process N switching out of CPU; will block on I/O until time 16200ms [Q AO]
time 15289ms: Process B completed I/O; added to ready queue [Q AOB]
time 15292ms: Process A started using the CPU for 200ms burst [Q OB]
time 15419ms: Process P completed I/O; added to ready queue [Q OBP]
time 15492ms: Process A completed a CPU burst; 1 burst to go [Q OBP]
time 15492ms: Process A switching out of CPU; will block on I/O until time 15604ms [Q OBP]
time 15496ms: Process O started using the CPU for 187ms burst [Q BP]
time 15513ms: Process F completed I/O; added to ready queue [Q BPF]
time 15519ms: Process M completed I/O; added to ready queue [Q BPFM]
time 15529ms: Process G completed I/O; added to ready queue [Q BPFMG]
time 15604ms: Process A completed I/O; added to ready queue [Q BPFMGA]
time 15683ms: Process O completed a CPU burst; 21 bursts to go [Q BPFMGA]
time 15683ms: Process O switching out of CPU; will block on I/O until time 17355ms [Q BPFMGA]
time 15687ms: Process B started using the CPU for 183ms burst [Q PFMGA]
time 15870ms: Process B completed a CPU burst; 6 bursts to go [Q PFMGA]
time 15870ms: Process B switching out of CPU; will block on I/O until time 15932ms [Q PFMGA]
time 15874ms: Process P started using the CPU for 70ms burst [Q FMGA]
time 15895ms: Process I completed I/O; added to ready queue [Q FMGAI]
time 15932ms: Process B completed I/O; added to ready queue [Q FMGAIB]
time 15944ms: Process P completed a CPU burst; 7 bursts to go [Q FMGAIB]
time 15944ms: Process P switching out of CPU; will block on I/O until time 17216ms [Q FMGAIB]
time 15948ms: Process F started using the CPU for 135ms burst [Q MGAIB]
time 16083ms: Process F completed a CPU burst; 16 bursts to go [Q MGAIB]
time 16083ms: Process F switching out of CPU; will block on I/O until time 16705ms [Q MGAIB]
time 16087ms: Process M started using the CPU for 141ms burst [Q GAIB]
time 16200ms: Process N completed I/O; added to ready queue [Q GAIBN]
time 16228ms: Process M completed a CPU burst; 37 bursts to go [Q GAIBN]
time 16228ms: Process M switching out of CPU; will block on I/O until time 16450ms [Q GAIBN]
time 16232ms: Process G started using the CPU for 31ms burst [Q AIBN]
time 16263ms: Process G completed a CPU burst; 68 bursts to go [Q AIBN]
time 16263ms: Process G switching out of CPU; will block on I/O until time 16335ms [Q AIBN]
time 16267ms: Process A started using the CPU for 197ms burst [Q IBN]
time 16335ms: Process G completed I/O; added to ready queue [Q IBNG]
time 16345ms: Process H completed I/O; added to ready queue [Q IBNGH]
time 16450ms: Process M completed I/O; added to ready queue [Q IBNGHM]
time 16464ms: Process A terminated [Q IBNGHM]
time 16468ms: Process I started using the CPU for 65ms burst [Q BNGHM]
time 16533ms: Process I completed a CPU burst; 64 bursts to go [Q BNGHM]
time 16533ms: Process I switching out of CPU; will block on I/O until time 16855ms [Q BNGHM]
time 16537ms: Process B started using the CPU for 219ms burst [Q NGHM]
time 16705ms: Process F completed I/O; added to ready queue [Q NGHMF]
time 16756ms: Process B completed a CPU burst; 5 bursts to go [Q NGHMF]
time 16756ms: Process B switching out of CPU; will block on I/O until time 16988ms [Q NGHMF]
time 16760ms: Process N started using the CPU for 39ms burst [Q GHMF]
time 16799ms: Process N completed a CPU burst; 18 bursts to go [Q GHMF]
time 16799ms: Process N switching out of CPU; will block on I/O until time 16811ms [Q GHMF]
time 16803ms: Process G started using the CPU for 61ms burst [Q HMF]
time 16811ms: Process N completed I/O; added to ready queue [Q HMFN]
time 16855ms: Process I completed I/O; added to ready queue [Q HMFNI]
time 16864ms: Process G completed a CPU burst; 67 bursts to go [Q HMFNI]
time 16864ms: Process G switching out of CPU; will block on I/O until time 17606ms [Q HMFNI]
time 16868ms: Process H started using the CPU for 143ms burst [Q MFNI]
time 16988ms: Process B completed I/O; added to ready queue [Q MFNIB]
time 17011ms: Process H completed a CPU burst; 68 bursts to go [Q MFNIB]
time 17011ms: Process H switching out of CPU; will block on I/O until time 18853ms [Q MFNIB]
time 17015ms: Process M started using the CPU for 13ms burst [Q FNIB]
time 17028ms: Process M completed a CPU burst; 36 bursts to go [Q FNIB]
time 17028ms: Process M switching out of CPU; will block on I/O until time 17150ms [Q FNIB]
time 17032ms: Process F started using the CPU for 87ms burst [Q NIB]
time 17033ms: Process E completed I/O; added to ready queue [Q NIBE]
time 17119ms: Process F completed a CPU burst; 15 bursts to go [Q NIBE]
time 17119ms: Process F switching out of CPU; will block on I/O until time 18161ms [Q NIBE]
time 17123ms: Process N started using the CPU for 137ms burst [Q IBE]
time 17150ms: Process M completed I/O; added to ready queue [Q IBEM]
time 17216ms: Process P completed I/O; added to ready queue [Q IBEMP]
time 17260ms: Process N completed a CPU burst; 17 bursts to go [Q IBEMP]
time 17260ms: Process N switching out of CPU; will block on I/O until time 17452ms [Q IBEMP]
time 17264ms: Process I started using the CPU for 58ms burst [Q BEMP]
time 17322ms: Process I completed a CPU burst; 63 bursts to go [Q BEMP]
time 17322ms: Process I switching out of CPU; will block on I/O until time 19064ms [Q BEMP]
time 17326ms: Process B started using the CPU for 64ms burst [Q EMP]
time 17355ms: Process O completed I/O; added to ready queue [Q EMPO]
time 17390ms: Process B completed a CPU burst; 4 bursts to go [Q EMPO]
time 17390ms: Process B switching out of CPU; will block on I/O until time 18192ms [Q EMPO]
time 17394ms: Process E started using the CPU for 168ms burst [Q MPO]
time 17452ms: Process N completed I/O; added to ready queue [Q MPON]
time 17562ms: Process E completed a CPU burst; 41 bursts to go [Q MPON]
time 17562ms: Process E switching out of CPU; will block on I/O until time 18064ms [Q MPON]
time 17566ms: Process M started using the CPU for 103ms burst [Q PON]
time 17606ms: Process G completed I/O; added to ready queue [Q PONG]
time 17669ms: Process M completed a CPU burst; 35 bursts to go [Q PONG]
time 17669ms: Process M switching out of CPU; will block on I/O until time 17811ms [Q PONG]
time 17673ms: Process P started using the CPU for 55ms burst [Q ONG]
time 17728ms: Process P completed a CPU burst; 6 bursts to go [Q ONG]
time 17728ms: Process P switching out of CPU; will block on I/O until time 20180ms [Q ONG]
time 17732ms: Process O started using the CPU for 89ms burst [Q NG]
time 17811ms: Process M completed I/O; added to ready queue [Q NGM]
time 17821ms: Process O completed a CPU burst; 20 bursts to go [Q NGM]
time 17821ms: Process O switching out of CPU; will block on I/O until time 19223ms [Q NGM]
time 17825ms: Process N started using the CPU for 189ms burst [Q GM]
time 18014ms: Process N completed a CPU burst; 16 bursts to go [Q GM]
time 18014ms: Process N switching out of CPU; will block on I/O until time 19646ms [Q GM]
time 18018ms: Process G started using the CPU for 7ms burst [Q M]
time 18025ms: Process G completed a CPU burst; 66 bursts to go [Q M]
time 18025ms: Process G switching out of CPU; will block on I/O until time 19667ms [Q M]
time 18029ms: Process M started using the CPU for 15ms burst [Q empty]
time 18044ms: Process M completed a CPU burst; 34 bursts to go [Q empty]
time 18044ms: Process M switching out of CPU; will block on I/O until time 19156ms [Q empty]
time 18064ms: Process E completed I/O; added to ready queue [Q E]
time 18066ms: Process E started using the CPU for 23ms burst [Q empty]
time 18089ms: Process E completed a CPU burst; 40 bursts to go [Q empty]
time 18089ms: Process E switching out of CPU; will block on I/O until time 18181ms [Q empty]
time 18161ms: Process F completed I/O; added to ready queue [Q F]
time 18163ms: Process F started using the CPU for 22ms burst [Q empty]
time 18181ms: Process E completed I/O; added to ready queue [Q E]
time 18185ms: Process F completed a CPU burst; 14 bursts to go [Q E]
time 18185ms: Process F switching out of CPU; will block on I/O until time 18337ms [Q E]
time 18189ms: Process E started using the CPU for 68ms burst [Q empty]
time 18192ms: Process B completed I/O; added to ready queue [Q B]
time 18257ms: Process E completed a CPU burst; 39 bursts to go [Q B]
time 18257ms: Process E switching out of CPU; will block on I/O until time 18839ms [Q B]
time 18261ms: Process B started using the CPU for 33ms burst [Q empty]
time 18294ms: Process B completed a CPU burst; 3 bursts to go [Q empty]
time 18294ms: Process B switching out of CPU; will block on I/O until time 19036ms [Q empty]
time 18337ms: Process F completed I/O; added to ready queue [Q F]
time 18339ms: Process F started using the CPU for 52ms burst [Q empty]
time 18391ms: Process F completed a CPU burst; 13 bursts to go [Q empty]
time 18391ms: Process F switching out of CPU; will block on I/O until time 18483ms [Q empty]
time 18483ms: Process F completed I/O; added to ready queue [Q F]
time 18485ms: Process F started using the CPU for 90ms burst [Q empty]
time 18575ms: Process F completed a CPU burst; 12 bursts to go [Q empty]
time 18575ms: Process F switching out of CPU; will block on I/O until time 20787ms [Q empty]
time 18839ms: Process E completed I/O; added to ready queue [Q E]
time 18841ms: Process E started using the CPU for 41ms burst [Q empty]
time 18853ms: Process H completed I/O; added to ready queue [Q H]
time 18882ms: Process E completed a CPU burst; 38 bursts to go [Q H]
time 18882ms: Process E switching out of CPU; will block on I/O until time 19084ms [Q H]
time 18886ms: Process H started using the CPU for 32ms burst [Q empty]
time 18918ms: Process H completed a CPU burst; 67 bursts to go [Q empty]
time 18918ms: Process H switching out of CPU; will block on I/O until time 19740ms [Q empty]
time 19036ms: Process B completed I/O; added to ready queue [Q B]
time 19038ms: Process B started using the CPU for 63ms burst [Q empty]
time 19064ms: Process I completed I/O; added to ready queue [Q I]
time 19084ms: Process E completed I/O; added to ready queue [Q IE]
time 19101ms: Process B completed a CPU burst; 2 bursts to go [Q IE]
time 19101ms: Process B switching out of CPU; will block on I/O until time 21413ms [Q IE]
time 19105ms: Process I started using the CPU for 95ms burst [Q E]
time 19156ms: Process M completed I/O; added to ready queue [Q EM]
time 19200ms: Process I completed a CPU burst; 62 bursts to go [Q EM]
time 19200ms: Process I switching out of CPU; will block on I/O until time 20622ms [Q EM]
time 19204ms: Process E started using the CPU for 44ms burst [Q M]
time 19223ms: Process O completed I/O; added to ready queue [Q MO]
time 19248ms: Process E completed a CPU burst; 37 bursts to go [Q MO]
time 19248ms: Process E switching out of CPU; will block on I/O until time 19860ms [Q MO]
time 19252ms: Process M started using the CPU for 26ms burst [Q O]
time 19278ms: Process M completed a CPU burst; 33 bursts to go [Q O]
time 19278ms: Process M switching out of CPU; will block on I/O until time 19880ms [Q O]
time 19282ms: Process O started using the CPU for 45ms burst [Q empty]
time 19327ms: Process O completed a CPU burst; 19 bursts to go [Q empty]
time 19327ms: Process O switching out of CPU; will block on I/O until time 19789ms [Q empty]
time 19646ms: Process N completed I/O; added to ready queue [Q N]
time 19648ms: Process N started using the CPU for 67ms burst [Q empty]
time 19667ms: Process G completed I/O; added to ready queue [Q G]
time 19715ms: Process N completed a CPU burst; 15 bursts to go [Q G]
time 19715ms: Process N switching out of CPU; will block on I/O until time 20137ms [Q G]
time 19719ms: Process G started using the CPU for 2ms burst [Q empty]
time 19721ms: Process G completed a CPU burst; 65 bursts to go [Q empty]
time 19721ms: Process G switching out of CPU; will block on I/O until time 19833ms [Q empty]
time 19740ms: Process H completed I/O; added to ready queue [Q H]
time 19742ms: Process H started using the CPU for 78ms burst [Q empty]
time 19789ms: Process O completed I/O; added to ready queue [Q O]
time 19820ms: Process H completed a CPU burst; 66 bursts to go [Q O]
time 19820ms: Process H switching out of CPU; will block on I/O until time 19882ms [Q O]
time 19824ms: Process O started using the CPU for 50ms burst [Q empty]
time 19833ms: Process G completed I/O; added to ready queue [Q G]
time 19860ms: Process E completed I/O; added to ready queue [Q GE]
time 19874ms: Process O completed a CPU burst; 18 bursts to go [Q GE]
time 19874ms: Process O switching out of CPU; will block on I/O until time 20986ms [Q GE]
time 19878ms: Process G started using the CPU for 209ms burst [Q E]
time 19880ms: Process M completed I/O; added to ready queue [Q EM]
time 19882ms: Process H completed I/O; added to ready queue [Q EMH]
time 20087ms: Process G completed a CPU burst; 64 bursts to go [Q EMH]
time 20087ms: Process G switching out of CPU; will block on I/O until time 20569ms [Q EMH]
time 20091ms: Process E started using the CPU for 74ms burst [Q MH]
time 20137ms: Process N completed I/O; added to ready queue [Q MHN]
time 20165ms: Process E completed a CPU burst; 36 bursts to go [Q MHN]
time 20165ms: Process E switching out of CPU; will block on I/O until time 22027ms [Q MHN]
time 20169ms: Process M started using the CPU for 74ms burst [Q HN]
time 20180ms: Process P completed I/O; added to ready queue [Q HNP]
time 20243ms: Process M completed a CPU burst; 32 bursts to go [Q HNP]
time 20243ms: Process M switching out of CPU; will block on I/O until time 21455ms [Q HNP]
time 20247ms: Process H started using the CPU for 16ms burst [Q NP]
time 20263ms: Process H completed a CPU burst; 65 bursts to go [Q NP]
time 20263ms: Process H switching out of CPU; will block on I/O until time 20815ms [Q NP]
time 20267ms: Process N started using the CPU for 35ms burst [Q P]
time 20302ms: Process N completed a CPU burst; 14 bursts to go [Q P]
time 20302ms: Process N switching out of CPU; will block on I/O until time 21344ms [Q P]
time 20306ms: Process P started using the CPU for 212ms burst [Q empty]
time 20518ms: Process P completed a CPU burst; 5 bursts to go [Q empty]
time 20518ms: Process P switching out of CPU; will block on I/O until time 22690ms [Q empty]
time 20569ms: Process G completed I/O; added to ready queue [Q G]
time 20571ms: Process G started using the CPU for 6ms burst [Q empty]
time 20577ms: Process G completed a CPU burst; 63 bursts to go [Q empty]
time 20577ms: Process G switching out of CPU; will block on I/O until time 22059ms [Q empty]
time 20622ms: Process I completed I/O; added to ready queue [Q I]
time 20624ms: Process I started using the CPU for 78ms burst [Q empty]
time 20702ms: Process I completed a CPU burst; 61 bursts to go [Q empty]
time 20702ms: Process I switching out of CPU; will block on I/O until time 21474ms [Q empty]
time 20787ms: Process F completed I/O; added to ready queue [Q F]
time 20789ms: Process F started using the CPU for 4ms burst [Q empty]
time 20793ms: Process F completed a CPU burst; 11 bursts to go [Q empty]
time 20793ms: Process F switching out of CPU; will block on I/O until time 21345ms [Q empty]
time 20815ms: Process H completed I/O; added to ready queue [Q H]
time 20817ms: Process H started using the CPU for 142ms burst [Q empty]
time 20959ms: Process H completed a CPU burst; 64 bursts to go [Q empty]
time 20959ms: Process H switching out of CPU; will block on I/O until time 21931ms [Q empty]
time 20986ms: Process O completed I/O; added to ready queue [Q O]
time 20988ms: Process O started using the CPU for 133ms burst [Q empty]
time 21121ms: Process O completed a CPU burst; 17 bursts to go [Q empty]
time 21121ms: Process O switching out of CPU; will block on I/O until time 22403ms [Q empty]
time 21344ms: Process N completed I/O; added to ready queue [Q N]
time 21345ms: Process F completed I/O; added to ready queue [Q F]
time 21346ms: Process N started using the CPU for 2ms burst [Q F]
time 21348ms: Process N completed a CPU burst; 13 bursts to go [Q F]
time 21348ms: Process N switching out of CPU; will block on I/O until time 22650ms [Q F]
time 21352ms: Process F started using the CPU for 30ms burst [Q empty]
time 21382ms: Process F completed a CPU burst; 10 bursts to go [Q empty]
time 21382ms: Process F switching out of CPU; will block on I/O until time 21844ms [Q empty]
time 21413ms: Process B completed I/O; added to ready queue [Q B]
time 21415ms: Process B started using the CPU for 170ms burst [Q empty]
time 21455ms: Process M completed I/O; added to ready queue [Q M]
time 21474ms: Process I completed I/O; added to ready queue [Q MI]
time 21585ms: Process B completed a CPU burst; 1 burst to go [Q MI]
time 21585ms: Process B switching out of CPU; will block on I/O until time 22157ms [Q MI]
time 21589ms: Process M started using the CPU for 6ms burst [Q I]
time 21595ms: Process M completed a CPU burst; 31 bursts to go [Q I]
time 21595ms: Process M switching out of CPU; will block on I/O until time 22637ms [Q I]
time 21599ms: Process I started using the CPU for 31ms burst [Q empty]
time 21630ms: Process I completed a CPU burst; 60 bursts to go [Q empty]
time 21630ms: Process I switching out of CPU; will block on I/O until time 22722ms [Q empty]
time 21844ms: Process F completed I/O; added to ready queue [Q F]
time 21846ms: Process F started using the CPU for 183ms burst [Q empty]
time 21931ms: Process H completed I/O; added to ready queue [Q H]
time 22027ms: Process E completed I/O; added to ready queue [Q HE]
time 22029ms: Process F completed a CPU burst; 9 bursts to go [Q HE]
time 22029ms: Process F switching out of CPU; will block on I/O until time 22441ms [Q HE]
time 22033ms: Process H started using the CPU for 62ms burst [Q E]
time 22059ms: Process G completed I/O; added to ready queue [Q EG]
time 22095ms: Process H completed a CPU burst; 63 bursts to go [Q EG]
time 22095ms: Process H switching out of CPU; will block on I/O until time 22347ms [Q EG]
time 22099ms: Process E started using the CPU for 117ms burst [Q G]
time 22157ms: Process B completed I/O; added to ready queue [Q GB]
time 22216ms: Process E completed a CPU burst; 35 bursts to go [Q GB]
time 22216ms: Process E switching out of CPU; will block on I/O until time 23218ms [Q GB]
time 22220ms: Process G started using the CPU for 37ms burst [Q B]
time 22257ms: Process G completed a CPU burst; 62 bursts to go [Q B]
time 22257ms: Process G switching out of CPU; will block on I/O until time 23569ms [Q B]
time 22261ms: Process B started using the CPU for 212ms burst [Q empty]
time 22347ms: Process H completed I/O; added to ready queue [Q H]
time 22403ms: Process O completed I/O; added to ready queue [Q HO]
time 22441ms: Process F completed I/O; added to ready queue [Q HOF]
time 22473ms: Process B terminated [Q HOF]
time 22477ms: Process H started using the CPU for 248ms burst [Q OF]
time 22637ms: Process M completed I/O; added to ready queue [Q OFM]
time 22650ms: Process N completed I/O; added to ready queue [Q OFMN]
time 22690ms: Process P completed I/O; added to ready queue [Q OFMNP]
time 22722ms: Process I completed I/O; added to ready queue [Q OFMNPI]
time 22725ms: Process H completed a CPU burst; 62 bursts to go [Q OFMNPI]
time 22725ms: Process H switching out of CPU; will block on I/O until time 23547ms [Q OFMNPI]
time 22729ms: Process O started using the CPU for 74ms burst [Q FMNPI]
time 22803ms: Process O completed a CPU burst; 16 bursts to go [Q FMNPI]
time 22803ms: Process O switching out of CPU; will block on I/O until time 23695ms [Q FMNPI]
time 22807ms: Process F started using the CPU for 21ms burst [Q MNPI]
time 22828ms: Process F completed a CPU burst; 8 bursts to go [Q MNPI]
time 22828ms: Process F switching out of CPU; will block on I/O until time 24000ms [Q MNPI]
time 22832ms: Process M started using the CPU for 216ms burst [Q NPI]
time 23048ms: Process M completed a CPU burst; 30 bursts to go [Q NPI]
time 23048ms: Process M switching out of CPU; will block on I/O until time 24250ms [Q NPI]
time 23052ms: Process N started using the CPU for 158ms burst [Q PI]
time 23210ms: Process N completed a CPU burst; 12 bursts to go [Q PI]
time 23210ms: Process N switching out of CPU; will block on I/O until time 25122ms [Q PI]
time 23214ms: Process P started using the CPU for 83ms burst [Q I]
time 23218ms: Process E completed I/O; added to ready queue [Q IE]
time 23297ms: Process P completed a CPU burst; 4 bursts to go [Q IE]
time 23297ms: Process P switching out of CPU; will block on I/O until time 23569ms [Q IE]
time 23301ms: Process I started using the CPU for 97ms burst [Q E]
time 23398ms: Process I completed a CPU burst; 59 bursts to go [Q E]
time 23398ms: Process I switching out of CPU; will block on I/O until time 23580ms [Q E]
time 23402ms: Process E started using the CPU for 14ms burst [Q empty]
time 23416ms: Process E completed a CPU burst; 34 bursts to go [Q empty]
time 23416ms: Process E switching out of CPU; will block on I/O until time 23438ms [Q empty]
time 23438ms: Process E completed I/O; added to ready queue [Q E]
time 23440ms: Process E started using the CPU for 156ms burst [Q empty]
time 23547ms: Process H completed I/O; added to ready queue [Q H]
time 23569ms: Process G completed I/O; added to ready queue [Q HG]
time 23569ms: Process P completed I/O; added to ready queue [Q HGP]
time 23580ms: Process I completed I/O; added to ready queue [Q HGPI]
time 23596ms: Process E completed a CPU burst; 33 bursts to go [Q HGPI]
time 23596ms: Process E switching out of CPU; will block on I/O until time 24598ms [Q HGPI]
time 23600ms: Process H started using the CPU for 37ms burst [Q GPI]
time 23637ms: Process H completed a CPU burst; 61 bursts to go [Q GPI]
time 23637ms: Process H switching out of CPU; will block on I/O until time 23669ms [Q GPI]
time 23641ms: Process G started using the CPU for 15ms burst [Q PI]
time 23656ms: Process G completed a CPU burst; 61 bursts to go [Q PI]
time 23656ms: Process G switching out of CPU; will block on I/O until time 23878ms [Q PI]
time 23660ms: Process P started using the CPU for 75ms burst [Q I]
time 23669ms: Process H completed I/O; added to ready queue [Q IH]
time 23695ms: Process O completed I/O; added to ready queue [Q IHO]
time 23735ms: Process P completed a CPU burst; 3 bursts to go [Q IHO]
time 23735ms: Process P switching out of CPU; will block on I/O until time 23917ms [Q IHO]
time 23739ms: Process I started using the CPU for 103ms burst [Q HO]
time 23842ms: Process I completed a CPU burst; 58 bursts to go [Q HO]
time 23842ms: Process I switching out of CPU; will block on I/O until time 24714ms [Q HO]
time 23846ms: Process H started using the CPU for 10ms burst [Q O]
time 23856ms: Process H completed a CPU burst; 60 bursts to go [Q O]
time 23856ms: Process H switching out of CPU; will block on I/O until time 23918ms [Q O]
time 23860ms: Process O started using the CPU for 41ms burst [Q empty]
time 23878ms: Process G completed I/O; added to ready queue [Q G]
time 23901ms: Process O completed a CPU burst; 15 bursts to go [Q G]
time 23901ms: Process O switching out of CPU; will block on I/O until time 24473ms [Q G]
time 23905ms: Process G started using the CPU for 47ms burst [Q empty]
time 23917ms: Process P completed I/O; added to ready queue [Q P]
time 23918ms: Process H completed I/O; added to ready queue [Q PH]
time 23952ms: Process G completed a CPU burst; 60 bursts to go [Q PH]
time 23952ms: Process G switching out of CPU; will block on I/O until time 24714ms [Q PH]
time 23956ms: Process P started using the CPU for 1ms burst [Q H]
time 23957ms: Process P completed a CPU burst; 2 bursts to go [Q H]
time 23957ms: Process P switching out of CPU; will block on I/O until time 24139ms [Q H]
time 23961ms: Process H started using the CPU for 189ms burst [Q empty]
time 24000ms: Process F completed I/O; added to ready queue [Q F]
time 24139ms: Process P completed I/O; added to ready queue [Q FP]
time 24150ms: Process H completed a CPU burst; 59 bursts to go [Q FP]
time 24150ms: Process H switching out of CPU; will block on I/O until time 24632ms [Q FP]
time 24154ms: Process F started using the CPU for 101ms burst [Q P]
time 24250ms: Process M completed I/O; added to ready queue [Q PM]
time 24255ms: Process F completed a CPU burst; 7 bursts to go [Q PM]
time 24255ms: Process F switching out of CPU; will block on I/O until time 25157ms [Q PM]
time 24259ms: Process P started using the CPU for 131ms burst [Q M]
time 24390ms: Process P completed a CPU burst; 1 burst to go [Q M]
time 24390ms: Process P switching out of CPU; will block on I/O until time 24842ms [Q M]
time 24394ms: Process M started using the CPU for 3ms burst [Q empty]
time 24397ms: Process M completed a CPU burst; 29 bursts to go [Q empty]
time 24397ms: Process M switching out of CPU; will block on I/O until time 24649ms [Q empty]
time 24473ms: Process O completed I/O; added to ready queue [Q O]
time 24475ms: Process O started using the CPU for 57ms burst [Q empty]
time 24532ms: Process O completed a CPU burst; 14 bursts to go [Q empty]
time 24532ms: Process O switching out of CPU; will block on I/O until time 24814ms [Q empty]
time 24598ms: Process E completed I/O; added to ready queue [Q E]
time 24600ms: Process E started using the CPU for 18ms burst [Q empty]
time 24618ms: Process E completed a CPU burst; 32 bursts to go [Q empty]
time 24618ms: Process E switching out of CPU; will block on I/O until time 25060ms [Q empty]
time 24632ms: Process H completed I/O; added to ready queue [Q H]
time 24634ms: Process H started using the CPU for 134ms burst [Q empty]
time 24649ms: Process M completed I/O; added to ready queue [Q M]
time 24714ms: Process G completed I/O; added to ready queue [Q MG]
time 24714ms: Process I completed I/O; added to ready queue [Q MGI]
time 24768ms: Process H completed a CPU burst; 58 bursts to go [Q MGI]
time 24768ms: Process H switching out of CPU; will block on I/O until time 25100ms [Q MGI]
time 24772ms: Process M started using the CPU for 67ms burst [Q GI]
time 24814ms: Process O completed I/O; added to ready queue [Q GIO]
time 24839ms: Process M completed a CPU burst; 28 bursts to go [Q GIO]
time 24839ms: Process M switching out of CPU; will block on I/O until time 25131ms [Q GIO]
time 24842ms: Process P completed I/O; added to ready queue [Q IOP]
time 24843ms: Process G started using the CPU for 82ms burst [Q IOP]
time 24925ms: Process G completed a CPU burst; 59 bursts to go [Q IOP]
time 24925ms: Process G switching out of CPU; will block on I/O until time 24957ms [Q IOP]
time 24929ms: Process I started using the CPU for 44ms burst [Q OP]
time 24957ms: Process G completed I/O; added to ready queue [Q OPG]
time 24973ms: Process I completed a CPU burst; 57 bursts to go [Q OPG]
time 24973ms: Process I switching out of CPU; will block on I/O until time 26965ms [Q OPG]
time 24977ms: Process O started using the CPU for 159ms burst [Q PG]
time 25060ms: Process E completed I/O; added to ready queue [Q PGE]
time 25100ms: Process H completed I/O; added to ready queue [Q PGEH]
time 25122ms: Process N completed I/O; added to ready queue [Q PGEHN]
time 25131ms: Process M completed I/O; added to ready queue [Q PGEHNM]
time 25136ms: Process O completed a CPU burst; 13 bursts to go [Q PGEHNM]
time 25136ms: Process O switching out of CPU; will block on I/O until time 26148ms [Q PGEHNM]
time 25140ms: Process P started using the CPU for 9ms burst [Q GEHNM]
time 25149ms: Process P terminated [Q GEHNM]
time 25153ms: Process G started using the CPU for 57ms burst [Q EHNM]
time 25157ms: Process F completed I/O; added to ready queue [Q EHNMF]
time 25210ms: Process G completed a CPU burst; 58 bursts to go [Q EHNMF]
time 25210ms: Process G switching out of CPU; will block on I/O until time 25422ms [Q EHNMF]
time 25214ms: Process E started using the CPU for 215ms burst [Q HNMF]
time 25422ms: Process G completed I/O; added to ready queue [Q HNMFG]
time 25429ms: Process E completed a CPU burst; 31 bursts to go [Q HNMFG]
time 25429ms: Process E switching out of CPU; will block on I/O until time 25521ms [Q HNMFG]
time 25433ms: Process H started using the CPU for 25ms burst [Q NMFG]
time 25458ms: Process H completed a CPU burst; 57 bursts to go [Q NMFG]
time 25458ms: Process H switching out of CPU; will block on I/O until time 26270ms [Q NMFG]
time 25462ms: Process N started using the CPU for 52ms burst [Q MFG]
time 25514ms: Process N completed a CPU burst; 11 bursts to go [Q MFG]
time 25514ms: Process N switching out of CPU; will block on I/O until time 25536ms [Q MFG]
time 25518ms: Process M started using the CPU for 217ms burst [Q FG]
time 25521ms: Process E completed I/O; added to ready queue [Q FGE]
time 25536ms: Process N completed I/O; added to ready queue [Q FGEN]
time 25735ms: Process M completed a CPU burst; 27 bursts to go [Q FGEN]
time 25735ms: Process M switching out of CPU; will block on I/O until time 26177ms [Q FGEN]
time 25739ms: Process F started using the CPU for 2ms burst [Q GEN]
time 25741ms: Process F completed a CPU burst; 6 bursts to go [Q GEN]
time 25741ms: Process F switching out of CPU; will block on I/O until time 27853ms [Q GEN]
time 25745ms: Process G started using the CPU for 89ms burst [Q EN]
time 25834ms: Process G completed a CPU burst; 57 bursts to go [Q EN]
time 25834ms: Process G switching out of CPU; will block on I/O until time 26756ms [Q EN]
time 25838ms: Process E started using the CPU for 224ms burst [Q N]
time 26062ms: Process E completed a CPU burst; 30 bursts to go [Q N]
time 26062ms: Process E switching out of CPU; will block on I/O until time 27144ms [Q N]
time 26066ms: Process N started using the CPU for 251ms burst [Q empty]
time 26148ms: Process O completed I/O; added to ready queue [Q O]
time 26177ms: Process M completed I/O; added to ready queue [Q OM]
time 26270ms: Process H completed I/O; added to ready queue [Q OMH]
time 26317ms: Process N completed a CPU burst; 10 bursts to go [Q OMH]
time 26317ms: Process N switching out of CPU; will block on I/O until time 28719ms [Q OMH]
time 26321ms: Process O started using the CPU for 87ms burst [Q MH]
time 26408ms: Process O completed a CPU burst; 12 bursts to go [Q MH]
time 26408ms: Process O switching out of CPU; will block on I/O until time 28020ms [Q MH]
time 26412ms: Process M started using the CPU for 19ms burst [Q H]
time 26431ms: Process M completed a CPU burst; 26 bursts to go [Q H]
time 26431ms: Process M switching out of CPU; will block on I/O until time 27833ms [Q H]
time 26435ms: Process H started using the CPU for 235ms burst [Q empty]
time 26670ms: Process H completed a CPU burst; 56 bursts to go [Q empty]
time 26670ms: Process H switching out of CPU; will block on I/O until time 28192ms [Q empty]
time 26756ms: Process G completed I/O; added to ready queue [Q G]
time 26758ms: Process G started using the CPU for 3ms burst [Q empty]
time 26761ms: Process G completed a CPU burst; 56 bursts to go [Q empty]
time 26761ms: Process G switching out of CPU; will block on I/O until time 28123ms [Q empty]
time 26965ms: Process I completed I/O; added to ready queue [Q I]
time 26967ms: Process I started using the CPU for 37ms burst [Q empty]
time 27004ms: Process I completed a CPU burst; 56 bursts to go [Q empty]
time 27004ms: Process I switching out of CPU; will block on I/O until time 27906ms [Q empty]
time 27144ms: Process E completed I/O; added to ready queue [Q E]
time 27146ms: Process E started using the CPU for 1ms burst [Q empty]
time 27147ms: Process E completed a CPU burst; 29 bursts to go [Q empty]
time 27147ms: Process E switching out of CPU; will block on I/O until time 27809ms [Q empty]
time 27809ms: Process E completed I/O; added to ready queue [Q E]
time 27811ms: Process E started using the CPU for 168ms burst [Q empty]
time 27833ms: Process M completed I/O; added to ready queue [Q M]
time 27853ms: Process F completed I/O; added to ready queue [Q MF]
time 27906ms: Process I completed I/O; added to ready queue [Q MFI]
time 27979ms: Process E completed a CPU burst; 28 bursts to go [Q MFI]
time 27979ms: Process E switching out of CPU; will block on I/O until time 29161ms [Q MFI]
time 27983ms: Process M started using the CPU for 73ms burst [Q FI]
time 28020ms: Process O completed I/O; added to ready queue [Q FIO]
time 28056ms: Process M completed a CPU burst; 25 bursts to go [Q FIO]
time 28056ms: Process M switching out of CPU; will block on I/O until time 28928ms [Q FIO]
time 28060ms: Process F started using the CPU for 170ms burst [Q IO]
time 28123ms: Process G completed I/O; added to ready queue [Q IOG]
time 28192ms: Process H completed I/O; added to ready queue [Q IOGH]
time 28230ms: Process F completed a CPU burst; 5 bursts to go [Q IOGH]
time 28230ms: Process F switching out of CPU; will block on I/O until time 28812ms [Q IOGH]
time 28234ms: Process I started using the CPU for 1ms burst [Q OGH]
time 28235ms: Process I completed a CPU burst; 55 bursts to go [Q OGH]
time 28235ms: Process I switching out of CPU; will block on I/O until time 28257ms [Q OGH]
time 28239ms: Process O started using the CPU for 127ms burst [Q GH]
time 28257ms: Process I completed I/O; added to ready queue [Q GHI]
time 28366ms: Process O completed a CPU burst; 11 bursts to go [Q GHI]
time 28366ms: Process O switching out of CPU; will block on I/O until time 30528ms [Q GHI]
time 28370ms: Process G started using the CPU for 11ms burst [Q HI]
time 28381ms: Process G completed a CPU burst; 55 bursts to go [Q HI]
time 28381ms: Process G switching out of CPU; will block on I/O until time 30833ms [Q HI]
time 28385ms: Process H started using the CPU for 105ms burst [Q I]
time 28490ms: Process H completed a CPU burst; 55 bursts to go [Q I]
time 28490ms: Process H switching out of CPU; will block on I/O until time 29232ms [Q I]
time 28494ms: Process I started using the CPU for 96ms burst [Q empty]
time 28590ms: Process I completed a CPU burst; 54 bursts to go [Q empty]
time 28590ms: Process I switching out of CPU; will block on I/O until time 28782ms [Q empty]
time 28719ms: Process N completed I/O; added to ready queue [Q N]
time 28721ms: Process N started using the CPU for 55ms burst [Q empty]
time 28776ms: Process N completed a CPU burst; 9 bursts to go [Q empty]
time 28776ms: Process N switching out of CPU; will block on I/O until time 28928ms [Q empty]
time 28782ms: Process I completed I/O; added to ready queue [Q I]
time 28784ms: Process I started using the CPU for 143ms burst [Q empty]
time 28812ms: Process F completed I/O; added to ready queue [Q F]
time 28927ms: Process I completed a CPU burst; 53 bursts to go [Q F]
time 28927ms: Process I switching out of CPU; will block on I/O until time 29659ms [Q F]
time 28928ms: Process M completed I/O; added to ready queue [Q FM]
time 28928ms: Process N completed I/O; added to ready queue [Q FMN]
time 28931ms: Process F started using the CPU for 154ms burst [Q MN]
time 29085ms: Process F completed a CPU burst; 4 bursts to go [Q MN]
time 29085ms: Process F switching out of CPU; will block on I/O until time 29447ms [Q MN]
time 29089ms: Process M started using the CPU for 36ms burst [Q N]
time 29125ms: Process M completed a CPU burst; 24 bursts to go [Q N]
time 29125ms: Process M switching out of CPU; will block on I/O until time 31007ms [Q N]
time 29129ms: Process N started using the CPU for 32ms burst [Q empty]
time 29161ms: Process N completed a CPU burst; 8 bursts to go [Q empty]
time 29161ms: Process N switching out of CPU; will block on I/O until time 30083ms [Q empty]
time 29161ms: Process E completed I/O; added to ready queue [Q E]
time 29165ms: Process E started using the CPU for 10ms burst [Q empty]
time 29175ms: Process E completed a CPU burst; 27 bursts to go [Q empty]
time 29175ms: Process E switching out of CPU; will block on I/O until time 29647ms [Q empty]
time 29232ms: Process H completed I/O; added to ready queue [Q H]
time 29234ms: Process H started using the CPU for 75ms burst [Q empty]
time 29309ms: Process H completed a CPU burst; 54 bursts to go [Q empty]
time 29309ms: Process H switching out of CPU; will block on I/O until time 29991ms [Q empty]
time 29447ms: Process F completed I/O; added to ready queue [Q F]
time 29449ms: Process F started using the CPU for 55ms burst [Q empty]
time 29504ms: Process F completed a CPU burst; 3 bursts to go [Q empty]
time 29504ms: Process F switching out of CPU; will block on I/O until time 30756ms [Q empty]
time 29647ms: Process E completed I/O; added to ready queue [Q E]
time 29649ms: Process E started using the CPU for 68ms burst [Q empty]
time 29659ms: Process I completed I/O; added to ready queue [Q I]
time 29717ms: Process E completed a CPU burst; 26 bursts to go [Q I]
time 29717ms: Process E switching out of CPU; will block on I/O until time 30269ms [Q I]
time 29721ms: Process I started using the CPU for 71ms burst [Q empty]
time 29792ms: Process I completed a CPU burst; 52 bursts to go [Q empty]
time 29792ms: Process I switching out of CPU; will block on I/O until time 29824ms [Q empty]
time 29824ms: Process I completed I/O; added to ready queue [Q I]
time 29826ms: Process I started using the CPU for 111ms burst [Q empty]
time 29937ms: Process I completed a CPU burst; 51 bursts to go [Q empty]
time 29937ms: Process I switching out of CPU; will block on I/O until time 30999ms [Q empty]
time 29991ms: Process H completed I/O; added to ready queue [Q H]
time 29993ms: Process H started using the CPU for 141ms burst [Q empty]
time 30083ms: Process N completed I/O; added to ready queue [Q N]
time 30134ms: Process H completed a CPU burst; 53 bursts to go [Q N]
time 30134ms: Process H switching out of CPU; will block on I/O until time 30216ms [Q N]
time 30138ms: Process N started using the CPU for 101ms burst [Q empty]
time 30216ms: Process H completed I/O; added to ready queue [Q H]
time 30239ms: Process N completed a CPU burst; 7 bursts to go [Q H]
time 30239ms: Process N switching out of CPU; will block on I/O until time 31991ms [Q H]
time 30243ms: Process H started using the CPU for 63ms burst [Q empty]
time 30269ms: Process E completed I/O; added to ready queue [Q E]
time 30306ms: Process H completed a CPU burst; 52 bursts to go [Q E]
time 30306ms: Process H switching out of CPU; will block on I/O until time 31018ms [Q E]
time 30310ms: Process E started using the CPU for 30ms burst [Q empty]
time 30340ms: Process E completed a CPU burst; 25 bursts to go [Q empty]
time 30340ms: Process E switching out of CPU; will block on I/O until time 31312ms [Q empty]
time 30528ms: Process O completed I/O; added to ready queue [Q O]
time 30530ms: Process O started using the CPU for 9ms burst [Q empty]
time 30539ms: Process O completed a CPU burst; 10 bursts to go [Q empty]
time 30539ms: Process O switching out of CPU; will block on I/O until time 30611ms [Q empty]
time 30611ms: Process O completed I/O; added to ready queue [Q O]
time 30613ms: Process O started using the CPU for 54ms burst [Q empty]
time 30667ms: Process O completed a CPU burst; 9 bursts to go [Q empty]
time 30667ms: Process O switching out of CPU; will block on I/O until time 30899ms [Q empty]
time 30756ms: Process F completed I/O; added to ready queue [Q F]
time 30758ms: Process F started using the CPU for 234ms burst [Q empty]
time 30833ms: Process G completed I/O; added to ready queue [Q G]
time 30899ms: Process O completed I/O; added to ready queue [Q GO]
time 30992ms: Process F completed a CPU burst; 2 bursts to go [Q GO]
time 30992ms: Process F switching out of CPU; will block on I/O until time 31264ms [Q GO]
time 30996ms: Process G started using the CPU for 17ms burst [Q O]
time 30999ms: Process I completed I/O; added to ready queue [Q OI]
time 31007ms: Process M completed I/O; added to ready queue [Q OIM]
time 31013ms: Process G completed a CPU burst; 54 bursts to go [Q OIM]
time 31013ms: Process G switching out of CPU; will block on I/O until time 31665ms [Q OIM]
time 31017ms: Process O started using the CPU for 41ms burst [Q IM]
time 31018ms: Process H completed I/O; added to ready queue [Q IMH]
time 31058ms: Process O completed a CPU burst; 8 bursts to go [Q IMH]
time 31058ms: Process O switching out of CPU; will block on I/O until time 31330ms [Q IMH]
time 31062ms: Process I started using the CPU for 81ms burst [Q MH]
time 31143ms: Process I completed a CPU burst; 50 bursts to go [Q MH]
time 31143ms: Process I switching out of CPU; will block on I/O until time 32125ms [Q MH]
time 31147ms: Process M started using the CPU for 212ms burst [Q H]
time 31264ms: Process F completed I/O; added to ready queue [Q HF]
time 31312ms: Process E completed I/O; added to ready queue [Q HFE]
time 31330ms: Process O completed I/O; added to ready queue [Q HFEO]
time 31359ms: Process M completed a CPU burst; 23 bursts to go [Q HFEO]
time 31359ms: Process M switching out of CPU; will block on I/O until time 31721ms [Q HFEO]
time 31363ms: Process H started using the CPU for 93ms burst [Q FEO]
time 31456ms: Process H completed a CPU burst; 51 bursts to go [Q FEO]
time 31456ms: Process H switching out of CPU; will block on I/O until time 32098ms [Q FEO]
time 31460ms: Process F started using the CPU for 122ms burst [Q EO]
time 31582ms: Process F completed a CPU burst; 1 burst to go [Q EO]
time 31582ms: Process F switching out of CPU; will block on I/O until time 32314ms [Q EO]
time 31586ms: Process E started using the CPU for 54ms burst [Q O]
time 31640ms: Process E completed a CPU burst; 24 bursts to go [Q O]
time 31640ms: Process E switching out of CPU; will block on I/O until time 33872ms [Q O]
time 31644ms: Process O started using the CPU for 190ms burst [Q empty]
time 31665ms: Process G completed I/O; added to ready queue [Q G]
time 31721ms: Process M completed I/O; added to ready queue [Q GM]
time 31834ms: Process O completed a CPU burst; 7 bursts to go [Q GM]
time 31834ms: Process O switching out of CPU; will block on I/O until time 32056ms [Q GM]
time 31838ms: Process G started using the CPU for 55ms burst [Q M]
time 31893ms: Process G completed a CPU burst; 53 bursts to go [Q M]
time 31893ms: Process G switching out of CPU; will block on I/O until time 33935ms [Q M]
time 31897ms: Process M started using the CPU for 31ms burst [Q empty]
time 31928ms: Process M completed a CPU burst; 22 bursts to go [Q empty]
time 31928ms: Process M switching out of CPU; will block on I/O until time 33030ms [Q empty]
time 31991ms: Process N completed I/O; added to ready queue [Q N]
time 31993ms: Process N started using the CPU for 77ms burst [Q empty]
time 32056ms: Process O completed I/O; added to ready queue [Q O]
time 32070ms: Process N completed a CPU burst; 6 bursts to go [Q O]
time 32070ms: Process N switching out of CPU; will block on I/O until time 32112ms [Q O]
time 32074ms: Process O started using the CPU for 30ms burst [Q empty]
time 32098ms: Process H completed I/O; added to ready queue [Q H]
time 32104ms: Process O completed a CPU burst; 6 bursts to go [Q H]
time 32104ms: Process O switching out of CPU; will block on I/O until time 32416ms [Q H]
time 32108ms: Process H started using the CPU for 37ms burst [Q empty]
time 32112ms: Process N completed I/O; added to ready queue [Q N]
time 32125ms: Process I completed I/O; added to ready queue [Q NI]
time 32145ms: Process H completed a CPU burst; 50 bursts to go [Q NI]
time 32145ms: Process H switching out of CPU; will block on I/O until time 32317ms [Q NI]
time 32149ms: Process N started using the CPU for 18ms burst [Q I]
time 32167ms: Process N completed a CPU burst; 5 bursts to go [Q I]
time 32167ms: Process N switching out of CPU; will block on I/O until time 32999ms [Q I]
time 32171ms: Process I started using the CPU for 55ms burst [Q empty]
time 32226ms: Process I completed a CPU burst; 49 bursts to go [Q empty]
time 32226ms: Process I switching out of CPU; will block on I/O until time 32428ms [Q empty]
time 32314ms: Process F completed I/O; added to ready queue [Q F]
time 32316ms: Process F started using the CPU for 55ms burst [Q empty]
time 32317ms: Process H completed I/O; added to ready queue [Q H]
time 32371ms: Process F terminated [Q H]
time 32375ms: Process H started using the CPU for 20ms burst [Q empty]
time 32395ms: Process H completed a CPU burst; 49 bursts to go [Q empty]
time 32395ms: Process H switching out of CPU; will block on I/O until time 32417ms [Q empty]
time 32416ms: Process O completed I/O; added to ready queue [Q O]
time 32417ms: Process H completed I/O; added to ready queue [Q H]
time 32418ms: Process O started using the CPU for 250ms burst [Q H]
time 32428ms: Process I completed I/O; added to ready queue [Q HI]
time 32668ms: Process O completed a CPU burst; 5 bursts to go [Q HI]
time 32668ms: Process O switching out of CPU; will block on I/O until time 33190ms [Q HI]
time 32672ms: Process H started using the CPU for 148ms burst [Q I]
time 32820ms: Process H completed a CPU burst; 48 bursts to go [Q I]
time 32820ms: Process H switching out of CPU; will block on I/O until time 33032ms [Q I]
