Process A (arrival time 9 ms) 16 CPU bursts (tau 100ms)
Process B (arrival time 18 ms) 21 CPU bursts (tau 100ms)

time 0ms: Simulator started for FCFS [Q empty]
time 9ms: Process A arrived; added to ready queue [Q A]
time 11ms: Process A started using the CPU for 56ms burst [Q empty]
time 18ms: Process B arrived; added to ready queue [Q B]
time 67ms: Process A completed a CPU burst; 15 bursts to go [Q B]
time 67ms: Process A switching out of CPU; will block on I/O until time 299ms [Q B]
time 71ms: Process B started using the CPU for 106ms burst [Q empty]
time 177ms: Process B completed a CPU burst; 20 bursts to go [Q empty]
time 177ms: Process B switching out of CPU; will block on I/O until time 1739ms [Q empty]
time 299ms: Process A completed I/O; added to ready queue [Q A]
time 301ms: Process A started using the CPU for 60ms burst [Q empty]
time 361ms: Process A completed a CPU burst; 14 bursts to go [Q empty]
time 361ms: Process A switching out of CPU; will block on I/O until time 1893ms [Q empty]
time 1739ms: Process B completed I/O; added to ready queue [Q B]
time 1741ms: Process B started using the CPU for 198ms burst [Q empty]
time 1893ms: Process A completed I/O; added to ready queue [Q A]
time 1939ms: Process B completed a CPU burst; 19 bursts to go [Q A]
time 1939ms: Process B switching out of CPU; will block on I/O until time 3071ms [Q A]
time 1943ms: Process A started using the CPU for 39ms burst [Q empty]
time 1982ms: Process A completed a CPU burst; 13 bursts to go [Q empty]
time 1982ms: Process A switching out of CPU; will block on I/O until time 2484ms [Q empty]
time 2484ms: Process A completed I/O; added to ready queue [Q A]
time 2486ms: Process A started using the CPU for 47ms burst [Q empty]
time 2533ms: Process A completed a CPU burst; 12 bursts to go [Q empty]
time 2533ms: Process A switching out of CPU; will block on I/O until time 2555ms [Q empty]
time 2555ms: Process A completed I/O; added to ready queue [Q A]
time 2557ms: Process A started using the CPU for 137ms burst [Q empty]
time 2694ms: Process A completed a CPU burst; 11 bursts to go [Q empty]
time 2694ms: Process A switching out of CPU; will block on I/O until time 2936ms [Q empty]
time 2936ms: Process A completed I/O; added to ready queue [Q A]
time 2938ms: Process A started using the CPU for 64ms burst [Q empty]
time 3002ms: Process A completed a CPU burst; 10 bursts to go [Q empty]
time 3002ms: Process A switching out of CPU; will block on I/O until time 3154ms [Q empty]
time 3071ms: Process B completed I/O; added to ready queue [Q B]
time 3073ms: Process B started using the CPU for 208ms burst [Q empty]
time 3154ms: Process A completed I/O; added to ready queue [Q A]
time 3281ms: Process B completed a CPU burst; 18 bursts to go [Q A]
time 3281ms: Process B switching out of CPU; will block on I/O until time 4903ms [Q A]
time 3285ms: Process A started using the CPU for 68ms burst [Q empty]
time 3353ms: Process A completed a CPU burst; 9 bursts to go [Q empty]
time 3353ms: Process A switching out of CPU; will block on I/O until time 3995ms [Q empty]
time 3995ms: Process A completed I/O; added to ready queue [Q A]
time 3997ms: Process A started using the CPU for 113ms burst [Q empty]
time 4110ms: Process A completed a CPU burst; 8 bursts to go [Q empty]
time 4110ms: Process A switching out of CPU; will block on I/O until time 4272ms [Q empty]
time 4272ms: Process A completed I/O; added to ready queue [Q A]
time 4274ms: Process A started using the CPU for 11ms burst [Q empty]
time 4285ms: Process A completed a CPU burst; 7 bursts to go [Q empty]
time 4285ms: Process A switching out of CPU; will block on I/O until time 5907ms [Q empty]
time 4903ms: Process B completed I/O; added to ready queue [Q B]
time 4905ms: Process B started using the CPU for 50ms burst [Q empty]
time 4955ms: Process B completed a CPU burst; 17 bursts to go [Q empty]
time 4955ms: Process B switching out of CPU; will block on I/O until time 5417ms [Q empty]
time 5417ms: Process B completed I/O; added to ready queue [Q B]
time 5419ms: Process B started using the CPU for 82ms burst [Q empty]
time 5501ms: Process B completed a CPU burst; 16 bursts to go [Q empty]
time 5501ms: Process B switching out of CPU; will block on I/O until time 5663ms [Q empty]
time 5663ms: Process B completed I/O; added to ready queue [Q B]
time 5665ms: Process B started using the CPU for 7ms burst [Q empty]
time 5672ms: Process B completed a CPU burst; 15 bursts to go [Q empty]
time 5672ms: Process B switching out of CPU; will block on I/O until time 5974ms [Q empty]
time 5907ms: Process A completed I/O; added to ready queue [Q A]
time 5909ms: Process A started using the CPU for 24ms burst [Q empty]
time 5933ms: Process A completed a CPU burst; 6 bursts to go [Q empty]
time 5933ms: Process A switching out of CPU; will block on I/O until time 7105ms [Q empty]
time 5974ms: Process B completed I/O; added to ready queue [Q B]
time 5976ms: Process B started using the CPU for 52ms burst [Q empty]
time 6028ms: Process B completed a CPU burst; 14 bursts to go [Q empty]
time 6028ms: Process B switching out of CPU; will block on I/O until time 6150ms [Q empty]
time 6150ms: Process B completed I/O; added to ready queue [Q B]
time 6152ms: Process B started using the CPU for 228ms burst [Q empty]
time 6380ms: Process B completed a CPU burst; 13 bursts to go [Q empty]
time 6380ms: Process B switching out of CPU; will block on I/O until time 7152ms [Q empty]
time 7105ms: Process A completed I/O; added to ready queue [Q A]
time 7107ms: Process A started using the CPU for 76ms burst [Q empty]
time 7152ms: Process B completed I/O; added to ready queue [Q B]
time 7183ms: Process A completed a CPU burst; 5 bursts to go [Q B]
time 7183ms: Process A switching out of CPU; will block on I/O until time 7465ms [Q B]
time 7187ms: Process B started using the CPU for 138ms burst [Q empty]
time 7325ms: Process B completed a CPU burst; 12 bursts to go [Q empty]
time 7325ms: Process B switching out of CPU; will block on I/O until time 8147ms [Q empty]
time 7465ms: Process A completed I/O; added to ready queue [Q A]
time 7467ms: Process A started using the CPU for 122ms burst [Q empty]
time 7589ms: Process A completed a CPU burst; 4 bursts to go [Q empty]
time 7589ms: Process A switching out of CPU; will block on I/O until time 7921ms [Q empty]
time 7921ms: Process A completed I/O; added to ready queue [Q A]
time 7923ms: Process A started using the CPU for 9ms burst [Q empty]
time 7932ms: Process A completed a CPU burst; 3 bursts to go [Q empty]
time 7932ms: Process A switching out of CPU; will block on I/O until time 8614ms [Q empty]
time 8147ms: Process B completed I/O; added to ready queue [Q B]
time 8149ms: Process B started using the CPU for 67ms burst [Q empty]
time 8216ms: Process B completed a CPU burst; 11 bursts to go [Q empty]
time 8216ms: Process B switching out of CPU; will block on I/O until time 8288ms [Q empty]
time 8288ms: Process B completed I/O; added to ready queue [Q B]
time 8290ms: Process B started using the CPU for 120ms burst [Q empty]
time 8410ms: Process B completed a CPU burst; 10 bursts to go [Q empty]
time 8410ms: Process B switching out of CPU; will block on I/O until time 8542ms [Q empty]
time 8542ms: Process B completed I/O; added to ready queue [Q B]
time 8544ms: Process B started using the CPU for 49ms burst [Q empty]
time 8593ms: Process B completed a CPU burst; 9 bursts to go [Q empty]
time 8593ms: Process B switching out of CPU; will block on I/O until time 9015ms [Q empty]
time 8614ms: Process A completed I/O; added to ready queue [Q A]
time 8616ms: Process A started using the CPU for 62ms burst [Q empty]
time 8678ms: Process A completed a CPU burst; 2 bursts to go [Q empty]
time 8678ms: Process A switching out of CPU; will block on I/O until time 9450ms [Q empty]
time 9015ms: Process B completed I/O; added to ready queue [Q B]
time 9017ms: Process B started using the CPU for 134ms burst [Q empty]
time 9151ms: Process B completed a CPU burst; 8 bursts to go [Q empty]
time 9151ms: Process B switching out of CPU; will block on I/O until time 9473ms [Q empty]
time 9450ms: Process A completed I/O; added to ready queue [Q A]
time 9452ms: Process A started using the CPU for 200ms burst [Q empty]
time 9473ms: Process B completed I/O; added to ready queue [Q B]
time 9652ms: Process A completed a CPU burst; 1 burst to go [Q B]
time 9652ms: Process A switching out of CPU; will block on I/O until time 9764ms [Q B]
time 9656ms: Process B started using the CPU for 144ms burst [Q empty]
time 9764ms: Process A completed I/O; added to ready queue [Q A]
time 9800ms: Process B completed a CPU burst; 7 bursts to go [Q A]
time 9800ms: Process B switching out of CPU; will block on I/O until time 10592ms [Q A]
time 9804ms: Process A started using the CPU for 197ms burst [Q empty]
time 10001ms: Process A terminated [Q empty]
time 10592ms: Process B completed I/O; added to ready queue [Q B]
time 10594ms: Process B started using the CPU for 183ms burst [Q empty]
time 10777ms: Process B completed a CPU burst; 6 bursts to go [Q empty]
time 10777ms: Process B switching out of CPU; will block on I/O until time 10839ms [Q empty]
time 10839ms: Process B completed I/O; added to ready queue [Q B]
time 10841ms: Process B started using the CPU for 219ms burst [Q empty]
time 11060ms: Process B completed a CPU burst; 5 bursts to go [Q empty]
time 11060ms: Process B switching out of CPU; will block on I/O until time 11292ms [Q empty]
time 11292ms: Process B completed I/O; added to ready queue [Q B]
time 11294ms: Process B started using the CPU for 64ms burst [Q empty]
time 11358ms: Process B completed a CPU burst; 4 bursts to go [Q empty]
time 11358ms: Process B switching out of CPU; will block on I/O until time 12160ms [Q empty]
time 12160ms: Process B completed I/O; added to ready queue [Q B]
time 12162ms: Process B started using the CPU for 33ms burst [Q empty]
time 12195ms: Process B completed a CPU burst; 3 bursts to go [Q empty]
time 12195ms: Process B switching out of CPU; will block on I/O until time 12937ms [Q empty]
time 12937ms: Process B completed I/O; added to ready queue [Q B]
time 12939ms: Process B started using the CPU for 63ms burst [Q empty]
time 13002ms: Process B completed a CPU burst; 2 bursts to go [Q empty]
time 13002ms: Process B switching out of CPU; will block on I/O until time 15314ms [Q empty]
time 15314ms: Process B completed I/O; added to ready queue [Q B]
time 15316ms: Process B started using the CPU for 170ms burst [Q empty]
time 15486ms: Process B completed a CPU burst; 1 burst to go [Q empty]
time 15486ms: Process B switching out of CPU; will block on I/O until time 16058ms [Q empty]
time 16058ms: Process B completed I/O; added to ready queue [Q B]
time 16060ms: Process B started using the CPU for 212ms burst [Q empty]
time 16272ms: Process B terminated [Q empty]
time 16274ms: Simulator ended for FCFS [Q empty]

