Process A (arrival time 9 ms) 16 CPU bursts (tau 100ms)
Process B (arrival time 18 ms) 21 CPU bursts (tau 100ms)
Process C (arrival time 42 ms) 4 CPU bursts (tau 100ms)
Process D (arrival time 156 ms) 11 CPU bursts (tau 100ms)
Process E (arrival time 134 ms) 55 CPU bursts (tau 100ms)
Process F (arrival time 106 ms) 34 CPU bursts (tau 100ms)
Process G (arrival time 65 ms) 80 CPU bursts (tau 100ms)
Process H (arrival time 11 ms) 83 CPU bursts (tau 100ms)
Process I (arrival time 68 ms) 77 CPU bursts (tau 100ms)
Process J (arrival time 0 ms) 10 CPU bursts (tau 100ms)
Process K (arrival time 7 ms) 13 CPU bursts (tau 100ms)
Process L (arrival time 189 ms) 7 CPU bursts (tau 100ms)

time 0ms: Simulator started for FCFS [Q empty]
time 0ms: Process J arrived; added to ready queue [Q J]
time 2ms: Process J started using the CPU for 40ms burst [Q empty]
time 7ms: Process K arrived; added to ready queue [Q K]
time 9ms: Process A arrived; added to ready queue [Q KA]
time 11ms: Process H arrived; added to ready queue [Q KAH]
time 18ms: Process B arrived; added to ready queue [Q KAHB]
time 42ms: Process J completed a CPU burst; 9 bursts to go [Q KAHB]
time 42ms: Process J switching out of CPU; will block on I/O until time 74ms [Q KAHB]
time 42ms: Process C arrived; added to ready queue [Q KAHBC]
time 46ms: Process K started using the CPU for 64ms burst [Q AHBC]
time 65ms: Process G arrived; added to ready queue [Q AHBCG]
time 68ms: Process I arrived; added to ready queue [Q AHBCGI]
time 74ms: Process J completed I/O; added to ready queue [Q AHBCGIJ]
time 106ms: Process F arrived; added to ready queue [Q AHBCGIJF]
time 110ms: Process K completed a CPU burst; 12 bursts to go [Q AHBCGIJF]
time 110ms: Process K switching out of CPU; will block on I/O until time 1072ms [Q AHBCGIJF]
time 114ms: Process A started using the CPU for 56ms burst [Q HBCGIJF]
time 134ms: Process E arrived; added to ready queue [Q HBCGIJFE]
time 156ms: Process D arrived; added to ready queue [Q HBCGIJFED]
time 170ms: Process A completed a CPU burst; 15 bursts to go [Q HBCGIJFED]
time 170ms: Process A switching out of CPU; will block on I/O until time 402ms [Q HBCGIJFED]
time 174ms: Process H started using the CPU for 96ms burst [Q BCGIJFED]
time 189ms: Process L arrived; added to ready queue [Q BCGIJFEDL]
time 270ms: Process H completed a CPU burst; 82 bursts to go [Q BCGIJFEDL]
time 270ms: Process H switching out of CPU; will block on I/O until time 942ms [Q BCGIJFEDL]
time 274ms: Process B started using the CPU for 106ms burst [Q CGIJFEDL]
time 380ms: Process B completed a CPU burst; 20 bursts to go [Q CGIJFEDL]
time 380ms: Process B switching out of CPU; will block on I/O until time 1942ms [Q CGIJFEDL]
time 384ms: Process C started using the CPU for 94ms burst [Q GIJFEDL]
time 402ms: Process A completed I/O; added to ready queue [Q GIJFEDLA]
time 478ms: Process C completed a CPU burst; 3 bursts to go [Q GIJFEDLA]
time 478ms: Process C switching out of CPU; will block on I/O until time 2060ms [Q GIJFEDLA]
time 482ms: Process G started using the CPU for 70ms burst [Q IJFEDLA]
time 552ms: Process G completed a CPU burst; 79 bursts to go [Q IJFEDLA]
time 552ms: Process G switching out of CPU; will block on I/O until time 864ms [Q IJFEDLA]
time 556ms: Process I started using the CPU for 220ms burst [Q JFEDLA]
time 776ms: Process I completed a CPU burst; 76 bursts to go [Q JFEDLA]
time 776ms: Process I switching out of CPU; will block on I/O until time 968ms [Q JFEDLA]
time 780ms: Process J started using the CPU for 204ms burst [Q FEDLA]
time 864ms: Process G completed I/O; added to ready queue [Q FEDLAG]
time 942ms: Process H completed I/O; added to ready queue [Q FEDLAGH]
time 968ms: Process I completed I/O; added to ready queue [Q FEDLAGHI]
time 984ms: Process J completed a CPU burst; 8 bursts to go [Q FEDLAGHI]
time 984ms: Process J switching out of CPU; will block on I/O until time 1686ms [Q FEDLAGHI]
time 988ms: Process F started using the CPU for 129ms burst [Q EDLAGHI]
time 1072ms: Process K completed I/O; added to ready queue [Q EDLAGHIK]
time 1117ms: Process F completed a CPU burst; 33 bursts to go [Q EDLAGHIK]
time 1117ms: Process F switching out of CPU; will block on I/O until time 1689ms [Q EDLAGHIK]
time 1121ms: Process E started using the CPU for 152ms burst [Q DLAGHIK]
time 1273ms: Process E completed a CPU burst; 54 bursts to go [Q DLAGHIK]
time 1273ms: Process E switching out of CPU; will block on I/O until time 1735ms [Q DLAGHIK]
time 1277ms: Process D started using the CPU for 148ms burst [Q LAGHIK]
time 1425ms: Process D completed a CPU burst; 10 bursts to go [Q LAGHIK]
time 1425ms: Process D switching out of CPU; will block on I/O until time 1447ms [Q LAGHIK]
time 1429ms: Process L started using the CPU for 135ms burst [Q AGHIK]
time 1447ms: Process D completed I/O; added to ready queue [Q AGHIKD]
time 1564ms: Process L completed a CPU burst; 6 bursts to go [Q AGHIKD]
time 1564ms: Process L switching out of CPU; will block on I/O until time 2306ms [Q AGHIKD]
time 1568ms: Process A started using the CPU for 60ms burst [Q GHIKD]
time 1628ms: Process A completed a CPU burst; 14 bursts to go [Q GHIKD]
time 1628ms: Process A switching out of CPU; will block on I/O until time 3160ms [Q GHIKD]
time 1632ms: Process G started using the CPU for 40ms burst [Q HIKD]
time 1672ms: Process G completed a CPU burst; 78 bursts to go [Q HIKD]
time 1672ms: Process G switching out of CPU; will block on I/O until time 1734ms [Q HIKD]
time 1676ms: Process H started using the CPU for 48ms burst [Q IKD]
time 1686ms: Process J completed I/O; added to ready queue [Q IKDJ]
time 1689ms: Process F completed I/O; added to ready queue [Q IKDJF]
time 1724ms: Process H completed a CPU burst; 81 bursts to go [Q IKDJF]
time 1724ms: Process H switching out of CPU; will block on I/O until time 1946ms [Q IKDJF]
time 1728ms: Process I started using the CPU for 16ms burst [Q KDJF]
time 1734ms: Process G completed I/O; added to ready queue [Q KDJFG]
time 1735ms: Process E completed I/O; added to ready queue [Q KDJFGE]
time 1744ms: Process I completed a CPU burst; 75 bursts to go [Q KDJFGE]
time 1744ms: Process I switching out of CPU; will block on I/O until time 3506ms [Q KDJFGE]
time 1748ms: Process K started using the CPU for 56ms burst [Q DJFGE]
time 1804ms: Process K completed a CPU burst; 11 bursts to go [Q DJFGE]
time 1804ms: Process K switching out of CPU; will block on I/O until time 2536ms [Q DJFGE]
time 1808ms: Process D started using the CPU for 211ms burst [Q JFGE]
time 1942ms: Process B completed I/O; added to ready queue [Q JFGEB]
time 1946ms: Process H completed I/O; added to ready queue [Q JFGEBH]
time 2019ms: Process D completed a CPU burst; 9 bursts to go [Q JFGEBH]
time 2019ms: Process D switching out of CPU; will block on I/O until time 4161ms [Q JFGEBH]
time 2023ms: Process J started using the CPU for 28ms burst [Q FGEBH]
time 2051ms: Process J completed a CPU burst; 7 bursts to go [Q FGEBH]
time 2051ms: Process J switching out of CPU; will block on I/O until time 2273ms [Q FGEBH]
time 2055ms: Process F started using the CPU for 39ms burst [Q GEBH]
time 2060ms: Process C completed I/O; added to ready queue [Q GEBHC]
time 2094ms: Process F completed a CPU burst; 32 bursts to go [Q GEBHC]
time 2094ms: Process F switching out of CPU; will block on I/O until time 2746ms [Q GEBHC]
time 2098ms: Process G started using the CPU for 65ms burst [Q EBHC]
time 2163ms: Process G completed a CPU burst; 77 bursts to go [Q EBHC]
time 2163ms: Process G switching out of CPU; will block on I/O until time 2605ms [Q EBHC]
time 2167ms: Process E started using the CPU for 44ms burst [Q BHC]
time 2211ms: Process E completed a CPU burst; 53 bursts to go [Q BHC]
time 2211ms: Process E switching out of CPU; will block on I/O until time 2773ms [Q BHC]
time 2215ms: Process B started using the CPU for 198ms burst [Q HC]
time 2273ms: Process J completed I/O; added to ready queue [Q HCJ]
time 2306ms: Process L completed I/O; added to ready queue [Q HCJL]
time 2413ms: Process B completed a CPU burst; 19 bursts to go [Q HCJL]
time 2413ms: Process B switching out of CPU; will block on I/O until time 3545ms [Q HCJL]
time 2417ms: Process H started using the CPU for 72ms burst [Q CJL]
time 2489ms: Process H completed a CPU burst; 80 bursts to go [Q CJL]
time 2489ms: Process H switching out of CPU; will block on I/O until time 2911ms [Q CJL]
time 2493ms: Process C started using the CPU for 117ms burst [Q JL]
time 2536ms: Process K completed I/O; added to ready queue [Q JLK]
time 2605ms: Process G completed I/O; added to ready queue [Q JLKG]
time 2610ms: Process C completed a CPU burst; 2 bursts to go [Q JLKG]
time 2610ms: Process C switching out of CPU; will block on I/O until time 2782ms [Q JLKG]
time 2614ms: Process J started using the CPU for 120ms burst [Q LKG]
time 2734ms: Process J completed a CPU burst; 6 bursts to go [Q LKG]
time 2734ms: Process J switching out of CPU; will block on I/O until time 3296ms [Q LKG]
time 2738ms: Process L started using the CPU for 4ms burst [Q KG]
time 2742ms: Process L completed a CPU burst; 5 bursts to go [Q KG]
time 2742ms: Process L switching out of CPU; will block on I/O until time 3164ms [Q KG]
time 2746ms: Process K started using the CPU for 6ms burst [Q G]
time 2746ms: Process F completed I/O; added to ready queue [Q GF]
time 2752ms: Process K completed a CPU burst; 10 bursts to go [Q GF]
time 2752ms: Process K switching out of CPU; will block on I/O until time 3454ms [Q GF]
time 2756ms: Process G started using the CPU for 13ms burst [Q F]
time 2769ms: Process G completed a CPU burst; 76 bursts to go [Q F]
time 2769ms: Process G switching out of CPU; will block on I/O until time 3151ms [Q F]
time 2773ms: Process F started using the CPU for 195ms burst [Q empty]
time 2773ms: Process E completed I/O; added to ready queue [Q E]
time 2782ms: Process C completed I/O; added to ready queue [Q EC]
time 2911ms: Process H completed I/O; added to ready queue [Q ECH]
time 2968ms: Process F completed a CPU burst; 31 bursts to go [Q ECH]
time 2968ms: Process F switching out of CPU; will block on I/O until time 2980ms [Q ECH]
time 2972ms: Process E started using the CPU for 2ms burst [Q CH]
time 2974ms: Process E completed a CPU burst; 52 bursts to go [Q CH]
time 2974ms: Process E switching out of CPU; will block on I/O until time 3226ms [Q CH]
time 2978ms: Process C started using the CPU for 85ms burst [Q H]
time 2980ms: Process F completed I/O; added to ready queue [Q HF]
time 3063ms: Process C completed a CPU burst; 1 burst to go [Q HF]
time 3063ms: Process C switching out of CPU; will block on I/O until time 3275ms [Q HF]
time 3067ms: Process H started using the CPU for 12ms burst [Q F]
time 3079ms: Process H completed a CPU burst; 79 bursts to go [Q F]
time 3079ms: Process H switching out of CPU; will block on I/O until time 3211ms [Q F]
time 3083ms: Process F started using the CPU for 72ms burst [Q empty]
time 3151ms: Process G completed I/O; added to ready queue [Q G]
time 3155ms: Process F completed a CPU burst; 30 bursts to go [Q G]
time 3155ms: Process F switching out of CPU; will block on I/O until time 3417ms [Q G]
time 3159ms: Process G started using the CPU for 128ms burst [Q empty]
time 3160ms: Process A completed I/O; added to ready queue [Q A]
time 3164ms: Process L completed I/O; added to ready queue [Q AL]
time 3211ms: Process H completed I/O; added to ready queue [Q ALH]
time 3226ms: Process E completed I/O; added to ready queue [Q ALHE]
time 3275ms: Process C completed I/O; added to ready queue [Q ALHEC]
time 3287ms: Process G completed a CPU burst; 75 bursts to go [Q ALHEC]
time 3287ms: Process G switching out of CPU; will block on I/O until time 5509ms [Q ALHEC]
time 3291ms: Process A started using the CPU for 39ms burst [Q LHEC]
time 3296ms: Process J completed I/O; added to ready queue [Q LHECJ]
time 3330ms: Process A completed a CPU burst; 13 bursts to go [Q LHECJ]
time 3330ms: Process A switching out of CPU; will block on I/O until time 3832ms [Q LHECJ]
time 3334ms: Process L started using the CPU for 69ms burst [Q HECJ]
time 3403ms: Process L completed a CPU burst; 4 bursts to go [Q HECJ]
time 3403ms: Process L switching out of CPU; will block on I/O until time 4355ms [Q HECJ]
time 3407ms: Process H started using the CPU for 41ms burst [Q ECJ]
time 3417ms: Process F completed I/O; added to ready queue [Q ECJF]
time 3448ms: Process H completed a CPU burst; 78 bursts to go [Q ECJF]
time 3448ms: Process H switching out of CPU; will block on I/O until time 3660ms [Q ECJF]
time 3452ms: Process E started using the CPU for 42ms burst [Q CJF]
time 3454ms: Process K completed I/O; added to ready queue [Q CJFK]
time 3494ms: Process E completed a CPU burst; 51 bursts to go [Q CJFK]
time 3494ms: Process E switching out of CPU; will block on I/O until time 3546ms [Q CJFK]
time 3498ms: Process C started using the CPU for 79ms burst [Q JFK]
time 3506ms: Process I completed I/O; added to ready queue [Q JFKI]
time 3545ms: Process B completed I/O; added to ready queue [Q JFKIB]
time 3546ms: Process E completed I/O; added to ready queue [Q JFKIBE]
time 3577ms: Process C terminated [Q JFKIBE]
time 3581ms: Process J started using the CPU for 31ms burst [Q FKIBE]
time 3612ms: Process J completed a CPU burst; 5 bursts to go [Q FKIBE]
time 3612ms: Process J switching out of CPU; will block on I/O until time 4474ms [Q FKIBE]
time 3616ms: Process F started using the CPU for 8ms burst [Q KIBE]
time 3624ms: Process F completed a CPU burst; 29 bursts to go [Q KIBE]
time 3624ms: Process F switching out of CPU; will block on I/O until time 3956ms [Q KIBE]
time 3628ms: Process K started using the CPU for 6ms burst [Q IBE]
time 3634ms: Process K completed a CPU burst; 9 bursts to go [Q IBE]
time 3634ms: Process K switching out of CPU; will block on I/O until time 4386ms [Q IBE]
time 3638ms: Process I started using the CPU for 26ms burst [Q BE]
time 3660ms: Process H completed I/O; added to ready queue [Q BEH]
time 3664ms: Process I completed a CPU burst; 74 bursts to go [Q BEH]
time 3664ms: Process I switching out of CPU; will block on I/O until time 4296ms [Q BEH]
time 3668ms: Process B started using the CPU for 208ms burst [Q EH]
time 3832ms: Process A completed I/O; added to ready queue [Q EHA]
time 3876ms: Process B completed a CPU burst; 18 bursts to go [Q EHA]
time 3876ms: Process B switching out of CPU; will block on I/O until time 5498ms [Q EHA]
time 3880ms: Process E started using the CPU for 108ms burst [Q HA]
time 3956ms: Process F completed I/O; added to ready queue [Q HAF]
time 3988ms: Process E completed a CPU burst; 50 bursts to go [Q HAF]
time 3988ms: Process E switching out of CPU; will block on I/O until time 4080ms [Q HAF]
time 3992ms: Process H started using the CPU for 160ms burst [Q AF]
time 4080ms: Process E completed I/O; added to ready queue [Q AFE]
time 4152ms: Process H completed a CPU burst; 77 bursts to go [Q AFE]
time 4152ms: Process H switching out of CPU; will block on I/O until time 4754ms [Q AFE]
time 4156ms: Process A started using the CPU for 47ms burst [Q FE]
time 4161ms: Process D completed I/O; added to ready queue [Q FED]
time 4203ms: Process A completed a CPU burst; 12 bursts to go [Q FED]
time 4203ms: Process A switching out of CPU; will block on I/O until time 4225ms [Q FED]
time 4207ms: Process F started using the CPU for 230ms burst [Q ED]
time 4225ms: Process A completed I/O; added to ready queue [Q EDA]
time 4296ms: Process I completed I/O; added to ready queue [Q EDAI]
time 4355ms: Process L completed I/O; added to ready queue [Q EDAIL]
time 4386ms: Process K completed I/O; added to ready queue [Q EDAILK]
time 4437ms: Process F completed a CPU burst; 28 bursts to go [Q EDAILK]
time 4437ms: Process F switching out of CPU; will block on I/O until time 4469ms [Q EDAILK]
time 4441ms: Process E started using the CPU for 6ms burst [Q DAILK]
time 4447ms: Process E completed a CPU burst; 49 bursts to go [Q DAILK]
time 4447ms: Process E switching out of CPU; will block on I/O until time 4769ms [Q DAILK]
time 4451ms: Process D started using the CPU for 9ms burst [Q AILK]
time 4460ms: Process D completed a CPU burst; 8 bursts to go [Q AILK]
time 4460ms: Process D switching out of CPU; will block on I/O until time 4842ms [Q AILK]
time 4464ms: Process A started using the CPU for 137ms burst [Q ILK]
time 4469ms: Process F completed I/O; added to ready queue [Q ILKF]
time 4474ms: Process J completed I/O; added to ready queue [Q ILKFJ]
time 4601ms: Process A completed a CPU burst; 11 bursts to go [Q ILKFJ]
time 4601ms: Process A switching out of CPU; will block on I/O until time 4843ms [Q ILKFJ]
time 4605ms: Process I started using the CPU for 45ms burst [Q LKFJ]
time 4650ms: Process I completed a CPU burst; 73 bursts to go [Q LKFJ]
time 4650ms: Process I switching out of CPU; will block on I/O until time 4952ms [Q LKFJ]
time 4654ms: Process L started using the CPU for 25ms burst [Q KFJ]
time 4679ms: Process L completed a CPU burst; 3 bursts to go [Q KFJ]
time 4679ms: Process L switching out of CPU; will block on I/O until time 5871ms [Q KFJ]
time 4683ms: Process K started using the CPU for 157ms burst [Q FJ]
time 4754ms: Process H completed I/O; added to ready queue [Q FJH]
time 4769ms: Process E completed I/O; added to ready queue [Q FJHE]
time 4840ms: Process K completed a CPU burst; 8 bursts to go [Q FJHE]
time 4840ms: Process K switching out of CPU; will block on I/O until time 5002ms [Q FJHE]
time 4842ms: Process D completed I/O; added to ready queue [Q FJHED]
time 4843ms: Process A completed I/O; added to ready queue [Q JHEDA]
time 4844ms: Process F started using the CPU for 33ms burst [Q JHEDA]
time 4877ms: Process F completed a CPU burst; 27 bursts to go [Q JHEDA]
time 4877ms: Process F switching out of CPU; will block on I/O until time 5439ms [Q JHEDA]
time 4881ms: Process J started using the CPU for 32ms burst [Q HEDA]
time 4913ms: Process J completed a CPU burst; 4 bursts to go [Q HEDA]
time 4913ms: Process J switching out of CPU; will block on I/O until time 5045ms [Q HEDA]
time 4917ms: Process H started using the CPU for 28ms burst [Q EDA]
time 4945ms: Process H completed a CPU burst; 76 bursts to go [Q EDA]
time 4945ms: Process H switching out of CPU; will block on I/O until time 5907ms [Q EDA]
time 4949ms: Process E started using the CPU for 112ms burst [Q DA]
time 4952ms: Process I completed I/O; added to ready queue [Q DAI]
time 5002ms: Process K completed I/O; added to ready queue [Q DAIK]
time 5045ms: Process J completed I/O; added to ready queue [Q DAIKJ]
time 5061ms: Process E completed a CPU burst; 48 bursts to go [Q DAIKJ]
time 5061ms: Process E switching out of CPU; will block on I/O until time 6173ms [Q DAIKJ]
time 5065ms: Process D started using the CPU for 4ms burst [Q AIKJ]
time 5069ms: Process D completed a CPU burst; 7 bursts to go [Q AIKJ]
time 5069ms: Process D switching out of CPU; will block on I/O until time 5551ms [Q AIKJ]
time 5073ms: Process A started using the CPU for 64ms burst [Q IKJ]
time 5137ms: Process A completed a CPU burst; 10 bursts to go [Q IKJ]
time 5137ms: Process A switching out of CPU; will block on I/O until time 5289ms [Q IKJ]
time 5141ms: Process I started using the CPU for 38ms burst [Q KJ]
time 5179ms: Process I completed a CPU burst; 72 bursts to go [Q KJ]
time 5179ms: Process I switching out of CPU; will block on I/O until time 5761ms [Q KJ]
time 5183ms: Process K started using the CPU for 104ms burst [Q J]
time 5287ms: Process K completed a CPU burst; 7 bursts to go [Q J]
time 5287ms: Process K switching out of CPU; will block on I/O until time 6739ms [Q J]
time 5289ms: Process A completed I/O; added to ready queue [Q JA]
time 5291ms: Process J started using the CPU for 23ms burst [Q A]
time 5314ms: Process J completed a CPU burst; 3 bursts to go [Q A]
time 5314ms: Process J switching out of CPU; will block on I/O until time 5476ms [Q A]
time 5318ms: Process A started using the CPU for 68ms burst [Q empty]
time 5386ms: Process A completed a CPU burst; 9 bursts to go [Q empty]
time 5386ms: Process A switching out of CPU; will block on I/O until time 6028ms [Q empty]
time 5439ms: Process F completed I/O; added to ready queue [Q F]
time 5441ms: Process F started using the CPU for 76ms burst [Q empty]
time 5476ms: Process J completed I/O; added to ready queue [Q J]
time 5498ms: Process B completed I/O; added to ready queue [Q JB]
time 5509ms: Process G completed I/O; added to ready queue [Q JBG]
time 5517ms: Process F completed a CPU burst; 26 bursts to go [Q JBG]
time 5517ms: Process F switching out of CPU; will block on I/O until time 5899ms [Q JBG]
time 5521ms: Process J started using the CPU for 51ms burst [Q BG]
time 5551ms: Process D completed I/O; added to ready queue [Q BGD]
time 5572ms: Process J completed a CPU burst; 2 bursts to go [Q BGD]
time 5572ms: Process J switching out of CPU; will block on I/O until time 6544ms [Q BGD]
time 5576ms: Process B started using the CPU for 50ms burst [Q GD]
time 5626ms: Process B completed a CPU burst; 17 bursts to go [Q GD]
time 5626ms: Process B switching out of CPU; will block on I/O until time 6088ms [Q GD]
time 5630ms: Process G started using the CPU for 15ms burst [Q D]
time 5645ms: Process G completed a CPU burst; 74 bursts to go [Q D]
time 5645ms: Process G switching out of CPU; will block on I/O until time 6587ms [Q D]
time 5649ms: Process D started using the CPU for 149ms burst [Q empty]
time 5761ms: Process I completed I/O; added to ready queue [Q I]
time 5798ms: Process D completed a CPU burst; 6 bursts to go [Q I]
time 5798ms: Process D switching out of CPU; will block on I/O until time 6610ms [Q I]
time 5802ms: Process I started using the CPU for 79ms burst [Q empty]
time 5871ms: Process L completed I/O; added to ready queue [Q L]
time 5881ms: Process I completed a CPU burst; 71 bursts to go [Q L]
time 5881ms: Process I switching out of CPU; will block on I/O until time 7043ms [Q L]
time 5885ms: Process L started using the CPU for 2ms burst [Q empty]
time 5887ms: Process L completed a CPU burst; 2 bursts to go [Q empty]
time 5887ms: Process L switching out of CPU; will block on I/O until time 6259ms [Q empty]
time 5899ms: Process F completed I/O; added to ready queue [Q F]
time 5901ms: Process F started using the CPU for 107ms burst [Q empty]
time 5907ms: Process H completed I/O; added to ready queue [Q H]
time 6008ms: Process F completed a CPU burst; 25 bursts to go [Q H]
time 6008ms: Process F switching out of CPU; will block on I/O until time 6190ms [Q H]
time 6012ms: Process H started using the CPU for 51ms burst [Q empty]
time 6028ms: Process A completed I/O; added to ready queue [Q A]
time 6063ms: Process H completed a CPU burst; 75 bursts to go [Q A]
time 6063ms: Process H switching out of CPU; will block on I/O until time 6295ms [Q A]
time 6067ms: Process A started using the CPU for 113ms burst [Q empty]
time 6088ms: Process B completed I/O; added to ready queue [Q B]
time 6173ms: Process E completed I/O; added to ready queue [Q BE]
time 6180ms: Process A completed a CPU burst; 8 bursts to go [Q BE]
time 6180ms: Process A switching out of CPU; will block on I/O until time 6342ms [Q BE]
time 6184ms: Process B started using the CPU for 82ms burst [Q E]
time 6190ms: Process F completed I/O; added to ready queue [Q EF]
time 6259ms: Process L completed I/O; added to ready queue [Q EFL]
time 6266ms: Process B completed a CPU burst; 16 bursts to go [Q EFL]
time 6266ms: Process B switching out of CPU; will block on I/O until time 6428ms [Q EFL]
time 6270ms: Process E started using the CPU for 12ms burst [Q FL]
time 6282ms: Process E completed a CPU burst; 47 bursts to go [Q FL]
time 6282ms: Process E switching out of CPU; will block on I/O until time 6734ms [Q FL]
time 6286ms: Process F started using the CPU for 89ms burst [Q L]
time 6295ms: Process H completed I/O; added to ready queue [Q LH]
time 6342ms: Process A completed I/O; added to ready queue [Q LHA]
time 6375ms: Process F completed a CPU burst; 24 bursts to go [Q LHA]
time 6375ms: Process F switching out of CPU; will block on I/O until time 7207ms [Q LHA]
time 6379ms: Process L started using the CPU for 164ms burst [Q HA]
time 6428ms: Process B completed I/O; added to ready queue [Q HAB]
time 6543ms: Process L completed a CPU burst; 1 burst to go [Q HAB]
time 6543ms: Process L switching out of CPU; will block on I/O until time 7045ms [Q HAB]
time 6544ms: Process J completed I/O; added to ready queue [Q HABJ]
time 6547ms: Process H started using the CPU for 87ms burst [Q ABJ]
time 6587ms: Process G completed I/O; added to ready queue [Q ABJG]
time 6610ms: Process D completed I/O; added to ready queue [Q ABJGD]
time 6634ms: Process H completed a CPU burst; 74 bursts to go [Q ABJGD]
time 6634ms: Process H switching out of CPU; will block on I/O until time 7206ms [Q ABJGD]
time 6638ms: Process A started using the CPU for 11ms burst [Q BJGD]
time 6649ms: Process A completed a CPU burst; 7 bursts to go [Q BJGD]
time 6649ms: Process A switching out of CPU; will block on I/O until time 8271ms [Q BJGD]
time 6653ms: Process B started using the CPU for 7ms burst [Q JGD]
time 6660ms: Process B completed a CPU burst; 15 bursts to go [Q JGD]
time 6660ms: Process B switching out of CPU; will block on I/O until time 6962ms [Q JGD]
time 6664ms: Process J started using the CPU for 216ms burst [Q GD]
time 6734ms: Process E completed I/O; added to ready queue [Q GDE]
time 6739ms: Process K completed I/O; added to ready queue [Q GDEK]
time 6880ms: Process J completed a CPU burst; 1 burst to go [Q GDEK]
time 6880ms: Process J switching out of CPU; will block on I/O until time 6962ms [Q GDEK]
time 6884ms: Process G started using the CPU for 112ms burst [Q DEK]
time 6962ms: Process B completed I/O; added to ready queue [Q DEKB]
time 6962ms: Process J completed I/O; added to ready queue [Q DEKBJ]
time 6996ms: Process G completed a CPU burst; 73 bursts to go [Q DEKBJ]
time 6996ms: Process G switching out of CPU; will block on I/O until time 7428ms [Q DEKBJ]
time 7000ms: Process D started using the CPU for 52ms burst [Q EKBJ]
time 7043ms: Process I completed I/O; added to ready queue [Q EKBJI]
time 7045ms: Process L completed I/O; added to ready queue [Q EKBJIL]
time 7052ms: Process D completed a CPU burst; 5 bursts to go [Q EKBJIL]
time 7052ms: Process D switching out of CPU; will block on I/O until time 7084ms [Q EKBJIL]
time 7056ms: Process E started using the CPU for 9ms burst [Q KBJIL]
time 7065ms: Process E completed a CPU burst; 46 bursts to go [Q KBJIL]
time 7065ms: Process E switching out of CPU; will block on I/O until time 7737ms [Q KBJIL]
time 7069ms: Process K started using the CPU for 86ms burst [Q BJIL]
time 7084ms: Process D completed I/O; added to ready queue [Q BJILD]
time 7155ms: Process K completed a CPU burst; 6 bursts to go [Q BJILD]
time 7155ms: Process K switching out of CPU; will block on I/O until time 7437ms [Q BJILD]
time 7159ms: Process B started using the CPU for 52ms burst [Q JILD]
time 7206ms: Process H completed I/O; added to ready queue [Q JILDH]
time 7207ms: Process F completed I/O; added to ready queue [Q JILDHF]
time 7211ms: Process B completed a CPU burst; 14 bursts to go [Q JILDHF]
time 7211ms: Process B switching out of CPU; will block on I/O until time 7333ms [Q JILDHF]
time 7215ms: Process J started using the CPU for 7ms burst [Q ILDHF]
time 7222ms: Process J terminated [Q ILDHF]
time 7226ms: Process I started using the CPU for 84ms burst [Q LDHF]
time 7310ms: Process I completed a CPU burst; 70 bursts to go [Q LDHF]
time 7310ms: Process I switching out of CPU; will block on I/O until time 7822ms [Q LDHF]
time 7314ms: Process L started using the CPU for 111ms burst [Q DHF]
time 7333ms: Process B completed I/O; added to ready queue [Q DHFB]
time 7425ms: Process L terminated [Q DHFB]
time 7428ms: Process G completed I/O; added to ready queue [Q HFBG]
time 7429ms: Process D started using the CPU for 23ms burst [Q HFBG]
time 7437ms: Process K completed I/O; added to ready queue [Q HFBGK]
time 7452ms: Process D completed a CPU burst; 4 bursts to go [Q HFBGK]
time 7452ms: Process D switching out of CPU; will block on I/O until time 9394ms [Q HFBGK]
time 7456ms: Process H started using the CPU for 156ms burst [Q FBGK]
time 7612ms: Process H completed a CPU burst; 73 bursts to go [Q FBGK]
time 7612ms: Process H switching out of CPU; will block on I/O until time 8174ms [Q FBGK]
time 7616ms: Process F started using the CPU for 102ms burst [Q BGK]
time 7718ms: Process F completed a CPU burst; 23 bursts to go [Q BGK]
time 7718ms: Process F switching out of CPU; will block on I/O until time 9070ms [Q BGK]
time 7722ms: Process B started using the CPU for 228ms burst [Q GK]
time 7737ms: Process E completed I/O; added to ready queue [Q GKE]
time 7822ms: Process I completed I/O; added to ready queue [Q GKEI]
time 7950ms: Process B completed a CPU burst; 13 bursts to go [Q GKEI]
time 7950ms: Process B switching out of CPU; will block on I/O until time 8722ms [Q GKEI]
time 7954ms: Process G started using the CPU for 30ms burst [Q KEI]
time 7984ms: Process G completed a CPU burst; 72 bursts to go [Q KEI]
time 7984ms: Process G switching out of CPU; will block on I/O until time 8456ms [Q KEI]
time 7988ms: Process K started using the CPU for 50ms burst [Q EI]
time 8038ms: Process K completed a CPU burst; 5 bursts to go [Q EI]
time 8038ms: Process K switching out of CPU; will block on I/O until time 8540ms [Q EI]
time 8042ms: Process E started using the CPU for 62ms burst [Q I]
time 8104ms: Process E completed a CPU burst; 45 bursts to go [Q I]
time 8104ms: Process E switching out of CPU; will block on I/O until time 8706ms [Q I]
time 8108ms: Process I started using the CPU for 27ms burst [Q empty]
time 8135ms: Process I completed a CPU burst; 69 bursts to go [Q empty]
time 8135ms: Process I switching out of CPU; will block on I/O until time 10037ms [Q empty]
time 8174ms: Process H completed I/O; added to ready queue [Q H]
time 8176ms: Process H started using the CPU for 184ms burst [Q empty]
time 8271ms: Process A completed I/O; added to ready queue [Q A]
time 8360ms: Process H completed a CPU burst; 72 bursts to go [Q A]
time 8360ms: Process H switching out of CPU; will block on I/O until time 8622ms [Q A]
time 8364ms: Process A started using the CPU for 24ms burst [Q empty]
time 8388ms: Process A completed a CPU burst; 6 bursts to go [Q empty]
time 8388ms: Process A switching out of CPU; will block on I/O until time 9560ms [Q empty]
time 8456ms: Process G completed I/O; added to ready queue [Q G]
time 8458ms: Process G started using the CPU for 50ms burst [Q empty]
time 8508ms: Process G completed a CPU burst; 71 bursts to go [Q empty]
time 8508ms: Process G switching out of CPU; will block on I/O until time 10710ms [Q empty]
time 8540ms: Process K completed I/O; added to ready queue [Q K]
time 8542ms: Process K started using the CPU for 4ms burst [Q empty]
time 8546ms: Process K completed a CPU burst; 4 bursts to go [Q empty]
time 8546ms: Process K switching out of CPU; will block on I/O until time 9148ms [Q empty]
time 8622ms: Process H completed I/O; added to ready queue [Q H]
time 8624ms: Process H started using the CPU for 2ms burst [Q empty]
time 8626ms: Process H completed a CPU burst; 71 bursts to go [Q empty]
time 8626ms: Process H switching out of CPU; will block on I/O until time 8768ms [Q empty]
time 8706ms: Process E completed I/O; added to ready queue [Q E]
time 8708ms: Process E started using the CPU for 213ms burst [Q empty]
time 8722ms: Process B completed I/O; added to ready queue [Q B]
time 8768ms: Process H completed I/O; added to ready queue [Q BH]
time 8921ms: Process E completed a CPU burst; 44 bursts to go [Q BH]
time 8921ms: Process E switching out of CPU; will block on I/O until time 10853ms [Q BH]
time 8925ms: Process B started using the CPU for 138ms burst [Q H]
time 9063ms: Process B completed a CPU burst; 12 bursts to go [Q H]
time 9063ms: Process B switching out of CPU; will block on I/O until time 9885ms [Q H]
time 9067ms: Process H started using the CPU for 29ms burst [Q empty]
time 9070ms: Process F completed I/O; added to ready queue [Q F]
time 9096ms: Process H completed a CPU burst; 70 bursts to go [Q F]
time 9096ms: Process H switching out of CPU; will block on I/O until time 11318ms [Q F]
time 9100ms: Process F started using the CPU for 147ms burst [Q empty]
time 9148ms: Process K completed I/O; added to ready queue [Q K]
time 9247ms: Process F completed a CPU burst; 22 bursts to go [Q K]
time 9247ms: Process F switching out of CPU; will block on I/O until time 9299ms [Q K]
time 9251ms: Process K started using the CPU for 21ms burst [Q empty]
time 9272ms: Process K completed a CPU burst; 3 bursts to go [Q empty]
time 9272ms: Process K switching out of CPU; will block on I/O until time 9924ms [Q empty]
time 9299ms: Process F completed I/O; added to ready queue [Q F]
time 9301ms: Process F started using the CPU for 97ms burst [Q empty]
time 9394ms: Process D completed I/O; added to ready queue [Q D]
time 9398ms: Process F completed a CPU burst; 21 bursts to go [Q D]
time 9398ms: Process F switching out of CPU; will block on I/O until time 9440ms [Q D]
time 9402ms: Process D started using the CPU for 76ms burst [Q empty]
time 9440ms: Process F completed I/O; added to ready queue [Q F]
time 9478ms: Process D completed a CPU burst; 3 bursts to go [Q F]
time 9478ms: Process D switching out of CPU; will block on I/O until time 10210ms [Q F]
time 9482ms: Process F started using the CPU for 157ms burst [Q empty]
time 9560ms: Process A completed I/O; added to ready queue [Q A]
time 9639ms: Process F completed a CPU burst; 20 bursts to go [Q A]
time 9639ms: Process F switching out of CPU; will block on I/O until time 9741ms [Q A]
time 9643ms: Process A started using the CPU for 76ms burst [Q empty]
time 9719ms: Process A completed a CPU burst; 5 bursts to go [Q empty]
time 9719ms: Process A switching out of CPU; will block on I/O until time 10001ms [Q empty]
time 9741ms: Process F completed I/O; added to ready queue [Q F]
time 9743ms: Process F started using the CPU for 24ms burst [Q empty]
time 9767ms: Process F completed a CPU burst; 19 bursts to go [Q empty]
time 9767ms: Process F switching out of CPU; will block on I/O until time 10739ms [Q empty]
time 9885ms: Process B completed I/O; added to ready queue [Q B]
time 9887ms: Process B started using the CPU for 67ms burst [Q empty]
time 9924ms: Process K completed I/O; added to ready queue [Q K]
time 9954ms: Process B completed a CPU burst; 11 bursts to go [Q K]
time 9954ms: Process B switching out of CPU; will block on I/O until time 10026ms [Q K]
time 9958ms: Process K started using the CPU for 120ms burst [Q empty]
time 10001ms: Process A completed I/O; added to ready queue [Q A]
time 10026ms: Process B completed I/O; added to ready queue [Q AB]
time 10037ms: Process I completed I/O; added to ready queue [Q ABI]
time 10078ms: Process K completed a CPU burst; 2 bursts to go [Q ABI]
time 10078ms: Process K switching out of CPU; will block on I/O until time 10770ms [Q ABI]
time 10082ms: Process A started using the CPU for 122ms burst [Q BI]
time 10204ms: Process A completed a CPU burst; 4 bursts to go [Q BI]
time 10204ms: Process A switching out of CPU; will block on I/O until time 10536ms [Q BI]
time 10208ms: Process B started using the CPU for 120ms burst [Q I]
time 10210ms: Process D completed I/O; added to ready queue [Q ID]
time 10328ms: Process B completed a CPU burst; 10 bursts to go [Q ID]
time 10328ms: Process B switching out of CPU; will block on I/O until time 10460ms [Q ID]
time 10332ms: Process I started using the CPU for 70ms burst [Q D]
time 10402ms: Process I completed a CPU burst; 68 bursts to go [Q D]
time 10402ms: Process I switching out of CPU; will block on I/O until time 11944ms [Q D]
time 10406ms: Process D started using the CPU for 50ms burst [Q empty]
time 10456ms: Process D completed a CPU burst; 2 bursts to go [Q empty]
time 10456ms: Process D switching out of CPU; will block on I/O until time 10578ms [Q empty]
time 10460ms: Process B completed I/O; added to ready queue [Q B]
time 10462ms: Process B started using the CPU for 49ms burst [Q empty]
time 10511ms: Process B completed a CPU burst; 9 bursts to go [Q empty]
time 10511ms: Process B switching out of CPU; will block on I/O until time 10933ms [Q empty]
time 10536ms: Process A completed I/O; added to ready queue [Q A]
time 10538ms: Process A started using the CPU for 9ms burst [Q empty]
time 10547ms: Process A completed a CPU burst; 3 bursts to go [Q empty]
time 10547ms: Process A switching out of CPU; will block on I/O until time 11229ms [Q empty]
time 10578ms: Process D completed I/O; added to ready queue [Q D]
time 10580ms: Process D started using the CPU for 24ms burst [Q empty]
time 10604ms: Process D completed a CPU burst; 1 burst to go [Q empty]
time 10604ms: Process D switching out of CPU; will block on I/O until time 10856ms [Q empty]
time 10710ms: Process G completed I/O; added to ready queue [Q G]
time 10712ms: Process G started using the CPU for 5ms burst [Q empty]
time 10717ms: Process G completed a CPU burst; 70 bursts to go [Q empty]
time 10717ms: Process G switching out of CPU; will block on I/O until time 12699ms [Q empty]
time 10739ms: Process F completed I/O; added to ready queue [Q F]
time 10741ms: Process F started using the CPU for 31ms burst [Q empty]
time 10770ms: Process K completed I/O; added to ready queue [Q K]
time 10772ms: Process F completed a CPU burst; 18 bursts to go [Q K]
time 10772ms: Process F switching out of CPU; will block on I/O until time 10984ms [Q K]
time 10776ms: Process K started using the CPU for 199ms burst [Q empty]
time 10853ms: Process E completed I/O; added to ready queue [Q E]
time 10856ms: Process D completed I/O; added to ready queue [Q ED]
time 10933ms: Process B completed I/O; added to ready queue [Q EDB]
time 10975ms: Process K completed a CPU burst; 1 burst to go [Q EDB]
time 10975ms: Process K switching out of CPU; will block on I/O until time 11627ms [Q EDB]
time 10979ms: Process E started using the CPU for 54ms burst [Q DB]
time 10984ms: Process F completed I/O; added to ready queue [Q DBF]
time 11033ms: Process E completed a CPU burst; 43 bursts to go [Q DBF]
time 11033ms: Process E switching out of CPU; will block on I/O until time 11985ms [Q DBF]
time 11037ms: Process D started using the CPU for 1ms burst [Q BF]
time 11038ms: Process D terminated [Q BF]
time 11042ms: Process B started using the CPU for 134ms burst [Q F]
time 11176ms: Process B completed a CPU burst; 8 bursts to go [Q F]
time 11176ms: Process B switching out of CPU; will block on I/O until time 11498ms [Q F]
time 11180ms: Process F started using the CPU for 24ms burst [Q empty]
time 11204ms: Process F completed a CPU burst; 17 bursts to go [Q empty]
time 11204ms: Process F switching out of CPU; will block on I/O until time 11796ms [Q empty]
time 11229ms: Process A completed I/O; added to ready queue [Q A]
time 11231ms: Process A started using the CPU for 62ms burst [Q empty]
time 11293ms: Process A completed a CPU burst; 2 bursts to go [Q empty]
time 11293ms: Process A switching out of CPU; will block on I/O until time 12065ms [Q empty]
time 11318ms: Process H completed I/O; added to ready queue [Q H]
time 11320ms: Process H started using the CPU for 76ms burst [Q empty]
time 11396ms: Process H completed a CPU burst; 69 bursts to go [Q empty]
time 11396ms: Process H switching out of CPU; will block on I/O until time 13518ms [Q empty]
time 11498ms: Process B completed I/O; added to ready queue [Q B]
time 11500ms: Process B started using the CPU for 144ms burst [Q empty]
time 11627ms: Process K completed I/O; added to ready queue [Q K]
time 11644ms: Process B completed a CPU burst; 7 bursts to go [Q K]
time 11644ms: Process B switching out of CPU; will block on I/O until time 12436ms [Q K]
time 11648ms: Process K started using the CPU for 47ms burst [Q empty]
time 11695ms: Process K terminated [Q empty]
time 11796ms: Process F completed I/O; added to ready queue [Q F]
time 11798ms: Process F started using the CPU for 135ms burst [Q empty]
time 11933ms: Process F completed a CPU burst; 16 bursts to go [Q empty]
time 11933ms: Process F switching out of CPU; will block on I/O until time 12555ms [Q empty]
time 11944ms: Process I completed I/O; added to ready queue [Q I]
time 11946ms: Process I started using the CPU for 107ms burst [Q empty]
time 11985ms: Process E completed I/O; added to ready queue [Q E]
time 12053ms: Process I completed a CPU burst; 67 bursts to go [Q E]
time 12053ms: Process I switching out of CPU; will block on I/O until time 12525ms [Q E]
time 12057ms: Process E started using the CPU for 126ms burst [Q empty]
time 12065ms: Process A completed I/O; added to ready queue [Q A]
time 12183ms: Process E completed a CPU burst; 42 bursts to go [Q A]
time 12183ms: Process E switching out of CPU; will block on I/O until time 14165ms [Q A]
time 12187ms: Process A started using the CPU for 200ms burst [Q empty]
time 12387ms: Process A completed a CPU burst; 1 burst to go [Q empty]
time 12387ms: Process A switching out of CPU; will block on I/O until time 12499ms [Q empty]
time 12436ms: Process B completed I/O; added to ready queue [Q B]
time 12438ms: Process B started using the CPU for 183ms burst [Q empty]
time 12499ms: Process A completed I/O; added to ready queue [Q A]
time 12525ms: Process I completed I/O; added to ready queue [Q AI]
time 12555ms: Process F completed I/O; added to ready queue [Q AIF]
time 12621ms: Process B completed a CPU burst; 6 bursts to go [Q AIF]
time 12621ms: Process B switching out of CPU; will block on I/O until time 12683ms [Q AIF]
time 12625ms: Process A started using the CPU for 197ms burst [Q IF]
time 12683ms: Process B completed I/O; added to ready queue [Q IFB]
time 12699ms: Process G completed I/O; added to ready queue [Q IFBG]
time 12822ms: Process A terminated [Q IFBG]
time 12826ms: Process I started using the CPU for 21ms burst [Q FBG]
time 12847ms: Process I completed a CPU burst; 66 bursts to go [Q FBG]
time 12847ms: Process I switching out of CPU; will block on I/O until time 12939ms [Q FBG]
time 12851ms: Process F started using the CPU for 87ms burst [Q BG]
time 12938ms: Process F completed a CPU burst; 15 bursts to go [Q BG]
time 12938ms: Process F switching out of CPU; will block on I/O until time 13980ms [Q BG]
time 12939ms: Process I completed I/O; added to ready queue [Q BGI]
time 12942ms: Process B started using the CPU for 219ms burst [Q GI]
time 13161ms: Process B completed a CPU burst; 5 bursts to go [Q GI]
time 13161ms: Process B switching out of CPU; will block on I/O until time 13393ms [Q GI]
time 13165ms: Process G started using the CPU for 122ms burst [Q I]
time 13287ms: Process G completed a CPU burst; 69 bursts to go [Q I]
time 13287ms: Process G switching out of CPU; will block on I/O until time 13639ms [Q I]
time 13291ms: Process I started using the CPU for 179ms burst [Q empty]
time 13393ms: Process B completed I/O; added to ready queue [Q B]
time 13470ms: Process I completed a CPU burst; 65 bursts to go [Q B]
time 13470ms: Process I switching out of CPU; will block on I/O until time 14472ms [Q B]
time 13474ms: Process B started using the CPU for 64ms burst [Q empty]
time 13518ms: Process H completed I/O; added to ready queue [Q H]
time 13538ms: Process B completed a CPU burst; 4 bursts to go [Q H]
time 13538ms: Process B switching out of CPU; will block on I/O until time 14340ms [Q H]
time 13542ms: Process H started using the CPU for 143ms burst [Q empty]
time 13639ms: Process G completed I/O; added to ready queue [Q G]
time 13685ms: Process H completed a CPU burst; 68 bursts to go [Q G]
time 13685ms: Process H switching out of CPU; will block on I/O until time 15527ms [Q G]
time 13689ms: Process G started using the CPU for 31ms burst [Q empty]
time 13720ms: Process G completed a CPU burst; 68 bursts to go [Q empty]
time 13720ms: Process G switching out of CPU; will block on I/O until time 13792ms [Q empty]
time 13792ms: Process G completed I/O; added to ready queue [Q G]
time 13794ms: Process G started using the CPU for 61ms burst [Q empty]
time 13855ms: Process G completed a CPU burst; 67 bursts to go [Q empty]
time 13855ms: Process G switching out of CPU; will block on I/O until time 14597ms [Q empty]
time 13980ms: Process F completed I/O; added to ready queue [Q F]
time 13982ms: Process F started using the CPU for 22ms burst [Q empty]
time 14004ms: Process F completed a CPU burst; 14 bursts to go [Q empty]
time 14004ms: Process F switching out of CPU; will block on I/O until time 14156ms [Q empty]
time 14156ms: Process F completed I/O; added to ready queue [Q F]
time 14158ms: Process F started using the CPU for 52ms burst [Q empty]
time 14165ms: Process E completed I/O; added to ready queue [Q E]
time 14210ms: Process F completed a CPU burst; 13 bursts to go [Q E]
time 14210ms: Process F switching out of CPU; will block on I/O until time 14302ms [Q E]
time 14214ms: Process E started using the CPU for 168ms burst [Q empty]
time 14302ms: Process F completed I/O; added to ready queue [Q F]
time 14340ms: Process B completed I/O; added to ready queue [Q FB]
time 14382ms: Process E completed a CPU burst; 41 bursts to go [Q FB]
time 14382ms: Process E switching out of CPU; will block on I/O until time 14884ms [Q FB]
time 14386ms: Process F started using the CPU for 90ms burst [Q B]
time 14472ms: Process I completed I/O; added to ready queue [Q BI]
time 14476ms: Process F completed a CPU burst; 12 bursts to go [Q BI]
time 14476ms: Process F switching out of CPU; will block on I/O until time 16688ms [Q BI]
time 14480ms: Process B started using the CPU for 33ms burst [Q I]
time 14513ms: Process B completed a CPU burst; 3 bursts to go [Q I]
time 14513ms: Process B switching out of CPU; will block on I/O until time 15255ms [Q I]
time 14517ms: Process I started using the CPU for 65ms burst [Q empty]
time 14582ms: Process I completed a CPU burst; 64 bursts to go [Q empty]
time 14582ms: Process I switching out of CPU; will block on I/O until time 14904ms [Q empty]
time 14597ms: Process G completed I/O; added to ready queue [Q G]
time 14599ms: Process G started using the CPU for 7ms burst [Q empty]
time 14606ms: Process G completed a CPU burst; 66 bursts to go [Q empty]
time 14606ms: Process G switching out of CPU; will block on I/O until time 16248ms [Q empty]
time 14884ms: Process E completed I/O; added to ready queue [Q E]
time 14886ms: Process E started using the CPU for 23ms burst [Q empty]
time 14904ms: Process I completed I/O; added to ready queue [Q I]
time 14909ms: Process E completed a CPU burst; 40 bursts to go [Q I]
time 14909ms: Process E switching out of CPU; will block on I/O until time 15001ms [Q I]
time 14913ms: Process I started using the CPU for 58ms burst [Q empty]
time 14971ms: Process I completed a CPU burst; 63 bursts to go [Q empty]
time 14971ms: Process I switching out of CPU; will block on I/O until time 16713ms [Q empty]
time 15001ms: Process E completed I/O; added to ready queue [Q E]
time 15003ms: Process E started using the CPU for 68ms burst [Q empty]
time 15071ms: Process E completed a CPU burst; 39 bursts to go [Q empty]
time 15071ms: Process E switching out of CPU; will block on I/O until time 15653ms [Q empty]
time 15255ms: Process B completed I/O; added to ready queue [Q B]
time 15257ms: Process B started using the CPU for 63ms burst [Q empty]
time 15320ms: Process B completed a CPU burst; 2 bursts to go [Q empty]
time 15320ms: Process B switching out of CPU; will block on I/O until time 17632ms [Q empty]
time 15527ms: Process H completed I/O; added to ready queue [Q H]
time 15529ms: Process H started using the CPU for 32ms burst [Q empty]
time 15561ms: Process H completed a CPU burst; 67 bursts to go [Q empty]
time 15561ms: Process H switching out of CPU; will block on I/O until time 16383ms [Q empty]
time 15653ms: Process E completed I/O; added to ready queue [Q E]
time 15655ms: Process E started using the CPU for 41ms burst [Q empty]
time 15696ms: Process E completed a CPU burst; 38 bursts to go [Q empty]
time 15696ms: Process E switching out of CPU; will block on I/O until time 15898ms [Q empty]
time 15898ms: Process E completed I/O; added to ready queue [Q E]
time 15900ms: Process E started using the CPU for 44ms burst [Q empty]
time 15944ms: Process E completed a CPU burst; 37 bursts to go [Q empty]
time 15944ms: Process E switching out of CPU; will block on I/O until time 16556ms [Q empty]
time 16248ms: Process G completed I/O; added to ready queue [Q G]
time 16250ms: Process G started using the CPU for 2ms burst [Q empty]
time 16252ms: Process G completed a CPU burst; 65 bursts to go [Q empty]
time 16252ms: Process G switching out of CPU; will block on I/O until time 16364ms [Q empty]
time 16364ms: Process G completed I/O; added to ready queue [Q G]
time 16366ms: Process G started using the CPU for 209ms burst [Q empty]
time 16383ms: Process H completed I/O; added to ready queue [Q H]
time 16556ms: Process E completed I/O; added to ready queue [Q HE]
time 16575ms: Process G completed a CPU burst; 64 bursts to go [Q HE]
time 16575ms: Process G switching out of CPU; will block on I/O until time 17057ms [Q HE]
time 16579ms: Process H started using the CPU for 78ms burst [Q E]
time 16657ms: Process H completed a CPU burst; 66 bursts to go [Q E]
time 16657ms: Process H switching out of CPU; will block on I/O until time 16719ms [Q E]
time 16661ms: Process E started using the CPU for 74ms burst [Q empty]
time 16688ms: Process F completed I/O; added to ready queue [Q F]
time 16713ms: Process I completed I/O; added to ready queue [Q FI]
time 16719ms: Process H completed I/O; added to ready queue [Q FIH]
time 16735ms: Process E completed a CPU burst; 36 bursts to go [Q FIH]
time 16735ms: Process E switching out of CPU; will block on I/O until time 18597ms [Q FIH]
time 16739ms: Process F started using the CPU for 4ms burst [Q IH]
time 16743ms: Process F completed a CPU burst; 11 bursts to go [Q IH]
time 16743ms: Process F switching out of CPU; will block on I/O until time 17295ms [Q IH]
time 16747ms: Process I started using the CPU for 95ms burst [Q H]
time 16842ms: Process I completed a CPU burst; 62 bursts to go [Q H]
time 16842ms: Process I switching out of CPU; will block on I/O until time 18264ms [Q H]
time 16846ms: Process H started using the CPU for 16ms burst [Q empty]
time 16862ms: Process H completed a CPU burst; 65 bursts to go [Q empty]
time 16862ms: Process H switching out of CPU; will block on I/O until time 17414ms [Q empty]
time 17057ms: Process G completed I/O; added to ready queue [Q G]
time 17059ms: Process G started using the CPU for 6ms burst [Q empty]
time 17065ms: Process G completed a CPU burst; 63 bursts to go [Q empty]
time 17065ms: Process G switching out of CPU; will block on I/O until time 18547ms [Q empty]
time 17295ms: Process F completed I/O; added to ready queue [Q F]
time 17297ms: Process F started using the CPU for 30ms burst [Q empty]
time 17327ms: Process F completed a CPU burst; 10 bursts to go [Q empty]
time 17327ms: Process F switching out of CPU; will block on I/O until time 17789ms [Q empty]
time 17414ms: Process H completed I/O; added to ready queue [Q H]
time 17416ms: Process H started using the CPU for 142ms burst [Q empty]
time 17558ms: Process H completed a CPU burst; 64 bursts to go [Q empty]
time 17558ms: Process H switching out of CPU; will block on I/O until time 18530ms [Q empty]
time 17632ms: Process B completed I/O; added to ready queue [Q B]
time 17634ms: Process B started using the CPU for 170ms burst [Q empty]
time 17789ms: Process F completed I/O; added to ready queue [Q F]
time 17804ms: Process B completed a CPU burst; 1 burst to go [Q F]
time 17804ms: Process B switching out of CPU; will block on I/O until time 18376ms [Q F]
time 17808ms: Process F started using the CPU for 183ms burst [Q empty]
time 17991ms: Process F completed a CPU burst; 9 bursts to go [Q empty]
time 17991ms: Process F switching out of CPU; will block on I/O until time 18403ms [Q empty]
time 18264ms: Process I completed I/O; added to ready queue [Q I]
time 18266ms: Process I started using the CPU for 78ms burst [Q empty]
time 18344ms: Process I completed a CPU burst; 61 bursts to go [Q empty]
time 18344ms: Process I switching out of CPU; will block on I/O until time 19116ms [Q empty]
time 18376ms: Process B completed I/O; added to ready queue [Q B]
time 18378ms: Process B started using the CPU for 212ms burst [Q empty]
time 18403ms: Process F completed I/O; added to ready queue [Q F]
time 18530ms: Process H completed I/O; added to ready queue [Q FH]
time 18547ms: Process G completed I/O; added to ready queue [Q FHG]
time 18590ms: Process B terminated [Q FHG]
time 18594ms: Process F started using the CPU for 21ms burst [Q HG]
time 18597ms: Process E completed I/O; added to ready queue [Q HGE]
time 18615ms: Process F completed a CPU burst; 8 bursts to go [Q HGE]
time 18615ms: Process F switching out of CPU; will block on I/O until time 19787ms [Q HGE]
time 18619ms: Process H started using the CPU for 62ms burst [Q GE]
time 18681ms: Process H completed a CPU burst; 63 bursts to go [Q GE]
time 18681ms: Process H switching out of CPU; will block on I/O until time 18933ms [Q GE]
time 18685ms: Process G started using the CPU for 37ms burst [Q E]
time 18722ms: Process G completed a CPU burst; 62 bursts to go [Q E]
time 18722ms: Process G switching out of CPU; will block on I/O until time 20034ms [Q E]
time 18726ms: Process E started using the CPU for 117ms burst [Q empty]
time 18843ms: Process E completed a CPU burst; 35 bursts to go [Q empty]
time 18843ms: Process E switching out of CPU; will block on I/O until time 19845ms [Q empty]
time 18933ms: Process H completed I/O; added to ready queue [Q H]
time 18935ms: Process H started using the CPU for 248ms burst [Q empty]
time 19116ms: Process I completed I/O; added to ready queue [Q I]
time 19183ms: Process H completed a CPU burst; 62 bursts to go [Q I]
time 19183ms: Process H switching out of CPU; will block on I/O until time 20005ms [Q I]
time 19187ms: Process I started using the CPU for 31ms burst [Q empty]
time 19218ms: Process I completed a CPU burst; 60 bursts to go [Q empty]
time 19218ms: Process I switching out of CPU; will block on I/O until time 20310ms [Q empty]
time 19787ms: Process F completed I/O; added to ready queue [Q F]
time 19789ms: Process F started using the CPU for 101ms burst [Q empty]
time 19845ms: Process E completed I/O; added to ready queue [Q E]
time 19890ms: Process F completed a CPU burst; 7 bursts to go [Q E]
time 19890ms: Process F switching out of CPU; will block on I/O until time 20792ms [Q E]
time 19894ms: Process E started using the CPU for 14ms burst [Q empty]
time 19908ms: Process E completed a CPU burst; 34 bursts to go [Q empty]
time 19908ms: Process E switching out of CPU; will block on I/O until time 19930ms [Q empty]
time 19930ms: Process E completed I/O; added to ready queue [Q E]
time 19932ms: Process E started using the CPU for 156ms burst [Q empty]
time 20005ms: Process H completed I/O; added to ready queue [Q H]
time 20034ms: Process G completed I/O; added to ready queue [Q HG]
time 20088ms: Process E completed a CPU burst; 33 bursts to go [Q HG]
time 20088ms: Process E switching out of CPU; will block on I/O until time 21090ms [Q HG]
time 20092ms: Process H started using the CPU for 37ms burst [Q G]
time 20129ms: Process H completed a CPU burst; 61 bursts to go [Q G]
time 20129ms: Process H switching out of CPU; will block on I/O until time 20161ms [Q G]
time 20133ms: Process G started using the CPU for 15ms burst [Q empty]
time 20148ms: Process G completed a CPU burst; 61 bursts to go [Q empty]
time 20148ms: Process G switching out of CPU; will block on I/O until time 20370ms [Q empty]
time 20161ms: Process H completed I/O; added to ready queue [Q H]
time 20163ms: Process H started using the CPU for 10ms burst [Q empty]
time 20173ms: Process H completed a CPU burst; 60 bursts to go [Q empty]
time 20173ms: Process H switching out of CPU; will block on I/O until time 20235ms [Q empty]
time 20235ms: Process H completed I/O; added to ready queue [Q H]
time 20237ms: Process H started using the CPU for 189ms burst [Q empty]
time 20310ms: Process I completed I/O; added to ready queue [Q I]
time 20370ms: Process G completed I/O; added to ready queue [Q IG]
time 20426ms: Process H completed a CPU burst; 59 bursts to go [Q IG]
time 20426ms: Process H switching out of CPU; will block on I/O until time 20908ms [Q IG]
time 20430ms: Process I started using the CPU for 97ms burst [Q G]
time 20527ms: Process I completed a CPU burst; 59 bursts to go [Q G]
time 20527ms: Process I switching out of CPU; will block on I/O until time 20709ms [Q G]
time 20531ms: Process G started using the CPU for 47ms burst [Q empty]
time 20578ms: Process G completed a CPU burst; 60 bursts to go [Q empty]
time 20578ms: Process G switching out of CPU; will block on I/O until time 21340ms [Q empty]
time 20709ms: Process I completed I/O; added to ready queue [Q I]
time 20711ms: Process I started using the CPU for 103ms burst [Q empty]
time 20792ms: Process F completed I/O; added to ready queue [Q F]
time 20814ms: Process I completed a CPU burst; 58 bursts to go [Q F]
time 20814ms: Process I switching out of CPU; will block on I/O until time 21686ms [Q F]
time 20818ms: Process F started using the CPU for 2ms burst [Q empty]
time 20820ms: Process F completed a CPU burst; 6 bursts to go [Q empty]
time 20820ms: Process F switching out of CPU; will block on I/O until time 22932ms [Q empty]
time 20908ms: Process H completed I/O; added to ready queue [Q H]
time 20910ms: Process H started using the CPU for 134ms burst [Q empty]
time 21044ms: Process H completed a CPU burst; 58 bursts to go [Q empty]
time 21044ms: Process H switching out of CPU; will block on I/O until time 21376ms [Q empty]
time 21090ms: Process E completed I/O; added to ready queue [Q E]
time 21092ms: Process E started using the CPU for 18ms burst [Q empty]
time 21110ms: Process E completed a CPU burst; 32 bursts to go [Q empty]
time 21110ms: Process E switching out of CPU; will block on I/O until time 21552ms [Q empty]
time 21340ms: Process G completed I/O; added to ready queue [Q G]
time 21342ms: Process G started using the CPU for 82ms burst [Q empty]
time 21376ms: Process H completed I/O; added to ready queue [Q H]
time 21424ms: Process G completed a CPU burst; 59 bursts to go [Q H]
time 21424ms: Process G switching out of CPU; will block on I/O until time 21456ms [Q H]
time 21428ms: Process H started using the CPU for 25ms burst [Q empty]
time 21453ms: Process H completed a CPU burst; 57 bursts to go [Q empty]
time 21453ms: Process H switching out of CPU; will block on I/O until time 22265ms [Q empty]
time 21456ms: Process G completed I/O; added to ready queue [Q G]
time 21458ms: Process G started using the CPU for 57ms burst [Q empty]
time 21515ms: Process G completed a CPU burst; 58 bursts to go [Q empty]
time 21515ms: Process G switching out of CPU; will block on I/O until time 21727ms [Q empty]
time 21552ms: Process E completed I/O; added to ready queue [Q E]
time 21554ms: Process E started using the CPU for 215ms burst [Q empty]
time 21686ms: Process I completed I/O; added to ready queue [Q I]
time 21727ms: Process G completed I/O; added to ready queue [Q IG]
time 21769ms: Process E completed a CPU burst; 31 bursts to go [Q IG]
time 21769ms: Process E switching out of CPU; will block on I/O until time 21861ms [Q IG]
time 21773ms: Process I started using the CPU for 44ms burst [Q G]
time 21817ms: Process I completed a CPU burst; 57 bursts to go [Q G]
time 21817ms: Process I switching out of CPU; will block on I/O until time 23809ms [Q G]
time 21821ms: Process G started using the CPU for 89ms burst [Q empty]
time 21861ms: Process E completed I/O; added to ready queue [Q E]
time 21910ms: Process G completed a CPU burst; 57 bursts to go [Q E]
time 21910ms: Process G switching out of CPU; will block on I/O until time 22832ms [Q E]
time 21914ms: Process E started using the CPU for 224ms burst [Q empty]
time 22138ms: Process E completed a CPU burst; 30 bursts to go [Q empty]
time 22138ms: Process E switching out of CPU; will block on I/O until time 23220ms [Q empty]
time 22265ms: Process H completed I/O; added to ready queue [Q H]
time 22267ms: Process H started using the CPU for 235ms burst [Q empty]
time 22502ms: Process H completed a CPU burst; 56 bursts to go [Q empty]
time 22502ms: Process H switching out of CPU; will block on I/O until time 24024ms [Q empty]
time 22832ms: Process G completed I/O; added to ready queue [Q G]
time 22834ms: Process G started using the CPU for 3ms burst [Q empty]
time 22837ms: Process G completed a CPU burst; 56 bursts to go [Q empty]
time 22837ms: Process G switching out of CPU; will block on I/O until time 24199ms [Q empty]
time 22932ms: Process F completed I/O; added to ready queue [Q F]
time 22934ms: Process F started using the CPU for 170ms burst [Q empty]
time 23104ms: Process F completed a CPU burst; 5 bursts to go [Q empty]
time 23104ms: Process F switching out of CPU; will block on I/O until time 23686ms [Q empty]
time 23220ms: Process E completed I/O; added to ready queue [Q E]
time 23222ms: Process E started using the CPU for 1ms burst [Q empty]
time 23223ms: Process E completed a CPU burst; 29 bursts to go [Q empty]
time 23223ms: Process E switching out of CPU; will block on I/O until time 23885ms [Q empty]
time 23686ms: Process F completed I/O; added to ready queue [Q F]
time 23688ms: Process F started using the CPU for 154ms burst [Q empty]
time 23809ms: Process I completed I/O; added to ready queue [Q I]
time 23842ms: Process F completed a CPU burst; 4 bursts to go [Q I]
time 23842ms: Process F switching out of CPU; will block on I/O until time 24204ms [Q I]
time 23846ms: Process I started using the CPU for 37ms burst [Q empty]
time 23883ms: Process I completed a CPU burst; 56 bursts to go [Q empty]
time 23883ms: Process I switching out of CPU; will block on I/O until time 24785ms [Q empty]
time 23885ms: Process E completed I/O; added to ready queue [Q E]
time 23887ms: Process E started using the CPU for 168ms burst [Q empty]
time 24024ms: Process H completed I/O; added to ready queue [Q H]
time 24055ms: Process E completed a CPU burst; 28 bursts to go [Q H]
time 24055ms: Process E switching out of CPU; will block on I/O until time 25237ms [Q H]
time 24059ms: Process H started using the CPU for 105ms burst [Q empty]
time 24164ms: Process H completed a CPU burst; 55 bursts to go [Q empty]
time 24164ms: Process H switching out of CPU; will block on I/O until time 24906ms [Q empty]
time 24199ms: Process G completed I/O; added to ready queue [Q G]
time 24201ms: Process G started using the CPU for 11ms burst [Q empty]
time 24204ms: Process F completed I/O; added to ready queue [Q F]
time 24212ms: Process G completed a CPU burst; 55 bursts to go [Q F]
time 24212ms: Process G switching out of CPU; will block on I/O until time 26664ms [Q F]
time 24216ms: Process F started using the CPU for 55ms burst [Q empty]
time 24271ms: Process F completed a CPU burst; 3 bursts to go [Q empty]
time 24271ms: Process F switching out of CPU; will block on I/O until time 25523ms [Q empty]
time 24785ms: Process I completed I/O; added to ready queue [Q I]
time 24787ms: Process I started using the CPU for 1ms burst [Q empty]
time 24788ms: Process I completed a CPU burst; 55 bursts to go [Q empty]
time 24788ms: Process I switching out of CPU; will block on I/O until time 24810ms [Q empty]
time 24810ms: Process I completed I/O; added to ready queue [Q I]
time 24812ms: Process I started using the CPU for 96ms burst [Q empty]
time 24906ms: Process H completed I/O; added to ready queue [Q H]
time 24908ms: Process I completed a CPU burst; 54 bursts to go [Q H]
time 24908ms: Process I switching out of CPU; will block on I/O until time 25100ms [Q H]
time 24912ms: Process H started using the CPU for 75ms burst [Q empty]
time 24987ms: Process H completed a CPU burst; 54 bursts to go [Q empty]
time 24987ms: Process H switching out of CPU; will block on I/O until time 25669ms [Q empty]
time 25100ms: Process I completed I/O; added to ready queue [Q I]
time 25102ms: Process I started using the CPU for 143ms burst [Q empty]
time 25237ms: Process E completed I/O; added to ready queue [Q E]
time 25245ms: Process I completed a CPU burst; 53 bursts to go [Q E]
time 25245ms: Process I switching out of CPU; will block on I/O until time 25977ms [Q E]
time 25249ms: Process E started using the CPU for 10ms burst [Q empty]
time 25259ms: Process E completed a CPU burst; 27 bursts to go [Q empty]
time 25259ms: Process E switching out of CPU; will block on I/O until time 25731ms [Q empty]
time 25523ms: Process F completed I/O; added to ready queue [Q F]
time 25525ms: Process F started using the CPU for 234ms burst [Q empty]
time 25669ms: Process H completed I/O; added to ready queue [Q H]
time 25731ms: Process E completed I/O; added to ready queue [Q HE]
time 25759ms: Process F completed a CPU burst; 2 bursts to go [Q HE]
time 25759ms: Process F switching out of CPU; will block on I/O until time 26031ms [Q HE]
time 25763ms: Process H started using the CPU for 141ms burst [Q E]
time 25904ms: Process H completed a CPU burst; 53 bursts to go [Q E]
time 25904ms: Process H switching out of CPU; will block on I/O until time 25986ms [Q E]
time 25908ms: Process E started using the CPU for 68ms burst [Q empty]
time 25976ms: Process E completed a CPU burst; 26 bursts to go [Q empty]
time 25976ms: Process E switching out of CPU; will block on I/O until time 26528ms [Q empty]
time 25977ms: Process I completed I/O; added to ready queue [Q I]
time 25980ms: Process I started using the CPU for 71ms burst [Q empty]
time 25986ms: Process H completed I/O; added to ready queue [Q H]
time 26031ms: Process F completed I/O; added to ready queue [Q HF]
time 26051ms: Process I completed a CPU burst; 52 bursts to go [Q HF]
time 26051ms: Process I switching out of CPU; will block on I/O until time 26083ms [Q HF]
time 26055ms: Process H started using the CPU for 63ms burst [Q F]
time 26083ms: Process I completed I/O; added to ready queue [Q FI]
time 26118ms: Process H completed a CPU burst; 52 bursts to go [Q FI]
time 26118ms: Process H switching out of CPU; will block on I/O until time 26830ms [Q FI]
time 26122ms: Process F started using the CPU for 122ms burst [Q I]
time 26244ms: Process F completed a CPU burst; 1 burst to go [Q I]
time 26244ms: Process F switching out of CPU; will block on I/O until time 26976ms [Q I]
time 26248ms: Process I started using the CPU for 111ms burst [Q empty]
time 26359ms: Process I completed a CPU burst; 51 bursts to go [Q empty]
time 26359ms: Process I switching out of CPU; will block on I/O until time 27421ms [Q empty]
time 26528ms: Process E completed I/O; added to ready queue [Q E]
time 26530ms: Process E started using the CPU for 30ms burst [Q empty]
time 26560ms: Process E completed a CPU burst; 25 bursts to go [Q empty]
time 26560ms: Process E switching out of CPU; will block on I/O until time 27532ms [Q empty]
time 26664ms: Process G completed I/O; added to ready queue [Q G]
time 26666ms: Process G started using the CPU for 17ms burst [Q empty]
time 26683ms: Process G completed a CPU burst; 54 bursts to go [Q empty]
time 26683ms: Process G switching out of CPU; will block on I/O until time 27335ms [Q empty]
time 26830ms: Process H completed I/O; added to ready queue [Q H]
time 26832ms: Process H started using the CPU for 93ms burst [Q empty]
time 26925ms: Process H completed a CPU burst; 51 bursts to go [Q empty]
time 26925ms: Process H switching out of CPU; will block on I/O until time 27567ms [Q empty]
time 26976ms: Process F completed I/O; added to ready queue [Q F]
time 26978ms: Process F started using the CPU for 55ms burst [Q empty]
time 27033ms: Process F terminated [Q empty]
time 27335ms: Process G completed I/O; added to ready queue [Q G]
time 27337ms: Process G started using the CPU for 55ms burst [Q empty]
time 27392ms: Process G completed a CPU burst; 53 bursts to go [Q empty]
time 27392ms: Process G switching out of CPU; will block on I/O until time 29434ms [Q empty]
time 27421ms: Process I completed I/O; added to ready queue [Q I]
time 27423ms: Process I started using the CPU for 81ms burst [Q empty]
time 27504ms: Process I completed a CPU burst; 50 bursts to go [Q empty]
time 27504ms: Process I switching out of CPU; will block on I/O until time 28486ms [Q empty]
time 27532ms: Process E completed I/O; added to ready queue [Q E]
time 27534ms: Process E started using the CPU for 54ms burst [Q empty]
time 27567ms: Process H completed I/O; added to ready queue [Q H]
time 27588ms: Process E completed a CPU burst; 24 bursts to go [Q H]
time 27588ms: Process E switching out of CPU; will block on I/O until time 29820ms [Q H]
time 27592ms: Process H started using the CPU for 37ms burst [Q empty]
time 27629ms: Process H completed a CPU burst; 50 bursts to go [Q empty]
time 27629ms: Process H switching out of CPU; will block on I/O until time 27801ms [Q empty]
time 27801ms: Process H completed I/O; added to ready queue [Q H]
time 27803ms: Process H started using the CPU for 20ms burst [Q empty]
time 27823ms: Process H completed a CPU burst; 49 bursts to go [Q empty]
time 27823ms: Process H switching out of CPU; will block on I/O until time 27845ms [Q empty]
time 27845ms: Process H completed I/O; added to ready queue [Q H]
time 27847ms: Process H started using the CPU for 148ms burst [Q empty]
time 27995ms: Process H completed a CPU burst; 48 bursts to go [Q empty]
time 27995ms: Process H switching out of CPU; will block on I/O until time 28207ms [Q empty]
time 28207ms: Process H completed I/O; added to ready queue [Q H]
time 28209ms: Process H started using the CPU for 141ms burst [Q empty]
time 28350ms: Process H completed a CPU burst; 47 bursts to go [Q empty]
time 28350ms: Process H switching out of CPU; will block on I/O until time 28572ms [Q empty]
time 28486ms: Process I completed I/O; added to ready queue [Q I]
time 28488ms: Process I started using the CPU for 55ms burst [Q empty]
time 28543ms: Process I completed a CPU burst; 49 bursts to go [Q empty]
time 28543ms: Process I switching out of CPU; will block on I/O until time 28745ms [Q empty]
time 28572ms: Process H completed I/O; added to ready queue [Q H]
time 28574ms: Process H started using the CPU for 86ms burst [Q empty]
time 28660ms: Process H completed a CPU burst; 46 bursts to go [Q empty]
time 28660ms: Process H switching out of CPU; will block on I/O until time 29382ms [Q empty]
time 28745ms: Process I completed I/O; added to ready queue [Q I]
time 28747ms: Process I started using the CPU for 151ms burst [Q empty]
time 28898ms: Process I completed a CPU burst; 48 bursts to go [Q empty]
time 28898ms: Process I switching out of CPU; will block on I/O until time 29400ms [Q empty]
time 29382ms: Process H completed I/O; added to ready queue [Q H]
time 29384ms: Process H started using the CPU for 192ms burst [Q empty]
time 29400ms: Process I completed I/O; added to ready queue [Q I]
time 29434ms: Process G completed I/O; added to ready queue [Q IG]
time 29576ms: Process H completed a CPU burst; 45 bursts to go [Q IG]
time 29576ms: Process H switching out of CPU; will block on I/O until time 29708ms [Q IG]
time 29580ms: Process I started using the CPU for 62ms burst [Q G]
time 29642ms: Process I completed a CPU burst; 47 bursts to go [Q G]
time 29642ms: Process I switching out of CPU; will block on I/O until time 30194ms [Q G]
time 29646ms: Process G started using the CPU for 52ms burst [Q empty]
time 29698ms: Process G completed a CPU burst; 52 bursts to go [Q empty]
time 29698ms: Process G switching out of CPU; will block on I/O until time 30660ms [Q empty]
time 29708ms: Process H completed I/O; added to ready queue [Q H]
time 29710ms: Process H started using the CPU for 109ms burst [Q empty]
time 29819ms: Process H completed a CPU burst; 44 bursts to go [Q empty]
time 29819ms: Process H switching out of CPU; will block on I/O until time 30261ms [Q empty]
time 29820ms: Process E completed I/O; added to ready queue [Q E]
time 29823ms: Process E started using the CPU for 46ms burst [Q empty]
time 29869ms: Process E completed a CPU burst; 23 bursts to go [Q empty]
time 29869ms: Process E switching out of CPU; will block on I/O until time 31191ms [Q empty]
time 30194ms: Process I completed I/O; added to ready queue [Q I]
time 30196ms: Process I started using the CPU for 18ms burst [Q empty]
time 30214ms: Process I completed a CPU burst; 46 bursts to go [Q empty]
time 30214ms: Process I switching out of CPU; will block on I/O until time 30686ms [Q empty]
time 30261ms: Process H completed I/O; added to ready queue [Q H]
time 30263ms: Process H started using the CPU for 95ms burst [Q empty]
time 30358ms: Process H completed a CPU burst; 43 bursts to go [Q empty]
time 30358ms: Process H switching out of CPU; will block on I/O until time 30640ms [Q empty]
time 30640ms: Process H completed I/O; added to ready queue [Q H]
time 30642ms: Process H started using the CPU for 30ms burst [Q empty]
time 30660ms: Process G completed I/O; added to ready queue [Q G]
time 30672ms: Process H completed a CPU burst; 42 bursts to go [Q G]
time 30672ms: Process H switching out of CPU; will block on I/O until time 30864ms [Q G]
time 30676ms: Process G started using the CPU for 199ms burst [Q empty]
time 30686ms: Process I completed I/O; added to ready queue [Q I]
time 30864ms: Process H completed I/O; added to ready queue [Q IH]
time 30875ms: Process G completed a CPU burst; 51 bursts to go [Q IH]
time 30875ms: Process G switching out of CPU; will block on I/O until time 30977ms [Q IH]
time 30879ms: Process I started using the CPU for 220ms burst [Q H]
time 30977ms: Process G completed I/O; added to ready queue [Q HG]
time 31099ms: Process I completed a CPU burst; 45 bursts to go [Q HG]
time 31099ms: Process I switching out of CPU; will block on I/O until time 33481ms [Q HG]
time 31103ms: Process H started using the CPU for 21ms burst [Q G]
time 31124ms: Process H completed a CPU burst; 41 bursts to go [Q G]
time 31124ms: Process H switching out of CPU; will block on I/O until time 31146ms [Q G]
time 31128ms: Process G started using the CPU for 35ms burst [Q empty]
time 31146ms: Process H completed I/O; added to ready queue [Q H]
time 31163ms: Process G completed a CPU burst; 50 bursts to go [Q H]
time 31163ms: Process G switching out of CPU; will block on I/O until time 31875ms [Q H]
time 31167ms: Process H started using the CPU for 71ms burst [Q empty]
time 31191ms: Process E completed I/O; added to ready queue [Q E]
time 31238ms: Process H completed a CPU burst; 40 bursts to go [Q E]
time 31238ms: Process H switching out of CPU; will block on I/O until time 31500ms [Q E]
time 31242ms: Process E started using the CPU for 163ms burst [Q empty]
time 31405ms: Process E completed a CPU burst; 22 bursts to go [Q empty]
time 31405ms: Process E switching out of CPU; will block on I/O until time 31777ms [Q empty]
time 31500ms: Process H completed I/O; added to ready queue [Q H]
time 31502ms: Process H started using the CPU for 27ms burst [Q empty]
time 31529ms: Process H completed a CPU burst; 39 bursts to go [Q empty]
time 31529ms: Process H switching out of CPU; will block on I/O until time 32021ms [Q empty]
time 31777ms: Process E completed I/O; added to ready queue [Q E]
time 31779ms: Process E started using the CPU for 106ms burst [Q empty]
time 31875ms: Process G completed I/O; added to ready queue [Q G]
time 31885ms: Process E completed a CPU burst; 21 bursts to go [Q G]
time 31885ms: Process E switching out of CPU; will block on I/O until time 31907ms [Q G]
time 31889ms: Process G started using the CPU for 44ms burst [Q empty]
time 31907ms: Process E completed I/O; added to ready queue [Q E]
time 31933ms: Process G completed a CPU burst; 49 bursts to go [Q E]
time 31933ms: Process G switching out of CPU; will block on I/O until time 32175ms [Q E]
time 31937ms: Process E started using the CPU for 86ms burst [Q empty]
time 32021ms: Process H completed I/O; added to ready queue [Q H]
time 32023ms: Process E completed a CPU burst; 20 bursts to go [Q H]
time 32023ms: Process E switching out of CPU; will block on I/O until time 33045ms [Q H]
time 32027ms: Process H started using the CPU for 17ms burst [Q empty]
time 32044ms: Process H completed a CPU burst; 38 bursts to go [Q empty]
time 32044ms: Process H switching out of CPU; will block on I/O until time 33896ms [Q empty]
time 32175ms: Process G completed I/O; added to ready queue [Q G]
time 32177ms: Process G started using the CPU for 27ms burst [Q empty]
time 32204ms: Process G completed a CPU burst; 48 bursts to go [Q empty]
time 32204ms: Process G switching out of CPU; will block on I/O until time 33436ms [Q empty]
time 33045ms: Process E completed I/O; added to ready queue [Q E]
time 33047ms: Process E started using the CPU for 123ms burst [Q empty]
time 33170ms: Process E completed a CPU burst; 19 bursts to go [Q empty]
time 33170ms: Process E switching out of CPU; will block on I/O until time 33292ms [Q empty]
time 33292ms: Process E completed I/O; added to ready queue [Q E]
time 33294ms: Process E started using the CPU for 7ms burst [Q empty]
time 33301ms: Process E completed a CPU burst; 18 bursts to go [Q empty]
time 33301ms: Process E switching out of CPU; will block on I/O until time 35283ms [Q empty]
time 33436ms: Process G completed I/O; added to ready queue [Q G]
time 33438ms: Process G started using the CPU for 171ms burst [Q empty]
time 33481ms: Process I completed I/O; added to ready queue [Q I]
time 33609ms: Process G completed a CPU burst; 47 bursts to go [Q I]
time 33609ms: Process G switching out of CPU; will block on I/O until time 33901ms [Q I]
time 33613ms: Process I started using the CPU for 133ms burst [Q empty]
time 33746ms: Process I completed a CPU burst; 44 bursts to go [Q empty]
time 33746ms: Process I switching out of CPU; will block on I/O until time 33858ms [Q empty]
time 33858ms: Process I completed I/O; added to ready queue [Q I]
time 33860ms: Process I started using the CPU for 176ms burst [Q empty]
time 33896ms: Process H completed I/O; added to ready queue [Q H]
time 33901ms: Process G completed I/O; added to ready queue [Q HG]
time 34036ms: Process I completed a CPU burst; 43 bursts to go [Q HG]
time 34036ms: Process I switching out of CPU; will block on I/O until time 34218ms [Q HG]
time 34040ms: Process H started using the CPU for 34ms burst [Q G]
time 34074ms: Process H completed a CPU burst; 37 bursts to go [Q G]
time 34074ms: Process H switching out of CPU; will block on I/O until time 34886ms [Q G]
time 34078ms: Process G started using the CPU for 3ms burst [Q empty]
time 34081ms: Process G completed a CPU burst; 46 bursts to go [Q empty]
time 34081ms: Process G switching out of CPU; will block on I/O until time 35383ms [Q empty]
time 34218ms: Process I completed I/O; added to ready queue [Q I]
time 34220ms: Process I started using the CPU for 151ms burst [Q empty]
time 34371ms: Process I completed a CPU burst; 42 bursts to go [Q empty]
time 34371ms: Process I switching out of CPU; will block on I/O until time 34833ms [Q empty]
time 34833ms: Process I completed I/O; added to ready queue [Q I]
time 34835ms: Process I started using the CPU for 106ms burst [Q empty]
time 34886ms: Process H completed I/O; added to ready queue [Q H]
time 34941ms: Process I completed a CPU burst; 41 bursts to go [Q H]
time 34941ms: Process I switching out of CPU; will block on I/O until time 35453ms [Q H]
time 34945ms: Process H started using the CPU for 45ms burst [Q empty]
time 34990ms: Process H completed a CPU burst; 36 bursts to go [Q empty]
time 34990ms: Process H switching out of CPU; will block on I/O until time 37112ms [Q empty]
time 35283ms: Process E completed I/O; added to ready queue [Q E]
time 35285ms: Process E started using the CPU for 113ms burst [Q empty]
time 35383ms: Process G completed I/O; added to ready queue [Q G]
time 35398ms: Process E completed a CPU burst; 17 bursts to go [Q G]
time 35398ms: Process E switching out of CPU; will block on I/O until time 36570ms [Q G]
time 35402ms: Process G started using the CPU for 107ms burst [Q empty]
time 35453ms: Process I completed I/O; added to ready queue [Q I]
time 35509ms: Process G completed a CPU burst; 45 bursts to go [Q I]
time 35509ms: Process G switching out of CPU; will block on I/O until time 35681ms [Q I]
time 35513ms: Process I started using the CPU for 98ms burst [Q empty]
time 35611ms: Process I completed a CPU burst; 40 bursts to go [Q empty]
time 35611ms: Process I switching out of CPU; will block on I/O until time 35753ms [Q empty]
time 35681ms: Process G completed I/O; added to ready queue [Q G]
time 35683ms: Process G started using the CPU for 111ms burst [Q empty]
time 35753ms: Process I completed I/O; added to ready queue [Q I]
time 35794ms: Process G completed a CPU burst; 44 bursts to go [Q I]
time 35794ms: Process G switching out of CPU; will block on I/O until time 36106ms [Q I]
time 35798ms: Process I started using the CPU for 11ms burst [Q empty]
time 35809ms: Process I completed a CPU burst; 39 bursts to go [Q empty]
time 35809ms: Process I switching out of CPU; will block on I/O until time 38131ms [Q empty]
time 36106ms: Process G completed I/O; added to ready queue [Q G]
time 36108ms: Process G started using the CPU for 11ms burst [Q empty]
time 36119ms: Process G completed a CPU burst; 43 bursts to go [Q empty]
time 36119ms: Process G switching out of CPU; will block on I/O until time 36901ms [Q empty]
time 36570ms: Process E completed I/O; added to ready queue [Q E]
time 36572ms: Process E started using the CPU for 104ms burst [Q empty]
time 36676ms: Process E completed a CPU burst; 16 bursts to go [Q empty]
time 36676ms: Process E switching out of CPU; will block on I/O until time 37738ms [Q empty]
time 36901ms: Process G completed I/O; added to ready queue [Q G]
time 36903ms: Process G started using the CPU for 28ms burst [Q empty]
time 36931ms: Process G completed a CPU burst; 42 bursts to go [Q empty]
time 36931ms: Process G switching out of CPU; will block on I/O until time 36993ms [Q empty]
time 36993ms: Process G completed I/O; added to ready queue [Q G]
time 36995ms: Process G started using the CPU for 137ms burst [Q empty]
time 37112ms: Process H completed I/O; added to ready queue [Q H]
time 37132ms: Process G completed a CPU burst; 41 bursts to go [Q H]
time 37132ms: Process G switching out of CPU; will block on I/O until time 37684ms [Q H]
time 37136ms: Process H started using the CPU for 57ms burst [Q empty]
time 37193ms: Process H completed a CPU burst; 35 bursts to go [Q empty]
time 37193ms: Process H switching out of CPU; will block on I/O until time 37865ms [Q empty]
time 37684ms: Process G completed I/O; added to ready queue [Q G]
time 37686ms: Process G started using the CPU for 124ms burst [Q empty]
time 37738ms: Process E completed I/O; added to ready queue [Q E]
time 37810ms: Process G completed a CPU burst; 40 bursts to go [Q E]
time 37810ms: Process G switching out of CPU; will block on I/O until time 38562ms [Q E]
time 37814ms: Process E started using the CPU for 28ms burst [Q empty]
time 37842ms: Process E completed a CPU burst; 15 bursts to go [Q empty]
time 37842ms: Process E switching out of CPU; will block on I/O until time 38044ms [Q empty]
time 37865ms: Process H completed I/O; added to ready queue [Q H]
time 37867ms: Process H started using the CPU for 100ms burst [Q empty]
time 37967ms: Process H completed a CPU burst; 34 bursts to go [Q empty]
time 37967ms: Process H switching out of CPU; will block on I/O until time 38339ms [Q empty]
time 38044ms: Process E completed I/O; added to ready queue [Q E]
time 38046ms: Process E started using the CPU for 114ms burst [Q empty]
time 38131ms: Process I completed I/O; added to ready queue [Q I]
time 38160ms: Process E completed a CPU burst; 14 bursts to go [Q I]
time 38160ms: Process E switching out of CPU; will block on I/O until time 38352ms [Q I]
time 38164ms: Process I started using the CPU for 4ms burst [Q empty]
time 38168ms: Process I completed a CPU burst; 38 bursts to go [Q empty]
time 38168ms: Process I switching out of CPU; will block on I/O until time 38360ms [Q empty]
time 38339ms: Process H completed I/O; added to ready queue [Q H]
time 38341ms: Process H started using the CPU for 51ms burst [Q empty]
time 38352ms: Process E completed I/O; added to ready queue [Q E]
time 38360ms: Process I completed I/O; added to ready queue [Q EI]
time 38392ms: Process H completed a CPU burst; 33 bursts to go [Q EI]
time 38392ms: Process H switching out of CPU; will block on I/O until time 38454ms [Q EI]
time 38396ms: Process E started using the CPU for 241ms burst [Q I]
time 38454ms: Process H completed I/O; added to ready queue [Q IH]
time 38562ms: Process G completed I/O; added to ready queue [Q IHG]
time 38637ms: Process E completed a CPU burst; 13 bursts to go [Q IHG]
time 38637ms: Process E switching out of CPU; will block on I/O until time 38769ms [Q IHG]
time 38641ms: Process I started using the CPU for 19ms burst [Q HG]
time 38660ms: Process I completed a CPU burst; 37 bursts to go [Q HG]
time 38660ms: Process I switching out of CPU; will block on I/O until time 39252ms [Q HG]
time 38664ms: Process H started using the CPU for 138ms burst [Q G]
time 38769ms: Process E completed I/O; added to ready queue [Q GE]
time 38802ms: Process H completed a CPU burst; 32 bursts to go [Q GE]
time 38802ms: Process H switching out of CPU; will block on I/O until time 38924ms [Q GE]
time 38806ms: Process G started using the CPU for 108ms burst [Q E]
time 38914ms: Process G completed a CPU burst; 39 bursts to go [Q E]
time 38914ms: Process G switching out of CPU; will block on I/O until time 40086ms [Q E]
time 38918ms: Process E started using the CPU for 10ms burst [Q empty]
time 38924ms: Process H completed I/O; added to ready queue [Q H]
time 38928ms: Process E completed a CPU burst; 12 bursts to go [Q H]
time 38928ms: Process E switching out of CPU; will block on I/O until time 39190ms [Q H]
time 38932ms: Process H started using the CPU for 63ms burst [Q empty]
time 38995ms: Process H completed a CPU burst; 31 bursts to go [Q empty]
time 38995ms: Process H switching out of CPU; will block on I/O until time 39387ms [Q empty]
time 39190ms: Process E completed I/O; added to ready queue [Q E]
time 39192ms: Process E started using the CPU for 106ms burst [Q empty]
time 39252ms: Process I completed I/O; added to ready queue [Q I]
time 39298ms: Process E completed a CPU burst; 11 bursts to go [Q I]
time 39298ms: Process E switching out of CPU; will block on I/O until time 40690ms [Q I]
time 39302ms: Process I started using the CPU for 10ms burst [Q empty]
time 39312ms: Process I completed a CPU burst; 36 bursts to go [Q empty]
time 39312ms: Process I switching out of CPU; will block on I/O until time 40234ms [Q empty]
time 39387ms: Process H completed I/O; added to ready queue [Q H]
time 39389ms: Process H started using the CPU for 126ms burst [Q empty]
time 39515ms: Process H completed a CPU burst; 30 bursts to go [Q empty]
time 39515ms: Process H switching out of CPU; will block on I/O until time 39857ms [Q empty]
time 39857ms: Process H completed I/O; added to ready queue [Q H]
time 39859ms: Process H started using the CPU for 52ms burst [Q empty]
time 39911ms: Process H completed a CPU burst; 29 bursts to go [Q empty]
time 39911ms: Process H switching out of CPU; will block on I/O until time 41583ms [Q empty]
time 40086ms: Process G completed I/O; added to ready queue [Q G]
time 40088ms: Process G started using the CPU for 110ms burst [Q empty]
time 40198ms: Process G completed a CPU burst; 38 bursts to go [Q empty]
time 40198ms: Process G switching out of CPU; will block on I/O until time 41770ms [Q empty]
time 40234ms: Process I completed I/O; added to ready queue [Q I]
time 40236ms: Process I started using the CPU for 126ms burst [Q empty]
time 40362ms: Process I completed a CPU burst; 35 bursts to go [Q empty]
time 40362ms: Process I switching out of CPU; will block on I/O until time 42604ms [Q empty]
time 40690ms: Process E completed I/O; added to ready queue [Q E]
time 40692ms: Process E started using the CPU for 14ms burst [Q empty]
time 40706ms: Process E completed a CPU burst; 10 bursts to go [Q empty]
time 40706ms: Process E switching out of CPU; will block on I/O until time 41008ms [Q empty]
time 41008ms: Process E completed I/O; added to ready queue [Q E]
time 41010ms: Process E started using the CPU for 244ms burst [Q empty]
time 41254ms: Process E completed a CPU burst; 9 bursts to go [Q empty]
time 41254ms: Process E switching out of CPU; will block on I/O until time 41956ms [Q empty]
time 41583ms: Process H completed I/O; added to ready queue [Q H]
time 41585ms: Process H started using the CPU for 88ms burst [Q empty]
time 41673ms: Process H completed a CPU burst; 28 bursts to go [Q empty]
time 41673ms: Process H switching out of CPU; will block on I/O until time 41715ms [Q empty]
time 41715ms: Process H completed I/O; added to ready queue [Q H]
time 41717ms: Process H started using the CPU for 168ms burst [Q empty]
time 41770ms: Process G completed I/O; added to ready queue [Q G]
time 41885ms: Process H completed a CPU burst; 27 bursts to go [Q G]
time 41885ms: Process H switching out of CPU; will block on I/O until time 42337ms [Q G]
time 41889ms: Process G started using the CPU for 77ms burst [Q empty]
time 41956ms: Process E completed I/O; added to ready queue [Q E]
time 41966ms: Process G completed a CPU burst; 37 bursts to go [Q E]
time 41966ms: Process G switching out of CPU; will block on I/O until time 42188ms [Q E]
time 41970ms: Process E started using the CPU for 102ms burst [Q empty]
time 42072ms: Process E completed a CPU burst; 8 bursts to go [Q empty]
time 42072ms: Process E switching out of CPU; will block on I/O until time 42394ms [Q empty]
time 42188ms: Process G completed I/O; added to ready queue [Q G]
time 42190ms: Process G started using the CPU for 187ms burst [Q empty]
time 42337ms: Process H completed I/O; added to ready queue [Q H]
time 42377ms: Process G completed a CPU burst; 36 bursts to go [Q H]
time 42377ms: Process G switching out of CPU; will block on I/O until time 44439ms [Q H]
time 42381ms: Process H started using the CPU for 32ms burst [Q empty]
time 42394ms: Process E completed I/O; added to ready queue [Q E]
time 42413ms: Process H completed a CPU burst; 26 bursts to go [Q E]
time 42413ms: Process H switching out of CPU; will block on I/O until time 44825ms [Q E]
time 42417ms: Process E started using the CPU for 122ms burst [Q empty]
time 42539ms: Process E completed a CPU burst; 7 bursts to go [Q empty]
time 42539ms: Process E switching out of CPU; will block on I/O until time 42791ms [Q empty]
time 42604ms: Process I completed I/O; added to ready queue [Q I]
time 42606ms: Process I started using the CPU for 29ms burst [Q empty]
time 42635ms: Process I completed a CPU burst; 34 bursts to go [Q empty]
time 42635ms: Process I switching out of CPU; will block on I/O until time 42667ms [Q empty]
time 42667ms: Process I completed I/O; added to ready queue [Q I]
time 42669ms: Process I started using the CPU for 94ms burst [Q empty]
time 42763ms: Process I completed a CPU burst; 33 bursts to go [Q empty]
time 42763ms: Process I switching out of CPU; will block on I/O until time 42885ms [Q empty]
time 42791ms: Process E completed I/O; added to ready queue [Q E]
time 42793ms: Process E started using the CPU for 153ms burst [Q empty]
time 42885ms: Process I completed I/O; added to ready queue [Q I]
time 42946ms: Process E completed a CPU burst; 6 bursts to go [Q I]
time 42946ms: Process E switching out of CPU; will block on I/O until time 43348ms [Q I]
time 42950ms: Process I started using the CPU for 11ms burst [Q empty]
time 42961ms: Process I completed a CPU burst; 32 bursts to go [Q empty]
time 42961ms: Process I switching out of CPU; will block on I/O until time 44843ms [Q empty]
time 43348ms: Process E completed I/O; added to ready queue [Q E]
time 43350ms: Process E started using the CPU for 8ms burst [Q empty]
time 43358ms: Process E completed a CPU burst; 5 bursts to go [Q empty]
time 43358ms: Process E switching out of CPU; will block on I/O until time 44090ms [Q empty]
time 44090ms: Process E completed I/O; added to ready queue [Q E]
time 44092ms: Process E started using the CPU for 5ms burst [Q empty]
time 44097ms: Process E completed a CPU burst; 4 bursts to go [Q empty]
time 44097ms: Process E switching out of CPU; will block on I/O until time 44609ms [Q empty]
time 44439ms: Process G completed I/O; added to ready queue [Q G]
time 44441ms: Process G started using the CPU for 62ms burst [Q empty]
time 44503ms: Process G completed a CPU burst; 35 bursts to go [Q empty]
time 44503ms: Process G switching out of CPU; will block on I/O until time 44725ms [Q empty]
time 44609ms: Process E completed I/O; added to ready queue [Q E]
time 44611ms: Process E started using the CPU for 60ms burst [Q empty]
time 44671ms: Process E completed a CPU burst; 3 bursts to go [Q empty]
time 44671ms: Process E switching out of CPU; will block on I/O until time 44943ms [Q empty]
time 44725ms: Process G completed I/O; added to ready queue [Q G]
time 44727ms: Process G started using the CPU for 116ms burst [Q empty]
time 44825ms: Process H completed I/O; added to ready queue [Q H]
time 44843ms: Process G completed a CPU burst; 34 bursts to go [Q H]
time 44843ms: Process G switching out of CPU; will block on I/O until time 45645ms [Q H]
time 44843ms: Process I completed I/O; added to ready queue [Q HI]
time 44847ms: Process H started using the CPU for 61ms burst [Q I]
time 44908ms: Process H completed a CPU burst; 25 bursts to go [Q I]
time 44908ms: Process H switching out of CPU; will block on I/O until time 45160ms [Q I]
time 44912ms: Process I started using the CPU for 145ms burst [Q empty]
time 44943ms: Process E completed I/O; added to ready queue [Q E]
time 45057ms: Process I completed a CPU burst; 31 bursts to go [Q E]
time 45057ms: Process I switching out of CPU; will block on I/O until time 46199ms [Q E]
time 45061ms: Process E started using the CPU for 51ms burst [Q empty]
time 45112ms: Process E completed a CPU burst; 2 bursts to go [Q empty]
time 45112ms: Process E switching out of CPU; will block on I/O until time 45584ms [Q empty]
time 45160ms: Process H completed I/O; added to ready queue [Q H]
time 45162ms: Process H started using the CPU for 207ms burst [Q empty]
time 45369ms: Process H completed a CPU burst; 24 bursts to go [Q empty]
time 45369ms: Process H switching out of CPU; will block on I/O until time 46911ms [Q empty]
time 45584ms: Process E completed I/O; added to ready queue [Q E]
time 45586ms: Process E started using the CPU for 39ms burst [Q empty]
time 45625ms: Process E completed a CPU burst; 1 burst to go [Q empty]
time 45625ms: Process E switching out of CPU; will block on I/O until time 45747ms [Q empty]
time 45645ms: Process G completed I/O; added to ready queue [Q G]
time 45647ms: Process G started using the CPU for 127ms burst [Q empty]
time 45747ms: Process E completed I/O; added to ready queue [Q E]
time 45774ms: Process G completed a CPU burst; 33 bursts to go [Q E]
time 45774ms: Process G switching out of CPU; will block on I/O until time 46236ms [Q E]
time 45778ms: Process E started using the CPU for 131ms burst [Q empty]
time 45909ms: Process E terminated [Q empty]
time 46199ms: Process I completed I/O; added to ready queue [Q I]
time 46201ms: Process I started using the CPU for 34ms burst [Q empty]
time 46235ms: Process I completed a CPU burst; 30 bursts to go [Q empty]
time 46235ms: Process I switching out of CPU; will block on I/O until time 47227ms [Q empty]
time 46236ms: Process G completed I/O; added to ready queue [Q G]
time 46238ms: Process G started using the CPU for 155ms burst [Q empty]
time 46393ms: Process G completed a CPU burst; 32 bursts to go [Q empty]
time 46393ms: Process G switching out of CPU; will block on I/O until time 46935ms [Q empty]
time 46911ms: Process H completed I/O; added to ready queue [Q H]
time 46913ms: Process H started using the CPU for 172ms burst [Q empty]
time 46935ms: Process G completed I/O; added to ready queue [Q G]
time 47085ms: Process H completed a CPU burst; 23 bursts to go [Q G]
time 47085ms: Process H switching out of CPU; will block on I/O until time 47307ms [Q G]
time 47089ms: Process G started using the CPU for 6ms burst [Q empty]
time 47095ms: Process G completed a CPU burst; 31 bursts to go [Q empty]
time 47095ms: Process G switching out of CPU; will block on I/O until time 48737ms [Q empty]
time 47227ms: Process I completed I/O; added to ready queue [Q I]
time 47229ms: Process I started using the CPU for 1ms burst [Q empty]
time 47230ms: Process I completed a CPU burst; 29 bursts to go [Q empty]
time 47230ms: Process I switching out of CPU; will block on I/O until time 47542ms [Q empty]
time 47307ms: Process H completed I/O; added to ready queue [Q H]
time 47309ms: Process H started using the CPU for 43ms burst [Q empty]
time 47352ms: Process H completed a CPU burst; 22 bursts to go [Q empty]
time 47352ms: Process H switching out of CPU; will block on I/O until time 48364ms [Q empty]
time 47542ms: Process I completed I/O; added to ready queue [Q I]
time 47544ms: Process I started using the CPU for 163ms burst [Q empty]
time 47707ms: Process I completed a CPU burst; 28 bursts to go [Q empty]
time 47707ms: Process I switching out of CPU; will block on I/O until time 47729ms [Q empty]
time 47729ms: Process I completed I/O; added to ready queue [Q I]
time 47731ms: Process I started using the CPU for 196ms burst [Q empty]
time 47927ms: Process I completed a CPU burst; 27 bursts to go [Q empty]
time 47927ms: Process I switching out of CPU; will block on I/O until time 49009ms [Q empty]
time 48364ms: Process H completed I/O; added to ready queue [Q H]
time 48366ms: Process H started using the CPU for 8ms burst [Q empty]
time 48374ms: Process H completed a CPU burst; 21 bursts to go [Q empty]
time 48374ms: Process H switching out of CPU; will block on I/O until time 50866ms [Q empty]
time 48737ms: Process G completed I/O; added to ready queue [Q G]
time 48739ms: Process G started using the CPU for 15ms burst [Q empty]
time 48754ms: Process G completed a CPU burst; 30 bursts to go [Q empty]
time 48754ms: Process G switching out of CPU; will block on I/O until time 51046ms [Q empty]
time 49009ms: Process I completed I/O; added to ready queue [Q I]
time 49011ms: Process I started using the CPU for 75ms burst [Q empty]
time 49086ms: Process I completed a CPU burst; 26 bursts to go [Q empty]
time 49086ms: Process I switching out of CPU; will block on I/O until time 49748ms [Q empty]
time 49748ms: Process I completed I/O; added to ready queue [Q I]
time 49750ms: Process I started using the CPU for 40ms burst [Q empty]
time 49790ms: Process I completed a CPU burst; 25 bursts to go [Q empty]
time 49790ms: Process I switching out of CPU; will block on I/O until time 50942ms [Q empty]
time 50866ms: Process H completed I/O; added to ready queue [Q H]
time 50868ms: Process H started using the CPU for 23ms burst [Q empty]
time 50891ms: Process H completed a CPU burst; 20 bursts to go [Q empty]
time 50891ms: Process H switching out of CPU; will block on I/O until time 52173ms [Q empty]
time 50942ms: Process I completed I/O; added to ready queue [Q I]
