Process A (arrival time 9 ms) 16 CPU bursts (tau 100ms)
Process B (arrival time 18 ms) 21 CPU bursts (tau 100ms)
Process C (arrival time 42 ms) 4 CPU bursts (tau 100ms)
Process D (arrival time 156 ms) 11 CPU bursts (tau 100ms)
Process E (arrival time 134 ms) 55 CPU bursts (tau 100ms)
Process F (arrival time 106 ms) 34 CPU bursts (tau 100ms)
Process G (arrival time 65 ms) 80 CPU bursts (tau 100ms)
Process H (arrival time 11 ms) 83 CPU bursts (tau 100ms)

time 0ms: Simulator started for FCFS [Q empty]
time 9ms: Process A arrived; added to ready queue [Q A]
time 11ms: Process A started using the CPU for 56ms burst [Q empty]
time 11ms: Process H arrived; added to ready queue [Q H]
time 18ms: Process B arrived; added to ready queue [Q HB]
time 42ms: Process C arrived; added to ready queue [Q HBC]
time 65ms: Process G arrived; added to ready queue [Q HBCG]
time 67ms: Process A completed a CPU burst; 15 bursts to go [Q HBCG]
time 67ms: Process A switching out of CPU; will block on I/O until time 299ms [Q HBCG]
time 71ms: Process H started using the CPU for 96ms burst [Q BCG]
time 106ms: Process F arrived; added to ready queue [Q BCGF]
time 134ms: Process E arrived; added to ready queue [Q BCGFE]
time 156ms: Process D arrived; added to ready queue [Q BCGFED]
time 167ms: Process H completed a CPU burst; 82 bursts to go [Q BCGFED]
time 167ms: Process H switching out of CPU; will block on I/O until time 839ms [Q BCGFED]
time 171ms: Process B started using the CPU for 106ms burst [Q CGFED]
time 277ms: Process B completed a CPU burst; 20 bursts to go [Q CGFED]
time 277ms: Process B switching out of CPU; will block on I/O until time 1839ms [Q CGFED]
time 281ms: Process C started using the CPU for 94ms burst [Q GFED]
time 299ms: Process A completed I/O; added to ready queue [Q GFEDA]
time 375ms: Process C completed a CPU burst; 3 bursts to go [Q GFEDA]
time 375ms: Process C switching out of CPU; will block on I/O until time 1957ms [Q GFEDA]
time 379ms: Process G started using the CPU for 70ms burst [Q FEDA]
time 449ms: Process G completed a CPU burst; 79 bursts to go [Q FEDA]
time 449ms: Process G switching out of CPU; will block on I/O until time 761ms [Q FEDA]
time 453ms: Process F started using the CPU for 129ms burst [Q EDA]
time 582ms: Process F completed a CPU burst; 33 bursts to go [Q EDA]
time 582ms: Process F switching out of CPU; will block on I/O until time 1154ms [Q EDA]
time 586ms: Process E started using the CPU for 152ms burst [Q DA]
time 738ms: Process E completed a CPU burst; 54 bursts to go [Q DA]
time 738ms: Process E switching out of CPU; will block on I/O until time 1200ms [Q DA]
time 742ms: Process D started using the CPU for 148ms burst [Q A]
time 761ms: Process G completed I/O; added to ready queue [Q AG]
time 839ms: Process H completed I/O; added to ready queue [Q AGH]
time 890ms: Process D completed a CPU burst; 10 bursts to go [Q AGH]
time 890ms: Process D switching out of CPU; will block on I/O until time 912ms [Q AGH]
time 894ms: Process A started using the CPU for 60ms burst [Q GH]
time 912ms: Process D completed I/O; added to ready queue [Q GHD]
time 954ms: Process A completed a CPU burst; 14 bursts to go [Q GHD]
time 954ms: Process A switching out of CPU; will block on I/O until time 2486ms [Q GHD]
time 958ms: Process G started using the CPU for 40ms burst [Q HD]
time 998ms: Process G completed a CPU burst; 78 bursts to go [Q HD]
time 998ms: Process G switching out of CPU; will block on I/O until time 1060ms [Q HD]
time 1002ms: Process H started using the CPU for 48ms burst [Q D]
time 1050ms: Process H completed a CPU burst; 81 bursts to go [Q D]
time 1050ms: Process H switching out of CPU; will block on I/O until time 1272ms [Q D]
time 1054ms: Process D started using the CPU for 211ms burst [Q empty]
time 1060ms: Process G completed I/O; added to ready queue [Q G]
time 1154ms: Process F completed I/O; added to ready queue [Q GF]
time 1200ms: Process E completed I/O; added to ready queue [Q GFE]
time 1265ms: Process D completed a CPU burst; 9 bursts to go [Q GFE]
time 1265ms: Process D switching out of CPU; will block on I/O until time 3407ms [Q GFE]
time 1269ms: Process G started using the CPU for 65ms burst [Q FE]
time 1272ms: Process H completed I/O; added to ready queue [Q FEH]
time 1334ms: Process G completed a CPU burst; 77 bursts to go [Q FEH]
time 1334ms: Process G switching out of CPU; will block on I/O until time 1776ms [Q FEH]
time 1338ms: Process F started using the CPU for 39ms burst [Q EH]
time 1377ms: Process F completed a CPU burst; 32 bursts to go [Q EH]
time 1377ms: Process F switching out of CPU; will block on I/O until time 2029ms [Q EH]
time 1381ms: Process E started using the CPU for 44ms burst [Q H]
time 1425ms: Process E completed a CPU burst; 53 bursts to go [Q H]
time 1425ms: Process E switching out of CPU; will block on I/O until time 1987ms [Q H]
time 1429ms: Process H started using the CPU for 72ms burst [Q empty]
time 1501ms: Process H completed a CPU burst; 80 bursts to go [Q empty]
time 1501ms: Process H switching out of CPU; will block on I/O until time 1923ms [Q empty]
time 1776ms: Process G completed I/O; added to ready queue [Q G]
time 1778ms: Process G started using the CPU for 13ms burst [Q empty]
time 1791ms: Process G completed a CPU burst; 76 bursts to go [Q empty]
time 1791ms: Process G switching out of CPU; will block on I/O until time 2173ms [Q empty]
time 1839ms: Process B completed I/O; added to ready queue [Q B]
time 1841ms: Process B started using the CPU for 198ms burst [Q empty]
time 1923ms: Process H completed I/O; added to ready queue [Q H]
time 1957ms: Process C completed I/O; added to ready queue [Q HC]
time 1987ms: Process E completed I/O; added to ready queue [Q HCE]
time 2029ms: Process F completed I/O; added to ready queue [Q HCEF]
time 2039ms: Process B completed a CPU burst; 19 bursts to go [Q HCEF]
time 2039ms: Process B switching out of CPU; will block on I/O until time 3171ms [Q HCEF]
time 2043ms: Process H started using the CPU for 12ms burst [Q CEF]
time 2055ms: Process H completed a CPU burst; 79 bursts to go [Q CEF]
time 2055ms: Process H switching out of CPU; will block on I/O until time 2187ms [Q CEF]
time 2059ms: Process C started using the CPU for 117ms burst [Q EF]
time 2173ms: Process G completed I/O; added to ready queue [Q EFG]
time 2176ms: Process C completed a CPU burst; 2 bursts to go [Q EFG]
time 2176ms: Process C switching out of CPU; will block on I/O until time 2348ms [Q EFG]
time 2180ms: Process E started using the CPU for 2ms burst [Q FG]
time 2182ms: Process E completed a CPU burst; 52 bursts to go [Q FG]
time 2182ms: Process E switching out of CPU; will block on I/O until time 2434ms [Q FG]
time 2186ms: Process F started using the CPU for 195ms burst [Q G]
time 2187ms: Process H completed I/O; added to ready queue [Q GH]
time 2348ms: Process C completed I/O; added to ready queue [Q GHC]
time 2381ms: Process F completed a CPU burst; 31 bursts to go [Q GHC]
time 2381ms: Process F switching out of CPU; will block on I/O until time 2393ms [Q GHC]
time 2385ms: Process G started using the CPU for 128ms burst [Q HC]
time 2393ms: Process F completed I/O; added to ready queue [Q HCF]
time 2434ms: Process E completed I/O; added to ready queue [Q HCFE]
time 2486ms: Process A completed I/O; added to ready queue [Q HCFEA]
time 2513ms: Process G completed a CPU burst; 75 bursts to go [Q HCFEA]
time 2513ms: Process G switching out of CPU; will block on I/O until time 4735ms [Q HCFEA]
time 2517ms: Process H started using the CPU for 41ms burst [Q CFEA]
time 2558ms: Process H completed a CPU burst; 78 bursts to go [Q CFEA]
time 2558ms: Process H switching out of CPU; will block on I/O until time 2770ms [Q CFEA]
time 2562ms: Process C started using the CPU for 85ms burst [Q FEA]
time 2647ms: Process C completed a CPU burst; 1 burst to go [Q FEA]
time 2647ms: Process C switching out of CPU; will block on I/O until time 2859ms [Q FEA]
time 2651ms: Process F started using the CPU for 72ms burst [Q EA]
time 2723ms: Process F completed a CPU burst; 30 bursts to go [Q EA]
time 2723ms: Process F switching out of CPU; will block on I/O until time 2985ms [Q EA]
time 2727ms: Process E started using the CPU for 42ms burst [Q A]
time 2769ms: Process E completed a CPU burst; 51 bursts to go [Q A]
time 2769ms: Process E switching out of CPU; will block on I/O until time 2821ms [Q A]
time 2770ms: Process H completed I/O; added to ready queue [Q AH]
time 2773ms: Process A started using the CPU for 39ms burst [Q H]
time 2812ms: Process A completed a CPU burst; 13 bursts to go [Q H]
time 2812ms: Process A switching out of CPU; will block on I/O until time 3314ms [Q H]
time 2816ms: Process H started using the CPU for 160ms burst [Q empty]
time 2821ms: Process E completed I/O; added to ready queue [Q E]
time 2859ms: Process C completed I/O; added to ready queue [Q EC]
time 2976ms: Process H completed a CPU burst; 77 bursts to go [Q EC]
time 2976ms: Process H switching out of CPU; will block on I/O until time 3578ms [Q EC]
time 2980ms: Process E started using the CPU for 108ms burst [Q C]
time 2985ms: Process F completed I/O; added to ready queue [Q CF]
time 3088ms: Process E completed a CPU burst; 50 bursts to go [Q CF]
time 3088ms: Process E switching out of CPU; will block on I/O until time 3180ms [Q CF]
time 3092ms: Process C started using the CPU for 79ms burst [Q F]
time 3171ms: Process C terminated [Q F]
time 3171ms: Process B completed I/O; added to ready queue [Q FB]
time 3175ms: Process F started using the CPU for 8ms burst [Q B]
time 3180ms: Process E completed I/O; added to ready queue [Q BE]
time 3183ms: Process F completed a CPU burst; 29 bursts to go [Q BE]
time 3183ms: Process F switching out of CPU; will block on I/O until time 3515ms [Q BE]
time 3187ms: Process B started using the CPU for 208ms burst [Q E]
time 3314ms: Process A completed I/O; added to ready queue [Q EA]
time 3395ms: Process B completed a CPU burst; 18 bursts to go [Q EA]
time 3395ms: Process B switching out of CPU; will block on I/O until time 5017ms [Q EA]
time 3399ms: Process E started using the CPU for 6ms burst [Q A]
time 3405ms: Process E completed a CPU burst; 49 bursts to go [Q A]
time 3405ms: Process E switching out of CPU; will block on I/O until time 3727ms [Q A]
time 3407ms: Process D completed I/O; added to ready queue [Q AD]
time 3409ms: Process A started using the CPU for 47ms burst [Q D]
time 3456ms: Process A completed a CPU burst; 12 bursts to go [Q D]
time 3456ms: Process A switching out of CPU; will block on I/O until time 3478ms [Q D]
time 3460ms: Process D started using the CPU for 9ms burst [Q empty]
time 3469ms: Process D completed a CPU burst; 8 bursts to go [Q empty]
time 3469ms: Process D switching out of CPU; will block on I/O until time 3851ms [Q empty]
time 3478ms: Process A completed I/O; added to ready queue [Q A]
time 3480ms: Process A started using the CPU for 137ms burst [Q empty]
time 3515ms: Process F completed I/O; added to ready queue [Q F]
time 3578ms: Process H completed I/O; added to ready queue [Q FH]
time 3617ms: Process A completed a CPU burst; 11 bursts to go [Q FH]
time 3617ms: Process A switching out of CPU; will block on I/O until time 3859ms [Q FH]
time 3621ms: Process F started using the CPU for 230ms burst [Q H]
time 3727ms: Process E completed I/O; added to ready queue [Q HE]
time 3851ms: Process F completed a CPU burst; 28 bursts to go [Q HE]
time 3851ms: Process F switching out of CPU; will block on I/O until time 3883ms [Q HE]
time 3851ms: Process D completed I/O; added to ready queue [Q HED]
time 3855ms: Process H started using the CPU for 28ms burst [Q ED]
time 3859ms: Process A completed I/O; added to ready queue [Q EDA]
time 3883ms: Process H completed a CPU burst; 76 bursts to go [Q EDA]
time 3883ms: Process H switching out of CPU; will block on I/O until time 4845ms [Q EDA]
time 3883ms: Process F completed I/O; added to ready queue [Q EDAF]
time 3887ms: Process E started using the CPU for 112ms burst [Q DAF]
time 3999ms: Process E completed a CPU burst; 48 bursts to go [Q DAF]
time 3999ms: Process E switching out of CPU; will block on I/O until time 5111ms [Q DAF]
time 4003ms: Process D started using the CPU for 4ms burst [Q AF]
time 4007ms: Process D completed a CPU burst; 7 bursts to go [Q AF]
time 4007ms: Process D switching out of CPU; will block on I/O until time 4489ms [Q AF]
time 4011ms: Process A started using the CPU for 64ms burst [Q F]
time 4075ms: Process A completed a CPU burst; 10 bursts to go [Q F]
time 4075ms: Process A switching out of CPU; will block on I/O until time 4227ms [Q F]
time 4079ms: Process F started using the CPU for 33ms burst [Q empty]
time 4112ms: Process F completed a CPU burst; 27 bursts to go [Q empty]
time 4112ms: Process F switching out of CPU; will block on I/O until time 4674ms [Q empty]
time 4227ms: Process A completed I/O; added to ready queue [Q A]
time 4229ms: Process A started using the CPU for 68ms burst [Q empty]
time 4297ms: Process A completed a CPU burst; 9 bursts to go [Q empty]
time 4297ms: Process A switching out of CPU; will block on I/O until time 4939ms [Q empty]
time 4489ms: Process D completed I/O; added to ready queue [Q D]
time 4491ms: Process D started using the CPU for 149ms burst [Q empty]
time 4640ms: Process D completed a CPU burst; 6 bursts to go [Q empty]
time 4640ms: Process D switching out of CPU; will block on I/O until time 5452ms [Q empty]
time 4674ms: Process F completed I/O; added to ready queue [Q F]
time 4676ms: Process F started using the CPU for 76ms burst [Q empty]
time 4735ms: Process G completed I/O; added to ready queue [Q G]
time 4752ms: Process F completed a CPU burst; 26 bursts to go [Q G]
time 4752ms: Process F switching out of CPU; will block on I/O until time 5134ms [Q G]
time 4756ms: Process G started using the CPU for 15ms burst [Q empty]
time 4771ms: Process G completed a CPU burst; 74 bursts to go [Q empty]
time 4771ms: Process G switching out of CPU; will block on I/O until time 5713ms [Q empty]
time 4845ms: Process H completed I/O; added to ready queue [Q H]
time 4847ms: Process H started using the CPU for 51ms burst [Q empty]
time 4898ms: Process H completed a CPU burst; 75 bursts to go [Q empty]
time 4898ms: Process H switching out of CPU; will block on I/O until time 5130ms [Q empty]
time 4939ms: Process A completed I/O; added to ready queue [Q A]
time 4941ms: Process A started using the CPU for 113ms burst [Q empty]
time 5017ms: Process B completed I/O; added to ready queue [Q B]
time 5054ms: Process A completed a CPU burst; 8 bursts to go [Q B]
time 5054ms: Process A switching out of CPU; will block on I/O until time 5216ms [Q B]
time 5058ms: Process B started using the CPU for 50ms burst [Q empty]
time 5108ms: Process B completed a CPU burst; 17 bursts to go [Q empty]
time 5108ms: Process B switching out of CPU; will block on I/O until time 5570ms [Q empty]
time 5111ms: Process E completed I/O; added to ready queue [Q E]
time 5113ms: Process E started using the CPU for 12ms burst [Q empty]
time 5125ms: Process E completed a CPU burst; 47 bursts to go [Q empty]
time 5125ms: Process E switching out of CPU; will block on I/O until time 5577ms [Q empty]
time 5130ms: Process H completed I/O; added to ready queue [Q H]
time 5132ms: Process H started using the CPU for 87ms burst [Q empty]
time 5134ms: Process F completed I/O; added to ready queue [Q F]
time 5216ms: Process A completed I/O; added to ready queue [Q FA]
time 5219ms: Process H completed a CPU burst; 74 bursts to go [Q FA]
time 5219ms: Process H switching out of CPU; will block on I/O until time 5791ms [Q FA]
time 5223ms: Process F started using the CPU for 107ms burst [Q A]
time 5330ms: Process F completed a CPU burst; 25 bursts to go [Q A]
time 5330ms: Process F switching out of CPU; will block on I/O until time 5512ms [Q A]
time 5334ms: Process A started using the CPU for 11ms burst [Q empty]
time 5345ms: Process A completed a CPU burst; 7 bursts to go [Q empty]
time 5345ms: Process A switching out of CPU; will block on I/O until time 6967ms [Q empty]
time 5452ms: Process D completed I/O; added to ready queue [Q D]
time 5454ms: Process D started using the CPU for 52ms burst [Q empty]
time 5506ms: Process D completed a CPU burst; 5 bursts to go [Q empty]
time 5506ms: Process D switching out of CPU; will block on I/O until time 5538ms [Q empty]
time 5512ms: Process F completed I/O; added to ready queue [Q F]
time 5514ms: Process F started using the CPU for 89ms burst [Q empty]
time 5538ms: Process D completed I/O; added to ready queue [Q D]
time 5570ms: Process B completed I/O; added to ready queue [Q DB]
time 5577ms: Process E completed I/O; added to ready queue [Q DBE]
time 5603ms: Process F completed a CPU burst; 24 bursts to go [Q DBE]
time 5603ms: Process F switching out of CPU; will block on I/O until time 6435ms [Q DBE]
time 5607ms: Process D started using the CPU for 23ms burst [Q BE]
time 5630ms: Process D completed a CPU burst; 4 bursts to go [Q BE]
time 5630ms: Process D switching out of CPU; will block on I/O until time 7572ms [Q BE]
time 5634ms: Process B started using the CPU for 82ms burst [Q E]
time 5713ms: Process G completed I/O; added to ready queue [Q EG]
time 5716ms: Process B completed a CPU burst; 16 bursts to go [Q EG]
time 5716ms: Process B switching out of CPU; will block on I/O until time 5878ms [Q EG]
time 5720ms: Process E started using the CPU for 9ms burst [Q G]
time 5729ms: Process E completed a CPU burst; 46 bursts to go [Q G]
time 5729ms: Process E switching out of CPU; will block on I/O until time 6401ms [Q G]
time 5733ms: Process G started using the CPU for 112ms burst [Q empty]
time 5791ms: Process H completed I/O; added to ready queue [Q H]
time 5845ms: Process G completed a CPU burst; 73 bursts to go [Q H]
time 5845ms: Process G switching out of CPU; will block on I/O until time 6277ms [Q H]
time 5849ms: Process H started using the CPU for 156ms burst [Q empty]
time 5878ms: Process B completed I/O; added to ready queue [Q B]
time 6005ms: Process H completed a CPU burst; 73 bursts to go [Q B]
time 6005ms: Process H switching out of CPU; will block on I/O until time 6567ms [Q B]
time 6009ms: Process B started using the CPU for 7ms burst [Q empty]
time 6016ms: Process B completed a CPU burst; 15 bursts to go [Q empty]
time 6016ms: Process B switching out of CPU; will block on I/O until time 6318ms [Q empty]
time 6277ms: Process G completed I/O; added to ready queue [Q G]
time 6279ms: Process G started using the CPU for 30ms burst [Q empty]
time 6309ms: Process G completed a CPU burst; 72 bursts to go [Q empty]
time 6309ms: Process G switching out of CPU; will block on I/O until time 6781ms [Q empty]
time 6318ms: Process B completed I/O; added to ready queue [Q B]
time 6320ms: Process B started using the CPU for 52ms burst [Q empty]
time 6372ms: Process B completed a CPU burst; 14 bursts to go [Q empty]
time 6372ms: Process B switching out of CPU; will block on I/O until time 6494ms [Q empty]
time 6401ms: Process E completed I/O; added to ready queue [Q E]
time 6403ms: Process E started using the CPU for 62ms burst [Q empty]
time 6435ms: Process F completed I/O; added to ready queue [Q F]
time 6465ms: Process E completed a CPU burst; 45 bursts to go [Q F]
time 6465ms: Process E switching out of CPU; will block on I/O until time 7067ms [Q F]
time 6469ms: Process F started using the CPU for 102ms burst [Q empty]
time 6494ms: Process B completed I/O; added to ready queue [Q B]
time 6567ms: Process H completed I/O; added to ready queue [Q BH]
time 6571ms: Process F completed a CPU burst; 23 bursts to go [Q BH]
time 6571ms: Process F switching out of CPU; will block on I/O until time 7923ms [Q BH]
time 6575ms: Process B started using the CPU for 228ms burst [Q H]
time 6781ms: Process G completed I/O; added to ready queue [Q HG]
time 6803ms: Process B completed a CPU burst; 13 bursts to go [Q HG]
time 6803ms: Process B switching out of CPU; will block on I/O until time 7575ms [Q HG]
time 6807ms: Process H started using the CPU for 184ms burst [Q G]
time 6967ms: Process A completed I/O; added to ready queue [Q GA]
time 6991ms: Process H completed a CPU burst; 72 bursts to go [Q GA]
time 6991ms: Process H switching out of CPU; will block on I/O until time 7253ms [Q GA]
time 6995ms: Process G started using the CPU for 50ms burst [Q A]
time 7045ms: Process G completed a CPU burst; 71 bursts to go [Q A]
time 7045ms: Process G switching out of CPU; will block on I/O until time 9247ms [Q A]
time 7049ms: Process A started using the CPU for 24ms burst [Q empty]
time 7067ms: Process E completed I/O; added to ready queue [Q E]
time 7073ms: Process A completed a CPU burst; 6 bursts to go [Q E]
time 7073ms: Process A switching out of CPU; will block on I/O until time 8245ms [Q E]
time 7077ms: Process E started using the CPU for 213ms burst [Q empty]
time 7253ms: Process H completed I/O; added to ready queue [Q H]
time 7290ms: Process E completed a CPU burst; 44 bursts to go [Q H]
time 7290ms: Process E switching out of CPU; will block on I/O until time 9222ms [Q H]
time 7294ms: Process H started using the CPU for 2ms burst [Q empty]
time 7296ms: Process H completed a CPU burst; 71 bursts to go [Q empty]
time 7296ms: Process H switching out of CPU; will block on I/O until time 7438ms [Q empty]
time 7438ms: Process H completed I/O; added to ready queue [Q H]
time 7440ms: Process H started using the CPU for 29ms burst [Q empty]
time 7469ms: Process H completed a CPU burst; 70 bursts to go [Q empty]
time 7469ms: Process H switching out of CPU; will block on I/O until time 9691ms [Q empty]
time 7572ms: Process D completed I/O; added to ready queue [Q D]
time 7574ms: Process D started using the CPU for 76ms burst [Q empty]
time 7575ms: Process B completed I/O; added to ready queue [Q B]
time 7650ms: Process D completed a CPU burst; 3 bursts to go [Q B]
time 7650ms: Process D switching out of CPU; will block on I/O until time 8382ms [Q B]
time 7654ms: Process B started using the CPU for 138ms burst [Q empty]
time 7792ms: Process B completed a CPU burst; 12 bursts to go [Q empty]
time 7792ms: Process B switching out of CPU; will block on I/O until time 8614ms [Q empty]
time 7923ms: Process F completed I/O; added to ready queue [Q F]
time 7925ms: Process F started using the CPU for 147ms burst [Q empty]
time 8072ms: Process F completed a CPU burst; 22 bursts to go [Q empty]
time 8072ms: Process F switching out of CPU; will block on I/O until time 8124ms [Q empty]
time 8124ms: Process F completed I/O; added to ready queue [Q F]
time 8126ms: Process F started using the CPU for 97ms burst [Q empty]
time 8223ms: Process F completed a CPU burst; 21 bursts to go [Q empty]
time 8223ms: Process F switching out of CPU; will block on I/O until time 8265ms [Q empty]
time 8245ms: Process A completed I/O; added to ready queue [Q A]
time 8247ms: Process A started using the CPU for 76ms burst [Q empty]
time 8265ms: Process F completed I/O; added to ready queue [Q F]
time 8323ms: Process A completed a CPU burst; 5 bursts to go [Q F]
time 8323ms: Process A switching out of CPU; will block on I/O until time 8605ms [Q F]
time 8327ms: Process F started using the CPU for 157ms burst [Q empty]
time 8382ms: Process D completed I/O; added to ready queue [Q D]
time 8484ms: Process F completed a CPU burst; 20 bursts to go [Q D]
time 8484ms: Process F switching out of CPU; will block on I/O until time 8586ms [Q D]
time 8488ms: Process D started using the CPU for 50ms burst [Q empty]
time 8538ms: Process D completed a CPU burst; 2 bursts to go [Q empty]
time 8538ms: Process D switching out of CPU; will block on I/O until time 8660ms [Q empty]
time 8586ms: Process F completed I/O; added to ready queue [Q F]
time 8588ms: Process F started using the CPU for 24ms burst [Q empty]
time 8605ms: Process A completed I/O; added to ready queue [Q A]
time 8612ms: Process F completed a CPU burst; 19 bursts to go [Q A]
time 8612ms: Process F switching out of CPU; will block on I/O until time 9584ms [Q A]
time 8614ms: Process B completed I/O; added to ready queue [Q AB]
time 8616ms: Process A started using the CPU for 122ms burst [Q B]
time 8660ms: Process D completed I/O; added to ready queue [Q BD]
time 8738ms: Process A completed a CPU burst; 4 bursts to go [Q BD]
time 8738ms: Process A switching out of CPU; will block on I/O until time 9070ms [Q BD]
time 8742ms: Process B started using the CPU for 67ms burst [Q D]
time 8809ms: Process B completed a CPU burst; 11 bursts to go [Q D]
time 8809ms: Process B switching out of CPU; will block on I/O until time 8881ms [Q D]
time 8813ms: Process D started using the CPU for 24ms burst [Q empty]
time 8837ms: Process D completed a CPU burst; 1 burst to go [Q empty]
time 8837ms: Process D switching out of CPU; will block on I/O until time 9089ms [Q empty]
time 8881ms: Process B completed I/O; added to ready queue [Q B]
time 8883ms: Process B started using the CPU for 120ms burst [Q empty]
time 9003ms: Process B completed a CPU burst; 10 bursts to go [Q empty]
time 9003ms: Process B switching out of CPU; will block on I/O until time 9135ms [Q empty]
time 9070ms: Process A completed I/O; added to ready queue [Q A]
time 9072ms: Process A started using the CPU for 9ms burst [Q empty]
time 9081ms: Process A completed a CPU burst; 3 bursts to go [Q empty]
time 9081ms: Process A switching out of CPU; will block on I/O until time 9763ms [Q empty]
time 9089ms: Process D completed I/O; added to ready queue [Q D]
time 9091ms: Process D started using the CPU for 1ms burst [Q empty]
time 9092ms: Process D terminated [Q empty]
time 9135ms: Process B completed I/O; added to ready queue [Q B]
time 9137ms: Process B started using the CPU for 49ms burst [Q empty]
time 9186ms: Process B completed a CPU burst; 9 bursts to go [Q empty]
time 9186ms: Process B switching out of CPU; will block on I/O until time 9608ms [Q empty]
time 9222ms: Process E completed I/O; added to ready queue [Q E]
time 9224ms: Process E started using the CPU for 54ms burst [Q empty]
time 9247ms: Process G completed I/O; added to ready queue [Q G]
time 9278ms: Process E completed a CPU burst; 43 bursts to go [Q G]
time 9278ms: Process E switching out of CPU; will block on I/O until time 10230ms [Q G]
time 9282ms: Process G started using the CPU for 5ms burst [Q empty]
time 9287ms: Process G completed a CPU burst; 70 bursts to go [Q empty]
time 9287ms: Process G switching out of CPU; will block on I/O until time 11269ms [Q empty]
time 9584ms: Process F completed I/O; added to ready queue [Q F]
time 9586ms: Process F started using the CPU for 31ms burst [Q empty]
time 9608ms: Process B completed I/O; added to ready queue [Q B]
time 9617ms: Process F completed a CPU burst; 18 bursts to go [Q B]
time 9617ms: Process F switching out of CPU; will block on I/O until time 9829ms [Q B]
time 9621ms: Process B started using the CPU for 134ms burst [Q empty]
time 9691ms: Process H completed I/O; added to ready queue [Q H]
time 9755ms: Process B completed a CPU burst; 8 bursts to go [Q H]
time 9755ms: Process B switching out of CPU; will block on I/O until time 10077ms [Q H]
time 9759ms: Process H started using the CPU for 76ms burst [Q empty]
time 9763ms: Process A completed I/O; added to ready queue [Q A]
time 9829ms: Process F completed I/O; added to ready queue [Q AF]
time 9835ms: Process H completed a CPU burst; 69 bursts to go [Q AF]
time 9835ms: Process H switching out of CPU; will block on I/O until time 11957ms [Q AF]
time 9839ms: Process A started using the CPU for 62ms burst [Q F]
time 9901ms: Process A completed a CPU burst; 2 bursts to go [Q F]
time 9901ms: Process A switching out of CPU; will block on I/O until time 10673ms [Q F]
time 9905ms: Process F started using the CPU for 24ms burst [Q empty]
time 9929ms: Process F completed a CPU burst; 17 bursts to go [Q empty]
time 9929ms: Process F switching out of CPU; will block on I/O until time 10521ms [Q empty]
time 10077ms: Process B completed I/O; added to ready queue [Q B]
time 10079ms: Process B started using the CPU for 144ms burst [Q empty]
time 10223ms: Process B completed a CPU burst; 7 bursts to go [Q empty]
time 10223ms: Process B switching out of CPU; will block on I/O until time 11015ms [Q empty]
time 10230ms: Process E completed I/O; added to ready queue [Q E]
time 10232ms: Process E started using the CPU for 126ms burst [Q empty]
time 10358ms: Process E completed a CPU burst; 42 bursts to go [Q empty]
time 10358ms: Process E switching out of CPU; will block on I/O until time 12340ms [Q empty]
time 10521ms: Process F completed I/O; added to ready queue [Q F]
time 10523ms: Process F started using the CPU for 135ms burst [Q empty]
time 10658ms: Process F completed a CPU burst; 16 bursts to go [Q empty]
time 10658ms: Process F switching out of CPU; will block on I/O until time 11280ms [Q empty]
time 10673ms: Process A completed I/O; added to ready queue [Q A]
time 10675ms: Process A started using the CPU for 200ms burst [Q empty]
time 10875ms: Process A completed a CPU burst; 1 burst to go [Q empty]
time 10875ms: Process A switching out of CPU; will block on I/O until time 10987ms [Q empty]
time 10987ms: Process A completed I/O; added to ready queue [Q A]
time 10989ms: Process A started using the CPU for 197ms burst [Q empty]
time 11015ms: Process B completed I/O; added to ready queue [Q B]
time 11186ms: Process A terminated [Q B]
time 11190ms: Process B started using the CPU for 183ms burst [Q empty]
time 11269ms: Process G completed I/O; added to ready queue [Q G]
time 11280ms: Process F completed I/O; added to ready queue [Q GF]
time 11373ms: Process B completed a CPU burst; 6 bursts to go [Q GF]
time 11373ms: Process B switching out of CPU; will block on I/O until time 11435ms [Q GF]
time 11377ms: Process G started using the CPU for 122ms burst [Q F]
time 11435ms: Process B completed I/O; added to ready queue [Q FB]
time 11499ms: Process G completed a CPU burst; 69 bursts to go [Q FB]
time 11499ms: Process G switching out of CPU; will block on I/O until time 11851ms [Q FB]
time 11503ms: Process F started using the CPU for 87ms burst [Q B]
time 11590ms: Process F completed a CPU burst; 15 bursts to go [Q B]
time 11590ms: Process F switching out of CPU; will block on I/O until time 12632ms [Q B]
time 11594ms: Process B started using the CPU for 219ms burst [Q empty]
time 11813ms: Process B completed a CPU burst; 5 bursts to go [Q empty]
time 11813ms: Process B switching out of CPU; will block on I/O until time 12045ms [Q empty]
time 11851ms: Process G completed I/O; added to ready queue [Q G]
time 11853ms: Process G started using the CPU for 31ms burst [Q empty]
time 11884ms: Process G completed a CPU burst; 68 bursts to go [Q empty]
time 11884ms: Process G switching out of CPU; will block on I/O until time 11956ms [Q empty]
time 11956ms: Process G completed I/O; added to ready queue [Q G]
time 11957ms: Process H completed I/O; added to ready queue [Q H]
time 11958ms: Process G started using the CPU for 61ms burst [Q H]
time 12019ms: Process G completed a CPU burst; 67 bursts to go [Q H]
time 12019ms: Process G switching out of CPU; will block on I/O until time 12761ms [Q H]
time 12023ms: Process H started using the CPU for 143ms burst [Q empty]
time 12045ms: Process B completed I/O; added to ready queue [Q B]
time 12166ms: Process H completed a CPU burst; 68 bursts to go [Q B]
time 12166ms: Process H switching out of CPU; will block on I/O until time 14008ms [Q B]
time 12170ms: Process B started using the CPU for 64ms burst [Q empty]
time 12234ms: Process B completed a CPU burst; 4 bursts to go [Q empty]
time 12234ms: Process B switching out of CPU; will block on I/O until time 13036ms [Q empty]
time 12340ms: Process E completed I/O; added to ready queue [Q E]
time 12342ms: Process E started using the CPU for 168ms burst [Q empty]
time 12510ms: Process E completed a CPU burst; 41 bursts to go [Q empty]
time 12510ms: Process E switching out of CPU; will block on I/O until time 13012ms [Q empty]
time 12632ms: Process F completed I/O; added to ready queue [Q F]
time 12634ms: Process F started using the CPU for 22ms burst [Q empty]
time 12656ms: Process F completed a CPU burst; 14 bursts to go [Q empty]
time 12656ms: Process F switching out of CPU; will block on I/O until time 12808ms [Q empty]
time 12761ms: Process G completed I/O; added to ready queue [Q G]
time 12763ms: Process G started using the CPU for 7ms burst [Q empty]
time 12770ms: Process G completed a CPU burst; 66 bursts to go [Q empty]
time 12770ms: Process G switching out of CPU; will block on I/O until time 14412ms [Q empty]
time 12808ms: Process F completed I/O; added to ready queue [Q F]
time 12810ms: Process F started using the CPU for 52ms burst [Q empty]
time 12862ms: Process F completed a CPU burst; 13 bursts to go [Q empty]
time 12862ms: Process F switching out of CPU; will block on I/O until time 12954ms [Q empty]
time 12954ms: Process F completed I/O; added to ready queue [Q F]
time 12956ms: Process F started using the CPU for 90ms burst [Q empty]
time 13012ms: Process E completed I/O; added to ready queue [Q E]
time 13036ms: Process B completed I/O; added to ready queue [Q EB]
time 13046ms: Process F completed a CPU burst; 12 bursts to go [Q EB]
time 13046ms: Process F switching out of CPU; will block on I/O until time 15258ms [Q EB]
time 13050ms: Process E started using the CPU for 23ms burst [Q B]
time 13073ms: Process E completed a CPU burst; 40 bursts to go [Q B]
time 13073ms: Process E switching out of CPU; will block on I/O until time 13165ms [Q B]
time 13077ms: Process B started using the CPU for 33ms burst [Q empty]
time 13110ms: Process B completed a CPU burst; 3 bursts to go [Q empty]
time 13110ms: Process B switching out of CPU; will block on I/O until time 13852ms [Q empty]
time 13165ms: Process E completed I/O; added to ready queue [Q E]
time 13167ms: Process E started using the CPU for 68ms burst [Q empty]
time 13235ms: Process E completed a CPU burst; 39 bursts to go [Q empty]
time 13235ms: Process E switching out of CPU; will block on I/O until time 13817ms [Q empty]
time 13817ms: Process E completed I/O; added to ready queue [Q E]
time 13819ms: Process E started using the CPU for 41ms burst [Q empty]
time 13852ms: Process B completed I/O; added to ready queue [Q B]
time 13860ms: Process E completed a CPU burst; 38 bursts to go [Q B]
time 13860ms: Process E switching out of CPU; will block on I/O until time 14062ms [Q B]
time 13864ms: Process B started using the CPU for 63ms burst [Q empty]
time 13927ms: Process B completed a CPU burst; 2 bursts to go [Q empty]
time 13927ms: Process B switching out of CPU; will block on I/O until time 16239ms [Q empty]
time 14008ms: Process H completed I/O; added to ready queue [Q H]
time 14010ms: Process H started using the CPU for 32ms burst [Q empty]
time 14042ms: Process H completed a CPU burst; 67 bursts to go [Q empty]
time 14042ms: Process H switching out of CPU; will block on I/O until time 14864ms [Q empty]
time 14062ms: Process E completed I/O; added to ready queue [Q E]
time 14064ms: Process E started using the CPU for 44ms burst [Q empty]
time 14108ms: Process E completed a CPU burst; 37 bursts to go [Q empty]
time 14108ms: Process E switching out of CPU; will block on I/O until time 14720ms [Q empty]
time 14412ms: Process G completed I/O; added to ready queue [Q G]
time 14414ms: Process G started using the CPU for 2ms burst [Q empty]
time 14416ms: Process G completed a CPU burst; 65 bursts to go [Q empty]
time 14416ms: Process G switching out of CPU; will block on I/O until time 14528ms [Q empty]
time 14528ms: Process G completed I/O; added to ready queue [Q G]
time 14530ms: Process G started using the CPU for 209ms burst [Q empty]
time 14720ms: Process E completed I/O; added to ready queue [Q E]
time 14739ms: Process G completed a CPU burst; 64 bursts to go [Q E]
time 14739ms: Process G switching out of CPU; will block on I/O until time 15221ms [Q E]
time 14743ms: Process E started using the CPU for 74ms burst [Q empty]
time 14817ms: Process E completed a CPU burst; 36 bursts to go [Q empty]
time 14817ms: Process E switching out of CPU; will block on I/O until time 16679ms [Q empty]
time 14864ms: Process H completed I/O; added to ready queue [Q H]
time 14866ms: Process H started using the CPU for 78ms burst [Q empty]
time 14944ms: Process H completed a CPU burst; 66 bursts to go [Q empty]
time 14944ms: Process H switching out of CPU; will block on I/O until time 15006ms [Q empty]
time 15006ms: Process H completed I/O; added to ready queue [Q H]
time 15008ms: Process H started using the CPU for 16ms burst [Q empty]
time 15024ms: Process H completed a CPU burst; 65 bursts to go [Q empty]
time 15024ms: Process H switching out of CPU; will block on I/O until time 15576ms [Q empty]
time 15221ms: Process G completed I/O; added to ready queue [Q G]
time 15223ms: Process G started using the CPU for 6ms burst [Q empty]
time 15229ms: Process G completed a CPU burst; 63 bursts to go [Q empty]
time 15229ms: Process G switching out of CPU; will block on I/O until time 16711ms [Q empty]
time 15258ms: Process F completed I/O; added to ready queue [Q F]
time 15260ms: Process F started using the CPU for 4ms burst [Q empty]
time 15264ms: Process F completed a CPU burst; 11 bursts to go [Q empty]
time 15264ms: Process F switching out of CPU; will block on I/O until time 15816ms [Q empty]
time 15576ms: Process H completed I/O; added to ready queue [Q H]
time 15578ms: Process H started using the CPU for 142ms burst [Q empty]
time 15720ms: Process H completed a CPU burst; 64 bursts to go [Q empty]
time 15720ms: Process H switching out of CPU; will block on I/O until time 16692ms [Q empty]
time 15816ms: Process F completed I/O; added to ready queue [Q F]
time 15818ms: Process F started using the CPU for 30ms burst [Q empty]
time 15848ms: Process F completed a CPU burst; 10 bursts to go [Q empty]
time 15848ms: Process F switching out of CPU; will block on I/O until time 16310ms [Q empty]
time 16239ms: Process B completed I/O; added to ready queue [Q B]
time 16241ms: Process B started using the CPU for 170ms burst [Q empty]
time 16310ms: Process F completed I/O; added to ready queue [Q F]
time 16411ms: Process B completed a CPU burst; 1 burst to go [Q F]
time 16411ms: Process B switching out of CPU; will block on I/O until time 16983ms [Q F]
time 16415ms: Process F started using the CPU for 183ms burst [Q empty]
time 16598ms: Process F completed a CPU burst; 9 bursts to go [Q empty]
time 16598ms: Process F switching out of CPU; will block on I/O until time 17010ms [Q empty]
time 16679ms: Process E completed I/O; added to ready queue [Q E]
time 16681ms: Process E started using the CPU for 117ms burst [Q empty]
time 16692ms: Process H completed I/O; added to ready queue [Q H]
time 16711ms: Process G completed I/O; added to ready queue [Q HG]
time 16798ms: Process E completed a CPU burst; 35 bursts to go [Q HG]
time 16798ms: Process E switching out of CPU; will block on I/O until time 17800ms [Q HG]
time 16802ms: Process H started using the CPU for 62ms burst [Q G]
time 16864ms: Process H completed a CPU burst; 63 bursts to go [Q G]
time 16864ms: Process H switching out of CPU; will block on I/O until time 17116ms [Q G]
time 16868ms: Process G started using the CPU for 37ms burst [Q empty]
time 16905ms: Process G completed a CPU burst; 62 bursts to go [Q empty]
time 16905ms: Process G switching out of CPU; will block on I/O until time 18217ms [Q empty]
time 16983ms: Process B completed I/O; added to ready queue [Q B]
time 16985ms: Process B started using the CPU for 212ms burst [Q empty]
time 17010ms: Process F completed I/O; added to ready queue [Q F]
time 17116ms: Process H completed I/O; added to ready queue [Q FH]
time 17197ms: Process B terminated [Q FH]
time 17201ms: Process F started using the CPU for 21ms burst [Q H]
time 17222ms: Process F completed a CPU burst; 8 bursts to go [Q H]
time 17222ms: Process F switching out of CPU; will block on I/O until time 18394ms [Q H]
time 17226ms: Process H started using the CPU for 248ms burst [Q empty]
time 17474ms: Process H completed a CPU burst; 62 bursts to go [Q empty]
time 17474ms: Process H switching out of CPU; will block on I/O until time 18296ms [Q empty]
time 17800ms: Process E completed I/O; added to ready queue [Q E]
time 17802ms: Process E started using the CPU for 14ms burst [Q empty]
time 17816ms: Process E completed a CPU burst; 34 bursts to go [Q empty]
time 17816ms: Process E switching out of CPU; will block on I/O until time 17838ms [Q empty]
time 17838ms: Process E completed I/O; added to ready queue [Q E]
time 17840ms: Process E started using the CPU for 156ms burst [Q empty]
time 17996ms: Process E completed a CPU burst; 33 bursts to go [Q empty]
time 17996ms: Process E switching out of CPU; will block on I/O until time 18998ms [Q empty]
time 18217ms: Process G completed I/O; added to ready queue [Q G]
time 18219ms: Process G started using the CPU for 15ms burst [Q empty]
time 18234ms: Process G completed a CPU burst; 61 bursts to go [Q empty]
time 18234ms: Process G switching out of CPU; will block on I/O until time 18456ms [Q empty]
time 18296ms: Process H completed I/O; added to ready queue [Q H]
time 18298ms: Process H started using the CPU for 37ms burst [Q empty]
time 18335ms: Process H completed a CPU burst; 61 bursts to go [Q empty]
time 18335ms: Process H switching out of CPU; will block on I/O until time 18367ms [Q empty]
time 18367ms: Process H completed I/O; added to ready queue [Q H]
time 18369ms: Process H started using the CPU for 10ms burst [Q empty]
time 18379ms: Process H completed a CPU burst; 60 bursts to go [Q empty]
time 18379ms: Process H switching out of CPU; will block on I/O until time 18441ms [Q empty]
time 18394ms: Process F completed I/O; added to ready queue [Q F]
time 18396ms: Process F started using the CPU for 101ms burst [Q empty]
time 18441ms: Process H completed I/O; added to ready queue [Q H]
time 18456ms: Process G completed I/O; added to ready queue [Q HG]
time 18497ms: Process F completed a CPU burst; 7 bursts to go [Q HG]
time 18497ms: Process F switching out of CPU; will block on I/O until time 19399ms [Q HG]
time 18501ms: Process H started using the CPU for 189ms burst [Q G]
time 18690ms: Process H completed a CPU burst; 59 bursts to go [Q G]
time 18690ms: Process H switching out of CPU; will block on I/O until time 19172ms [Q G]
time 18694ms: Process G started using the CPU for 47ms burst [Q empty]
time 18741ms: Process G completed a CPU burst; 60 bursts to go [Q empty]
time 18741ms: Process G switching out of CPU; will block on I/O until time 19503ms [Q empty]
time 18998ms: Process E completed I/O; added to ready queue [Q E]
time 19000ms: Process E started using the CPU for 18ms burst [Q empty]
time 19018ms: Process E completed a CPU burst; 32 bursts to go [Q empty]
time 19018ms: Process E switching out of CPU; will block on I/O until time 19460ms [Q empty]
time 19172ms: Process H completed I/O; added to ready queue [Q H]
time 19174ms: Process H started using the CPU for 134ms burst [Q empty]
time 19308ms: Process H completed a CPU burst; 58 bursts to go [Q empty]
time 19308ms: Process H switching out of CPU; will block on I/O until time 19640ms [Q empty]
time 19399ms: Process F completed I/O; added to ready queue [Q F]
time 19401ms: Process F started using the CPU for 2ms burst [Q empty]
time 19403ms: Process F completed a CPU burst; 6 bursts to go [Q empty]
time 19403ms: Process F switching out of CPU; will block on I/O until time 21515ms [Q empty]
time 19460ms: Process E completed I/O; added to ready queue [Q E]
time 19462ms: Process E started using the CPU for 215ms burst [Q empty]
time 19503ms: Process G completed I/O; added to ready queue [Q G]
time 19640ms: Process H completed I/O; added to ready queue [Q GH]
time 19677ms: Process E completed a CPU burst; 31 bursts to go [Q GH]
time 19677ms: Process E switching out of CPU; will block on I/O until time 19769ms [Q GH]
time 19681ms: Process G started using the CPU for 82ms burst [Q H]
time 19763ms: Process G completed a CPU burst; 59 bursts to go [Q H]
time 19763ms: Process G switching out of CPU; will block on I/O until time 19795ms [Q H]
time 19767ms: Process H started using the CPU for 25ms burst [Q empty]
time 19769ms: Process E completed I/O; added to ready queue [Q E]
time 19792ms: Process H completed a CPU burst; 57 bursts to go [Q E]
time 19792ms: Process H switching out of CPU; will block on I/O until time 20604ms [Q E]
time 19795ms: Process G completed I/O; added to ready queue [Q G]
time 19796ms: Process E started using the CPU for 224ms burst [Q G]
time 20020ms: Process E completed a CPU burst; 30 bursts to go [Q G]
time 20020ms: Process E switching out of CPU; will block on I/O until time 21102ms [Q G]
time 20024ms: Process G started using the CPU for 57ms burst [Q empty]
time 20081ms: Process G completed a CPU burst; 58 bursts to go [Q empty]
time 20081ms: Process G switching out of CPU; will block on I/O until time 20293ms [Q empty]
time 20293ms: Process G completed I/O; added to ready queue [Q G]
time 20295ms: Process G started using the CPU for 89ms burst [Q empty]
time 20384ms: Process G completed a CPU burst; 57 bursts to go [Q empty]
time 20384ms: Process G switching out of CPU; will block on I/O until time 21306ms [Q empty]
time 20604ms: Process H completed I/O; added to ready queue [Q H]
time 20606ms: Process H started using the CPU for 235ms burst [Q empty]
time 20841ms: Process H completed a CPU burst; 56 bursts to go [Q empty]
time 20841ms: Process H switching out of CPU; will block on I/O until time 22363ms [Q empty]
time 21102ms: Process E completed I/O; added to ready queue [Q E]
time 21104ms: Process E started using the CPU for 1ms burst [Q empty]
time 21105ms: Process E completed a CPU burst; 29 bursts to go [Q empty]
time 21105ms: Process E switching out of CPU; will block on I/O until time 21767ms [Q empty]
time 21306ms: Process G completed I/O; added to ready queue [Q G]
time 21308ms: Process G started using the CPU for 3ms burst [Q empty]
time 21311ms: Process G completed a CPU burst; 56 bursts to go [Q empty]
time 21311ms: Process G switching out of CPU; will block on I/O until time 22673ms [Q empty]
time 21515ms: Process F completed I/O; added to ready queue [Q F]
time 21517ms: Process F started using the CPU for 170ms burst [Q empty]
time 21687ms: Process F completed a CPU burst; 5 bursts to go [Q empty]
time 21687ms: Process F switching out of CPU; will block on I/O until time 22269ms [Q empty]
time 21767ms: Process E completed I/O; added to ready queue [Q E]
time 21769ms: Process E started using the CPU for 168ms burst [Q empty]
time 21937ms: Process E completed a CPU burst; 28 bursts to go [Q empty]
time 21937ms: Process E switching out of CPU; will block on I/O until time 23119ms [Q empty]
time 22269ms: Process F completed I/O; added to ready queue [Q F]
time 22271ms: Process F started using the CPU for 154ms burst [Q empty]
time 22363ms: Process H completed I/O; added to ready queue [Q H]
time 22425ms: Process F completed a CPU burst; 4 bursts to go [Q H]
time 22425ms: Process F switching out of CPU; will block on I/O until time 22787ms [Q H]
time 22429ms: Process H started using the CPU for 105ms burst [Q empty]
time 22534ms: Process H completed a CPU burst; 55 bursts to go [Q empty]
time 22534ms: Process H switching out of CPU; will block on I/O until time 23276ms [Q empty]
time 22673ms: Process G completed I/O; added to ready queue [Q G]
time 22675ms: Process G started using the CPU for 11ms burst [Q empty]
time 22686ms: Process G completed a CPU burst; 55 bursts to go [Q empty]
time 22686ms: Process G switching out of CPU; will block on I/O until time 25138ms [Q empty]
time 22787ms: Process F completed I/O; added to ready queue [Q F]
time 22789ms: Process F started using the CPU for 55ms burst [Q empty]
time 22844ms: Process F completed a CPU burst; 3 bursts to go [Q empty]
time 22844ms: Process F switching out of CPU; will block on I/O until time 24096ms [Q empty]
time 23119ms: Process E completed I/O; added to ready queue [Q E]
time 23121ms: Process E started using the CPU for 10ms burst [Q empty]
time 23131ms: Process E completed a CPU burst; 27 bursts to go [Q empty]
time 23131ms: Process E switching out of CPU; will block on I/O until time 23603ms [Q empty]
time 23276ms: Process H completed I/O; added to ready queue [Q H]
time 23278ms: Process H started using the CPU for 75ms burst [Q empty]
time 23353ms: Process H completed a CPU burst; 54 bursts to go [Q empty]
time 23353ms: Process H switching out of CPU; will block on I/O until time 24035ms [Q empty]
time 23603ms: Process E completed I/O; added to ready queue [Q E]
time 23605ms: Process E started using the CPU for 68ms burst [Q empty]
time 23673ms: Process E completed a CPU burst; 26 bursts to go [Q empty]
time 23673ms: Process E switching out of CPU; will block on I/O until time 24225ms [Q empty]
time 24035ms: Process H completed I/O; added to ready queue [Q H]
time 24037ms: Process H started using the CPU for 141ms burst [Q empty]
time 24096ms: Process F completed I/O; added to ready queue [Q F]
time 24178ms: Process H completed a CPU burst; 53 bursts to go [Q F]
time 24178ms: Process H switching out of CPU; will block on I/O until time 24260ms [Q F]
time 24182ms: Process F started using the CPU for 234ms burst [Q empty]
time 24225ms: Process E completed I/O; added to ready queue [Q E]
time 24260ms: Process H completed I/O; added to ready queue [Q EH]
time 24416ms: Process F completed a CPU burst; 2 bursts to go [Q EH]
time 24416ms: Process F switching out of CPU; will block on I/O until time 24688ms [Q EH]
time 24420ms: Process E started using the CPU for 30ms burst [Q H]
time 24450ms: Process E completed a CPU burst; 25 bursts to go [Q H]
time 24450ms: Process E switching out of CPU; will block on I/O until time 25422ms [Q H]
time 24454ms: Process H started using the CPU for 63ms burst [Q empty]
time 24517ms: Process H completed a CPU burst; 52 bursts to go [Q empty]
time 24517ms: Process H switching out of CPU; will block on I/O until time 25229ms [Q empty]
time 24688ms: Process F completed I/O; added to ready queue [Q F]
time 24690ms: Process F started using the CPU for 122ms burst [Q empty]
time 24812ms: Process F completed a CPU burst; 1 burst to go [Q empty]
time 24812ms: Process F switching out of CPU; will block on I/O until time 25544ms [Q empty]
time 25138ms: Process G completed I/O; added to ready queue [Q G]
time 25140ms: Process G started using the CPU for 17ms burst [Q empty]
time 25157ms: Process G completed a CPU burst; 54 bursts to go [Q empty]
time 25157ms: Process G switching out of CPU; will block on I/O until time 25809ms [Q empty]
time 25229ms: Process H completed I/O; added to ready queue [Q H]
time 25231ms: Process H started using the CPU for 93ms burst [Q empty]
time 25324ms: Process H completed a CPU burst; 51 bursts to go [Q empty]
time 25324ms: Process H switching out of CPU; will block on I/O until time 25966ms [Q empty]
time 25422ms: Process E completed I/O; added to ready queue [Q E]
time 25424ms: Process E started using the CPU for 54ms burst [Q empty]
time 25478ms: Process E completed a CPU burst; 24 bursts to go [Q empty]
time 25478ms: Process E switching out of CPU; will block on I/O until time 27710ms [Q empty]
time 25544ms: Process F completed I/O; added to ready queue [Q F]
time 25546ms: Process F started using the CPU for 55ms burst [Q empty]
time 25601ms: Process F terminated [Q empty]
time 25809ms: Process G completed I/O; added to ready queue [Q G]
time 25811ms: Process G started using the CPU for 55ms burst [Q empty]
time 25866ms: Process G completed a CPU burst; 53 bursts to go [Q empty]
time 25866ms: Process G switching out of CPU; will block on I/O until time 27908ms [Q empty]
time 25966ms: Process H completed I/O; added to ready queue [Q H]
time 25968ms: Process H started using the CPU for 37ms burst [Q empty]
time 26005ms: Process H completed a CPU burst; 50 bursts to go [Q empty]
time 26005ms: Process H switching out of CPU; will block on I/O until time 26177ms [Q empty]
time 26177ms: Process H completed I/O; added to ready queue [Q H]
time 26179ms: Process H started using the CPU for 20ms burst [Q empty]
time 26199ms: Process H completed a CPU burst; 49 bursts to go [Q empty]
time 26199ms: Process H switching out of CPU; will block on I/O until time 26221ms [Q empty]
time 26221ms: Process H completed I/O; added to ready queue [Q H]
time 26223ms: Process H started using the CPU for 148ms burst [Q empty]
time 26371ms: Process H completed a CPU burst; 48 bursts to go [Q empty]
time 26371ms: Process H switching out of CPU; will block on I/O until time 26583ms [Q empty]
time 26583ms: Process H completed I/O; added to ready queue [Q H]
time 26585ms: Process H started using the CPU for 141ms burst [Q empty]
time 26726ms: Process H completed a CPU burst; 47 bursts to go [Q empty]
time 26726ms: Process H switching out of CPU; will block on I/O until time 26948ms [Q empty]
time 26948ms: Process H completed I/O; added to ready queue [Q H]
time 26950ms: Process H started using the CPU for 86ms burst [Q empty]
time 27036ms: Process H completed a CPU burst; 46 bursts to go [Q empty]
time 27036ms: Process H switching out of CPU; will block on I/O until time 27758ms [Q empty]
time 27710ms: Process E completed I/O; added to ready queue [Q E]
time 27712ms: Process E started using the CPU for 46ms burst [Q empty]
time 27758ms: Process E completed a CPU burst; 23 bursts to go [Q empty]
time 27758ms: Process E switching out of CPU; will block on I/O until time 29080ms [Q empty]
time 27758ms: Process H completed I/O; added to ready queue [Q H]
time 27760ms: Process H started using the CPU for 192ms burst [Q empty]
time 27908ms: Process G completed I/O; added to ready queue [Q G]
time 27952ms: Process H completed a CPU burst; 45 bursts to go [Q G]
time 27952ms: Process H switching out of CPU; will block on I/O until time 28084ms [Q G]
time 27956ms: Process G started using the CPU for 52ms burst [Q empty]
time 28008ms: Process G completed a CPU burst; 52 bursts to go [Q empty]
time 28008ms: Process G switching out of CPU; will block on I/O until time 28970ms [Q empty]
time 28084ms: Process H completed I/O; added to ready queue [Q H]
time 28086ms: Process H started using the CPU for 109ms burst [Q empty]
time 28195ms: Process H completed a CPU burst; 44 bursts to go [Q empty]
time 28195ms: Process H switching out of CPU; will block on I/O until time 28637ms [Q empty]
time 28637ms: Process H completed I/O; added to ready queue [Q H]
time 28639ms: Process H started using the CPU for 95ms burst [Q empty]
time 28734ms: Process H completed a CPU burst; 43 bursts to go [Q empty]
time 28734ms: Process H switching out of CPU; will block on I/O until time 29016ms [Q empty]
time 28970ms: Process G completed I/O; added to ready queue [Q G]
time 28972ms: Process G started using the CPU for 199ms burst [Q empty]
time 29016ms: Process H completed I/O; added to ready queue [Q H]
time 29080ms: Process E completed I/O; added to ready queue [Q HE]
time 29171ms: Process G completed a CPU burst; 51 bursts to go [Q HE]
time 29171ms: Process G switching out of CPU; will block on I/O until time 29273ms [Q HE]
time 29175ms: Process H started using the CPU for 30ms burst [Q E]
time 29205ms: Process H completed a CPU burst; 42 bursts to go [Q E]
time 29205ms: Process H switching out of CPU; will block on I/O until time 29397ms [Q E]
time 29209ms: Process E started using the CPU for 163ms burst [Q empty]
time 29273ms: Process G completed I/O; added to ready queue [Q G]
time 29372ms: Process E completed a CPU burst; 22 bursts to go [Q G]
time 29372ms: Process E switching out of CPU; will block on I/O until time 29744ms [Q G]
time 29376ms: Process G started using the CPU for 35ms burst [Q empty]
time 29397ms: Process H completed I/O; added to ready queue [Q H]
time 29411ms: Process G completed a CPU burst; 50 bursts to go [Q H]
time 29411ms: Process G switching out of CPU; will block on I/O until time 30123ms [Q H]
time 29415ms: Process H started using the CPU for 21ms burst [Q empty]
time 29436ms: Process H completed a CPU burst; 41 bursts to go [Q empty]
time 29436ms: Process H switching out of CPU; will block on I/O until time 29458ms [Q empty]
time 29458ms: Process H completed I/O; added to ready queue [Q H]
time 29460ms: Process H started using the CPU for 71ms burst [Q empty]
time 29531ms: Process H completed a CPU burst; 40 bursts to go [Q empty]
time 29531ms: Process H switching out of CPU; will block on I/O until time 29793ms [Q empty]
time 29744ms: Process E completed I/O; added to ready queue [Q E]
time 29746ms: Process E started using the CPU for 106ms burst [Q empty]
time 29793ms: Process H completed I/O; added to ready queue [Q H]
time 29852ms: Process E completed a CPU burst; 21 bursts to go [Q H]
time 29852ms: Process E switching out of CPU; will block on I/O until time 29874ms [Q H]
time 29856ms: Process H started using the CPU for 27ms burst [Q empty]
time 29874ms: Process E completed I/O; added to ready queue [Q E]
time 29883ms: Process H completed a CPU burst; 39 bursts to go [Q E]
time 29883ms: Process H switching out of CPU; will block on I/O until time 30375ms [Q E]
time 29887ms: Process E started using the CPU for 86ms burst [Q empty]
time 29973ms: Process E completed a CPU burst; 20 bursts to go [Q empty]
time 29973ms: Process E switching out of CPU; will block on I/O until time 30995ms [Q empty]
time 30123ms: Process G completed I/O; added to ready queue [Q G]
time 30125ms: Process G started using the CPU for 44ms burst [Q empty]
time 30169ms: Process G completed a CPU burst; 49 bursts to go [Q empty]
time 30169ms: Process G switching out of CPU; will block on I/O until time 30411ms [Q empty]
time 30375ms: Process H completed I/O; added to ready queue [Q H]
time 30377ms: Process H started using the CPU for 17ms burst [Q empty]
time 30394ms: Process H completed a CPU burst; 38 bursts to go [Q empty]
time 30394ms: Process H switching out of CPU; will block on I/O until time 32246ms [Q empty]
time 30411ms: Process G completed I/O; added to ready queue [Q G]
time 30413ms: Process G started using the CPU for 27ms burst [Q empty]
time 30440ms: Process G completed a CPU burst; 48 bursts to go [Q empty]
time 30440ms: Process G switching out of CPU; will block on I/O until time 31672ms [Q empty]
time 30995ms: Process E completed I/O; added to ready queue [Q E]
time 30997ms: Process E started using the CPU for 123ms burst [Q empty]
time 31120ms: Process E completed a CPU burst; 19 bursts to go [Q empty]
time 31120ms: Process E switching out of CPU; will block on I/O until time 31242ms [Q empty]
time 31242ms: Process E completed I/O; added to ready queue [Q E]
time 31244ms: Process E started using the CPU for 7ms burst [Q empty]
time 31251ms: Process E completed a CPU burst; 18 bursts to go [Q empty]
time 31251ms: Process E switching out of CPU; will block on I/O until time 33233ms [Q empty]
time 31672ms: Process G completed I/O; added to ready queue [Q G]
time 31674ms: Process G started using the CPU for 171ms burst [Q empty]
time 31845ms: Process G completed a CPU burst; 47 bursts to go [Q empty]
time 31845ms: Process G switching out of CPU; will block on I/O until time 32137ms [Q empty]
time 32137ms: Process G completed I/O; added to ready queue [Q G]
time 32139ms: Process G started using the CPU for 3ms burst [Q empty]
time 32142ms: Process G completed a CPU burst; 46 bursts to go [Q empty]
time 32142ms: Process G switching out of CPU; will block on I/O until time 33444ms [Q empty]
time 32246ms: Process H completed I/O; added to ready queue [Q H]
time 32248ms: Process H started using the CPU for 34ms burst [Q empty]
time 32282ms: Process H completed a CPU burst; 37 bursts to go [Q empty]
time 32282ms: Process H switching out of CPU; will block on I/O until time 33094ms [Q empty]
time 33094ms: Process H completed I/O; added to ready queue [Q H]
time 33096ms: Process H started using the CPU for 45ms burst [Q empty]
time 33141ms: Process H completed a CPU burst; 36 bursts to go [Q empty]
time 33141ms: Process H switching out of CPU; will block on I/O until time 35263ms [Q empty]
time 33233ms: Process E completed I/O; added to ready queue [Q E]
time 33235ms: Process E started using the CPU for 113ms burst [Q empty]
time 33348ms: Process E completed a CPU burst; 17 bursts to go [Q empty]
time 33348ms: Process E switching out of CPU; will block on I/O until time 34520ms [Q empty]
time 33444ms: Process G completed I/O; added to ready queue [Q G]
time 33446ms: Process G started using the CPU for 107ms burst [Q empty]
time 33553ms: Process G completed a CPU burst; 45 bursts to go [Q empty]
time 33553ms: Process G switching out of CPU; will block on I/O until time 33725ms [Q empty]
time 33725ms: Process G completed I/O; added to ready queue [Q G]
time 33727ms: Process G started using the CPU for 111ms burst [Q empty]
time 33838ms: Process G completed a CPU burst; 44 bursts to go [Q empty]
time 33838ms: Process G switching out of CPU; will block on I/O until time 34150ms [Q empty]
time 34150ms: Process G completed I/O; added to ready queue [Q G]
time 34152ms: Process G started using the CPU for 11ms burst [Q empty]
time 34163ms: Process G completed a CPU burst; 43 bursts to go [Q empty]
time 34163ms: Process G switching out of CPU; will block on I/O until time 34945ms [Q empty]
time 34520ms: Process E completed I/O; added to ready queue [Q E]
time 34522ms: Process E started using the CPU for 104ms burst [Q empty]
time 34626ms: Process E completed a CPU burst; 16 bursts to go [Q empty]
time 34626ms: Process E switching out of CPU; will block on I/O until time 35688ms [Q empty]
time 34945ms: Process G completed I/O; added to ready queue [Q G]
time 34947ms: Process G started using the CPU for 28ms burst [Q empty]
time 34975ms: Process G completed a CPU burst; 42 bursts to go [Q empty]
time 34975ms: Process G switching out of CPU; will block on I/O until time 35037ms [Q empty]
time 35037ms: Process G completed I/O; added to ready queue [Q G]
time 35039ms: Process G started using the CPU for 137ms burst [Q empty]
time 35176ms: Process G completed a CPU burst; 41 bursts to go [Q empty]
time 35176ms: Process G switching out of CPU; will block on I/O until time 35728ms [Q empty]
time 35263ms: Process H completed I/O; added to ready queue [Q H]
time 35265ms: Process H started using the CPU for 57ms burst [Q empty]
time 35322ms: Process H completed a CPU burst; 35 bursts to go [Q empty]
time 35322ms: Process H switching out of CPU; will block on I/O until time 35994ms [Q empty]
time 35688ms: Process E completed I/O; added to ready queue [Q E]
time 35690ms: Process E started using the CPU for 28ms burst [Q empty]
time 35718ms: Process E completed a CPU burst; 15 bursts to go [Q empty]
time 35718ms: Process E switching out of CPU; will block on I/O until time 35920ms [Q empty]
time 35728ms: Process G completed I/O; added to ready queue [Q G]
time 35730ms: Process G started using the CPU for 124ms burst [Q empty]
time 35854ms: Process G completed a CPU burst; 40 bursts to go [Q empty]
time 35854ms: Process G switching out of CPU; will block on I/O until time 36606ms [Q empty]
time 35920ms: Process E completed I/O; added to ready queue [Q E]
time 35922ms: Process E started using the CPU for 114ms burst [Q empty]
time 35994ms: Process H completed I/O; added to ready queue [Q H]
time 36036ms: Process E completed a CPU burst; 14 bursts to go [Q H]
time 36036ms: Process E switching out of CPU; will block on I/O until time 36228ms [Q H]
time 36040ms: Process H started using the CPU for 100ms burst [Q empty]
time 36140ms: Process H completed a CPU burst; 34 bursts to go [Q empty]
time 36140ms: Process H switching out of CPU; will block on I/O until time 36512ms [Q empty]
time 36228ms: Process E completed I/O; added to ready queue [Q E]
time 36230ms: Process E started using the CPU for 241ms burst [Q empty]
time 36471ms: Process E completed a CPU burst; 13 bursts to go [Q empty]
time 36471ms: Process E switching out of CPU; will block on I/O until time 36603ms [Q empty]
time 36512ms: Process H completed I/O; added to ready queue [Q H]
time 36514ms: Process H started using the CPU for 51ms burst [Q empty]
time 36565ms: Process H completed a CPU burst; 33 bursts to go [Q empty]
time 36565ms: Process H switching out of CPU; will block on I/O until time 36627ms [Q empty]
time 36603ms: Process E completed I/O; added to ready queue [Q E]
time 36605ms: Process E started using the CPU for 10ms burst [Q empty]
time 36606ms: Process G completed I/O; added to ready queue [Q G]
time 36615ms: Process E completed a CPU burst; 12 bursts to go [Q G]
time 36615ms: Process E switching out of CPU; will block on I/O until time 36877ms [Q G]
time 36619ms: Process G started using the CPU for 108ms burst [Q empty]
time 36627ms: Process H completed I/O; added to ready queue [Q H]
time 36727ms: Process G completed a CPU burst; 39 bursts to go [Q H]
time 36727ms: Process G switching out of CPU; will block on I/O until time 37899ms [Q H]
time 36731ms: Process H started using the CPU for 138ms burst [Q empty]
time 36869ms: Process H completed a CPU burst; 32 bursts to go [Q empty]
time 36869ms: Process H switching out of CPU; will block on I/O until time 36991ms [Q empty]
time 36877ms: Process E completed I/O; added to ready queue [Q E]
time 36879ms: Process E started using the CPU for 106ms burst [Q empty]
time 36985ms: Process E completed a CPU burst; 11 bursts to go [Q empty]
time 36985ms: Process E switching out of CPU; will block on I/O until time 38377ms [Q empty]
time 36991ms: Process H completed I/O; added to ready queue [Q H]
time 36993ms: Process H started using the CPU for 63ms burst [Q empty]
time 37056ms: Process H completed a CPU burst; 31 bursts to go [Q empty]
time 37056ms: Process H switching out of CPU; will block on I/O until time 37448ms [Q empty]
time 37448ms: Process H completed I/O; added to ready queue [Q H]
time 37450ms: Process H started using the CPU for 126ms burst [Q empty]
time 37576ms: Process H completed a CPU burst; 30 bursts to go [Q empty]
time 37576ms: Process H switching out of CPU; will block on I/O until time 37918ms [Q empty]
time 37899ms: Process G completed I/O; added to ready queue [Q G]
time 37901ms: Process G started using the CPU for 110ms burst [Q empty]
time 37918ms: Process H completed I/O; added to ready queue [Q H]
time 38011ms: Process G completed a CPU burst; 38 bursts to go [Q H]
time 38011ms: Process G switching out of CPU; will block on I/O until time 39583ms [Q H]
time 38015ms: Process H started using the CPU for 52ms burst [Q empty]
time 38067ms: Process H completed a CPU burst; 29 bursts to go [Q empty]
time 38067ms: Process H switching out of CPU; will block on I/O until time 39739ms [Q empty]
time 38377ms: Process E completed I/O; added to ready queue [Q E]
time 38379ms: Process E started using the CPU for 14ms burst [Q empty]
time 38393ms: Process E completed a CPU burst; 10 bursts to go [Q empty]
time 38393ms: Process E switching out of CPU; will block on I/O until time 38695ms [Q empty]
time 38695ms: Process E completed I/O; added to ready queue [Q E]
time 38697ms: Process E started using the CPU for 244ms burst [Q empty]
time 38941ms: Process E completed a CPU burst; 9 bursts to go [Q empty]
time 38941ms: Process E switching out of CPU; will block on I/O until time 39643ms [Q empty]
time 39583ms: Process G completed I/O; added to ready queue [Q G]
time 39585ms: Process G started using the CPU for 77ms burst [Q empty]
time 39643ms: Process E completed I/O; added to ready queue [Q E]
time 39662ms: Process G completed a CPU burst; 37 bursts to go [Q E]
time 39662ms: Process G switching out of CPU; will block on I/O until time 39884ms [Q E]
time 39666ms: Process E started using the CPU for 102ms burst [Q empty]
time 39739ms: Process H completed I/O; added to ready queue [Q H]
time 39768ms: Process E completed a CPU burst; 8 bursts to go [Q H]
time 39768ms: Process E switching out of CPU; will block on I/O until time 40090ms [Q H]
time 39772ms: Process H started using the CPU for 88ms burst [Q empty]
time 39860ms: Process H completed a CPU burst; 28 bursts to go [Q empty]
time 39860ms: Process H switching out of CPU; will block on I/O until time 39902ms [Q empty]
time 39884ms: Process G completed I/O; added to ready queue [Q G]
time 39886ms: Process G started using the CPU for 187ms burst [Q empty]
time 39902ms: Process H completed I/O; added to ready queue [Q H]
time 40073ms: Process G completed a CPU burst; 36 bursts to go [Q H]
time 40073ms: Process G switching out of CPU; will block on I/O until time 42135ms [Q H]
time 40077ms: Process H started using the CPU for 168ms burst [Q empty]
time 40090ms: Process E completed I/O; added to ready queue [Q E]
time 40245ms: Process H completed a CPU burst; 27 bursts to go [Q E]
time 40245ms: Process H switching out of CPU; will block on I/O until time 40697ms [Q E]
time 40249ms: Process E started using the CPU for 122ms burst [Q empty]
time 40371ms: Process E completed a CPU burst; 7 bursts to go [Q empty]
time 40371ms: Process E switching out of CPU; will block on I/O until time 40623ms [Q empty]
time 40623ms: Process E completed I/O; added to ready queue [Q E]
time 40625ms: Process E started using the CPU for 153ms burst [Q empty]
time 40697ms: Process H completed I/O; added to ready queue [Q H]
time 40778ms: Process E completed a CPU burst; 6 bursts to go [Q H]
time 40778ms: Process E switching out of CPU; will block on I/O until time 41180ms [Q H]
time 40782ms: Process H started using the CPU for 32ms burst [Q empty]
time 40814ms: Process H completed a CPU burst; 26 bursts to go [Q empty]
time 40814ms: Process H switching out of CPU; will block on I/O until time 43226ms [Q empty]
time 41180ms: Process E completed I/O; added to ready queue [Q E]
time 41182ms: Process E started using the CPU for 8ms burst [Q empty]
time 41190ms: Process E completed a CPU burst; 5 bursts to go [Q empty]
time 41190ms: Process E switching out of CPU; will block on I/O until time 41922ms [Q empty]
time 41922ms: Process E completed I/O; added to ready queue [Q E]
time 41924ms: Process E started using the CPU for 5ms burst [Q empty]
time 41929ms: Process E completed a CPU burst; 4 bursts to go [Q empty]
time 41929ms: Process E switching out of CPU; will block on I/O until time 42441ms [Q empty]
time 42135ms: Process G completed I/O; added to ready queue [Q G]
time 42137ms: Process G started using the CPU for 62ms burst [Q empty]
time 42199ms: Process G completed a CPU burst; 35 bursts to go [Q empty]
time 42199ms: Process G switching out of CPU; will block on I/O until time 42421ms [Q empty]
time 42421ms: Process G completed I/O; added to ready queue [Q G]
time 42423ms: Process G started using the CPU for 116ms burst [Q empty]
time 42441ms: Process E completed I/O; added to ready queue [Q E]
time 42539ms: Process G completed a CPU burst; 34 bursts to go [Q E]
time 42539ms: Process G switching out of CPU; will block on I/O until time 43341ms [Q E]
time 42543ms: Process E started using the CPU for 60ms burst [Q empty]
time 42603ms: Process E completed a CPU burst; 3 bursts to go [Q empty]
time 42603ms: Process E switching out of CPU; will block on I/O until time 42875ms [Q empty]
time 42875ms: Process E completed I/O; added to ready queue [Q E]
time 42877ms: Process E started using the CPU for 51ms burst [Q empty]
time 42928ms: Process E completed a CPU burst; 2 bursts to go [Q empty]
time 42928ms: Process E switching out of CPU; will block on I/O until time 43400ms [Q empty]
time 43226ms: Process H completed I/O; added to ready queue [Q H]
time 43228ms: Process H started using the CPU for 61ms burst [Q empty]
time 43289ms: Process H completed a CPU burst; 25 bursts to go [Q empty]
time 43289ms: Process H switching out of CPU; will block on I/O until time 43541ms [Q empty]
time 43341ms: Process G completed I/O; added to ready queue [Q G]
time 43343ms: Process G started using the CPU for 127ms burst [Q empty]
time 43400ms: Process E completed I/O; added to ready queue [Q E]
time 43470ms: Process G completed a CPU burst; 33 bursts to go [Q E]
time 43470ms: Process G switching out of CPU; will block on I/O until time 43932ms [Q E]
time 43474ms: Process E started using the CPU for 39ms burst [Q empty]
time 43513ms: Process E completed a CPU burst; 1 burst to go [Q empty]
time 43513ms: Process E switching out of CPU; will block on I/O until time 43635ms [Q empty]
time 43541ms: Process H completed I/O; added to ready queue [Q H]
time 43543ms: Process H started using the CPU for 207ms burst [Q empty]
time 43635ms: Process E completed I/O; added to ready queue [Q E]
time 43750ms: Process H completed a CPU burst; 24 bursts to go [Q E]
time 43750ms: Process H switching out of CPU; will block on I/O until time 45292ms [Q E]
time 43754ms: Process E started using the CPU for 131ms burst [Q empty]
time 43885ms: Process E terminated [Q empty]
time 43932ms: Process G completed I/O; added to ready queue [Q G]
time 43934ms: Process G started using the CPU for 155ms burst [Q empty]
time 44089ms: Process G completed a CPU burst; 32 bursts to go [Q empty]
time 44089ms: Process G switching out of CPU; will block on I/O until time 44631ms [Q empty]
time 44631ms: Process G completed I/O; added to ready queue [Q G]
time 44633ms: Process G started using the CPU for 6ms burst [Q empty]
time 44639ms: Process G completed a CPU burst; 31 bursts to go [Q empty]
time 44639ms: Process G switching out of CPU; will block on I/O until time 46281ms [Q empty]
time 45292ms: Process H completed I/O; added to ready queue [Q H]
time 45294ms: Process H started using the CPU for 172ms burst [Q empty]
time 45466ms: Process H completed a CPU burst; 23 bursts to go [Q empty]
time 45466ms: Process H switching out of CPU; will block on I/O until time 45688ms [Q empty]
time 45688ms: Process H completed I/O; added to ready queue [Q H]
time 45690ms: Process H started using the CPU for 43ms burst [Q empty]
time 45733ms: Process H completed a CPU burst; 22 bursts to go [Q empty]
time 45733ms: Process H switching out of CPU; will block on I/O until time 46745ms [Q empty]
time 46281ms: Process G completed I/O; added to ready queue [Q G]
time 46283ms: Process G started using the CPU for 15ms burst [Q empty]
time 46298ms: Process G completed a CPU burst; 30 bursts to go [Q empty]
time 46298ms: Process G switching out of CPU; will block on I/O until time 48590ms [Q empty]
time 46745ms: Process H completed I/O; added to ready queue [Q H]
time 46747ms: Process H started using the CPU for 8ms burst [Q empty]
time 46755ms: Process H completed a CPU burst; 21 bursts to go [Q empty]
time 46755ms: Process H switching out of CPU; will block on I/O until time 49247ms [Q empty]
time 48590ms: Process G completed I/O; added to ready queue [Q G]
time 48592ms: Process G started using the CPU for 131ms burst [Q empty]
time 48723ms: Process G completed a CPU burst; 29 bursts to go [Q empty]
time 48723ms: Process G switching out of CPU; will block on I/O until time 48805ms [Q empty]
time 48805ms: Process G completed I/O; added to ready queue [Q G]
time 48807ms: Process G started using the CPU for 17ms burst [Q empty]
time 48824ms: Process G completed a CPU burst; 28 bursts to go [Q empty]
time 48824ms: Process G switching out of CPU; will block on I/O until time 49086ms [Q empty]
time 49086ms: Process G completed I/O; added to ready queue [Q G]
time 49088ms: Process G started using the CPU for 97ms burst [Q empty]
time 49185ms: Process G completed a CPU burst; 27 bursts to go [Q empty]
time 49185ms: Process G switching out of CPU; will block on I/O until time 49427ms [Q empty]
time 49247ms: Process H completed I/O; added to ready queue [Q H]
time 49249ms: Process H started using the CPU for 23ms burst [Q empty]
time 49272ms: Process H completed a CPU burst; 20 bursts to go [Q empty]
time 49272ms: Process H switching out of CPU; will block on I/O until time 50554ms [Q empty]
time 49427ms: Process G completed I/O; added to ready queue [Q G]
time 49429ms: Process G started using the CPU for 66ms burst [Q empty]
time 49495ms: Process G completed a CPU burst; 26 bursts to go [Q empty]
time 49495ms: Process G switching out of CPU; will block on I/O until time 49647ms [Q empty]
time 49647ms: Process G completed I/O; added to ready queue [Q G]
time 49649ms: Process G started using the CPU for 80ms burst [Q empty]
time 49729ms: Process G completed a CPU burst; 25 bursts to go [Q empty]
time 49729ms: Process G switching out of CPU; will block on I/O until time 49741ms [Q empty]
time 49741ms: Process G completed I/O; added to ready queue [Q G]
time 49743ms: Process G started using the CPU for 56ms burst [Q empty]
time 49799ms: Process G completed a CPU burst; 24 bursts to go [Q empty]
time 49799ms: Process G switching out of CPU; will block on I/O until time 50051ms [Q empty]
time 50051ms: Process G completed I/O; added to ready queue [Q G]
time 50053ms: Process G started using the CPU for 3ms burst [Q empty]
time 50056ms: Process G completed a CPU burst; 23 bursts to go [Q empty]
time 50056ms: Process G switching out of CPU; will block on I/O until time 50528ms [Q empty]
time 50528ms: Process G completed I/O; added to ready queue [Q G]
time 50530ms: Process G started using the CPU for 189ms burst [Q empty]
time 50554ms: Process H completed I/O; added to ready queue [Q H]
time 50719ms: Process G completed a CPU burst; 22 bursts to go [Q H]
time 50719ms: Process G switching out of CPU; will block on I/O until time 51561ms [Q H]
time 50723ms: Process H started using the CPU for 86ms burst [Q empty]
time 50809ms: Process H completed a CPU burst; 19 bursts to go [Q empty]
time 50809ms: Process H switching out of CPU; will block on I/O until time 50831ms [Q empty]
time 50831ms: Process H completed I/O; added to ready queue [Q H]
time 50833ms: Process H started using the CPU for 7ms burst [Q empty]
time 50840ms: Process H completed a CPU burst; 18 bursts to go [Q empty]
time 50840ms: Process H switching out of CPU; will block on I/O until time 50982ms [Q empty]
time 50982ms: Process H completed I/O; added to ready queue [Q H]
time 50984ms: Process H started using the CPU for 54ms burst [Q empty]
time 51038ms: Process H completed a CPU burst; 17 bursts to go [Q empty]
time 51038ms: Process H switching out of CPU; will block on I/O until time 51070ms [Q empty]
time 51070ms: Process H completed I/O; added to ready queue [Q H]
time 51072ms: Process H started using the CPU for 62ms burst [Q empty]
time 51134ms: Process H completed a CPU burst; 16 bursts to go [Q empty]
time 51134ms: Process H switching out of CPU; will block on I/O until time 51926ms [Q empty]
time 51561ms: Process G completed I/O; added to ready queue [Q G]
time 51563ms: Process G started using the CPU for 95ms burst [Q empty]
time 51658ms: Process G completed a CPU burst; 21 bursts to go [Q empty]
time 51658ms: Process G switching out of CPU; will block on I/O until time 51920ms [Q empty]
time 51920ms: Process G completed I/O; added to ready queue [Q G]
time 51922ms: Process G started using the CPU for 168ms burst [Q empty]
time 51926ms: Process H completed I/O; added to ready queue [Q H]
time 52090ms: Process G completed a CPU burst; 20 bursts to go [Q H]
time 52090ms: Process G switching out of CPU; will block on I/O until time 53002ms [Q H]
time 52094ms: Process H started using the CPU for 256ms burst [Q empty]
time 52350ms: Process H completed a CPU burst; 15 bursts to go [Q empty]
time 52350ms: Process H switching out of CPU; will block on I/O until time 52462ms [Q empty]
time 52462ms: Process H completed I/O; added to ready queue [Q H]
time 52464ms: Process H started using the CPU for 185ms burst [Q empty]
time 52649ms: Process H completed a CPU burst; 14 bursts to go [Q empty]
time 52649ms: Process H switching out of CPU; will block on I/O until time 52781ms [Q empty]
time 52781ms: Process H completed I/O; added to ready queue [Q H]
time 52783ms: Process H started using the CPU for 192ms burst [Q empty]
time 52975ms: Process H completed a CPU burst; 13 bursts to go [Q empty]
time 52975ms: Process H switching out of CPU; will block on I/O until time 53277ms [Q empty]
time 53002ms: Process G completed I/O; added to ready queue [Q G]
time 53004ms: Process G started using the CPU for 35ms burst [Q empty]
time 53039ms: Process G completed a CPU burst; 19 bursts to go [Q empty]
time 53039ms: Process G switching out of CPU; will block on I/O until time 54701ms [Q empty]
time 53277ms: Process H completed I/O; added to ready queue [Q H]
time 53279ms: Process H started using the CPU for 16ms burst [Q empty]
time 53295ms: Process H completed a CPU burst; 12 bursts to go [Q empty]
time 53295ms: Process H switching out of CPU; will block on I/O until time 54557ms [Q empty]
time 54557ms: Process H completed I/O; added to ready queue [Q H]
time 54559ms: Process H started using the CPU for 15ms burst [Q empty]
time 54574ms: Process H completed a CPU burst; 11 bursts to go [Q empty]
time 54574ms: Process H switching out of CPU; will block on I/O until time 55326ms [Q empty]
time 54701ms: Process G completed I/O; added to ready queue [Q G]
time 54703ms: Process G started using the CPU for 59ms burst [Q empty]
time 54762ms: Process G completed a CPU burst; 18 bursts to go [Q empty]
time 54762ms: Process G switching out of CPU; will block on I/O until time 55434ms [Q empty]
time 55326ms: Process H completed I/O; added to ready queue [Q H]
time 55328ms: Process H started using the CPU for 57ms burst [Q empty]
time 55385ms: Process H completed a CPU burst; 10 bursts to go [Q empty]
time 55385ms: Process H switching out of CPU; will block on I/O until time 56067ms [Q empty]
time 55434ms: Process G completed I/O; added to ready queue [Q G]
time 55436ms: Process G started using the CPU for 191ms burst [Q empty]
time 55627ms: Process G completed a CPU burst; 17 bursts to go [Q empty]
time 55627ms: Process G switching out of CPU; will block on I/O until time 56409ms [Q empty]
time 56067ms: Process H completed I/O; added to ready queue [Q H]
time 56069ms: Process H started using the CPU for 34ms burst [Q empty]
time 56103ms: Process H completed a CPU burst; 9 bursts to go [Q empty]
time 56103ms: Process H switching out of CPU; will block on I/O until time 57125ms [Q empty]
time 56409ms: Process G completed I/O; added to ready queue [Q G]
time 56411ms: Process G started using the CPU for 91ms burst [Q empty]
time 56502ms: Process G completed a CPU burst; 16 bursts to go [Q empty]
time 56502ms: Process G switching out of CPU; will block on I/O until time 56884ms [Q empty]
time 56884ms: Process G completed I/O; added to ready queue [Q G]
time 56886ms: Process G started using the CPU for 250ms burst [Q empty]
time 57125ms: Process H completed I/O; added to ready queue [Q H]
time 57136ms: Process G completed a CPU burst; 15 bursts to go [Q H]
time 57136ms: Process G switching out of CPU; will block on I/O until time 57248ms [Q H]
time 57140ms: Process H started using the CPU for 43ms burst [Q empty]
time 57183ms: Process H completed a CPU burst; 8 bursts to go [Q empty]
time 57183ms: Process H switching out of CPU; will block on I/O until time 58075ms [Q empty]
time 57248ms: Process G completed I/O; added to ready queue [Q G]
time 57250ms: Process G started using the CPU for 120ms burst [Q empty]
time 57370ms: Process G completed a CPU burst; 14 bursts to go [Q empty]
time 57370ms: Process G switching out of CPU; will block on I/O until time 58572ms [Q empty]
time 58075ms: Process H completed I/O; added to ready queue [Q H]
time 58077ms: Process H started using the CPU for 1ms burst [Q empty]
time 58078ms: Process H completed a CPU burst; 7 bursts to go [Q empty]
time 58078ms: Process H switching out of CPU; will block on I/O until time 58230ms [Q empty]
time 58230ms: Process H completed I/O; added to ready queue [Q H]
time 58232ms: Process H started using the CPU for 23ms burst [Q empty]
time 58255ms: Process H completed a CPU burst; 6 bursts to go [Q empty]
time 58255ms: Process H switching out of CPU; will block on I/O until time 58797ms [Q empty]
time 58572ms: Process G completed I/O; added to ready queue [Q G]
time 58574ms: Process G started using the CPU for 62ms burst [Q empty]
time 58636ms: Process G completed a CPU burst; 13 bursts to go [Q empty]
time 58636ms: Process G switching out of CPU; will block on I/O until time 59688ms [Q empty]
time 58797ms: Process H completed I/O; added to ready queue [Q H]
time 58799ms: Process H started using the CPU for 37ms burst [Q empty]
time 58836ms: Process H completed a CPU burst; 5 bursts to go [Q empty]
time 58836ms: Process H switching out of CPU; will block on I/O until time 60178ms [Q empty]
time 59688ms: Process G completed I/O; added to ready queue [Q G]
time 59690ms: Process G started using the CPU for 40ms burst [Q empty]
time 59730ms: Process G completed a CPU burst; 12 bursts to go [Q empty]
time 59730ms: Process G switching out of CPU; will block on I/O until time 60992ms [Q empty]
time 60178ms: Process H completed I/O; added to ready queue [Q H]
time 60180ms: Process H started using the CPU for 96ms burst [Q empty]
time 60276ms: Process H completed a CPU burst; 4 bursts to go [Q empty]
time 60276ms: Process H switching out of CPU; will block on I/O until time 61648ms [Q empty]
time 60992ms: Process G completed I/O; added to ready queue [Q G]
time 60994ms: Process G started using the CPU for 167ms burst [Q empty]
time 61161ms: Process G completed a CPU burst; 11 bursts to go [Q empty]
time 61161ms: Process G switching out of CPU; will block on I/O until time 61903ms [Q empty]
time 61648ms: Process H completed I/O; added to ready queue [Q H]
time 61650ms: Process H started using the CPU for 96ms burst [Q empty]
time 61746ms: Process H completed a CPU burst; 3 bursts to go [Q empty]
time 61746ms: Process H switching out of CPU; will block on I/O until time 62588ms [Q empty]
time 61903ms: Process G completed I/O; added to ready queue [Q G]
time 61905ms: Process G started using the CPU for 45ms burst [Q empty]
time 61950ms: Process G completed a CPU burst; 10 bursts to go [Q empty]
time 61950ms: Process G switching out of CPU; will block on I/O until time 62892ms [Q empty]
time 62588ms: Process H completed I/O; added to ready queue [Q H]
time 62590ms: Process H started using the CPU for 26ms burst [Q empty]
time 62616ms: Process H completed a CPU burst; 2 bursts to go [Q empty]
time 62616ms: Process H switching out of CPU; will block on I/O until time 63328ms [Q empty]
time 62892ms: Process G completed I/O; added to ready queue [Q G]
time 62894ms: Process G started using the CPU for 96ms burst [Q empty]
time 62990ms: Process G completed a CPU burst; 9 bursts to go [Q empty]
time 62990ms: Process G switching out of CPU; will block on I/O until time 64822ms [Q empty]
time 63328ms: Process H completed I/O; added to ready queue [Q H]
time 63330ms: Process H started using the CPU for 52ms burst [Q empty]
time 63382ms: Process H completed a CPU burst; 1 burst to go [Q empty]
time 63382ms: Process H switching out of CPU; will block on I/O until time 64824ms [Q empty]
time 64822ms: Process G completed I/O; added to ready queue [Q G]
time 64824ms: Process G started using the CPU for 37ms burst [Q empty]
time 64824ms: Process H completed I/O; added to ready queue [Q H]
time 64861ms: Process G completed a CPU burst; 8 bursts to go [Q H]
time 64861ms: Process G switching out of CPU; will block on I/O until time 65453ms [Q H]
time 64865ms: Process H started using the CPU for 93ms burst [Q empty]
time 64958ms: Process H terminated [Q empty]
time 65453ms: Process G completed I/O; added to ready queue [Q G]
time 65455ms: Process G started using the CPU for 213ms burst [Q empty]
time 65668ms: Process G completed a CPU burst; 7 bursts to go [Q empty]
time 65668ms: Process G switching out of CPU; will block on I/O until time 65820ms [Q empty]
time 65820ms: Process G completed I/O; added to ready queue [Q G]
time 65822ms: Process G started using the CPU for 24ms burst [Q empty]
time 65846ms: Process G completed a CPU burst; 6 bursts to go [Q empty]
time 65846ms: Process G switching out of CPU; will block on I/O until time 66468ms [Q empty]
time 66468ms: Process G completed I/O; added to ready queue [Q G]
time 66470ms: Process G started using the CPU for 80ms burst [Q empty]
time 66550ms: Process G completed a CPU burst; 5 bursts to go [Q empty]
time 66550ms: Process G switching out of CPU; will block on I/O until time 67382ms [Q empty]
time 67382ms: Process G completed I/O; added to ready queue [Q G]
time 67384ms: Process G started using the CPU for 33ms burst [Q empty]
time 67417ms: Process G completed a CPU burst; 4 bursts to go [Q empty]
time 67417ms: Process G switching out of CPU; will block on I/O until time 69069ms [Q empty]
time 69069ms: Process G completed I/O; added to ready queue [Q G]
time 69071ms: Process G started using the CPU for 75ms burst [Q empty]
time 69146ms: Process G completed a CPU burst; 3 bursts to go [Q empty]
time 69146ms: Process G switching out of CPU; will block on I/O until time 69218ms [Q empty]
time 69218ms: Process G completed I/O; added to ready queue [Q G]
time 69220ms: Process G started using the CPU for 16ms burst [Q empty]
time 69236ms: Process G completed a CPU burst; 2 bursts to go [Q empty]
time 69236ms: Process G switching out of CPU; will block on I/O until time 70268ms [Q empty]
time 70268ms: Process G completed I/O; added to ready queue [Q G]
time 70270ms: Process G started using the CPU for 178ms burst [Q empty]
time 70448ms: Process G completed a CPU burst; 1 burst to go [Q empty]
time 70448ms: Process G switching out of CPU; will block on I/O until time 70980ms [Q empty]
time 70980ms: Process G completed I/O; added to ready queue [Q G]
time 70982ms: Process G started using the CPU for 41ms burst [Q empty]
time 71023ms: Process G terminated [Q empty]
time 71025ms: Simulator ended for FCFS [Q empty]

time 0ms: Simulator started for SJF [Q empty]
time 9ms: Process A (tau 100ms) arrived; added to ready queue [Q A]
time 11ms: Process A (tau 100ms) started using the CPU for 56ms burst [Q empty]
time 11ms: Process H (tau 100ms) arrived; added to ready queue [Q H]
time 18ms: Process B (tau 100ms) arrived; added to ready queue [Q BH]
time 42ms: Process C (tau 100ms) arrived; added to ready queue [Q BCH]
time 65ms: Process G (tau 100ms) arrived; added to ready queue [Q BCGH]
time 67ms: Process A (tau 100ms) completed a CPU burst; 15 bursts to go [Q BCGH]
time 67ms: Recalculated tau from 100ms to 74ms for process A [Q BCGH]
time 67ms: Process A switching out of CPU; will block on I/O until time 299ms [Q BCGH]
time 71ms: Process B (tau 100ms) started using the CPU for 106ms burst [Q CGH]
time 106ms: Process F (tau 100ms) arrived; added to ready queue [Q CFGH]
time 134ms: Process E (tau 100ms) arrived; added to ready queue [Q CEFGH]
time 156ms: Process D (tau 100ms) arrived; added to ready queue [Q CDEFGH]
time 177ms: Process B (tau 100ms) completed a CPU burst; 20 bursts to go [Q CDEFGH]
time 177ms: Recalculated tau from 100ms to 104ms for process B [Q CDEFGH]
time 177ms: Process B switching out of CPU; will block on I/O until time 1739ms [Q CDEFGH]
time 181ms: Process C (tau 100ms) started using the CPU for 94ms burst [Q DEFGH]
time 275ms: Process C (tau 100ms) completed a CPU burst; 3 bursts to go [Q DEFGH]
time 275ms: Recalculated tau from 100ms to 97ms for process C [Q DEFGH]
time 275ms: Process C switching out of CPU; will block on I/O until time 1857ms [Q DEFGH]
time 279ms: Process D (tau 100ms) started using the CPU for 148ms burst [Q EFGH]
time 299ms: Process A (tau 74ms) completed I/O; added to ready queue [Q AEFGH]
time 427ms: Process D (tau 100ms) completed a CPU burst; 10 bursts to go [Q AEFGH]
time 427ms: Recalculated tau from 100ms to 129ms for process D [Q AEFGH]
time 427ms: Process D switching out of CPU; will block on I/O until time 449ms [Q AEFGH]
time 431ms: Process A (tau 74ms) started using the CPU for 60ms burst [Q EFGH]
time 449ms: Process D (tau 129ms) completed I/O; added to ready queue [Q EFGHD]
time 491ms: Process A (tau 74ms) completed a CPU burst; 14 bursts to go [Q EFGHD]
time 491ms: Recalculated tau from 74ms to 66ms for process A [Q EFGHD]
time 491ms: Process A switching out of CPU; will block on I/O until time 2023ms [Q EFGHD]
time 495ms: Process E (tau 100ms) started using the CPU for 152ms burst [Q FGHD]
time 647ms: Process E (tau 100ms) completed a CPU burst; 54 bursts to go [Q FGHD]
time 647ms: Recalculated tau from 100ms to 132ms for process E [Q FGHD]
time 647ms: Process E switching out of CPU; will block on I/O until time 1109ms [Q FGHD]
time 651ms: Process F (tau 100ms) started using the CPU for 129ms burst [Q GHD]
time 780ms: Process F (tau 100ms) completed a CPU burst; 33 bursts to go [Q GHD]
time 780ms: Recalculated tau from 100ms to 118ms for process F [Q GHD]
time 780ms: Process F switching out of CPU; will block on I/O until time 1352ms [Q GHD]
time 784ms: Process G (tau 100ms) started using the CPU for 70ms burst [Q HD]
time 854ms: Process G (tau 100ms) completed a CPU burst; 79 bursts to go [Q HD]
time 854ms: Recalculated tau from 100ms to 82ms for process G [Q HD]
time 854ms: Process G switching out of CPU; will block on I/O until time 1166ms [Q HD]
time 858ms: Process H (tau 100ms) started using the CPU for 96ms burst [Q D]
time 954ms: Process H (tau 100ms) completed a CPU burst; 82 bursts to go [Q D]
time 954ms: Recalculated tau from 100ms to 98ms for process H [Q D]
time 954ms: Process H switching out of CPU; will block on I/O until time 1626ms [Q D]
time 958ms: Process D (tau 129ms) started using the CPU for 211ms burst [Q empty]
time 1109ms: Process E (tau 132ms) completed I/O; added to ready queue [Q E]
time 1166ms: Process G (tau 82ms) completed I/O; added to ready queue [Q GE]
time 1169ms: Process D (tau 129ms) completed a CPU burst; 9 bursts to go [Q GE]
time 1169ms: Recalculated tau from 129ms to 179ms for process D [Q GE]
time 1169ms: Process D switching out of CPU; will block on I/O until time 3311ms [Q GE]
time 1173ms: Process G (tau 82ms) started using the CPU for 40ms burst [Q E]
time 1213ms: Process G (tau 82ms) completed a CPU burst; 78 bursts to go [Q E]
time 1213ms: Recalculated tau from 82ms to 57ms for process G [Q E]
time 1213ms: Process G switching out of CPU; will block on I/O until time 1275ms [Q E]
time 1217ms: Process E (tau 132ms) started using the CPU for 44ms burst [Q empty]
time 1261ms: Process E (tau 132ms) completed a CPU burst; 53 bursts to go [Q empty]
time 1261ms: Recalculated tau from 132ms to 80ms for process E [Q empty]
time 1261ms: Process E switching out of CPU; will block on I/O until time 1823ms [Q empty]
time 1275ms: Process G (tau 57ms) completed I/O; added to ready queue [Q G]
time 1277ms: Process G (tau 57ms) started using the CPU for 65ms burst [Q empty]
time 1342ms: Process G (tau 57ms) completed a CPU burst; 77 bursts to go [Q empty]
time 1342ms: Recalculated tau from 57ms to 62ms for process G [Q empty]
time 1342ms: Process G switching out of CPU; will block on I/O until time 1784ms [Q empty]
time 1352ms: Process F (tau 118ms) completed I/O; added to ready queue [Q F]
time 1354ms: Process F (tau 118ms) started using the CPU for 39ms burst [Q empty]
time 1393ms: Process F (tau 118ms) completed a CPU burst; 32 bursts to go [Q empty]
time 1393ms: Recalculated tau from 118ms to 71ms for process F [Q empty]
time 1393ms: Process F switching out of CPU; will block on I/O until time 2045ms [Q empty]
time 1626ms: Process H (tau 98ms) completed I/O; added to ready queue [Q H]
time 1628ms: Process H (tau 98ms) started using the CPU for 48ms burst [Q empty]
time 1676ms: Process H (tau 98ms) completed a CPU burst; 81 bursts to go [Q empty]
time 1676ms: Recalculated tau from 98ms to 68ms for process H [Q empty]
time 1676ms: Process H switching out of CPU; will block on I/O until time 1898ms [Q empty]
time 1739ms: Process B (tau 104ms) completed I/O; added to ready queue [Q B]
time 1741ms: Process B (tau 104ms) started using the CPU for 198ms burst [Q empty]
time 1784ms: Process G (tau 62ms) completed I/O; added to ready queue [Q G]
time 1823ms: Process E (tau 80ms) completed I/O; added to ready queue [Q GE]
time 1857ms: Process C (tau 97ms) completed I/O; added to ready queue [Q GEC]
time 1898ms: Process H (tau 68ms) completed I/O; added to ready queue [Q GHEC]
time 1939ms: Process B (tau 104ms) completed a CPU burst; 19 bursts to go [Q GHEC]
time 1939ms: Recalculated tau from 104ms to 161ms for process B [Q GHEC]
time 1939ms: Process B switching out of CPU; will block on I/O until time 3071ms [Q GHEC]
time 1943ms: Process G (tau 62ms) started using the CPU for 13ms burst [Q HEC]
time 1956ms: Process G (tau 62ms) completed a CPU burst; 76 bursts to go [Q HEC]
time 1956ms: Recalculated tau from 62ms to 33ms for process G [Q HEC]
time 1956ms: Process G switching out of CPU; will block on I/O until time 2338ms [Q HEC]
time 1960ms: Process H (tau 68ms) started using the CPU for 72ms burst [Q EC]
time 2023ms: Process A (tau 66ms) completed I/O; added to ready queue [Q AEC]
time 2032ms: Process H (tau 68ms) completed a CPU burst; 80 bursts to go [Q AEC]
time 2032ms: Recalculated tau from 68ms to 71ms for process H [Q AEC]
time 2032ms: Process H switching out of CPU; will block on I/O until time 2454ms [Q AEC]
time 2036ms: Process A (tau 66ms) started using the CPU for 39ms burst [Q EC]
time 2045ms: Process F (tau 71ms) completed I/O; added to ready queue [Q FEC]
time 2075ms: Process A (tau 66ms) completed a CPU burst; 13 bursts to go [Q FEC]
time 2075ms: Recalculated tau from 66ms to 50ms for process A [Q FEC]
time 2075ms: Process A switching out of CPU; will block on I/O until time 2577ms [Q FEC]
time 2079ms: Process F (tau 71ms) started using the CPU for 195ms burst [Q EC]
time 2274ms: Process F (tau 71ms) completed a CPU burst; 31 bursts to go [Q EC]
time 2274ms: Recalculated tau from 71ms to 146ms for process F [Q EC]
time 2274ms: Process F switching out of CPU; will block on I/O until time 2286ms [Q EC]
time 2278ms: Process E (tau 80ms) started using the CPU for 2ms burst [Q C]
time 2280ms: Process E (tau 80ms) completed a CPU burst; 52 bursts to go [Q C]
time 2280ms: Recalculated tau from 80ms to 34ms for process E [Q C]
time 2280ms: Process E switching out of CPU; will block on I/O until time 2532ms [Q C]
time 2284ms: Process C (tau 97ms) started using the CPU for 117ms burst [Q empty]
time 2286ms: Process F (tau 146ms) completed I/O; added to ready queue [Q F]
time 2338ms: Process G (tau 33ms) completed I/O; added to ready queue [Q GF]
time 2401ms: Process C (tau 97ms) completed a CPU burst; 2 bursts to go [Q GF]
time 2401ms: Recalculated tau from 97ms to 109ms for process C [Q GF]
time 2401ms: Process C switching out of CPU; will block on I/O until time 2573ms [Q GF]
time 2405ms: Process G (tau 33ms) started using the CPU for 128ms burst [Q F]
time 2454ms: Process H (tau 71ms) completed I/O; added to ready queue [Q HF]
time 2532ms: Process E (tau 34ms) completed I/O; added to ready queue [Q EHF]
time 2533ms: Process G (tau 33ms) completed a CPU burst; 75 bursts to go [Q EHF]
time 2533ms: Recalculated tau from 33ms to 90ms for process G [Q EHF]
time 2533ms: Process G switching out of CPU; will block on I/O until time 4755ms [Q EHF]
time 2537ms: Process E (tau 34ms) started using the CPU for 42ms burst [Q HF]
time 2573ms: Process C (tau 109ms) completed I/O; added to ready queue [Q HCF]
time 2577ms: Process A (tau 50ms) completed I/O; added to ready queue [Q AHCF]
